{
    "xsize": 16,
    "zsize": 16,
    "slices": [
        [
            "¡¡¡¡¡¡¡¡¡¡¡¡¡¡¡¡",
            "¡¡¡¡¡¡¡¡¡¡¡¡¡¡¡¡",
            "¡¡¼¼¼¼¼¼¼¼¼¼¼¼¡¡",
            "¡¡¼¼¼¼¼¼¼¼¼££££¡",
            "¡¡¼½½½½½½½½££££¡",
            "¡¡¼¼¼¼¼¼¼¼¼££££¡",
            "¡¡¼½½½½½½½½££££¡",
            "¡¡¼¼¼¼¼¼¼¼¼££££¡",
            "¡¡½½½½½½½½½££££¡",
            "¡¡¼¼¼¼¼¼¼¼¼££££¡",
            "¡¡¼½½½½½½½½££££¡",
            "¡¡¼¼¼¼¼¼¼¼¼££¥£¡",
            "¡¡¼½½½½½½½½££££¡",
            "¡¡¼¼¼¼¼¼¼¼¼¼¼¼¡¡",
            "¡¡¡¡¡¡¡¡¡¡¡¡¡¡¡¡",
            "¡¡¡¡¡¡¡¡¡¡¡¡¡¡¡¡"
        ],
        [
            "                ",
            " ¾¾  ¿    ¿  ¾¾ ",
            " ¾ÀÀºÀ»»»»ÀºÀÀ¾Á",
            "  À¨ÂÃÃÃÃÄÅ»»®»¾",
            "  º  Æ  Æ Å£   Ç",
            " ÈÀ        ©   Ç",
            "  »       Å£   Ç",
            "  °   É   Å»»»»¾",
            "  ©       Å»»»»¾",
            "  »   Ê   Å£   Ç",
            " ÈÀ   Ë    °   Ç",
            "  ºÌ  Í   Å£ ¥ Ç",
            "  À³Î  ± ÎÅ»»»»¾",
            " ¾ÀÀºÀ»»»»ÀºÀÀ¾Á",
            " ¾¾  Ï    Ï  ¾¾ ",
            "                "
        ],
        [
            "                ",
            " ¾¾  ¿    ¿  ¾¾ ",
            " ¾ÀÀºÀ»ÇÇ»ÀºÀÀ¾Á",
            "  À       Å»»·»¾",
            "  º       Å£   Ç",
            " ÈÀ        ¶   Ç",
            "  »       Å£   Ç",
            "  ¸       Å»»»»¾",
            "  ¶       Å»»»»¾",
            "  »       Å£   Ç",
            " ÈÀ   Ð    ¸   Ç",
            "  ºÌ      Å£ ¥ Ç",
            "  À Î  Ñ ÎÅ»»»»¾",
            " ¾ÀÀºÀ»»»»ÀºÀÀ¾Á",
            " ¾¾  Ï    Ï  ¾¾ ",
            "                "
        ],
        [
            "                ",
            " ¾¾  ¿    ¿  ¾¾ ",
            " ¾ÀÀºÀ»ÇÇ»ÀºÀÀ¾Á",
            "  À       Å»»»»¾",
            "  º       Å££££Ç",
            " ÈÀ       Å££££Ç",
            "  »       Å££££Ç",
            "  »       Å»»»»¾",
            "  »       Å»»»»¾",
            "  »       Å£   Ç",
            " ÈÀ       Å£   Ç",
            "  ºÌ      Å£ ¥ Ç",
            "  À Î Ñ  ÎÅ»»»»¾",
            " ¾ÀÀºÀ»»»»ÀºÀÀ¾Á",
            " ¾¾  Ï    Ï  ¾¾ ",
            "                "
        ],
        [
            "                ",
            " ¾¾¾¾¾¾¾¾¾¾¾¾¾¾ ",
            " ¾ÀÀºÀ»»»»ÀºÀÀ¾Á",
            " ¾À       Å¤¤¤¤¾",
            " ¾º Ò    ÒÅ¤   Ç",
            " ¾À       Å¤   Ç",
            " ¾À       Å¤   Ç",
            " ¾À       Å¤¤¤¤¾",
            " ¾À       Å¤¤¤¤¾",
            " ¾À       Å¤   Ç",
            " ¾À       Å¤   Ç",
            " ¾ºÌÒ    ÒÅ¤ ¥ Ç",
            " ¾À Î    ÎÅ¤¤¤¤¾",
            " ¾ÀÀºÀ»»»»ÀºÀÀ¾Á",
            " ¾¾¾¾¾¾¾¾¾¾¾¾¾¾ ",
            "                "
        ],
        [
            "                ",
            " ¾¾          ¾¾ ",
            " ¾À¤¤¤¤¤¤¤¤¤¤À¾Á",
            "  ¤ÓÓÓÓÓÓÓÓ»»»»¾",
            "  ¤ÓÓÓÓÓÓÓÓ»   Ç",
            "  ¤ÓÓÓÓÓÓÓÓ»   Ç",
            "  ¤ÓÓÓÓÓÓÓÓ»   Ç",
            "  ¤ÓÓÓÓÓÓÓÓ»»»»¾",
            "  ¤ÓÓÓÓÓÓÓÓ»»»»¾",
            "  ¤ÓÓÓÓÓÓÓÓ»   Ç",
            "  ¤ÓÓÓÓÓÓÓÓ»   Ç",
            "  ¤ÓÓÓÓÓÓÓÓ» ¥ Ç",
            "  ¤ÓÓÓÓÓÓÓÓ»»»»¾",
            " ¾À¤¤¤¤¤¤¤¤¤¤À¾Á",
            " ¾¾          ¾¾ ",
            "                "
        ]
    ],
    "refpalette": "building002_palette"
}