{
    "xsize": 16,
    "zsize": 16,
    "slices": [
        [
            "¡¡¡¡¡ÍÍÐììììÃººº",
            "¡¡¡¡¡ÍÍĝÏÏêì¸ººº",
            "¡¡¡¡¡ÍÍÐ  ëì¸ººº",
            "¡¡¡¡¡ÍÍÐ  ëìÃ¸¸ż",
            "¡¡¡¡¡ÍÍÐ  ëììììì",
            "¡¡¡¡¡ÍÍÐ  œÏÏÏƏì",
            "¡¡¡¡¡ÍÍÐ      ëì",
            "¡¡¡¡¡ÍÍÐ      ëì",
            "¡¡¡¡¡ÍÍƐîîîîîîñî",
            "¡¡¡¡¡ÍÍÍÍÍÍÍÍÍÍÍ",
            "¡¡¡¡¡ÍÍÍÍÍÍÍÍÍÍÍ",
            "¡¡¡¡¡¡¡¡¡¡¡¡¡¡¡¡",
            "¡¡¡¡¡¡¡¡¡¡¡¡¡¡¡¡",
            "¡¡¡¡¡¡¡¡¡¡¡¡¡¡¡¡",
            "¡¡¡¡¡¡¡¡¡¡¡¡¡¡¡¡",
            "¡¡¡¡¡¡¡¡¡¡¡¡¡¡¡¡"
        ],
        [
            "¢Ù  Ú   ¬   Ê¨ Ƒ",
            "¢Û  ¢  Ö××ò Ê¨  ",
            "¢Ü§ ¢  Ø  ó Ê¬ŷÇ",
            "¢Ý  ¢  Ø  ó ÊÊÊÊ",
            "¢¢¢¢¢  Ø  ó     ",
            "¢   ¢  Ø  øôôôò ",
            "¢Ù  Ú  Ø      ó ",
            "¢Û  ¢  Ø      ó ",
            "¢Ü§ ¢  øôôôôôôõ ",
            "¢Ý  ¢ Õ         ",
            "¢¢¢¢¢           ",
            "¢    ¢¢¢¢¢ƅ¢¢¢¢¢",
            "¢       ¢     ¢ ",
            "¢       ¢   § ¢ ",
            "¢       ¢ ƆÇƇƈ¢ ",
            "¢¢¢¢¢¢¢¢¢¢¢¢¢¢¢¢"
        ],
        [
            "¢   ä       Êƒ  ",
            "¢   å       ÊŚ  ",
            "¢   à       Ê   ",
            "¢   à       ÊÊÊÊ",
            "¢ááá¢           ",
            "¢   ¢           ",
            "¢   ä           ",
            "¢   å           ",
            "¢   à           ",
            "¢   à           ",
            "¢¢¢¢¢           ",
            "¢    ¢¢¢¢¢ƍúáá¢¢",
            "¢       ¢     à ",
            "¢       ¢     à ",
            "¢       ¢     à ",
            "¢¢¢¢¢¢¢¢¢¢¢¢¢¢¢¢"
        ],
        [
            "¢   ¢       Ê   ",
            "¢   ¢       Ê   ",
            "¢   à       Ê   ",
            "¢   à       ÊÊÊÊ",
            "¢ááá¢           ",
            "¢   ¢           ",
            "¢   ¢           ",
            "¢   ¢           ",
            "¢   à           ",
            "¢   à           ",
            "¢¢¢¢¢           ",
            "¢    ¢¢¢¢¢¢¢áá¢¢",
            "¢       ¢     à ",
            "¢       ¢     à ",
            "¢       ¢     à ",
            "¢¢¢¢¢¢¢¢¢¢¢¢¢¢¢¢"
        ],
        [
            "¢ËËË¢ËËËËËËË¸ËËË",
            "¢ËËË¢ËËËËËËË¸ËËË",
            "¢ËËË¢ËËËËËËË¸ËËË",
            "¢ËËË¢ËËËËËËË¸¸¸¸",
            "Í¢¢¢¢ËËËËËËËËËËË",
            "¢ËËË¢ËËËËËËËËËËË",
            "¢ËËË¢ËËËËËËËËËËË",
            "¢ËËË¢ËËËËËËËËËËË",
            "¢ËËË¢ËËËËËËËËËËË",
            "¢ËËË¢ËËËËËËËËËËË",
            "Í¢¢¢¢ËËËËËËËËËËË",
            "¢ËËËË¢¢¢¢¢¢¢¢¢¢¢",
            "¢ËËËËËËË¢ËËËËË¢Ë",
            "¢ËËËËËËË¢ËËËËË¢Ë",
            "¢ËËËËËËË¢ËËËËË¢Ë",
            "¢¢¢¢¢¢¢¢¢¢¢¢¢¢Í¢"
        ],
        [
            "¡¡¡¡¡¡¡¡¡¡¡¡¡¡¡¡",
            "¡¡¡¡¡¡¡¡¡¡¡¡¡¡¡¡",
            "¡¡¡¡¡¡¡¡¡¡¡¡¡¡¡¡",
            "¡¡¡¡¡¡¡¡¡¡¡¡¡¡¡¡",
            "¡¡¡¡¡¡¡¡¡¡¡¡¡¡¡¡",
            "¡¡¡¡¡¡¡¡¡¡¡¡¡¡¡¡",
            "¡¡¡¡¡¡¡¡¡¡¡¡¡¡¡¡",
            "¡¡¡¡¡¡¡¡¡¡¡¡¡¡¡¡",
            "¡¡¡¡¡¡¡¡¡¡¡¡¡¡¡¡",
            "¡¡¡¡¡¡¡¡¡¡¡¡¡¡¡¡",
            "¡¡¡¡¡¡¡¡¡¡¡¡¡¡¡¡",
            "¡¡¡¡¡¡¡¡¡¡¡¡¡¡¡¡",
            "¡¡¡¡¡¡¡¡¡¡¡¡¡¡¡¡",
            "¡¡¡¡¡¡¡¡¡¡¡¡¡¡¡¡",
            "¡¡¡¡¡¡¡¡¡¡¡¡¡¡¡¡",
            "¡¡¡¡¡¡¡¡¡¡¡¡¡¡¡¡"
        ]
    ],
    "refpalette": "building004_palette"
}