{
    "xsize": 16,
    "zsize": 16,
    "slices": [
        [
            "ººªǃ    ëÍÍ¡¡¡¡¡",
            "ººº¸    ëÍÍ¡¡¡¡¡",
            "ººº¸    ëÍÍ¡¡¡¡¡",
            "ż¸¸ż    ëÍÍ¡¡¡¡¡",
            "        ëÍÍ¡¡¡¡¡",
            "        ëÍÍ¡¡¡¡¡",
            "        ëÍÍ¡¡¡¡¡",
            "        ëÍÍ¡¡¡¡¡",
            "îîîîîîîîïÍÍ¡¡¡¡¡",
            "ÍÍÍÍÍÍÍÍÍÍÍ¡¡¡¡¡",
            "ÍÍÍÍÍÍÍÍÍÍÍ¡¡¡¡¡",
            "¡¡¡¡¡¡¡¡¡¡¡¡¡¡¡¡",
            "¡¡¡¡¡¡¡¡¡¡¡¡¡¡¡¡",
            "¡¡¡¡¡¡¡¡¡¡¡¡¡¡¡¡",
            "¡¡¡¡¡¡¡¡¡¡¡¡¡¡¡¡",
            "¡¡¡¡¡¡¡¡¡¡¡¡¡¡¡¡"
        ],
        [
            "  ªƸ    ó  ¢   ¢",
            "   ¸    ó  ¢¢¢¢¢",
            "ÇȆÇ¸    ó  ¢  ǋ¢",
            "Ŷ¸¸Ƹ    ó  ¢ ±ǌ¢",
            "        ó  ¢  Ǎ¢",
            "        ó  ǎ  Ǐ¢",
            "        ó  ¢ƁƂ ¢",
            "        ó  ¢ƃ¢¢¢",
            "ôôôôôôôôõ  ¢   ¢",
            "¬        Õ ¢   ¢",
            "           ¢   ¢",
            "ƅ¢¢¢¢¢ƅ¢¢¢¢ȇ   ¢",
            "    ¢     ¢Û   ¢",
            "  § ¢   § ¢    ¢",
            "ƆÇƇƈ¢ ƆÇƇƈ¢    ¢",
            "¢¢¢¢¢¢¢¢¢¢¢¢¢¢¢¢"
        ],
        [
            "  ªǃ       ¢   ¢",
            "   ¸       ¢ááá¢",
            " Ʃ ¸       à   ¢",
            "ż¸¸ż       à   ¢",
            "           Ǒ   ¢",
            "           ǒ   ¢",
            "           ¢Ƌƌ ¢",
            "           ¢ƃ¢¢¢",
            "           ¢   ¢",
            "           ¢   ¢",
            "           ¢   ¢",
            "ƍúáá¢¢ƍúáá¢    ¢",
            "    à     ¢    ¢",
            "    à     ¢    ¢",
            "    à     ¢    ¢",
            "¢¢¢¢¢¢¢¢¢¢¢¢¢¢¢¢"
        ],
        [
            "  ªƸ       ¢   ¢",
            "   ¸       ¢ááá¢",
            "   ¸       à   ¢",
            "Ŷ¸¸Ƹ       à   ¢",
            "           ¢   ¢",
            "           ¢   ¢",
            "           ¢   ¢",
            "           ¢¢¢¢¢",
            "           ¢   ¢",
            "           ¢   ¢",
            "           ¢   ¢",
            "¢¢áá¢¢¢¢áá¢    ¢",
            "    à     ¢    ¢",
            "    à     ¢    ¢",
            "    à     ¢    ¢",
            "¢¢¢¢¢¢¢¢¢¢¢¢¢¢¢¢"
        ],
        [
            "  ªǃ       ¢   ¢",
            "   ¸       ¢¢¢¢¢",
            "   ¸       ¢   ¢",
            "ÊÊ¸ż       ¢   ¢",
            "           ¢   ¢",
            "           ¢   ¢",
            "           ¢   ¢",
            "           ¢¢¢¢¢",
            "           ¢   ¢",
            "           ¢   ¢",
            "           ¢   ¢",
            "¢¢¢¢¢¢¢¢¢¢¢    ¢",
            "    ¢     ¢    ¢",
            "    ¢     ¢    ¢",
            "    ¢     ¢    ¢",
            "¢¢¢¢¢¢¢¢¢¢¢¢¢¢¢¢"
        ],
        [
            "ÌÌªƸ     ËË¢ËËË¢",
            "ÌÌÌ¸     ËË¢¢¢¢¢",
            "ÌÌÌ¸     ËË¢ËËË¢",
            "ÊÊ¸Ƹ     ËË¢ËËË¢",
            "         ËË¢ËËË¢",
            "         ËË¢ËËË¢",
            "         ËË¢ËËË¢",
            "         ËË¢¢¢¢¢",
            "         ËË¢ËËË¢",
            "ËËËËËËËËËËË¢ËËË¢",
            "ËËËËËËËËËËË¢ËËË¢",
            "¢¢¢¢¢¢¢¢¢¢¢ËËËË¢",
            "ËËËË¢ËËËËË¢ËËËË¢",
            "ËËËË¢ËËËËË¢ËËËË¢",
            "ËËËË¢ËËËËË¢ËËËË¢",
            "¢¢¢¢¢¢¢¢¢¢¢¢¢¢¢¢"
        ]
    ],
    "refpalette": "building004_palette"
}