{
    "xsize": 16,
    "zsize": 16,
    "slices": [
        [
            "££ÿÿÿ££ÿÿ££ÿÿÿ££",
            "££āāāççāāççāāā££",
            "ÿā   ¥»¼½º»¼½ºāÿ",
            "ÿā   ¥¼½º»¼½º»āÿ",
            "ÿā   ¥½º»¼½º»¼āÿ",
            "£ç¥¥¥¥º»¼½º»¼½ç£",
            "£ç»¼½º»¼½º»¼½ºç£",
            "ÿā¼½º»¼½º»¼½º»āÿ",
            "ÿā½º»¼½º»¼½º»¼āÿ",
            "£çº»¼½º»¼½º»¼½ç£",
            "£ç»¼½º»¼½º»¼½ºç£",
            "ÿā¼½º»¼½º»¼½º»āÿ",
            "ÿā½º»¼½º»¼½º»¼āÿ",
            "ÿāº»¼½º»¼½º»¼½āÿ",
            "££āāāççāāççāāā££",
            "££ÿÿÿ££ÿÿ££ÿÿÿ££"
        ],
        [
            "££èèè££èè££èèè££",
            "££çççççççççççç££",
            "èç   ¥ Ąĝ  öĞëçè",
            "èç   ğ       Ġçè",
            "èç   ¥    ġ´Ģ çè",
            "£ç¥¨¥¥      ģ ç£",
            "£ç¥ Ĥ®¥     ĥëç£",
            "èç¥Ħĕ ¥    óħ çè",
            "èç¥Ĩ ĩ¥   ġ´ Īçè",
            "£ç¥ª  ¥     ģ ç£",
            "£ç¥ĉī ¥     Ĭ ç£",
            "èç¥č  ¥    ī ëçè",
            "èç¥Đ  §   ġ ěĭçè",
            "èç¥¥¥¥¥ Įį  ª çè",
            "££çççççççççççç££",
            "££èèè££èè££èèè££"
        ],
        [
            "££ÿÿÿ££ÿÿ££ÿÿÿ££",
            "££ÜÜÜççÜÜççÜÜÜ££",
            "ÿÝ   ¥ ĕĔ     Ýÿ",
            "ÿÝ   İ        Ýÿ",
            "ÿÝ   ¥        Ýÿ",
            "£ç¥¶¥¥        ç£",
            "£ç¥   ¥       ç£",
            "ÿÝ¥  ı¥       Ýÿ",
            "ÿÝ¥   ¥       Ýÿ",
            "£ç¥   ¥       ç£",
            "£ç¥Ĳ  ¥       ç£",
            "ÿÝ¥   ¥       Ýÿ",
            "ÿÝ¥ĳ  µ       Ýÿ",
            "ÿÝ¥¥¥¥¥       Ýÿ",
            "££ÜÜÜççÜÜççÜÜÜ££",
            "££ÿÿÿ££ÿÿ££ÿÿÿ££"
        ],
        [
            "££ÿÿÿ££ÿÿ££ÿÿÿ££",
            "££ăăăççăăççăăă££",
            "ÿă   ¥ ØØ  ØØ ăÿ",
            "ÿă   ¥       Ùăÿ",
            "ÿă   ¥       Ùăÿ",
            "£ç¥¥¥¥        ç£",
            "£ç¥   ¥       ç£",
            "ÿă¥   ¥      Ùăÿ",
            "ÿă¥   ¥      Ùăÿ",
            "£ç¥   ¥       ç£",
            "£ç¥   ¥       ç£",
            "ÿă¥   ¥      Ùăÿ",
            "ÿă¥   ¥      Ùăÿ",
            "ÿă¥¥¥¥¥ÛÛ  ÛÛ ăÿ",
            "££ăăăççăăççăăă££",
            "££ÿÿÿ££ÿÿ££ÿÿÿ££"
        ],
        [
            "££èèè££èè££èèè££",
            "££çççççççççççç££",
            "èç   ¥        çè",
            "èç   ¥        çè",
            "èç   ¥        çè",
            "£ç¥¥¥¥     Ă  ç£",
            "£ç¥Ĵ  ¥    Ă  ç£",
            "èç¥   ¥   Ă   çè",
            "èç¥   ¥   Ă   çè",
            "£ç¥   ¥    Ă  ç£",
            "£ç¥   ¥    Ă  ç£",
            "èç¥   ¥       çè",
            "èç¥   ¥       çè",
            "èç¥¥¥¥¥       çè",
            "££çççççççççççç££",
            "££èèè££èè££èèè££"
        ],
        [
            "££ÿÿÿ££ÿÿ££ÿÿÿ££",
            "££ÜÜÜççÜÜççÜÜÜ££",
            "ÿÝ   ¥ÞßßßßßßàÝÿ",
            "ÿÝ   ¥áââââââãÝÿ",
            "ÿÝ   ¥áââââââãÝÿ",
            "£ç¥¥¥¥áââââââãç£",
            "£çÞßßßâââââââãç£",
            "ÿÝáââââââââââãÝÿ",
            "ÿÝáââââââââââãÝÿ",
            "£çáââââââââââãç£",
            "£çáââââââââââãç£",
            "ÿÝáââââââââââãÝÿ",
            "ÿÝáââââââââââãÝÿ",
            "ÿÝäååååååååååæÝÿ",
            "££ÜÜÜççÜÜççÜÜÜ££",
            "££ÿÿÿ££ÿÿ££ÿÿÿ££"
        ]
    ],
    "refpalette": "building006_palette"
}