{
    "xsize": 16,
    "zsize": 16,
    "slices": [
        [
            "££ÿÿÿ££ÿÿ££ÿÿÿ££",
            "££¹¹¹çç¹¹çç¹¹¹££",
            "ÿ¹   ¥»¼½º»¼½º¹ÿ",
            "ÿ¹   ¥¼½º»¼½º»¹ÿ",
            "ÿ¹   ¥½º»¼½º»¼¹ÿ",
            "£ç¥¥¥¥º»¼½º»¼½ç£",
            "£ç»¼½º»¼½º»¼½ºç£",
            "ÿ¹¼½º»¼½º»¼½º»¹ÿ",
            "ÿ¹½º»¼½º»¼½º»¼¹ÿ",
            "£çº»¼½º»¼½º»¼½ç£",
            "£ç»¼½º»¼½º»¼½ºç£",
            "ÿ¹¼½º»¼½º»¼½º»¹ÿ",
            "ÿ¹½º»¼½º»¼½º»¼¹ÿ",
            "ÿ¹º»¼½º»¼½º»¼½¹ÿ",
            "££¹¹¹çç¹¹çç¹¹¹££",
            "££ÿÿÿ££ÿÿ££ÿÿÿ££"
        ],
        [
            "££ÿÿÿ££ÿÿ££ÿÿÿ££",
            "££¥¥¥££  ££  ®££",
            "ÿ¥   ¥    ĵ Ķ Æÿ",
            "ÿ¥   §   ķ  Â  ÿ",
            "ÿ¥   ¥     ĸ À ÿ",
            "££¥¨¥¥        ££",
            "££Åª          ££",
            "ÿð     ķ       ÿ",
            "ÿ ĹĺĻ      ļ   ÿ",
            "££Ľ Ļ         ££",
            "££Ľ ľ       Ŀ ££",
            "ÿ ŀĺľ     ŁłŃ  ÿ",
            "ÿ      ķ     ª ÿ",
            "ÿ Å        ń   ÿ",
            "££   ££  ££   ££",
            "££ÿÿÿ££ÿÿ££ÿÿÿ££"
        ],
        [
            "££ÿÿÿ££ÿÿ££ÿÿÿ££",
            "££¥¥¥££  ££   ££",
            "ÿ¥   ¥         ÿ",
            "ÿ¥   µ         ÿ",
            "ÿ¥   ¥         ÿ",
            "££¥¶¥¥        ££",
            "££            ££",
            "ÿ              ÿ",
            "ÿ              ÿ",
            "££            ££",
            "££          Ņ ££",
            "ÿ         ņ    ÿ",
            "ÿ              ÿ",
            "ÿ              ÿ",
            "££   ££  ££   ££",
            "££ÿÿÿ££ÿÿ££ÿÿÿ££"
        ],
        [
            "££ÿÿÿ££ÿÿ££ÿÿÿ££",
            "££¥¥¥££  ££   ££",
            "ÿ¥   ¥         ÿ",
            "ÿ¥   ¥         ÿ",
            "ÿ¥   ¥         ÿ",
            "££¥¥¥¥        ££",
            "££            ££",
            "ÿ              ÿ",
            "ÿ       Ň      ÿ",
            "££            ££",
            "££            ££",
            "ÿ              ÿ",
            "ÿ              ÿ",
            "ÿ              ÿ",
            "££   ££  ££   ££",
            "££ÿÿÿ££ÿÿ££ÿÿÿ££"
        ],
        [
            "££ÿÿÿ££ÿÿ££ÿÿÿ££",
            "££   ££  ££   ££",
            "ÿ ¥¥¥¥         ÿ",
            "ÿ ¥¥¥¥         ÿ",
            "ÿ ¥¥¥¥         ÿ",
            "££¥¥¥¥        ££",
            "££            ££",
            "ÿ              ÿ",
            "ÿ       ň      ÿ",
            "££            ££",
            "££            ££",
            "ÿ              ÿ",
            "ÿ              ÿ",
            "ÿ              ÿ",
            "££   ££  ££   ££",
            "££ÿÿÿ££ÿÿ££ÿÿÿ££"
        ],
        [
            "££ÿÿÿ££ÿÿ££ÿÿÿ££",
            "££   ££  ££   ££",
            "ÿ              ÿ",
            "ÿ              ÿ",
            "ÿ              ÿ",
            "££            ££",
            "££            ££",
            "ÿ              ÿ",
            "ÿ       ň      ÿ",
            "££            ££",
            "££            ££",
            "ÿ              ÿ",
            "ÿ              ÿ",
            "ÿ              ÿ",
            "££   ££  ££   ££",
            "££ÿÿÿ££ÿÿ££ÿÿÿ££"
        ],
        [
            "££   ££  ££   ££",
            "££££££££££££££££",
            " ££££££££££££££ ",
            " ££££££££££££££ ",
            " ££££££££££££££ ",
            "££££££££££££££££",
            "££££££££££££££££",
            " ££££££££££££££ ",
            " ££££££££££££££ ",
            "££££££££££££££££",
            "££££££££££££££££",
            " ££££££££££££££ ",
            " ££££££££££££££ ",
            " ££££££££££££££ ",
            "££££££££££££££££",
            "££   ££  ££   ££"
        ],
        [
            "££££££££££££££££",
            "££££££££££££££££",
            "£££ŉŉŉ££££ŉŉŉ£££",
            "£££ŉŉŉ££££ŉŉŉ£££",
            "£££ŉŉŉ££££ŉŉŉ£££",
            "£££ŉŉŉ££££ŉŉŉ£££",
            "£££ŉŉŉŉŉŉŉŉŉŉ£££",
            "£££ŉŉŉŉŉŉŉŉŉŉ£££",
            "£££ŉŉŉŉŉŉŉŉŉŉ£££",
            "£££ŉŉŉŉŉŉŉŉŉŉ£££",
            "£££ŉŉŉ££££ŉŉŉ£££",
            "£££ŉŉŉ££££ŉŉŉ£££",
            "£££ŉŉŉ££££ŉŉŉ£££",
            "£££ŉŉŉ££££ŉŉŉ£££",
            "££££££££££££££££",
            "££££££££££££££££"
        ]
    ],
    "refpalette": "building006_palette"
}