{
    "xsize": 16,
    "zsize": 16,
    "slices": [
        [
            "¤¤¤¤¤¤¤¤¤¤¤¤¤¤±±",
            "¤¤¤¤¤£¤¤¤¤¤¤¤±±±",
            "¤¤¤¤¤¤¤¤¤¤¤±±±±±",
            "¤¤¤¤¤¤¤¤¤¤±±±±±±",
            "¤¤¤¤¤¤¤¤¤±±±±±±±",
            "¤¤¤¤¤¤¤±±±±±±±££",
            "£¤¤¤¤¤±±±±±±££££",
            "¤¤¤¤¤±±±±±££££££",
            "¤¤¤¤±±±±±£££££££",
            "¤¤¤±±±±±££££££££",
            "¤¤±±±±±£££££££££",
            "¤±±±±±££££££££££",
            "¤±±±±±££££££££££",
            "¤±±±±±££££££££££",
            "±±±±±£££££££££££",
            "±±±±±£££££££££££"
        ],
        [
            "§  §§´§§§§½§§   ",
            "§´¼ §²©§§§ ©    ",
            "§ ¨³§§¨¼§§      ",
            "§§©§ §   §      ",
            "§§§§§ §         ",
            "¯§¨©§¨§       ÀÁ",
            "²§©©©       ÀÁÂÃ",
            " ¼©§§     ÀÁÂÄÄÄ",
            "§        ÀÂÅÄÅÄÅ",
            " §      ÀÂÃÄÃÃÄÃ",
            "©§     ÀÂÃÃÅÃÃÃ¥",
            "§     ÀÂÃÅÄÃÃÃ¥¥",
            "§     ÆÅÄÃÃÃÃ¥¥¥",
            "      ÆÃÃÄÃÃ¥¥¥¥",
            "     ÇÈÄÅÄÃ¥¥¥¥Ã",
            "     ÆÄÃÄÄÃ¥¥¥ÃÃ"
        ],
        [
            "                ",
            "     ²¬    ¬    ",
            "                ",
            "  ¬             ",
            "                ",
            "¶  ¬            ",
            "²¶¬¬¬           ",
            "¶ ¬             ",
            "                ",
            "              ÉÅ",
            "¬            ÄÄÊ",
            "            ÅÃËË",
            "           ÅÄËÌÌ",
            "          ÉÃËÌËË",
            "          ÄËÌÍÊ¥",
            "          ÃËÌË¥¥"
        ],
        [
            "   ¸·¶·¸        ",
            "   ·¶²¶·        ",
            "   ¸·¶·¸        ",
            "    ¸·¸         ",
            "·¸              ",
            "¶·¸             ",
            "²¶·             ",
            "¶·¸             ",
            "·¸              ",
            "                ",
            "                ",
            "                ",
            "              ÌÌ",
            "             ÌÃÃ",
            "            ËÌÃÌ",
            "            ÌÃÌË"
        ],
        [
            "     ¶          ",
            "    ¶²¶         ",
            "     ¶          ",
            "                ",
            "                ",
            "¶               ",
            "²¶              ",
            "¶               ",
            "                ",
            "                ",
            "                ",
            "                ",
            "              ËË",
            "             ËÎÎ",
            "             ËÎÌ",
            "            ËÎÌ "
        ],
        [
            "   ¸·¶·¸        ",
            "   ·¶²¶·        ",
            "   ¸·¶·¸        ",
            "    ¸·¸         ",
            "                ",
            "                ",
            "²               ",
            "                ",
            "                ",
            "                ",
            "                ",
            "                ",
            "                ",
            "                ",
            "               Ì",
            "              Ì¥"
        ]
    ],
    "refpalette": "building007_palette"
}