{
    "xsize": 16,
    "zsize": 16,
    "slices": [
        [
            "¡¡¡¡¡¡¡¡¡¡¡¡¡¡¡¡",
            "¡¡¡¡¡¡¡¡¡¡¡¡¡¡¡¡",
            "¡¡¡¡¡¡¡¡¡¡¡¡¡¡¡¡",
            "¡¡¡¡¡¡¡¡¡¡¡¡¡¡¡¡",
            "¢¢¢¢¢¢¢¢¢¢¢¢¢¢¢¢",
            "±±±±±¤¤¤¤¤¤¤¤¤¤¤",
            "±±±±±¤¤¤¤¤¤¤¤¤¤¤",
            "±±±±±¤¤¤¤¤¤¤¤¤¤¤",
            "±±±±±¤¤¤¤¤¤¤£¤¤¤",
            "±±±±±¤¤¤¤¤¤¤¤¤¤¤",
            "±±±±±¤¤¤¤¤¤¤¤¤¤¤",
            "±±±±±¤¤¤¤¤¤¤¤¤¤¤",
            "±±±±±¤¤¤¤¤¤¤¤¤£¤",
            "±±±±±¤¤¤¤¤¤¤¤¤¤¤",
            "±±±±±¤¤¤¤¤¤¤¤¤¤¤",
            "±±±±±¤¤¤¤£¤¤¤¤¤¤"
        ],
        [
            "                ",
            "                ",
            "                ",
            "                ",
            "                ",
            "     §§§§¨§© § §",
            "     §§¼ §©§ §©©",
            "     ¨©§§§¨©  ©§",
            "     §§©©§§§² §§",
            "      ¼§¨§§©§°  ",
            "     ³§§©§§§  § ",
            "     Ý© §§§¨§ ¨§",
            "     §§©©§ §¨©²§",
            "     §§§§¼§ §  §",
            "     §§§  § §§§½",
            "     ©§§§Þ§  §§§"
        ],
        [
            "                ",
            "                ",
            "                ",
            "                ",
            "                ",
            "           ¬    ",
            "          ¬   ¬¬",
            "      ¬    ¬¶ ¬ ",
            "       ¬¬  ¶²¶  ",
            "           ¬¶   ",
            "        ¬       ",
            "      ¬         ",
            "       ¬¬    ¬² ",
            "                ",
            "                ",
            "     ¬   ¶      "
        ],
        [
            "                ",
            "                ",
            "                ",
            "                ",
            "                ",
            "          º¹¸¹º ",
            "         º¹¸·¸¹º",
            "         ¹¸·¶·¸¹",
            "         ¸·¶²¶·¸",
            "         ¹¸·¶·¸¹",
            "         º¹¸·¸·¸",
            "          º¹¸·¶ ",
            "             ¶²¶",
            "              ¶ ",
            "        ¸·¸     ",
            "       ¸·¶·¸    "
        ],
        [
            "                ",
            "                ",
            "                ",
            "                ",
            "                ",
            "                ",
            "           ¸·¸  ",
            "          ¸·¶·¸ ",
            "          ·¶²¶· ",
            "          ¸·¶·¸ ",
            "           ¸·¸·¸",
            "            ¸·¶·",
            "            ·¶²¶",
            "            ¸·¶·",
            "             ¸·¸",
            "         ¶      "
        ],
        [
            "                ",
            "                ",
            "                ",
            "                ",
            "                ",
            "                ",
            "                ",
            "            ¶   ",
            "           ¶²¶  ",
            "            ¶   ",
            "                ",
            "              ¶ ",
            "             ¶²¶",
            "              ¶ ",
            "        ¸·¸     ",
            "       ¸·¶·¸    "
        ]
    ],
    "refpalette": "building007_palette"
}