{
    "xsize": 16,
    "zsize": 16,
    "slices": [
        [
            "¡¡¡¡¢¤¤¤¤¤¤¤¤¤¤¤",
            "¡¡¡¡¢¤¤¤¤¤¤¤¤¤¤¤",
            "¡¡¡¡¢££££££££££¤",
            "¡¡¡¡¢££££££££££¤",
            "¡¡¡¡¢££££££££££¤",
            "¡¡¡¡¢££££££££££¤",
            "¡¡¡¡¢££££££££££¤",
            "¡¡¡¡¢££££££££££¤",
            "¡¡¡¡¢££££££££££¤",
            "¡¡¡¡¢££££££££££¤",
            "¡¡¡¡¢££££££££££¤",
            "¡¡¡¡¢¢¢¢¢¢¢¢¢¢¢¢",
            "¡¡¡¡¡¡¡¡¡¡¡¡¡¡¡¡",
            "¡¡¡¡¡¡¡¡¡¡¡¡¡¡¡¡",
            "¡¡¡¡¡¡¡¡¡¡¡¡¡¡¡¡",
            "¡¡¡¡¡¡¡¡¡¡¡¡¡¡¡¡"
        ],
        [
            "     §§§§©§³©§©§",
            "        §¨§ § §©",
            "    ¥¥¥¥¥¥¥¥¥¥¥§",
            "    ¥¦¦¦¦¦¦¦¦¦¥ ",
            "    ¥¦¦¦¦¦¦¦¦¦¥¾",
            "    ¥¦¦¦¦¦¦¦¦¦¥ ",
            "    ¥¦¦¦¦¦¦¦¦¦¥§",
            "    ¥¦¦¦¦¦¦¦¦¦¥§",
            "    ¥¦¦¦¦¦¦¦¦¦¥ ",
            "    ¥¦¦¦¦¦¦¦¦¦¥§",
            "    ¥¦¦¦¦¦¦¦¦¦¥§",
            "    ¥¦¦¦¦¦¦¦¦¦¥ ",
            "    ¥¦¦¦¦¦¦¦¦¦¥ ",
            "    ¥¥¥¥¥¥¥¥¥¥¥ ",
            "                ",
            "                "
        ],
        [
            "         ¬  ¬ ¬ ",
            "               ¬",
            "                ",
            "     «««««««««  ",
            "     ªªªªªªªªª  ",
            "     ªªªªªªªªª  ",
            "     ªªªªªªªªª  ",
            "     ªªªªªªªªª  ",
            "     ªªªªªªªªª  ",
            "     ªªªªªªªªª  ",
            "     ªªªªªªªªª  ",
            "     ªªªªªªªªª  ",
            "     ªªªªªªªªª  ",
            "                ",
            "                ",
            "                "
        ],
        [
            "                ",
            "                ",
            "                ",
            "      ««««««««« ",
            "      «      «« ",
            "      «      «« ",
            "      «      «« ",
            "      «      «« ",
            "      «      «« ",
            "      «      «« ",
            "      « «    «« ",
            "      ««««««««« ",
            "                ",
            "                ",
            "                ",
            "                "
        ],
        [
            "                ",
            "                ",
            "       «««««««« ",
            "      ««««««««« ",
            "      «       « ",
            "      «       « ",
            "      «       « ",
            "      «       « ",
            "      «       « ",
            "      «       « ",
            "      « ««««««« ",
            "      ««««««««« ",
            "                ",
            "                ",
            "                ",
            "                "
        ],
        [
            "                ",
            "                ",
            "        ««««««««",
            "       «      ««",
            "       «      ««",
            "       «      ««",
            "       «      ««",
            "       «      ««",
            "       «      ««",
            "       «      ««",
            "       «««««««« ",
            "                ",
            "                ",
            "                ",
            "                ",
            "                "
        ]
    ],
    "refpalette": "building007_palette"
}