{
    "xsize": 16,
    "zsize": 16,
    "slices": [
        [
            "ÒÒÒÒÒÒÒÒÒÒÒÒÒÒÒÒ",
            "ÒÓÓÓÓÓÓÓÓÓÓÓÓÓÓÒ",
            "ÒÓÓÓÓÓÓÓÓÓÓÓÓÓÓÒ",
            "ÒÓÓÓÓÓÓÓÓÓÓÓÓÓÓÒ",
            "ÒÓÓÓÓÓÓÓÓÓÓÓÓÓÓÒ",
            "ÒÓÓÓÓÓÓÓÓÓÓÓÓÓÓÒ",
            "ÒÓÓÓÓÓÓÓÓÓÓÓÓÓÓÒ",
            "ÒÓÓÓÓÓÓÓÓÓÓÓÓÓÓÒ",
            "ÒÓÓÓÓÓÓÓÓÓÓÓÓÓÓÒ",
            "ÒÓÓÓÓÓÓÓÓÓÓÓÓÓÓÒ",
            "ÒÓÓÓÓÓÓÓÓ¤¤¤ÓÓÓÒ",
            "ÒÓÓ¥¥¥ÓÓ¤¥¥¥¤ÓÓÒ",
            "ÒÓÓ¥¥¥ÓÓ¤¥¥¥¤ÓÓÒ",
            "ÒÓÓ¥À¥ÓÓ¤¥¥¥¤ÓÓÒ",
            "ÒÓÓ¡¤¡ÓÓÓ¤¤¤ÓÓÓÒ",
            "ÒÒÒÒÒÒÒÒÒÒÒÒÒÒÒÒ"
        ],
        [
            "   Ô¡ÕÐÖÖÐÕ¡Ô   ",
            " ×Ø¡¡¡¡¡¡¡¡¡¡Ø× ",
            " ¡Ù     Ú    Ù¡ ",
            " ¡    Û  Û    ¡ ",
            " Ø   ÜÝÞÞÝÜ   Ø ",
            " Ø      º     Ø ",
            " Ø      ß     Ø ",
            " à            á ",
            " â   ã   ã    ä ",
            " Ø »» »»»» »» Ø ",
            " Ø¼¤¤½¤¤¤¤½¤¤¾Ø ",
            " Ø¤   ¤¤¤   ¤¤Ø ",
            " ¡¤   ¤ ¤   ¿å¡ ",
            " ¡¤ À ¤ ¤   ¤å¡ ",
            " ×Ø¤¤¤¡¤¤¤¤¤¡Ø× ",
            "   ´¡ÕÐææÐÕ¡´   "
        ],
        [
            "   Ô¡ÕÐÖÖÐÕ¡Ô   ",
            " ×Ø¡¡¡¡¡¡¡¡¡¡Ø× ",
            " ¡     çè     ¡ ",
            " ¦            ¨ ",
            "éØ    ê  ê    Øë",
            " ì            ì ",
            " ì            ì ",
            " í            î ",
            " ï            ð ",
            " ì »» »»»» »» ì ",
            " ì¼¤¤Ê¤¤¤¤Ê¤¤¾ì ",
            "éØ¤   ¤¤¤   ¤¤Øë",
            " ¦¤   ¤ ¤   Ëå¨ ",
            " ¡¤ À ¤ ¤   ¤å¡ ",
            " ×Ø¤¤¤¡¤¤¤¤¤¡Ø× ",
            "   ´¡ÕÐææÐÕ¡´   "
        ],
        [
            "   Ô¡ÕÐÖÖÐÕ¡Ô   ",
            " ×Ø¡¡¡¡¡¡¡¡¡¡Ø× ",
            " ¡  ñ  èç  ñ  ¡ ",
            " ¦            ¨ ",
            "òØ            Øó",
            " ì            ì ",
            " ì            ì ",
            " ì            ì ",
            " ì            ì ",
            " ì »»»»»»»»»» ì ",
            " ì¼¤¤¤¤¤¤¤¤¤¤¾ì ",
            "òØ¤   ¤¤¤¥¥¥¤¤Øó",
            " ¦¤   ¤¤¤¥¥¥¤å¨ ",
            " ¡¤ À ¤¤¤¥¥¥¤å¡ ",
            " ×Ø¤¤¤¤¤¤¤¤¤¡Ø× ",
            "   ´¡ÕÐææÐÕ¡´   "
        ],
        [
            "   Ô¡ÕÐÖÖÐÕ¡Ô   ",
            " ×Ø¡¡¡¡¡¡¡¡¡¡Ø× ",
            " ¡            ¡ ",
            " ¦            ¨ ",
            "òØ   ô    ô   Øó",
            " ì            ì ",
            " ì            ì ",
            " ì            ì ",
            " ì            ì ",
            " ì »»»»»»»»»» ì ",
            " ì¼¤¤¤¤¤¤¤¤¤¤¾ì ",
            "òØ¤   ¤¤¤   ¤¤Øó",
            " ¦¤   ¤¤¤   ¤å¨ ",
            " ¡¤ À ¤¤¤   ¤å¡ ",
            " ×Ø¤¤¤¤¤¤¤¤¤¡Ø× ",
            "   ´¡ÕÐææÐÕ¡´   "
        ],
        [
            "   Ô¡ÕÐÖÖÐÕ¡Ô   ",
            " ×Ø¡¡¡¡¡¡¡¡¡¡Ø× ",
            " ¡ØØØØØØØØØØØØ¡ ",
            " ¦Ø¢¢¢¢¢¢¢¢¢¢Ø¨ ",
            " ØØ¢¢¢¢¢¢¢¢¢¢ØØ ",
            " ìØ¢¢¢¢¢¢¢¢¢¢Øì ",
            " ìØ¢¢¢¢¢¢¢¢¢¢Øì ",
            " ìØ¢¢¢¢¢¢¢¢¢¢Øì ",
            " ìØ¢¢¢¢¢¢¢¢¢¢Øì ",
            " ìØ¢¢¢¢¢¢¢¢¢¢Øì ",
            " ìØ¤¤¤¢¢¢¤¤¤¢Øì ",
            " Ø¤   ¤¤¤   ¤ØØ ",
            " ¦¤   ¤¤¤   ¤Ø¨ ",
            " ¡¤ À ¤¤¤   ¤Ø¡ ",
            " ×Ø¤¤¤¤¤¤¤¤¤¡Ø× ",
            "   ´¡ÕÐææÐÕ¡´   "
        ]
    ],
    "refpalette": "building001_palette"
}