{
    "xsize": 16,
    "zsize": 16,
    "slices": [
        [
            "  µÊÌÍÌËÌÍÌËÊµÉ ",
            "  µÊËÌÍÌËÌÍÌÊµÎ ",
            "  µÊÌËÌÍÌËÌËÊµ  ",
            "  µÊÍÌËÌÍÌÍÌÊµ  ",
            "  µÊÌÍÌËÌËÌÍÊµ  ",
            "  µÊËÌÍÌÍÌËÌÊµ  ",
            "  µÊÌËÌËÌÍÌËÊµ  ",
            "  µÊÍÌÍÌËÌÍÌÊµ  ",
            "  µÊÌËÌÍÌËÌÍÊµ  ",
            "  µÊÍÌËÌÍÌËÌÊµ  ",
            "  µÊÌÍÌËÌÍÌÍÊµ  ",
            "   ¦ÊÊÊÊÊÊÊÊ¦   ",
            "  čččččččččččč  ",
            "                ",
            "                ",
            "                "
        ],
        [
            "  ©   ÏÐÐÏ   ©  ",
            "  ©          ©  ",
            "  ©     Đ    ©  ",
            "  ©          ©  ",
            "  Ñ   ÏÐÐÏ   Ñ  ",
            "  Ñ          Ñ  ",
            "  ©          ©  ",
            "  ©   àãđ    ©  ",
            "  ©  ªØÏÏ×   ©  ",
            "  ©          ©  ",
            "  ©          ©  ",
            "   ¦   ĒĒ   ¦   ",
            "  čččččččččččč  ",
            "                ",
            "                ",
            "                "
        ],
        [
            "  ©  ÓÔÔÔÕÖ  ©  ",
            "  ©          ©  ",
            "  ©          ©  ",
            "  ©          ©  ",
            "  Ñ  Ó¨ÕÔÔÖ  Ñ  ",
            "  Ñ          Ñ  ",
            "  ©          ©  ",
            "  ©          ©  ",
            "  ©   ēĔ ĕ   ©  ",
            "  ©          ©  ",
            "  ©          ©  ",
            "   ¦   ĒĒ   ¦   ",
            "  čččččččččččč  ",
            "                ",
            "                ",
            "                "
        ],
        [
            "  ©  ×ÔÔÔÔØ  ©  ",
            "  ©          ©  ",
            "  ©          ©  ",
            "  ©          ©  ",
            "  Ñ  ×ÔÔÔÔØ  Ñ  ",
            "  Ñ          Ñ  ",
            "  ©          ©  ",
            "  ©          ©  ",
            "  ©          ©  ",
            "  ©          ©  ",
            "  ©          ©  ",
            "   ¦   ĒĒ   ¦   ",
            "  čččččččččččč  ",
            "                ",
            "                ",
            "                "
        ],
        [
            "  ©  ÓÔÕÔÔÖ  ©  ",
            "  ©          ©  ",
            "  ©          ©  ",
            "  ©          ©  ",
            "  Ñ  ÓÕÔÔÔÖ  Ñ  ",
            "  Ñ          Ñ  ",
            "  ©          ©  ",
            "  ©          ©  ",
            "  ©          ©  ",
            "  ©          ©  ",
            "  ©          ©  ",
            "   ¦   ĒĒ   ¦   ",
            "  čččččččččččč  ",
            "                ",
            "                ",
            "                "
        ],
        [
            "  ©   ÙÐÐÙ   ©  ",
            "  ©          ©  ",
            "  ©          ©  ",
            "  ©          ©  ",
            "  Ñ   ÙÐÐÙ   Ñ  ",
            "  Ñ          Ñ  ",
            "  ©          ©  ",
            "  ©          ©  ",
            "  ©          ©  ",
            "  ©          ©  ",
            "  ©          ©  ",
            "   ¦   ĒĒ   ¦   ",
            "  čččččččččččč  ",
            "                ",
            "                ",
            "                "
        ]
    ],
    "refpalette": "building003_palette"
}