{
    "xsize": 16,
    "zsize": 16,
    "slices": [
        [
            "¡¡¡¡¡¡¡¡¡¡¡¡¡¡¡¡",
            "¡¡¡¡¡¡¡¡¡¡¡¡¡¡¡¡",
            "¡¡¡¡¡¡¡¡¡¡¡¡¡¡¡¡",
            "¡¡¡¡¡¡¡¡¡¡¡¡¡¡¡¡",
            "¡¡¡¡¢¢¢¢¢¢¢¢¢¢¢¢",
            "¡¡¡¡¢£££££££££££",
            "¡¡¡¡¢£££££££££££",
            "¡¡¡¡¢£££££££££££",
            "¡¡¡¡¢£££££££££££",
            "¡¡¡¡¢£££££££££££",
            "¡¡¡¡¢£££££££££££",
            "¡¡¡¡¢£££££££££££",
            "¡¡¡¡¢£££££££££££",
            "¡¡¡¡¢£££££££££££",
            "¡¡¡¡¢¤¤¤¤¤¤¤¤¤¤¤",
            "¡¡¡¡¢¤¤¤¤¤¤¤¤¤¤¤"
        ],
        [
            "                ",
            "                ",
            "                ",
            "    ¥¥¥¥¥¥¥¥¥¥¥¥",
            "    ¥¦¦¦¦¦¦¦¦¦¦¥",
            "    ¥¦¦¦¦¦¦¦¦¦¦¥",
            "    ¥¦¦¦¦¦¦¦¦¦¦¥",
            "    ¥¦¦¦¦¦¦¦¦¦¦¥",
            "    ¥¦¦¦¦¦¦¦¦¦¦¥",
            "    ¥¦¦¦¦¦¦¦¦¦¦¥",
            "    ¥¦¦¦¦¦¦¦¦¦¦¥",
            "    ¥¦¦¦¦¦¦¦¦¦¦¥",
            "    ¥¦¦¦¦¦¦¦¦¦¦¥",
            "    ¥¥¥¥¥¥¥¥¥¥¥¥",
            "       §§§  §§§§",
            "       ¨§§§ §§©§"
        ],
        [
            "                ",
            "                ",
            "                ",
            "                ",
            "     ª«ªªªªªªªª ",
            "     ªª«ªªªªªªª ",
            "     ªªª ªªªªªª ",
            "     ªªªªªªªªªª ",
            "     ªªªªªªªªªª ",
            "     ªªªªªªªªªª ",
            "     ªªªªªªªªªª ",
            "     ªªªªªªªªªª ",
            "     «««ªªªªªªª ",
            "                ",
            "                ",
            "              ¬ "
        ],
        [
            "                ",
            "                ",
            "                ",
            "                ",
            "       «««««««« ",
            "      ««««««««« ",
            "      «       « ",
            "      «  ®   ®« ",
            "      «       « ",
            "      «       « ",
            "      «       « ",
            "      « ¯  ¯  « ",
            "      ««««««««« ",
            "      ««««««««« ",
            "                ",
            "                "
        ],
        [
            "                ",
            "                ",
            "                ",
            "                ",
            "                ",
            "      ««««««««««",
            "      ««  ««««««",
            "      ««      ««",
            "      ««      ««",
            "      ««      ««",
            "      ««      ««",
            "      ««      ««",
            "      ««     °««",
            "      ««««««««« ",
            "                ",
            "                "
        ],
        [
            "                ",
            "                ",
            "                ",
            "                ",
            "                ",
            "       «««««««««",
            "       «««««««««",
            "       «       «",
            "       «       «",
            "       «       «",
            "       «       «",
            "       «       «",
            "       «       «",
            "       «««««««««",
            "       «««««««« ",
            "                "
        ]
    ],
    "refpalette": "building007_palette"
}