{
    "xsize": 16,
    "zsize": 16,
    "slices": [
        [
            "   Ô¡ÕÐÖÖÐÕ¡Ô   ",
            " ×Ø¡¡¡¡¡¡¡¡¡¡Ø× ",
            " ¡ÐÐÐÐÐÐÐÐÐÐÐÐ¡ ",
            " ¦ÐõõõõõõõõõõÐ¨ ",
            " ØÐõõõõõõõõõõÐØ ",
            " ìÐõõõõõõõõõõÐì ",
            " ìÐõõõõõõõõõõÐì ",
            " ìÐõõõõõõõõõõÐì ",
            " ìÐõõõõõõõõõõÐì ",
            " ìÐõõõõõõõõõõÐì ",
            " ìÐ¤¤¤õöö¤¤¤öÐì ",
            " Ø¤¥¥¥¤¤¤   ¤¤Ø ",
            " ¦¤¥¥¥¤¤¤   ¤ ¨ ",
            " ¡¤¥À¥¤¤¤   ¤Ø¡ ",
            " ×Ø¤¤¤¤¤¤¤¤¤¡Ø× ",
            "   ´¡ÕÐææÐÕ¡´   "
        ],
        [
            "   Ô¡ÕÐÖÖÐÕ¡Ô   ",
            " ×Ø¡¡¡¡¡¡¡¡¡¡Ø× ",
            " ¡ ÷øøøø÷÷÷ø÷ ¡ ",
            " ¦ ù  Ú ú   ù ¨ ",
            " Ø  û   û   û Ø ",
            " ì      º     ì ",
            " ì ü    ù    ýì ",
            " ì  û   û   û ì ",
            " ì      ß     ì ",
            " ì » »»»»» »» ì ",
            " ì¼¤½¤¤¤¤¤½¤¤¾ì ",
            " Ø¤   ¤¤¤   ¤¤Ø ",
            " ¦¤   ¤ ¤   ¿ ¨ ",
            " ¡¤ À ¤ ¤   ¤Ø¡ ",
            " ×Ø¤¤¤   ¤¤¤¡Ø× ",
            "   ´¡ÕÐææÐÕ¡´   "
        ],
        [
            "   Ô¡ÕÐÖÖÐÕ¡Ô   ",
            " ×Ø¡¡¡¡¡¡¡¡¡¡Ø× ",
            " ¡ ø÷÷÷ø÷øø÷ø ¡ ",
            " ¦            ¨ ",
            " Ø  þÿ  Ā   ā Ø ",
            " ì            ì ",
            " ì            ì ",
            " ì  Ă   ā   ăĄì ",
            " ì            ì ",
            " ì » »»»»» »» ì ",
            " ì¼¤Ê¤¤¤¤¤Ê¤¤¾ì ",
            " Ø¤   ¤¤¤   ¤¤Ø ",
            " ¦¤   ¤ ¤   Ë ¨ ",
            " ¡¤ À ¤ ¤   ¤Ø¡ ",
            " ×Ø¤¤¤   ¤¤¤¡Ø× ",
            "   ´¡ÕÐææÐÕ¡´   "
        ],
        [
            "   Ô¡ÕÐÖÖÐÕ¡Ô   ",
            " ×Ø¡¡¡¡¡¡¡¡¡¡Ø× ",
            " ¡ øøøøøø÷÷ø÷ ¡ ",
            " ¦            ¨ ",
            " Ø            Ø ",
            " Ø            Ø ",
            " ì            ì ",
            " ì            ì ",
            " ì            ì ",
            " ì »»»»»»»»»» ì ",
            " ì¼¤¤¤¤¤¤¤¤¤¤¾ì ",
            " Ø¤   ¤¤¤   ¤¤Ø ",
            " ¦¤   ¤ ¤   ¤ ¨ ",
            " ¡¤ À ¤ ¤   ¤Ø¡ ",
            " ×Ø¤¤¤   ¤¤¤¡Ø× ",
            "   ´¡ÕÐææÐÕ¡´   "
        ],
        [
            "   Ô¡ÕÐÖÖÐÕ¡Ô   ",
            " ×Ø¡¡¡¡¡¡¡¡¡¡Ø× ",
            " ¡ ÷÷÷÷ø÷øø÷ø ¡ ",
            " ¦            ¨ ",
            " ¦            ¨ ",
            " Ø            Ø ",
            " Ø      ą     Ø ",
            " ì            ì ",
            " ì            ì ",
            " ì »»»»»»»»»» ì ",
            " ì¼¤¤¤¤¤¤¤¤¤¤¾ì ",
            " Ø¤   ¤¤¤   ¤¤Ø ",
            " ¦¤   ¤ ¤   ¤ ¨ ",
            " ¡¤ À ¤ ¤   ¤Ø¡ ",
            " ×Ø¤¤¤   ¤¤¤¡Ø× ",
            "   ´¡ÕÐææÐÕ¡´   "
        ],
        [
            "   Ô¡ÕÐÖÖÐÕ¡Ô   ",
            " ×Ø¡¡¡¡¡¡¡¡¡¡Ø× ",
            " ¡ØØØØØØØØØØØØ¡ ",
            " ¦ØĆĆĆĆĆĆĆĆĆĆØ¨ ",
            " ¦ØĆĆĆĆĆĆĆĆĆĆØ¨ ",
            " ¦ØĆĆĆĆĆĆĆĆĆĆØ¨ ",
            " ØØĆĆĆĆĆĆĆĆĆĆØØ ",
            " ØØĆĆĆĆĆĆĆĆĆĆØØ ",
            " ìØĆĆĆĆĆĆĆĆĆĆØì ",
            " ìØĆĆĆĆĆĆĆĆĆĆØì ",
            " ìØ¤¤¤ĆĆĆ¤¤¤ĆØì ",
            " Ø¤   ¤ ¤   ¤ØØ ",
            " ¦¤   ¤ ¤   ¤Ø¨ ",
            " ¡¤ À ¤ ¤   ¤Ć¡ ",
            " ×Ø¤¤¤   ¤¤¤¡Ø× ",
            "   ´¡ÕÐææÐÕ¡´   "
        ]
    ],
    "refpalette": "building001_palette"
}