{
    "xsize": 16,
    "zsize": 16,
    "slices": [
        [
            "¡¡¡¡¡¡¡¡¡¡¡¡¡¡¡¡",
            "¡¡¡¡¡¡¡¡¡¡¡¡¡¡¡¡",
            "¡¡¡¡¡¡¡¡¡¡¡¡¡¡¡¡",
            "¡¡¡¡¡¡¡¡¡¡¡¡¡¡¡¡",
            "¡¡¢¢¢¢¢¢¢¢¢¢¢¢¡¡",
            "¡¡¢¢¢¢¢¢¢¢¢¢¢¢¡¡",
            "¡¡¢¢¢¢¢¢¢¢¢¢¢¢¡¡",
            "¡¡¢¢¢¢¢¢¢¢¢¢¢¢¡¡",
            "¡¡¢¢¢¢¢¢¢¢¢¢¢¢¡¡",
            "¡¡¢¢¢¢¢¢¢¢¢¢¢¢¡¡",
            "¡¡¢¢¢¢¢¢¢¢¢¢¢¢¡¡",
            "¡¡¢¢¢¢¢¢¢¢¢¢¢¢¡¡",
            "¡¡¢¢¢¢¢¢¢¢¢¢¢¢£¡",
            "¡¡¢¢¢¢¢¢¢¢¢¢¢¢£¡",
            "¡¡¢¢¢¢¢¢¢¢¢¢¢¤¤¡",
            "¡¡¢¢¢¢¢¢¢¢¢¢¢¤¤¡"
        ],
        [
            "                ",
            "                ",
            "                ",
            "  ¥¥¥¥¥¥¥¥¥¥¥¥  ",
            "   ¦§¨     §¦   ",
            "  ©ª «      ª©  ",
            "  ©     ¬®¬  ©  ",
            "  ©¯ ° ± ²²  ©  ",
            "  ©   ³  ²²² ©  ",
            "  ©¯ ° ± ²²² ©  ",
            "  ©     ²²²´ ©  ",
            "  ©    ²²²   ©  ",
            "  ©    ²²    µ¶ ",
            "  ©·     ¸¸¸¸¹¹ ",
            "  © º   »  »    ",
            "  ©             "
        ],
        [
            "                ",
            "                ",
            "                ",
            "  ¥¥¥¥¥¥¥¥¥¥¥¥  ",
            "   ¦     ¼  ¦   ",
            "  ©     ½®½  ©  ",
            "  ©     ¾ ¾  ©  ",
            "  ©          ©  ",
            "  ©          ©  ",
            "  ©          ©  ",
            "  ©          ©  ",
            "  ©          ©  ",
            "  ©          µ¿ ",
            "  ©          ÀÀ ",
            "  ©ÁÂ           ",
            "  ©  Ã          "
        ],
        [
            "                ",
            "                ",
            "                ",
            "  ¥¥¥¥¥¥¥¥¥¥¥¥  ",
            "   ¦    Ä Å ¦   ",
            "  ©    ÆÇ ¾  ©  ",
            "  ©          ©  ",
            "  ©          ©  ",
            "  ©          ©  ",
            "  ©          ©  ",
            "  ©          ©  ",
            "  ©          ©  ",
            "  ©          µ¶ ",
            "  ©          ¹¹ ",
            "  ©             ",
            "  ©             "
        ],
        [
            "                ",
            "                ",
            "                ",
            "  ¥¥¥¥¥¥¥¥¥¥¥¥  ",
            "   ¦   Ä  ¾ ¦   ",
            "  ©   ÆÈÇ    ©  ",
            "  ©          ©  ",
            "  ©          ©  ",
            "  ©          ©  ",
            "  ©          ©  ",
            "  ©          ©  ",
            "  ©          ©  ",
            "  ©          µ¿ ",
            "  ©          ÀÀ ",
            "  ©             ",
            "  ©             "
        ],
        [
            "                ",
            "                ",
            "                ",
            "  ¥¥¥¥¥¥¥¥¥¥¥¥  ",
            "   ¦  Ä     ¦   ",
            "  ©  ÆÈÇ     ©  ",
            "  ©          ©  ",
            "  ©          ©  ",
            "  ©          ©  ",
            "  ©          ©  ",
            "  ©          ©  ",
            "  ©          ©  ",
            "  ©          µ¶ ",
            "  ©          µÉ ",
            "  ©          ÀÀ ",
            "  ©          ¤¤ "
        ]
    ],
    "refpalette": "building003_palette"
}