{
    "xsize": 16,
    "zsize": 16,
    "slices": [
        [
            "   Ô¡ÕÐÖÖÐÕ¡Ô   ",
            " ×Ø¡¡¡¡¡¡¡¡¡¡Ø× ",
            " ¡űűűűűűűűűŲűű¡ ",
            " ¦űųŴŴŴŴŴŴŴŴŴű¨ ",
            " ØűųŴŴŴŴŴŴŴŴŴűØ ",
            " ØűųŴŴŴŴŴŴŴŴŴűØ ",
            " ØűŴŴŴŴŴŴŴŴŴŴűØ ",
            " ¦űŴŴŴŴŴŴŴŴŴŴű¨ ",
            " ¦űŴŴŴŴŴŴŴŴŴŴű¨ ",
            " ¦űŴŴŴŴŴŴŴŴŴŴű¨ ",
            " ¦ű¤¤¤¤¤¤¤¤¤¤ű¨ ",
            " ¦¤¥¥¥¤ ¤   ¤¤¨ ",
            " ¦¤¥¥¥¤ ¤   ¤ ¨ ",
            " ¡¤¥À¥¤ ¤   ¤ ¡ ",
            " ×Ø¤¤¤¤¤¤¤¤¤¤Ø× ",
            "   ´¡ÕÐææÐÕ¡´   "
        ],
        [
            "   Ô¡ÕÐÖÖÐÕ¡Ô   ",
            " ×Ø¡¡¡¡¡¡¡¡¡¡Ø× ",
            " ¡ ŵŶŷŸŶŹŹŹŹźŻ¡ ",
            " ¦Ŷż ¬ŽŶžųųſźƀ¨ ",
            " ¦Ŷ±  ºƁƁ    Ɓ¨ ",
            " ¦ŶƂ   ƃƃ Ƅ  ų¨ ",
            " ¦ŶżƅƄ ųųƆ   ų¨ ",
            " ¦Ƈƈ   ƉƉ    ų¨ ",
            " ¦Ɗ    ƋƋ    ƌ¨ ",
            " Øƍ          ƎØ ",
            " Ø ¤½¤¤¤¤¤½¤¤ Ø ",
            " Ø¤   ¤ ¤   ¤¤Ø ",
            " ¦¤   ¤ ¤   ¿ ¨ ",
            " ¡¤ À ¤ ¤   ¤ ¡ ",
            " ×Ø¤¤¤¤¤¤¤¤¤¤Ø× ",
            "   ´¡ÕÐææÐÕ¡´   "
        ],
        [
            "   Ô¡ÕÐÖÖÐÕ¡Ô   ",
            " ×Ø¡¡¡¡¡¡¡¡¡¡Ø× ",
            " ¡ ŵŶÚŸŶƏƏƏƏźĖ¡ ",
            " ¦ƐƑ ÂƒŶƓ²ƔƔź ¨ ",
            " ¦ƐŹ   ƁƁ    Ɓ¨ ",
            " ¦Ɛż   °ƕ    °¨ ",
            " ¦Ŷ±Ɩ  ƗƘ    ƕ¨ ",
            " ¦ ƈ   ƙ±    ƚ¨ ",
            " Øƛ    ƋƋ    ƋØ ",
            " Ø            Ø ",
            " ì ¤Ê¤¤¤¤¤Ê¤¤ ì ",
            " Ø¤   ¤ ¤   ¤¤Ø ",
            " ¦¤   ¤ ¤   Ë ¨ ",
            " ¡¤ À ¤ ¤   ¤ ¡ ",
            " ×Ø¤¤¤¤¤¤¤¤¤¤Ø× ",
            "   ´¡ÕÐææÐÕ¡´   "
        ],
        [
            "   Ô¡ÕÐÖÖÐÕ¡Ô   ",
            " ×Ø¡¡¡¡¡¡¡¡¡¡Ø× ",
            " ¡ Ɯ ŹŹŶƏƏƏƏƝ ¡ ",
            " ¦Ɛƞ   ŶƟƓŷƟƝ ¨ ",
            " ¦Ɛž   ƁƁ    Ɓ¨ ",
            " ¦ƐŸ Ɠ ųų    ų¨ ",
            " ¦Ŷų   ųų    ų¨ ",
            " Ø Ơ   ųų    ųØ ",
            " Ø     ƋƋ  Ɠ ƋØ ",
            " ì            ì ",
            " ì ¤¤¤¤¤¤¤¤¤¤ ì ",
            " Ø¤   ¤ ¤   ¤¤Ø ",
            " ¦¤   ¤ ¤   ¤ ¨ ",
            " ¡¤ À ¤ ¤   ¤ ¡ ",
            " ×Ø¤¤¤¤¤¤¤¤¤¤Ø× ",
            "   ´¡ÕÐææÐÕ¡´   "
        ],
        [
            "   Ô¡ÕÐÖÖÐÕ¡Ô   ",
            " ×Ø¡¡¡¡¡¡¡¡¡¡Ø× ",
            " ¡     ơŹŹŹŹƢ ¡ ",
            " ¦ ƣ   ơŹŹŹŹƢ ¨ ",
            " ¦ ƣ   ƁƁ    Ɓ¨ ",
            " ¦ ƣ Ɵ ƤƑ    Ɨ¨ ",
            " Ø ƣ   ƥ     ƦØ ",
            " Ø     ƤƑ    ƤØ ",
            " ì     ƋƋ  Ɵ Ƌì ",
            " ì            ì ",
            " ì ¤¤¤¤¤¤¤¤¤¤ ì ",
            " Ø¤   ¤ ¤   ¤¤Ø ",
            " ¦¤   ¤ ¤   ¤ ¨ ",
            " ¡¤ À ¤ ¤   ¤ ¡ ",
            " ×Ø¤¤¤¤¤¤¤¤¤¤Ø× ",
            "   ´¡ÕÐææÐÕ¡´   "
        ],
        [
            "   Ô¡ÕÐÖÖÐÕ¡Ô   ",
            " ×Ø¡¡¡¡¡¡¡¡¡¡Ø× ",
            " ¡ØØØØØØØØØØØØ¡ ",
            " ¦ØƧƧƨƩƧƩƩƩƧƧØ¨ ",
            " ¦ØƩƧƩƧƩƩƩƧƩƨØ¨ ",
            " ØØƩƨƩƩƩƩƨƩƧƩØØ ",
            " ØØƨƩƩƩƩƩƩƨƧƩØØ ",
            " ìØƩƧƩƩƩƩƧƩƩƧØì ",
            " ìØƧƧƧƨƩƩƧƩƩƩØì ",
            " ìØƧƨƩƨƩƧƧƨƩƩØì ",
            " ìØ¤¤¤¤¤¤¤¤¤¤Øì ",
            " Ø¤   ¤ ¤   ¤ Ø ",
            " ¦¤   ¤ ¤   ¤ ¨ ",
            " ¡¤ À ¤ ¤   ¤ ¡ ",
            " ×Ø¤¤¤¤¤¤¤¤¤¤Ø× ",
            "   ´¡ÕÐææÐÕ¡´   "
        ]
    ],
    "refpalette": "building001_palette"
}