{
    "xsize": 16,
    "zsize": 16,
    "slices": [
        [
            "                ",
            "                ",
            "  Ėîîîîîîîîîîîîî",
            "  ëĴĴĴĴĴĴĴĴĴĴĴĴĴ",
            "  ëĴ««««««««««««",
            "  ëĴ««««««««««««",
            "  ëĴ««««««««««««",
            "  ëĴ««««««««««««",
            "  ëĴ«««««««««««ŀ",
            "  ëĴ«««««««««««ŀ",
            "  ëĴ««««««««««««",
            "  ëĴ««««««««««««",
            "  ëĴĴĴĴĴĴĴĴĴĴĴĴĴ",
            "  ĺÏÏÏÏÏÏÏÏÏÏÏÏÏ",
            "                ",
            "                "
        ],
        [
            "                ",
            "                ",
            "  āĂĂĂĂĂĂĂĂĂĂĂĂĂ",
            "  ăĴĴĴĴĴĴĴĴĴĴĴĴĴ",
            "  ăĴē  ũ  ĄĄĄ   ",
            "  ăĴÛ    Ū  Ū   ",
            "  ăĴ  ū         ",
            "  ăĴ     Ū  Ū  ŀ",
            "  ăĴ ľ Ŀ       ŀ",
            "  ăĴ     Ū     ŀ",
            "  ăĴ        Ŭ  Č",
            "  ăĴŭÇ ũ  ŮŮŮ  ŀ",
            "  ăĴĴĴĴĴĴĴĴĴĴĴĴĴ",
            "  Ĳċċċċċċċċċċċċċ",
            "                ",
            "                "
        ],
        [
            "                ",
            "                ",
            "  ĤĤĤĤĤĤĤĤĤĤĤĤĤĤ",
            "  ĤĠĠĠĠĠĠĠĠĠĠĠĠĠ",
            "  ĤĠ            ",
            "  ĤĠ            ",
            "  ĤĠ ů Ű        ",
            "  ĤĠű          ŀ",
            "  ĤĠ   Ų       ŀ",
            "  ĤĠ           ŀ",
            "  ĤĠ           Ě",
            "  ĤĠ           ŀ",
            "  ĤĠĠĠĠĠĠĠĠĠĠĠĠĠ",
            "  ĤĤĤĤĤĤĤĤĤĤĤĤĤĤ",
            "                ",
            "                "
        ],
        [
            "                ",
            "                ",
            "  ĤĤĤĤĤĤĤĤĤĤĤĤĤĤ",
            "  ĤĴĴĴĴĴĴĴĴĴĴĴĴĴ",
            "  ĤĴ            ",
            "  ĤĴ            ",
            "  ĤĴ            ",
            "  ĤĴ           ŀ",
            "  ĤĴű          ŀ",
            "  ĤĴ           ŀ",
            "  ĤĴ           ŀ",
            "  ĤĴ           ŀ",
            "  ĤĴĴĴĴĴĴĴĴĴĴĴĴĴ",
            "  ĤĤĤĤĤĤĤĤĤĤĤĤĤĤ",
            "                ",
            "                "
        ],
        [
            "                ",
            "                ",
            "  ĤĤĤĤĤĤĤĤĤĤĤĤĤĤ",
            "  ĤĴĴĴĴĴĴĴĴĴĴĴĴĴ",
            "  ĤĴ            ",
            "  ĤĴ            ",
            "  ĤĴ            ",
            "  ĤĴ     ş     ŀ",
            "  ĤĴ    ş ş    ŀ",
            "  ĤĴ           ŀ",
            "  ĤĴ           ŀ",
            "  ĤĴ           ŀ",
            "  ĤĴĴĴĴĴĴĴĴĴĴĴĴĴ",
            "  ĤĤĤĤĤĤĤĤĤĤĤĤĤĤ",
            "                ",
            "                "
        ],
        [
            "                ",
            "                ",
            "  ìììììììììììììì",
            "  ìĠĠĠĠĠĠĠĠĠĠĠĠĠ",
            "  ìĠŠššššššššššš",
            "  ìĠŢţţţţţţţţţţţ",
            "  ìĠŢţţţţţţţţţţţ",
            "  ìĠŢţţţţţţţţţţţ",
            "  ìĠŢţţţţţţţţţţţ",
            "  ìĠŢţţţţţţţţţţţ",
            "  ìĠŢţţţţţţţţţţţ",
            "  ìĠŦŧŧŧŧŧŧŧŧŧŧŧ",
            "  ìĠĠĠĠĠĠĠĠĠĠĠĠĠ",
            "  ìììììììììììììì",
            "                ",
            "                "
        ],
        [
            "                ",
            "                ",
            "  Ėîîîîîîîîîîîîî",
            "  ëĢĢĢĢĢĢĢĢĢĢĢĢĢ",
            "  ëĢĢĢĢĢĢĢĢĢĢĢĢĢ",
            "  ëĢĢĢĢĢĢĢĢĢĢĢĢĢ",
            "  ëĢĢĢĢĢĢĢĢĢĢĢĢĢ",
            "  ëĢĢĢĢĢĢĢĢĢĢĢĢĢ",
            "  ëĢĢĢĢĢĢĢĢĢĢĢĢĢ",
            "  ëĢĢĢĢĢĢĢĢĢĢĢĢĢ",
            "  ëĢĢĢĢĢĢĢĢĢĢĢĢĢ",
            "  ëĢĢĢĢĢĢĢĢĢĢĢĢĢ",
            "  ëĢĢĢĢĢĢĢĢĢĢĢĢĢ",
            "  œÏÏÏÏÏÏÏÏÏÏÏÏÏ",
            "                ",
            "                "
        ]
    ],
    "refpalette": "building004_palette"
}