{
    "xsize": 16,
    "zsize": 16,
    "slices": [
        [
            "ººªǃììììëÍÍ¡¡¡¡¡",
            "ººº¸ìĝÏÏƏÍÍ¡¡¡¡¡",
            "ººº¸ìÐ  ëÍÍ¡¡¡¡¡",
            "ż¸¸żìÐ  ëÍÍ¡¡¡¡¡",
            "ìììììÐ  ëÍÍ¡¡¡¡¡",
            "ìÎÏÏÏƫ  ëÍÍ¡¡¡¡¡",
            "ìÐ      ëÍÍ¡¡¡¡¡",
            "ìÐ      ëÍÍ¡¡¡¡¡",
            "îƐîîîîîîïÍÍ¡¡¡¡¡",
            "ÍÍÍÍÍÍÍÍÍÍÍ¡¡¡¡¡",
            "ÍÍÍÍÍÍÍÍÍÍÍ¡¡¡¡¡",
            "¡¡¡¡¡¡¡¡¡¡¡¡¡¡¡¡",
            "¡¡¡¡¡¡¡¡¡¡¡¡¡¡¡¡",
            "¡¡¡¡¡¡¡¡¡¡¡¡¡¡¡¡",
            "¡¡¡¡¡¡¡¡¡¡¡¡¡¡¡¡",
            "¡¡¡¡¡¡¡¡¡¡¡¡¡¡¡¡"
        ],
        [
            "  ªǃ       ¢   ¢",
            "   ¸ Ö××ò  ¢¢¢¢¢",
            "   ǃ Ø  ó  ¢  ǋ¢",
            "ÊÊżȈ Ø  ó  ¢ §ǌ¢",
            "     Ø  ó  ¢  Ǎ¢",
            " Öôôôõ  ó  ǎ  Ǐ¢",
            " ó      ó  ¢   ¢",
            "¬Ø      ó  ¢¢¢¢¢",
            " øôôôôôôõÕ ¢   ¢",
            "           ¢   ¢",
            "           ¢   ¢",
            "ƅ¢¢¢¢¢ƅ¢¢¢¢    ¢",
            "    ¢     ¢    ¢",
            "  § ¢   § ¢    ¢",
            "ƆÇƇƈ¢ ƆÇƇƈ¢    ¢",
            "¢¢¢¢¢¢¢¢¢¢¢¢¢¢¢¢"
        ],
        [
            "  ªƸ       ¢   ¢",
            "   ¸       ¢ááá¢",
            "   Ƹ       à   ¢",
            "ÊÊŶȉ       à   ¢",
            "           Ǒ   ¢",
            "           ǒ   ¢",
            "           ¢   ¢",
            "           ¢¢¢¢¢",
            "           ¢   ¢",
            "           ¢   ¢",
            "           ¢   ¢",
            "ƍúáá¢¢ƍúáá¢    ¢",
            "    à     ¢    ¢",
            "    à     ¢    ¢",
            "    à     ¢    ¢",
            "¢¢¢¢¢¢¢¢¢¢¢¢¢¢¢¢"
        ],
        [
            "   ǃ       ¢   ¢",
            "   ¸       ¢ááá¢",
            "   ǃ       à   ¢",
            "Ê¸żȊ       à   ¢",
            "           ¢   ¢",
            "           ¢   ¢",
            "           ¢   ¢",
            "           ¢¢¢¢¢",
            "           ¢   ¢",
            "           ¢   ¢",
            "           ¢   ¢",
            "¢¢áá¢¢¢¢áá¢    ¢",
            "    à     ¢    ¢",
            "    à     ¢    ¢",
            "    à     ¢    ¢",
            "¢¢¢¢¢¢¢¢¢¢¢¢¢¢¢¢"
        ],
        [
            "ËËËƸËËËËËËË¢ËËË¢",
            "ËËË¸ËËËËËËË¢¢¢¢Í",
            "ËËËƸËËËËËËË¢   ¢",
            "¸¸ŶȋËËËËËËË¢   ¢",
            "ËËËËËËËËËËË¢   ¢",
            "ËËËËËËËËËËË¢   ¢",
            "ËËËËËËËËËËË¢   ¢",
            "ËËËËËËËËËËË¢¢¢¢¢",
            "ËËËËËËËËËËË¢ËËË¢",
            "ËËËËËËËËËËË¢ËËË¢",
            "ËËËËËËËËËËË¢ËËË¢",
            "¢¢¢¢¢¢¢¢¢¢¢ËËËË¢",
            "ËËËË¢ËËËËË¢ËËËË¢",
            "ËËËË¢ËËËËË¢ËËËË¢",
            "ËËËË¢ËËËËË¢ËËËË¢",
            "¢¢¢¢Í¢¢¢¢¢Í¢¢¢¢¢"
        ],
        [
            "¡¡¡¡¡¡¡¡¡¡¡¡¡¡¡¡",
            "¡¡¡¡¡¡¡¡¡¡¡¡¡¡¡¡",
            "¡¡¡¸¡¡¡¡¡¡¡¡¡¡¡¡",
            "¡¡¸¸¡¡¡¡¡¡¡¡¡¡¡¡",
            "¡¡¡¡¡¡¡¡¡¡¡¡¡¡¡¡",
            "¡¡¡¡¡¡¡¡¡¡¡¡¡¡¡¡",
            "¡¡¡¡¡¡¡¡¡¡¡¡¡¡¡¡",
            "¡¡¡¡¡¡¡¡¡¡¡¡¡¡¡¡",
            "¡¡¡¡¡¡¡¡¡¡¡¡¡¡¡¡",
            "¡¡¡¡¡¡¡¡¡¡¡¡¡¡¡¡",
            "¡¡¡¡¡¡¡¡¡¡¡¡¡¡¡¡",
            "¡¡¡¡¡¡¡¡¡¡¡¡¡¡¡¡",
            "¡¡¡¡¡¡¡¡¡¡¡¡¡¡¡¡",
            "¡¡¡¡¡¡¡¡¡¡¡¡¡¡¡¡",
            "¡¡¡¡¡¡¡¡¡¡¡¡¡¡¡¡",
            "¡¡¡¡¡¡¡¡¡¡¡¡¡¡¡¡"
        ]
    ],
    "refpalette": "building004_palette"
}