{
    "xsize": 16,
    "zsize": 16,
    "slices": [
        [
            "¡¡¡¡¡¡¡¡¡¡¡¡¡¡¡¡",
            "¡¢¢££¢¢££¢¢££¢¢¡",
            "¡¢¢££¢¢££¢¢££¢¢¡",
            "¡££¢¢££¢¢££¢¢££¡",
            "¡££¢¢££¢¢££¢¢££¡",
            "¡¢¢££¢¢££¢¢££¢¢¡",
            "¡¢¢££¢¢££¢¢££¢¢¡",
            "¡££¢¢££¢¢££¢¢££¡",
            "¡££¢¢££¢¢££¢¢££¡",
            "¡¢¢££¢¢££¢¢££¢¢¡",
            "¡¢ ¤¤¤   ¤¤¤  ¢¡",
            "¡¢ ¥¥¥  ¤   ¤  ¡",
            "¡¢ ¥¥¥  ¤   ¤  ¡",
            "¡¢ ¥¥¥  ¤   ¤  ¡",
            "¡¢¢¤¤¤   ¤¤¤   ¡",
            "¡¡¡¡¡¡¡¡¡¡¡¡¡¡¡¡"
        ],
        [
            "¡¡¡¡¡¡¡¡¡¡¡¡¡¡¡¡",
            "¡¦§¨¦§¨¦§¨© © ©¡",
            "¡¦ª¨¦ª¨¦ª¨ «   ¡",
            "¡ ¬  ® ¯®     °¡",
            "¡±   ² ®    ³ ³¡",
            "¡´´¨   º   µµµµ¡",
            "¡  ¨   ¶    ·¸·¡",
            "¡¹             ¡",
            "¡´´            ¡",
            "¡ »» »»»»» »»» ¡",
            "¡¼¤¤½¤¤¤¤¤½¤¤¤¾¡",
            "¡¤¤   ¤ ¤   ¤¤¤¡",
            "¡ ¤   ¤ ¤   ¿  ¡",
            "¡ ¤ À ¤ ¤   ¤  ¡",
            "¡ Á¤¤¤   ¤¤¤   ¡",
            "¡¡¡¡¡¡¡¡¡¡¡¡¡¡¡¡"
        ],
        [
            "¡¡¡¡¡¡¡¡¡¡¡¡¡¡¡¡",
            "¡¦ ¨¦ ¨¦ ¨     ¡",
            "¡¦ ¨¦ ¨  ¨     ¡",
            "¡ Â            ¡",
            "¡          Ã Ä ¡",
            "¡´´¨       µµµµ¡",
            "¡ÅÆ¨       Ç È ¡",
            "¡É             ¡",
            "¡´´            ¡",
            "¡ »» »»»»» »»» ¡",
            "¡¼¤¤Ê¤¤¤¤¤Ê¤¤¤¾¡",
            "¡¤¤   ¤ ¤   ¤ ¤¡",
            "¡ ¤   ¤ ¤   Ë  ¡",
            "¡ ¤ À ¤ ¤   ¤  ¡",
            "¡  ¤¤¤   ¤¤¤   ¡",
            "¡¡¡¡¡¡¡¡¡¡¡¡¡¡¡¡"
        ],
        [
            "¡¡¡¡¡¡¡¡¡¡¡¡¡¡¡¡",
            "¡              ¡",
            "¡              ¡",
            "¡              ¡",
            "¡           Ì Ì¡",
            "¡           µµµ¡",
            "¡Í          Î Î¡",
            "¡              ¡",
            "¡              ¡",
            "¡ »»»»»»»»»»»» ¡",
            "¡¼¤¤¤¤¤¤¤¤¤¤¤¤¾¡",
            "¡¤¤   ¤ ¤   ¤ ¤¡",
            "¡ ¤   ¤ ¤   ¤  ¡",
            "¡ ¤ À ¤ ¤   ¤  ¡",
            "¡  ¤¤¤   ¤¤¤   ¡",
            "¡¡¡¡¡¡¡¡¡¡¡¡¡¡¡¡"
        ],
        [
            "¡¡¡¡¡¡¡¡¡¡¡¡¡¡¡¡",
            "¡              ¡",
            "¡              ¡",
            "¡              ¡",
            "¡              ¡",
            "¡              ¡",
            "¡              ¡",
            "¡              ¡",
            "¡              ¡",
            "¡ »»»»»»»»»»»» ¡",
            "¡¼¤¤¤¤¤¤¤¤¤¤¤¤¾¡",
            "¡¤¤   ¤ ¤   ¤ ¤¡",
            "¡ ¤   ¤ ¤   ¤  ¡",
            "¡ ¤ À ¤ ¤   ¤  ¡",
            "¡  ¤¤¤   ¤¤¤   ¡",
            "¡¡¡¡¡¡¡¡¡¡¡¡¡¡¡¡"
        ],
        [
            "ÏÏÏÏÏÏÏÏÏÏÏÏÏÏÏÏ",
            "ÏÐÐÐÐÐÐÐÐÐÐÐÐÐÐÏ",
            "ÏÐÑÑÑÑÑÑÑÑÑÑÑÑÐÏ",
            "ÏÐÑÑÑÑÑÑÑÑÑÑÑÑÐÏ",
            "ÏÐÑÑÑÑÑÑÑÑÑÑÑÑÐÏ",
            "ÏÐÑÑÑÑÑÑÑÑÑÑÑÑÐÏ",
            "ÏÐÑÑÑÑÑÑÑÑÑÑÑÑÐÏ",
            "ÏÐÑÑÑÑÑÑÑÑÑÑÑÑÐÏ",
            "ÏÐÑÑÑÑÑÑÑÑÑÑÑÑÐÏ",
            "ÏÐÐÐÐÐÐÐÐÐÐÐÐÐÐÏ",
            "ÏÐÏ¤¤¤ÏÏÏ¤¤¤ÏÏÐÏ",
            "ÏÐ¤   ¤Ï¤   ¤ÏÐÏ",
            "ÏÐ¤   ¤Ï¤   ¤ÏÐÏ",
            "ÏÐ¤ À ¤Ï¤   ¤ÏÐÏ",
            "ÏÐÐ¤¤¤¤ÐÐ¤¤¤ÐÐÐÏ",
            "ÏÏÏÏÏÏÏÏÏÏÏÏÏÏÏÏ"
        ]
    ],
    "refpalette": "building001_palette"
}