{
    "xsize": 16,
    "zsize": 16,
    "slices": [
        [
            "¡¡¡¡¢¤¤¤¤¤¤¤¤¤¤¤",
            "¡¡¡¡¢¤¤¤¤¤¤¤¤¤¤¤",
            "¡¡¡¡¢¤¤¤¤¤¤¤¤¤¤¤",
            "¡¡¡¡¢¤¤¤£¤¤¤¤¤¤¤",
            "¡¡¡¡¢¤¤¤¤¤¤¤¤¤¤¤",
            "¡¡¡¡¢¤¤¤¤¤¤¤¤¤¤¤",
            "¡¡¡¡¢¤¤¤¤¤¤£¤¤¤¤",
            "¡¡¡¡¢¤¤¤¤¤¤¤¤¤¤¤",
            "¡¡¡¡¢¤¤¤¤¤¤¤¤¤¤¤",
            "¡¡¡¡¢¤¤¤¤¤¤¤¤¤¤¤",
            "¡¡¡¡¢¤¤¤¤¤¤¤¤¤¤¤",
            "¡¡¡¡¢¤¤¤¤¤¤¤¤¤¤¤",
            "¡¡¡¡¢¤¤¤¤¤¤¤¤¤¤¤",
            "¡¡¡¡¢¤¤¤¤¤¤¤¤¤¤¤",
            "¡¡¡¡¢±±±±±±±±±±±",
            "¡¡¡¡¢±±±±±±±±±±±"
        ],
        [
            "     §§©©§ §©§©§",
            "       §§§  §§§§",
            "     §§  §§  §  ",
            "        ²§§§§ © ",
            "     §  §§§§§ § ",
            "     §¨§¨§§§³  §",
            "     §¨©§¨§²§§§§",
            "      §©§§§§§§  ",
            "      §§§  §§°§ ",
            "       § §§§ §§ ",
            "       §§©§§  §§",
            "        ¨´©§  ©©",
            "       §©©§  §§§",
            "        § µ   § ",
            "                ",
            "                "
        ],
        [
            "       ¬¬   ¬ ¬ ",
            "                ",
            "                ",
            "        ²¶·¸¹º¬ ",
            "        ¶·¸·¸¹¹ ",
            "        ·¸·¶·¸¸ ",
            "       ¬¸·¶²¶··¶",
            "       ¬¹¸·¶·¸¸ ",
            "        º¹¸·¸¹¹ ",
            "         º¹¸¹º  ",
            "         ¬      ",
            "          ¬   ¬¬",
            "        ¬¬      ",
            "                ",
            "                ",
            "                "
        ],
        [
            "                ",
            "                ",
            "        ¶       ",
            "       ¶²¶      ",
            "        ¶ ¸·¸  ¸",
            "         ¸·¶·¸¸·",
            "         ·¶²¶··¶",
            "         ¸·¶·¸¸·",
            "          ¸·¸  ¸",
            "                ",
            "                ",
            "                ",
            "                ",
            "                ",
            "                ",
            "                "
        ],
        [
            "                ",
            "       ¸·¸      ",
            "      ¸·¶·¸     ",
            "      ·¶²¶·     ",
            "      ¸·¶·¸     ",
            "       ¸·¸ ¶    ",
            "          ¶²¶  ¶",
            "           ¶    ",
            "                ",
            "                ",
            "                ",
            "                ",
            "                ",
            "                ",
            "                ",
            "                "
        ],
        [
            "                ",
            "                ",
            "        ¶       ",
            "       ¶²¶      ",
            "        ¶ ¸·¸   ",
            "         ¸·¶·¸  ",
            "         ·¶²¶·  ",
            "         ¸·¶·¸  ",
            "          ¸·¸   ",
            "                ",
            "                ",
            "                ",
            "                ",
            "                ",
            "                ",
            "                "
        ]
    ],
    "refpalette": "building007_palette"
}