{
    "xsize": 16,
    "zsize": 16,
    "slices": [
        [
            "                ",
            " ¾¾  ¿     ¿ ¾¾ ",
            " ¾À¤À»»Àº¤À»»À¾Á",
            "  »ÔÔÔÔÔÔÔÔ££££¾",
            " È»ÔÔÔÔÔÔÔÔ£   Ç",
            "  ÀÔÔÔÔÔÔÔÔ£   Ç",
            "  ¤ÔÔÔÔÔÔÔÔ£   Ç",
            "  ºÔÔÔÔÔÔÔÔ££££¾",
            "  ÀÔÔÔÔÔÔÔÔ££££¾",
            "  »ÔÔÔÔÔÔÔÔ££££Ç",
            " È»ÔÔÔÔÔÔÔÔ££££Ç",
            "  ÀÔÔÔÔÔÔÔÔ££¥£Ç",
            "  ¤ÔÔÔÔÔÔÔÔ££££¾",
            " ¾À»»À¤ºÀ»»À¤À¾Á",
            " ¾¾ Ï     Ï  ¾¾ ",
            "                "
        ],
        [
            "                ",
            " ¾¾ ¿     ¿  ¾¾ ",
            " ¾»À»»Àº¤À»»À»¾Á",
            "  ÀÂ óôóó ¨»»®»¾",
            "  »        £   Ç",
            " È»õ    ö  ©   Ç",
            "  À        £   Ç",
            "  ¤÷ ³øøù  »»»»¾",
            "  ºú  ôó  û»»»»¾",
            "  À        £   Ç",
            "  »õ       °   Ç",
            " È»        £ ¥ Ç",
            "  Àü±øøýø  »»»»¾",
            " ¾»À»»À¤ºÀ»»À»¾Á",
            " ¾¾  Ï     Ï ¾¾ ",
            "                "
        ],
        [
            "                ",
            " ¾¾¿     ¿   ¾¾ ",
            " ¾»»»Àº¤À»»Àº»¾Á",
            "  º  ôóóô  »»·»¾",
            "  À        £   Ç",
            "  »        ¶   Ç",
            " È»        £   Ç",
            "  À   ýø   »»»»¾",
            "  ¤   óó  þ»»»»¾",
            "  º        £   Ç",
            "  À        ¸   Ç",
            "  »        £ ¥ Ç",
            " È»  ýøøø  »»»»¾",
            " ¾»ºÀ»»À¤ºÀ»»»¾Á",
            " ¾¾   Ï     Ï¾¾ ",
            "                "
        ],
        [
            "                ",
            " ¾¾     ¿    ¾¾ ",
            " ¾À»Àº¤À»»Àº¤º¾Á",
            "  ¤   ú ÿ  »»»»¾",
            "  º        £   Ç",
            "  À        £   Ç",
            "  »        £   Ç",
            " È»    Ā   »»»»¾",
            "  À        »»»»¾",
            "  ¤        £   Ç",
            "  º        £   Ç",
            "  À        £ ¥ Ç",
            "  »  ā Ă   »»»»¾",
            " ¾À¤ºÀ»»À¤ºÀ»º¾Á",
            " ¾¾    Ï     ¾¾ ",
            "                "
        ],
        [
            "                ",
            " ¾¾    ¿     ¾¾ ",
            " ¾ÀÀº¤À»»Àº¤ÀÀ¾Á",
            "  À        ¤¤¤¤¾",
            "  ¤        ¤   Ç",
            "  º        ¤   Ç",
            "  À        ¤   Ç",
            "  »        ¤¤¤¤¾",
            " È»        ¤¤¤¤¾",
            "  À        ¤   Ç",
            "  ¤        ¤   Ç",
            "  º        ¤ ¥ Ç",
            "  À        ¤¤¤¤¾",
            " ¾ÀÀ¤ºÀ»»À¤ºÀÀ¾Á",
            " ¾¾     Ï    ¾¾ ",
            "                "
        ],
        [
            "                ",
            " ¾¾   ¿     ¿¾¾ ",
            " ¾Àº¤À»»Àº¤À»À¾Á",
            " È»ÔÔÔÔÔÔÔÔ»»»»¾",
            "  ÀÔÔÔÔÔÔÔÔ»   Ç",
            "  ¤ÔÔÔÔÔÔÔÔ»   Ç",
            "  ºÔÔÔÔÔÔÔÔ»   Ç",
            "  ÀÔÔÔÔÔÔÔÔ»»»»¾",
            "  »ÔÔÔÔÔÔÔÔ»»»»¾",
            " È»ÔÔÔÔÔÔÔÔ»   Ç",
            "  ÀÔÔÔÔÔÔÔÔ»   Ç",
            "  ¤ÔÔÔÔÔÔÔÔ» ¥ Ç",
            "  ºÔÔÔÔÔÔÔÔ»»»»¾",
            " ¾À»À¤ºÀ»»À¤ºÀ¾Á",
            " ¾¾Ï     Ï   ¾¾ ",
            "                "
        ]
    ],
    "refpalette": "building002_palette"
}