{
    "xsize": 16,
    "zsize": 16,
    "slices": [
        [
            "££   ££  ££   ££",
            "££çççççççççççç££",
            " ç   ¥»¼½º»¼½ºç ",
            " ç   ¥¼½º»¼½º»ç ",
            " ç   ¥½º»¼½º»¼ç ",
            "£ç¥¥¥¥º»¼½º»¼½ç£",
            "£ç»¼½º»¼½º»¼½ºç£",
            " ç¼½º»¼½º»¼½º»ç ",
            " ç½º»¼½º»¼½º»¼ç ",
            "£çº»¼½º»¼½º»¼½ç£",
            "£ç»¼½º»¼½º»¼½ºç£",
            " ç¼»º»¼½º»¼½º»ç ",
            " ç½º»¼½º»¼½º»¼ç ",
            " çº»¼½º»¼½º»¼½ç ",
            "££çççççççççççç££",
            "££   ££  ££   ££"
        ],
        [
            "££èèè££èè££èèè££",
            "££çççççççççççç££",
            "èç   ¥ éê    ëçè",
            "èç   §      Æìçè",
            "èç   ¥    í î çè",
            "£ç¥¨¥¥      ï ç£",
            "£çð          ëç£",
            "èç ñ ò      óôçè",
            "èçõ ö     í ÷ çè",
            "£çø         ï ç£",
            "£ç ù         ëç£",
            "èç ú ò  ª   óìçè",
            "èçû ö     í ü çè",
            "èçø    ýþ  ´ ôçè",
            "££çççççççççççç££",
            "££èèè££èè££èèè££"
        ],
        [
            "££ÿÿÿ££ÿÿ££ÿÿÿ££",
            "££ÜÜÜççÜÜççÜÜÜ££",
            "ÿÝ   ¥        Ýÿ",
            "ÿÝ   µ        Ýÿ",
            "ÿÝ   ¥        Ýÿ",
            "£ç¥¶¥¥        ç£",
            "£ç            ç£",
            "ÿÝ            Ýÿ",
            "ÿÝ            Ýÿ",
            "£ç            ç£",
            "£ç            ç£",
            "ÿÝ            Ýÿ",
            "ÿÝ            Ýÿ",
            "ÿÝ      Ā     Ýÿ",
            "££ÜÜÜççÜÜççÜÜÜ££",
            "££ÿÿÿ££ÿÿ££ÿÿÿ££"
        ],
        [
            "££ÿÿÿ££ÿÿ££ÿÿÿ££",
            "££āāāççāāççāāā££",
            "ÿā   ¥ ØØ  ØØ āÿ",
            "ÿā   ¥       Ùāÿ",
            "ÿā   ¥       Ùāÿ",
            "£ç¥¥¥¥        ç£",
            "£ç            ç£",
            "ÿāÚ          Ùāÿ",
            "ÿāÚ          Ùāÿ",
            "£ç            ç£",
            "£ç            ç£",
            "ÿāÚ          Ùāÿ",
            "ÿāÚ          Ùāÿ",
            "ÿā ÛÛ  ÛÛ  ÛÛ āÿ",
            "££āāāççāāççāāā££",
            "££ÿÿÿ££ÿÿ££ÿÿÿ££"
        ],
        [
            "££èèè££èè££èèè££",
            "££çççççççççççç££",
            "èç   ¥        çè",
            "èç   ¥        çè",
            "èç   ¥     Ă  çè",
            "£ç¥¥¥¥        ç£",
            "£ç            ç£",
            "èç  Ă         çè",
            "èç         Ă  çè",
            "£ç            ç£",
            "£ç            ç£",
            "èç  Ă         çè",
            "èç         Ă  çè",
            "èç            çè",
            "££çççççççççççç££",
            "££èèè££èè££èèè££"
        ],
        [
            "££ÿÿÿ££ÿÿ££ÿÿÿ££",
            "££ÜÜÜççÜÜççÜÜÜ££",
            "ÿÝ   ¥ÞßßßßßßàÝÿ",
            "ÿÝ   ¥áââââââãÝÿ",
            "ÿÝ   ¥áââââââãÝÿ",
            "£ç¥¥¥¥áââââââãç£",
            "£çÞßßßâââââââãç£",
            "ÿÝáââââââââââãÝÿ",
            "ÿÝáââââââââââãÝÿ",
            "£çáââââââââââãç£",
            "£çáââââââââââãç£",
            "ÿÝáââââââââââãÝÿ",
            "ÿÝáââââââââââãÝÿ",
            "ÿÝäååååååååååæÝÿ",
            "££ÜÜÜççÜÜççÜÜÜ££",
            "££ÿÿÿ££ÿÿ££ÿÿÿ££"
        ]
    ],
    "refpalette": "building006_palette"
}