{
    "xsize": 16,
    "zsize": 16,
    "slices": [
        [
            "¡¡¡¡¡¡¡¡¡¡¡¡¡¡¡¡",
            "¡ÍÍÍÍÍÍÍÍ¡¡¡¡¡¡¡",
            "¡ÍÍÍÍÍÍÍÍ¡¡¡¡¡¡¡",
            "¡ÍÍÍÍÍÍÍÍ¡¡¡¡¡¡¡",
            "¡ÍÍÍÍª«ÍÍ¡¡¡¡¡¡¡",
            "¡ÍÍÍÍª«ÍÍÍÍÍÍÍÍÍ",
            "¡ÍÍÍÍÍÍÍÍÍÍÍÍÍÍÍ",
            "¡ÍÍÍÍÍÍÎÏÏÏÏÏÏêÏ",
            "¡¡¡¡¡ÍÍÐ      ëì",
            "¡¡¡¡¡ÍÍÐ      ëì",
            "¡¡¡¡¡ÍÍÐ  íîîîïì",
            "¡¡¡¡¡ÍÍÐ  ëììììì",
            "¡¡¡¡¡ÍÍÐ  ëìÀ¸¸À",
            "¡¡¡¡¡ÍÍÐ  ëì¸ººº",
            "¡¡¡¡¡ÍÍðîîñì¸ººº",
            "¡¡¡¡¡ÍÍÐììììÃººº"
        ],
        [
            "¢¢¢¢¢¢¢¢¢¢¢¢¢¢¢¢",
            "¢        ¢ÑÒÅÓ ¢",
            "¢ ¬      ¢ §   ¢",
            "¢        ¢     ¢",
            "¢    ª«  ¢¢¢¢Ô¢¢",
            "¢  Õ ª«         ",
            "¢               ",
            "¢      Ö××××××ò ",
            "¢¢¢¢¢  Ø      ó¬",
            "¢   ¢  Ø      ó ",
            "¢Ù  Ú  Ø  Öôôôõ ",
            "¢Û  ¢  Ø  ó     ",
            "¢Ü§ ¢  Ø  ó öÀ¸÷",
            "¢Ý  ¢  Ø  ó Ã   ",
            "¢¢¢¢¢  ø××õ ÊÛ  ",
            "¢   ¢       Ê¨ ´"
        ],
        [
            "¢¢¢¢¢¢¢¢¢¢¢¢¢¢¢¢",
            "¢        ¢     à",
            "¢        ¢     à",
            "¢        ¢     à",
            "¢    ª«  ¢ááâã¢¢",
            "¢    ª«         ",
            "¢               ",
            "¢               ",
            "¢¢¢¢¢           ",
            "¢   ¢           ",
            "¢   ä           ",
            "¢   å           ",
            "¢   à       ù¹úû",
            "¢   à       ·   ",
            "¢ááá¢       Ê   ",
            "¢   ¢       Ê   "
        ],
        [
            "¢¢¢¢¢¢¢¢¢¢¢¢¢¢¢¢",
            "¢        ¢     à",
            "¢        ¢     à",
            "¢        ¢     à",
            "¢    ª«  ¢áá¢¢¢¢",
            "¢    ª«         ",
            "¢               ",
            "¢               ",
            "¢¢¢¢¢           ",
            "¢   ¢           ",
            "¢   ¢           ",
            "¢   ¢           ",
            "¢   à       üÀ¸¹",
            "¢   à       Ã   ",
            "¢ááá¢       ¸   ",
            "¢   ¢       Ê   "
        ],
        [
            "¢¢¢¢¢¢¢¢¢Í¢¢¢¢¢Í",
            "¢ËËËËËËËË¢ËËËËË¢",
            "¢ËËËËËËËË¢ËËËËË¢",
            "¢ËËËËËËËË¢ËËËËË¢",
            "¢ËËËËª«ËË¢¢¢¢¢¢¢",
            "¢ËËËËª«ËËËËËËËËË",
            "¢ËËËËËËËËËËËËËËË",
            "¢ËËËËËËËËËËËËËËË",
            "¢¢¢¢¢ËËËËËËËËËËË",
            "¢ËËË¢ËËËËËËËËËËË",
            "¢ËËË¢ËËËËËËËËËËË",
            "¢ËËË¢ËËËËËËËËËËË",
            "¢ËËË¢ËËËËËËËý¹¸À",
            "¢ËËË¢ËËËËËËË·ËËË",
            "Í¢¢¢¢ËËËËËËË¸ËËË",
            "¢ËËË¢ËËËËËËË¸ËËË"
        ],
        [
            "¡¡¡¡¡¡¡¡¡¡¡¡¡¡¡¡",
            "¡¡¡¡¡¡¡¡¡¡¡¡¡¡¡¡",
            "¡¡¡¡¡¡¡¡¡¡¡¡¡¡¡¡",
            "¡¡¡¡¡¡¡¡¡¡¡¡¡¡¡¡",
            "¡¡¡¡¡ª«¡¡¡¡¡¡¡¡¡",
            "¡¡¡¡¡ª«¡¡¡¡¡¡¡¡¡",
            "¡¡¡¡¡¡¡¡¡¡¡¡¡¡¡¡",
            "¡¡¡¡¡¡¡¡¡¡¡¡¡¡¡¡",
            "¡¡¡¡¡¡¡¡¡¡¡¡¡¡¡¡",
            "¡¡¡¡¡¡¡¡¡¡¡¡¡¡¡¡",
            "¡¡¡¡¡¡¡¡¡¡¡¡¡¡¡¡",
            "¡¡¡¡¡¡¡¡¡¡¡¡¡¡¡¡",
            "¡¡¡¡¡¡¡¡¡¡¡¡¸¸¡¡",
            "¡¡¡¡¡¡¡¡¡¡¡¡¸¡¡¡",
            "¡¡¡¡¡¡¡¡¡¡¡¡¡¡¡¡",
            "¡¡¡¡¡¡¡¡¡¡¡¡¡¡¡¡"
        ]
    ],
    "refpalette": "building004_palette"
}