{
    "xsize": 16,
    "zsize": 16,
    "slices": [
        [
            "ĀĀĀĀĀĀþþþþþþþþþþ",
            "ĀĀĀĀĀĀþþþþþþþþþþ",
            "ĀĀĀĀĀĀþþþþþþþþþþ",
            "ĀĀĀĀĀĀþþþþþþþþþþ",
            "ĀĀĀĀĀĀþþþþþþþþþþ",
            "ĀĀĀĀĀĀþþþþþþþþþþ",
            "ĀĀĀĀĀĀþþþþþþþþþþ",
            "ĀĀĀĀĀĀþþþþþþþþþþ",
            "ĀĀĀĀĀĀþþþþþþþþþþ",
            "ĀĀĀĀĀĀþþþþþþþþþþ",
            "ĀĀĀĀĀĀþþþþþþþþþþ",
            "ÿÿÿÿÿÿþþþþþþþþþþ",
            "þþþþþþþþþþþþþþþþ",
            "þþþþþþþþþþþþþþþþ",
            "þþþþþþþþþþþþþþþþ",
            "þþþþþþþþþþþþþþþþ"
        ],
        [
            " ¬              ",
            "   Ȍ            ",
            "ĔĔĔĔĔ           ",
            "   ǡ            ",
            " ȍ              ",
            "   Ȍ            ",
            "ĔĔĔĔĔ           ",
            "   ǡ            ",
            "     ´          ",
            "   Ȍ            ",
            "ĔĔĔĔĔ           ",
            "ƣƣƣƣƣȎ          ",
            "                ",
            "                ",
            "                ",
            "                "
        ],
        [
            "                ",
            "                ",
            "                ",
            "                ",
            "                ",
            "                ",
            "                ",
            "                ",
            "                ",
            "                ",
            "                ",
            "                ",
            "                ",
            "                ",
            "                ",
            "                "
        ],
        [
            "                ",
            "                ",
            "                ",
            "                ",
            "                ",
            "                ",
            "                ",
            "                ",
            "                ",
            "                ",
            "                ",
            "                ",
            "                ",
            "                ",
            "                ",
            "                "
        ],
        [
            "                ",
            "                ",
            "                ",
            "                ",
            "                ",
            "                ",
            "                ",
            "                ",
            "                ",
            "                ",
            "                ",
            "                ",
            "                ",
            "                ",
            "                ",
            "                "
        ],
        [
            "                ",
            "                ",
            "                ",
            "                ",
            "                ",
            "                ",
            "                ",
            "                ",
            "                ",
            "                ",
            "                ",
            "                ",
            "                ",
            "                ",
            "                ",
            "                "
        ]
    ],
    "refpalette": "building004_palette"
}