{
    "xsize": 16,
    "zsize": 16,
    "slices": [
        [
            "£££££££££££££££¡",
            "£££££££££££££££¡",
            "£££££££££££££££¡",
            "££££££££££££££¬¡",
            "£££££££££££££££¡",
            "£££££££££££££££¡",
            "£££££££££££££££¡",
            "£££££££££££££££¡",
            "£££££££££££££££¡",
            "£££££££££££££££¡",
            "£££££££££££££££¡",
            "£££££££££££££££¡",
            "£££££££££££££££¡",
            "£££££££££££££££¡",
            "£££££££££££££££¡",
            "¢¡¢¢¢¡¢¢¢¡¢¢¢¡¡¡"
        ],
        [
            "ººªƸ      ƛƝİİǵ¢",
            "ººº¸      ƛƝİİƷ¢",
            "ººº¸  µ®  ƛƝİİǵ¢",
            "Ŷ¸¸Ƹ      ƛƝ   ¢",
            "      µ®  ƛƝǶ Ƿ¢",
            "    ¬     ƛƝ  Ǹ¢",
            " ©        ƛƝ ǹǺ¢",
            " ®    µ®  ƛƝ ǻǹ¢",
            " ° §      ƛƝ ǼǺ¢",
            "      µ®  ƛƝ  ǽ¢",
            "  ±       ƛƝ   ¢",
            "      ´   ƛƝ   ¢",
            "          ƞǾǿƠƠ¢",
            "               ¢",
            "               ¢",
            "ŷŸŷŷŷŸŷŷŷŸŷŷŷŸ¢¢"
        ],
        [
            "Ǆ ªǃ      ƽȀ   ¢",
            "   ¸      ƹ    ¢",
            "Ǆ  ¸      ƺ    ¢",
            "ż¸¸ż       ƾ   ¢",
            "       Ż  ƽ    ¢",
            "          ƹ    ¢",
            "          ƺȁ  Ǽ¢",
            " ź            ǹ¢",
            "          ƽƾ   ¢",
            "          ƹ¼   ¢",
            "          ƺ    ¢",
            "               ¢",
            "          Ȃȃ ȂȄ¢",
            "               ¢",
            "               ¢",
            "ŸŷŸŸŸŷŸŸŸŷŸŸŸŷ¢¢"
        ],
        [
            "Ǆ ªƸ      ǆ   Ǉ¢",
            "   ¸      ǆ   Ǉ¢",
            "Ǆ  ¸      ǆ   Ǉ¢",
            "Ŷ¸¸Ƹ      ǆ    ¢",
            "          ǆ    ¢",
            "          ǆ    ¢",
            "          ǆ    ¢",
            "          ǆ    ¢",
            "          ǆ    ¢",
            "          ǆ    ¢",
            "          ǆ    ¢",
            "          ǆ    ¢",
            "          ǆǆǆǆǆ¢",
            "               ¢",
            "               ¢",
            "ŷŸŷŷŷŸŷŷŷŸŷŷŷŸ¢¢"
        ],
        [
            "Ǆ ªǃ          ǈ¢",
            "   ¸          ǈ¢",
            "Ǆ  ¸          ȅ¢",
            "ÊÊÊż           ¢",
            "               ¢",
            "               ¢",
            "               ¢",
            "               ¢",
            "               ¢",
            "               ¢",
            "               ¢",
            "               ¢",
            "               ¢",
            "               ¢",
            "               ¢",
            "ŸŷŸŸŸŷŸŸŸŷŸŸŸŷ¢¢"
        ],
        [
            "  ªƸ     ËËËËËË¢",
            "   ¸     ËËËËËË¢",
            "  Ì¸     ËËËËËË¢",
            "ÊÊÊƸ     ËËËËËË¢",
            "         ËËËËËË¢",
            "         ËËËËËË¢",
            "         ËËËËËË¢",
            "         ËËËËËË¢",
            "         ËËËËËË¢",
            "ËËËËËËËËËËËËËËË¢",
            "ËËËËËËËËËËËËËËË¢",
            "ËËËËËËËËËËËËËËË¢",
            "ËËËËËËËËËËËËËËË¢",
            "ËËËËËËËËËËËËËËË¢",
            "ËËËËËËËËËËËËËËË¢",
            "ŷŸŷŷŷŸŷŷŷŸŷŷŷŸ¢¢"
        ]
    ],
    "refpalette": "building004_palette"
}