{
    "xsize": 16,
    "zsize": 16,
    "slices": [
        [
            "¤¤¤¤¤¤¤¤¤¤¤¢¡¡¡¡",
            "¤¤¤¤¤¤¤¤¤¤¤¢¡¡¡¡",
            "¤¤¤¤¤¤¤¤¤¤¤¢¡¡¡¡",
            "¤¤¤££££££££¢¡¡¡¡",
            "¤¤¤££££££££¢¡¡¡¡",
            "¤¤¤££££££££¢¡¡¡¡",
            "¤¤¤££££££££¢¡¡¡¡",
            "¤¤¤££££££££¢¡¡¡¡",
            "¤¤¤££££££££¢¡¡¡¡",
            "¤¤¤££££££££¢¡¡¡¡",
            "¤¤¤££££££££¢¡¡¡¡",
            "¢¢¢¢¢¢¢¢¢¢¢¢¡¡¡¡",
            "¡¡¡¡¡¡¡¡¡¡¡¡¡¡¡¡",
            "¡¡¡¡¡¡¡¡¡¡¡¡¡¡¡¡",
            "¡¡¡¡¡¡¡¡¡¡¡¡¡¡¡¡",
            "¡¡¡¡¡¡¡¡¡¡¡¡¡¡¡¡"
        ],
        [
            "¼§ §³  §§©§     ",
            " § ¨§©§§ §§     ",
            "³§§¨Í§  §       ",
            "©©§¥¥¥¥¥¥¥¥¥¥¥¥ ",
            "§§§¥¦¦¦¦¦¦¦¦¦¦¥ ",
            "§¨§¥¦¦¦¦¦¦¦¦¦¦¥ ",
            "§§§¥¦¦¦¦¦¦¦¦¦¦¥ ",
            "§§§¥¦¦¦¦¦¦¦¦¦¦¥ ",
            "§§©¥¦¦¦¦¦¦¦¦¦¦¥ ",
            "©§§¥¦¦¦¦¦¦¦¦¦¦¥ ",
            "§  ¥¦¦¦¦¦¦¦¦¦¦¥ ",
            "   ¥¦¦¦¦¦¦¦¦¦¦¥ ",
            "   ¥¦¦¦¦¦¦¦¦¦¦¥ ",
            "   ¥¥¥¥¥¥¥¥¥¥¥¥ ",
            "                ",
            "                "
        ],
        [
            "¸        ¬      ",
            "     ¬          ",
            "                ",
            "¬¬              ",
            "    ªªªªªªª«««  ",
            "    ªªªªªªªªª«  ",
            "    ªªªªªªªªª«  ",
            "    ªªªªªªªªª«  ",
            "  ¬ ªªªªªªªªª«  ",
            "¬   ªªªªªªªªª«  ",
            "    ªªªªªª ªª«  ",
            "    ªªªªªªª«ª«  ",
            "    ªªªªªªªª««  ",
            "                ",
            "                ",
            "                "
        ],
        [
            "                ",
            "                ",
            "                ",
            "    «««««««««   ",
            "    «««««««««   ",
            "    «       «   ",
            "    «       «   ",
            "    «       «   ",
            "    «       «   ",
            "    «       «   ",
            "    «       «   ",
            "    «««««««««   ",
            "    «««««««««   ",
            "                ",
            "                ",
            "                "
        ],
        [
            "                ",
            "                ",
            "                ",
            "   «««««««««    ",
            "   ««      ««   ",
            "   ««      ««   ",
            "   ««      ««   ",
            "   ««      ««   ",
            "   ««      ««   ",
            "   ««      ««   ",
            "    «««««  ««   ",
            "    «««««««««   ",
            "                ",
            "                ",
            "                ",
            "                "
        ],
        [
            "                ",
            "                ",
            "   ««««««««     ",
            "   «««««««««    ",
            "   «       «    ",
            "   «       «    ",
            "   «       «    ",
            "   «       «    ",
            "   «       «    ",
            "   «       «    ",
            "   «««««««««    ",
            "    ««««««««    ",
            "                ",
            "                ",
            "                ",
            "                "
        ]
    ],
    "refpalette": "building007_palette"
}