{
    "xsize": 16,
    "zsize": 16,
    "slices": [
        [
            "¡¡¡¡¡¡¡¡¡¡¡¡¡¡¡¡",
            "¡¢¢¢¢¢¢¢¢¢¢¢¢¢¢¡",
            "¡¢¢¢¢¢¢¢¢¢¢¢¢¢¢¡",
            "¡¢¢¢¢¢¢¢¢¢¢££££¡",
            "¡¢¢¢¢¢¢¢¢¢¢£   £",
            "¡¢¢¢¢¢¢¢¢¢¢£   ¤",
            "¡¢¢¢¢¢¢¢¢¢¢£   £",
            "¡¢¢¢¢¢¢¢¢¢¢££££¡",
            "¡¢¢¢¢¢¢¢¢¢¢££££¡",
            "¡¢¢¢¢¢¢¢¢¢¢£££££",
            "¡¢¢¢¢¢¢¢¢¢¢£££££",
            "¡¢¢¢¢¢¢¢¢¢¢££¥££",
            "¡¢¢¢¢¢¢¢¢¢¢££££¡",
            "¡¢¢¢¢¢¢¢¢¢¢¢¢¢¢¡",
            "¡¢¢¢¢¢¢¢¢¢¢¢¢¢¢¡",
            "¡¡¡¡¡¡¡¡¡¡¡¡¡¡¡¡"
        ],
        [
            "¡¡¡¡¡¡¡¡¡¡¡¡¡¡¡¡",
            "¡ ¦§¨¦§    ©   ¡",
            "¡ ª§ ª§«   £  ¬¡",
            "¡ §§ §§    ££®£¡",
            "¡          £   £",
            "¡   ¯      °   ¤",
            "¡ §§ §§    £   £",
            "¡ ª§ ª§«   ££££¡",
            "¡±²§ ²§    ££££¡",
            "¡§§§§§§§   £   £",
            "¡ ´ ´ ´    ©   £",
            "¡          £ ¥ £",
            "¡   ³      ££££¡",
            "¡          ©   ¡",
            "¡ µ µ µ    £  ¬¡",
            "¡¡¡¡¡¡¡¡¡¡¡¡¡¡¡¡"
        ],
        [
            "¡¡¡¡¡¡¡¡¡¡¡¡¡¡¡¡",
            "¡  §  §    ¶   ¡",
            "¡  §  §    £   ¡",
            "¡ §§ §§    ££·£¡",
            "¡          £   £",
            "¡          ¸   ¤",
            "¡ §§ §§    £   £",
            "¡  §  §    ££££¡",
            "¡  §  §    ££££¡",
            "¡§§§§§§§   £   £",
            "¡          ¶   £",
            "¡          £ ¥ £",
            "¡          ££££¡",
            "¡          ¶   ¡",
            "¡          £   ¡",
            "¡¡¡¡¡¡¡¡¡¡¡¡¡¡¡¡"
        ],
        [
            "¡¡¡¡¡¡¡¡¡¡¡¡¡¡¡¡",
            "¡          £   ¡",
            "¡      ¹   £   ¡",
            "¡          ££££¡",
            "¡          £   £",
            "¡          £   ¤",
            "¡          £   £",
            "¡      ¹   ££££¡",
            "¡          ££££¡",
            "¡§§§§§§§   £   £",
            "¡          £   £",
            "¡          £ ¥ £",
            "¡          ££££¡",
            "¡          £   ¡",
            "¡          £   ¡",
            "¡¡¡¡¡¡¡¡¡¡¡¡¡¡¡¡"
        ],
        [
            "¡¡¡¡¡¡¡¡¡¡¡¡¡¡¡¡",
            "¡          £   ¡",
            "¡          £   ¡",
            "¡          ££££¡",
            "¡          £   £",
            "¡          £   ¤",
            "¡          £   £",
            "¡          ££££¡",
            "¡          ££££¡",
            "¡          £   £",
            "¡          £   £",
            "¡          £ ¥ £",
            "¡          ££££¡",
            "¡          £   ¡",
            "¡          £   ¡",
            "¡¡¡¡¡¡¡¡¡¡¡¡¡¡¡¡"
        ],
        [
            "¡¡¡¡¡¡¡¡¡¡¡¡¡¡¡¡",
            "¡º»»»»»»»»»»»»»¡",
            "¡º»»»»»»»»ººººº¡",
            "¡º»»»»»»»»º¤¤¤¤¤",
            "¡º»»»»»»»»º¤   ¤",
            "¡º»»»»»»»»º¤   ¤",
            "¡º»»»»»»»»º¤   ¤",
            "¡º»»»»»»»»º¤¤¤¤¤",
            "¡º»»»»»»»»º££££¡",
            "¡º»»»»»»»»º£   £",
            "¡º»»»»»»»»º£   £",
            "¡º»»»»»»»»º£ ¥ £",
            "¡º»»»»»»»»º££££¡",
            "¡º»»»»»»»»ººººº¡",
            "¡º»»»»»»»»»»»»»¡",
            "¡¡¡¡¡¡¡¡¡¡¡¡¡¡¡¡"
        ]
    ],
    "refpalette": "building002_palette"
}