{
    "xsize": 16,
    "zsize": 16,
    "slices": [
        [
            "                ",
            "îîîîîîîîîîîîîîǫ ",
            "ĢĢĢĢĢĢĢĢĢĢĢĢĢĢÐ ",
            "ĢĢĢĢĢġġġġġġĢĢĢÐ ",
            "ĢĢĢĢĢġĹ    ġĢĢÐ ",
            "ĢĢĢĢĢĢġġġġġĢĢĢÐ ",
            "ĢĢĢĢĢĢĢĢĢĢĢĢĢĢÐ ",
            "ĢĢĢĢĢĢĢĢĢĢĢĢĢĢÐ ",
            "ĢĢĢĢĢĢĢĢĢĢĢĢĢĢÐ ",
            "ĢĢĢĢĢĢĢĢĢĢĢĢĢĢÐ ",
            "ĢĢĢĢĢĢĢĢĢĢĢĢĢĢÐ ",
            "ĢĢĢĢĢĢĢĢĢĢĢĢĢĢÐ ",
            "ĢĢĢĢĢĢĢĢĢĢĢĢĢĢÐ ",
            "ĢĢĢĢĢĢĢĢĢĢĢĢĢĢÐ ",
            "ÏÏÏÏÏÏÏÏÏÏÏÏÏÏĻ ",
            "                "
        ],
        [
            "                ",
            "                ",
            "ĤĤĤĤĤĤĤĤĤĤĤĤĤĤ  ",
            "ĠĠĠĠĠĠĠĠĠĠĠĠĠĤ  ",
            "ģģģģģĹ     ģĠĤ  ",
            "ģģģģģģģģģģģģĠĤ  ",
            "ģģģģģģģģģģģģĠĤ  ",
            "ģģģģģģģģģģģģĠĤ  ",
            "ģģģģģģģģģģģģĠĤ  ",
            "ģģģģģģģģģģģģĠĤ  ",
            "ģģģģģģģģģģģģĠĤ  ",
            "ģģģģģģģģģģģģĠĤ  ",
            "ĠĠĠĠĠĠĠĠĠĠĠĠĠĤ  ",
            "ĤĤĤĤĤĤĤĤĤĤĤĤĤĤ  ",
            "                ",
            "                "
        ],
        [
            "                ",
            "                ",
            "                ",
            "ĂĂĂĂĂĂĂĂĂĂĂĂǬ   ",
            " Ĺ          Ć   ",
            "   ǭǭ       Ć   ",
            " ŹŹǭǭ       Ć   ",
            "ııŹŹ   Ǚ  ´ Ć   ",
            "ııŹŹ   Ǯ    Ć   ",
            "ııı    ǯ    Ć   ",
            "      ǰ ǰ   Ć   ",
            "       Ç  ¬ŭĆ   ",
            "ċċċċċċċċċċċċĳ   ",
            "                ",
            "                ",
            "                "
        ],
        [
            "                ",
            "                ",
            "                ",
            "ĴĴĴĴĴĴĴĴĴĴĴĴĴ   ",
            "Ĺ           Ĵ   ",
            "            Ĵ   ",
            "            Ĵ   ",
            "            Ĵ   ",
            "            Ĵ   ",
            "        ů   Ĵ   ",
            "            Ĵ   ",
            "            Ĵ   ",
            "ĴĴĴĴĴĴĴĴĴĴĴĴĴ   ",
            "                ",
            "                ",
            "                "
        ],
        [
            "                ",
            "                ",
            "                ",
            "îîîîîîîîîîîîǫ   ",
            "            Ð   ",
            "            Ð   ",
            "            Ð   ",
            "            Ð   ",
            "            Ð   ",
            "            Ð   ",
            "            Ð   ",
            "            Ð   ",
            "ÏÏÏÏÏÏÏÏÏÏÏÏĻ   ",
            "                ",
            "                ",
            "                "
        ],
        [
            "                ",
            "                ",
            "ìììììììììììììì  ",
            "ĠĠĠĠĠĠĠĠĠĠĠĠĠì  ",
            "  ĽĽļļĽĽļļĽĽĠì  ",
            "ļļĽĽļļĽĽļļĽĽĠì  ",
            "ĽĽļļĽĽļļĽĽļļĠì  ",
            "ĽĽļļĽĽļļĽĽļļĠì  ",
            "ļļĽĽļļĽĽļļĽĽĠì  ",
            "ļļĽĽļļĽĽļļĽĽĠì  ",
            "ĽĽļļĽĽļļĽĽļļĠì  ",
            "ĽĽļļĽĽļļĽĽļļĠì  ",
            "ĠĠĠĠĠĠĠĠĠĠĠĠĠì  ",
            "ìììììììììììììì  ",
            "                ",
            "                "
        ]
    ],
    "refpalette": "building004_palette"
}