{
    "xsize": 16,
    "zsize": 16,
    "slices": [
        [
            "                ",
            "  ĪĪĪĪĪøø       ",
            " īĝĝĝĝĝĝĝúúúúú  ",
            " īĝ¡¡¡¡¡¡¡¡ØØú  ",
            " īĝ¡¡¡¡¡¡¡¡¡¡ú  ",
            " īĝ¡¡¡¡¡¡¡¡¡¡ú  ",
            " īĝ¡¡¡¡¡¡¡¡¡¡ú  ",
            " øĝ¡¡¡¡¡¡¡¡¡¡ĝø ",
            " øĝ¡¡¡¡¡¡¡¡¡¡ĝø ",
            "  ú¡¡¡¡¡¡¡¡¡¡ĝĬ ",
            "  ú¡¡¡¡¡¡¡¡¡¡ĝĬ ",
            "  ú¡¡¡¡¡¡¡¡¡¡ĝĬ ",
            "  ú¡¡¡¡¡¡¡¡¡¡ĝĬ ",
            "  úúúúúĝĝĝĝĝĝĝĬ ",
            "       øøĭĭĭĭĭ  ",
            "                "
        ],
        [
            "                ",
            " ĘĘĘĘĘĘøø       ",
            " Ęĝĝĝĝĝĝĝċċċċċ  ",
            " ĘĝĮĮ      ØØċ  ",
            " ĘĝĮ  Ą  Ą   ċ  ",
            " Ęĝ          ċ  ",
            " Ęĝ   ¬  ½   ċ  ",
            " øĝį  į  į  įĝø ",
            " øĝ°İıâĲĳ°İıâĝø ",
            "  ċ°İıâĲĳ°İıâĝĘ ",
            "  ċ°İıâĲĳ°İıâĝĘ ",
            "  ċĴ  Ĵ  Ĵ  ĴĝĘ ",
            "  ċĵĵ   Ą  ĶĶĝĘ ",
            "  ċċċċċĝĝĝĝĝĝĝĘ ",
            "       øøĘĘĘĘĘĘ ",
            "                "
        ],
        [
            "                ",
            " Ěěěěěěøø       ",
            " Ĝķķķĝĝĝĝċċċċċ  ",
            " ĜķĮ       ØØċ  ",
            " Ĝķ          ċ  ",
            " Ĝĝ          ċ  ",
            " Ĝĝ          ċ  ",
            " øĝį  į  į  įĝø ",
            " øĝ°İıâĲĳ°İıâĝø ",
            "  ċ°İıâĲĳ°İıâĝĤ ",
            "  ċ°İıâĲĳ°İıâĝĤ ",
            "  ċĴ  Ĵ  Ĵ  ĴķĤ ",
            "  ċ         ĶķĤ ",
            "  ċċċċċĝĝĝĝķķķĤ ",
            "       øøĨĨĨĨĨĩ ",
            "                "
        ],
        [
            "                ",
            "     ĪĪøø       ",
            "  ķķķĝĝĝĝċċċċċ  ",
            "  ķ   ĸĹ   ØØċ  ",
            "  ķ          ċ  ",
            " īĝ          ċ  ",
            " īĝ          ċ  ",
            " øĝį  į  į  įĝø ",
            " øĝ°İıâĲĳ°İıâĝø ",
            "  ċ°İıâĲĳ°İıâĝĬ ",
            "  ċ°İıâĲĳ°İıâĝĬ ",
            "  ċĴ  Ĵ  Ĵ  Ĵķ  ",
            "  ċ          ķ  ",
            "  ċċċċċĝĝĝĝķķķ  ",
            "       øøĭĭ     ",
            "                "
        ],
        [
            "                ",
            " ĺĻĻĻĻĻøø       ",
            " ļķķķĝĝĝĝċċċċċ  ",
            " ļķ        ØØċ  ",
            " ļķ          ċ  ",
            " ļĝ          ċ  ",
            " ļĝ          ċ  ",
            " øĝ          ĝø ",
            " øĝĽ  Ľ  Ľ  Ľĝø ",
            "  ċĽ  Ľ  Ľ  Ľĝľ ",
            "  ċĽ  Ľ  Ľ  Ľĝľ ",
            "  ċ          ķľ ",
            "  ċ          ķľ ",
            "  ċċċċċĝĝĝĝķķķľ ",
            "       øøĿĿĿĿĿŀ ",
            "                "
        ],
        [
            "                ",
            " ŁŁŁŁŁŁøø       ",
            " Łĝĝĝĝĝĝĝúúúúú  ",
            " ŁĝĞğğğğğğĠØØú  ",
            " ŁĝġĢĢĢĢĢĢĢğĠú  ",
            " ŁĝġĢĢĢĢĢĢĢĢģú  ",
            " ŁĝġĢĢĢĢĢĢĢĢģú  ",
            " øĝġĢĢĢĢĢĢĢĢģĝø ",
            " øĝġĢĢĢĢĢĢĢĢģĝø ",
            "  úġĢĢĢĢĢĢĢĢģĝŁ ",
            "  úġĢĢĢĢĢĢĢĢģĝŁ ",
            "  úġĢĢĢĢĢĢĢĢģĝŁ ",
            "  úĥĦĦĦĦĦĦĦĦħĝŁ ",
            "  úúúúúĝĝĝĝĝĝĝŁ ",
            "       øøŁŁŁŁŁŁ ",
            "                "
        ]
    ],
    "refpalette": "building005_palette"
}