{
    "xsize": 16,
    "zsize": 16,
    "slices": [
        [
            "                ",
            " ¾¾¿¿¿¿¿¿¿¿¿¿¾¾ ",
            " ¾ÀÀÀÀÀÀÀÀÀÀÀÀ¾Á",
            " ÈÀÔÔÔÔÔÔÔÔ££££¾",
            " ÈÀÔÔÔÔÔÔÔÔ£   Ç",
            " ÈÀÔÔÔÔÔÔÔÔ£   Ç",
            " ÈÀÔÔÔÔÔÔÔÔ£   Ç",
            " ÈÀÔÔÔÔÔÔÔÔ££££¾",
            " ÈÀÔÔÔÔÔÔÔÔ££££¾",
            " ÈÀÔÔÔÔÔÔÔÔ££££Ç",
            " ÈÀÔÔÔÔÔÔÔÔ££££Ç",
            " ÈÀÔÔÔÔÔÔÔÔ££¥£Ç",
            " ÈÀÔÔÔÔÔÔÔÔ££££¾",
            " ¾ÀÀÀÀÀÀÀÀÀÀÀÀ¾Á",
            " ¾¾ÏÏÏÏÏÏÏÏÏÏ¾¾ ",
            "                "
        ],
        [
            "                ",
            " ¾¾          ¾¾ ",
            " ¾ºÇÇÇÇÇÇÇÇÇÇº¾Á",
            "  Çă      Ą»»®»¾",
            "  Ç  ą Ć   £   Ç",
            "  Ç ćĈ     ©   Ç",
            "  Ç   ßßß  £   Ç",
            "  Ç³ĉ ßßß ¬»»»»¾",
            "  Ç Ċ ßßß  »»»»¾",
            "  Ç ċ ßßß  £   Ç",
            "  Ç  ČčĎ   °   Ç",
            "  Ç  ď Đđ  £ ¥ Ç",
            "  ÇĒ      ē»»»»¾",
            " ¾ºÇÇÇÇÇÇÇÇÇÇº¾Á",
            " ¾¾          ¾¾ ",
            "                "
        ],
        [
            "                ",
            " ¾¾          ¾¾ ",
            " ¾ºÇÇÇÇÇÇÇÇÇÇº¾Á",
            "  Ç        »»·»¾",
            "  Ç        £   Ç",
            "  Ç        ¶   Ç",
            "  Ç        £   Ç",
            "  Ç        »»»»¾",
            "  Ç        »»»»¾",
            "  Ç        £   Ç",
            "  Ç        ¸   Ç",
            "  Ç        £ ¥ Ç",
            "  Ç        »»»»¾",
            " ¾ºÇÇÇÇÇÇÇÇÇÇº¾Á",
            " ¾¾          ¾¾ ",
            "                "
        ],
        [
            "                ",
            " ¾¾          ¾¾ ",
            " ¾ºÇÇÇÇÇÇÇÇÇÇº¾Á",
            "  Ç        »»»»¾",
            "  Ç        £   Ç",
            "  Ç        £   Ç",
            "  Ç        £   Ç",
            "  Ç        »»»»¾",
            "  Ç        »»»»¾",
            "  Ç        £   Ç",
            "  Ç        £   Ç",
            "  Ç        £ ¥ Ç",
            "  Ç        »»»»¾",
            " ¾ºÇÇÇÇÇÇÇÇÇÇº¾Á",
            " ¾¾          ¾¾ ",
            "                "
        ],
        [
            "                ",
            " ¾¾¿¿¿¿¿¿¿¿¿¿¾¾ ",
            " ¾ºººººººººººº¾Á",
            " Èº        ¤¤¤¤¾",
            " Èº        ¤   Ç",
            " Èº        ¤   Ç",
            " Èº        ¤   Ç",
            " Èº        ¤¤¤¤¾",
            " Èº        ¤¤¤¤¾",
            " Èº        ¤   Ç",
            " Èº        ¤   Ç",
            " Èº        ¤ ¥ Ç",
            " Èº        ¤¤¤¤¾",
            " ¾ºººººººººººº¾Á",
            " ¾¾ÏÏÏÏÏÏÏÏÏÏ¾¾ ",
            "                "
        ],
        [
            "                ",
            " ¤¤¤¤¤¤¤¤¤¤¤¤¤¤ ",
            " ¤ÀÀÀÀÀÀÀÀÀÀÀÀ¤ ",
            " ¤ÀÔÔÔÔÔÔÔÔ»»»»¤",
            " ¤ÀÔÔÔÔÔÔÔÔ»   Ç",
            " ¤ÀÔÔÔÔÔÔÔÔ»   Ç",
            " ¤ÀÔÔÔÔÔÔÔÔ»   Ç",
            " ¤ÀÔÔÔÔÔÔÔÔ»»»»¤",
            " ¤ÀÔÔÔÔÔÔÔÔ»»»»¤",
            " ¤ÀÔÔÔÔÔÔÔÔ»   Ç",
            " ¤ÀÔÔÔÔÔÔÔÔ»   Ç",
            " ¤ÀÔÔÔÔÔÔÔÔ» ¥ Ç",
            " ¤ÀÔÔÔÔÔÔÔÔ»»»»¤",
            " ¤ÀÀÀÀÀÀÀÀÀÀÀÀ¤ ",
            " ¤¤¤¤¤¤¤¤¤¤¤¤¤¤ ",
            "                "
        ],
        [
            "                ",
            " ¾¾¾¾¾¾¾¾¾¾¾¾¾¾ ",
            " ¾»»»»»»»»»»»»¾ ",
            " ¾»ĔĔĔĔĔĔĔĔ¾¾¾¾ ",
            " ¾»ĔĔĔĔĔĔĔĔ¾   Á",
            " ¾»ĔĔĔĔĔĔĔĔ¾   Á",
            " ¾»ĔĔĔĔĔĔĔĔ¾   Á",
            " ¾»ĔĔĔĔĔĔĔĔ¾¾¾¾¾",
            " ¾»ĔĔĔĔĔĔĔĔ¾¾¾¾¾",
            " ¾»ĔĔĔĔĔĔĔĔ¾¾¾¾Á",
            " ¾»ĔĔĔĔĔĔĔĔ¾¾¾¾Á",
            " ¾»ĔĔĔĔĔĔĔĔ¾¾¥¾Á",
            " ¾»ĔĔĔĔĔĔĔĔ¾¾¾¾ ",
            " ¾»»»»»»»»»»»»¾ ",
            " ¾¾¾¾¾¾¾¾¾¾¾¾¾¾ ",
            "                "
        ],
        [
            "                ",
            " ĕĖĖĖĖĖĖĖĖĖĖĖĖė ",
            " Ę            ę ",
            " Ę         ĚĚ®Ě ",
            " Ę ě       À   Á",
            " Ę         °   Á",
            " Ę    Ĝ    À   Á",
            " Ę         ĚĚĚĚ¾",
            " Ę  ³     ĝĚĚĚĚ¾",
            " Ę         À   Á",
            " Ę         ©   Á",
            " Ę ě       À   Á",
            " Ę         ĚĚĚĚ ",
            " Ę            ę ",
            " ĞğğğğğğğğğğğğĠ ",
            "                "
        ],
        [
            "                ",
            "                ",
            "                ",
            "           ĚĚ·Ě ",
            "           À   Á",
            "           ¸   Á",
            "           À   Á",
            "           ĚĚĚĚ¾",
            "           ĚĚĚĚ¾",
            "           À   Á",
            "           ¶   Á",
            "           À   Á",
            "           ĚĚĚĚ ",
            "                ",
            "                ",
            "                "
        ],
        [
            "                ",
            "                ",
            "                ",
            "          ġĚĚĚĚ ",
            "           À   Á",
            "           À   Á",
            "           À   Á",
            "           ĚĚĚĚ¾",
            "           ĚĚĚĚ¾",
            "           À   Á",
            "           À   Á",
            "           À   Á",
            "          ġĚĚĚĚ ",
            "                ",
            "                ",
            "                "
        ],
        [
            "                ",
            "                ",
            "          ĢĢĢĢĢĢ",
            "          ĢĢĢĢĢĢ",
            "          ĢĢĢĢĢĢ",
            "          ĢĢĢĢĢĢ",
            "          ĢĢĢĢĢĢ",
            "          ĢĢĢĢĢĢ",
            "          ĢĢĢĢĢĢ",
            "          ĢĢĢĢĢĢ",
            "          ĢĢĢĢĢĢ",
            "          ĢĢĢĢĢĢ",
            "          ĢĢĢĢĢĢ",
            "          ĢĢĢĢĢĢ",
            "                ",
            "                "
        ]
    ],
    "refpalette": "building002_palette"
}