{
    "xsize": 16,
    "zsize": 16,
    "slices": [
        [
            "¡¡¢¢¢¢¢¢¢¢¢¢¢¤¤¡",
            "¡¡¢¢¢¢¢¢¢¢¢¢¢¤¤¡",
            "¡¡¢¢¢¢¢¢¢¢¢¢¢¢£¡",
            "¡¡¢¢¢¢¢¢¢¢¢¢¢¢¡¡",
            "¡¡¢¢¢¢¢¢¢¢¢¢¢¢¡¡",
            "¡¡¢¢¢¢¢¢¢¢¢¢¢¢¡¡",
            "¡¡¢¢¢¢¢¢¢¢¢¢¢¢¡¡",
            "¡¡¢¢¢¢¢¢¢¢¢¢¢¢¡¡",
            "¡¡¢¢¢¢¢¢¢¢¢¢¢¢¡¡",
            "¡¡¢¢¢¢¢¢¢¢¢¢¢¢¡¡",
            "¡¡¢¢¢¢¢¢¢¢¢¢¢¢¡¡",
            "¡¡¢¢¢¢¢¢¢¢¢¢¢¢¡¡",
            "¡¡¡¡¡¡¡¡¡¡¡¡¡¡¡¡",
            "¡¡¡¡¡¡¡¡¡¡¡¡¡¡¡¡",
            "¡¡¡¡¡¡¡¡¡¡¡¡¡¡¡¡",
            "¡¡¡¡¡¡¡¡¡¡¡¡¡¡¡¡"
        ],
        [
            "  ©û ü          ",
            "  ©     ý  ý    ",
            "  ©þ     ÿÿÿÿ¶¶ ",
            "  © Ā        µ¹ ",
            "  ©  ā       ©  ",
            "  © Ăă       ©  ",
            "  © ĂĄ ą     ©  ",
            "  © ĂĄ     Ć ©  ",
            "  © ĂĄ       ©  ",
            "  © ĂćĈĈĈĉĊ  ©  ",
            "  ©ċĊÿÿÿÿÿ  Č©  ",
            "   ¦à¨     à¦   ",
            "  čččččččččččč  ",
            "                ",
            "                ",
            "                "
        ],
        [
            "  ©  Ď          ",
            "  ©             ",
            "  ©          ¿¿ ",
            "  ©          µÀ ",
            "  ©          ©  ",
            "  ©          ©  ",
            "  ©          ©  ",
            "  ©          ©  ",
            "  ©          ©  ",
            "  ©          ©  ",
            "  ©          ©  ",
            "   ¦        ¦   ",
            "  čččččččččččč  ",
            "                ",
            "                ",
            "                "
        ],
        [
            "  ©             ",
            "  ©             ",
            "  ©          ¶¶ ",
            "  ©          µ¹ ",
            "  ©          ©  ",
            "  ©          ©  ",
            "  ©          ©  ",
            "  ©          ©  ",
            "  ©          ©  ",
            "  ©          ©  ",
            "  ©          ©  ",
            "   ¦        ¦   ",
            "  čččččččččččč  ",
            "                ",
            "                ",
            "                "
        ],
        [
            "  ©             ",
            "  ©             ",
            "  ©          ¿¿ ",
            "  ©          µÀ ",
            "  ©          ©  ",
            "  ©          ©  ",
            "  ©          ©  ",
            "  ©          ©  ",
            "  ©          ©  ",
            "  ©          ©  ",
            "  ©          ©  ",
            "   ¦     ď  ¦   ",
            "  čččččččččččč  ",
            "                ",
            "                ",
            "                "
        ],
        [
            "  ©          ¤¤ ",
            "  ©          ¿¿ ",
            "  ©          µÉ ",
            "  ©          µ¹ ",
            "  ©          ©  ",
            "  ©          ©  ",
            "  ©          ©  ",
            "  ©          ©  ",
            "  ©          ©  ",
            "  ©          ©  ",
            "  ©          ©  ",
            "   ¦        ¦   ",
            "  čččččččččččč  ",
            "                ",
            "                ",
            "                "
        ]
    ],
    "refpalette": "building003_palette"
}