{
    "xsize": 16,
    "zsize": 16,
    "slices": [
        [
            "                ",
            "                ",
            "îîîîîîîîîîîîîǫ  ",
            "ĢĢĢĢĢĢĢĢĢĢĢĢĢÐ  ",
            " ««ĢĢĢĢĢĢĢĢĢĢÐ  ",
            "«««ĢĢĢĢĢĢĢĢĢĢÐ  ",
            "«««ĢĢĢĢĢĢĢĢĢĢÐ  ",
            "«««ĢĢĢĢĢĢĢĢĢĢÐ  ",
            "«««ĢĢĢĢĢĢĢĢĢĢÐ  ",
            "«««ĢĢĢĢĢĢĢĢĢĢÐ  ",
            "«««ĢĢĢĢĢĢĢĢĢĢÐ  ",
            "«««ĢĢĢĢĢĢĢĢĢĢÐ  ",
            "ĢĢĢĢĢĢĢĢĢĢĢĢĢÐ  ",
            "ÏÏÏÏÏÏÏÏÏÏÏÏÏƫ  ",
            "                ",
            "                "
        ],
        [
            "                ",
            "                ",
            "ĂĂĂĂǬ           ",
            "ĴĴĴĴĆ           ",
            "   ĴĆ           ",
            "   ĴĆ           ",
            "   ĴĆ           ",
            "ŀǱŀĴĆ           ",
            "   ĴĆ           ",
            "   ĴĆ           ",
            "   ĴĆ           ",
            "ŀŀŀĴĆ           ",
            "ĴĴĴĴĆ           ",
            "ċċċċĳ           ",
            "                ",
            "                "
        ],
        [
            "                ",
            "                ",
            "ĤĤĤĤĤ           ",
            "ĠĠĠĠĤ           ",
            "   ĠĤ           ",
            "   ĠĤ           ",
            "   ĠĤ           ",
            "ŀǲŀĠĤ           ",
            "   ĠĤ           ",
            "   ĠĤ           ",
            "   ĠĤ           ",
            "ŀŀŀĠĤ           ",
            "ĠĠĠĠĤ           ",
            "ĤĤĤĤĤ           ",
            "                ",
            "                "
        ],
        [
            "                ",
            "                ",
            "ĤĤĤĤĤ           ",
            "ĴĴĴĴĤ           ",
            "   ĴĤ           ",
            "   ĴĤ           ",
            "   ĴĤ           ",
            "ŀŀŀĴĤ           ",
            "«««ĴĤ           ",
            "«««ĴĤ           ",
            "«««ĴĤ           ",
            "ŀŀŀĴĤ           ",
            "ĴĴĴĴĤ           ",
            "ĤĤĤĤĤ           ",
            "                ",
            "                "
        ],
        [
            "                ",
            "                ",
            "ĤĤĤĤĤ           ",
            "ĴĴĴĴĤ           ",
            "   ĴĤ           ",
            "   ĴĤ           ",
            "   ĴĤ           ",
            "ŀŀŀĴĤ           ",
            "   ĴĤ           ",
            "   ĴĤ           ",
            "   ĴĤ           ",
            "ŀŀŀĴĤ           ",
            "ĴĴĴĴĤ           ",
            "ĤĤĤĤĤ           ",
            "                ",
            "                "
        ],
        [
            "                ",
            "                ",
            "ììììì           ",
            "ĠĠĠĠì           ",
            "ōŎŎĠì           ",
            "ōŎŎĠì           ",
            "ŎōōĠì           ",
            "ŀŀŀĠì           ",
            "   Ġì           ",
            "   Ġì           ",
            "   Ġì           ",
            "ŀŀŀĠì           ",
            "ĠĠĠĠì           ",
            "ììììì           ",
            "                ",
            "                "
        ]
    ],
    "refpalette": "building004_palette"
}