{
    "xsize": 16,
    "zsize": 16,
    "slices": [
        [
            "þþÿºººººººººÿĀĀĀ",
            "þþÿºººººººººÿĀĀĀ",
            "þþÿºººººººººÿĀĀĀ",
            "þþÿºººººººººÿĀĀĀ",
            "þþÿºººººººººÿĀĀĀ",
            "þþÿºººººººººÿĀĀĀ",
            "þþÿºººººººººÿĀĀĀ",
            "þþÿººº¬ºººººÿĀĀĀ",
            "þþÿºººººººººÿĀĀĀ",
            "þþÿºººººººººÿĀĀĀ",
            "þþÿºººººººººÿĀĀĀ",
            "þþÿºººººººººÿÿÿÿ",
            "þþÿÿÿÿÿÿÿÿÿÿÿþþþ",
            "þþþþþþþþþþþþþþþþ",
            "þþþþþþþþþþþþþþþþ",
            "þþþþþþþþþþþþþþþþ"
        ],
        [
            "  ăƓ ´     ƓĆ   ",
            "  ăƔƕ     čƔĆ Ɩ ",
            "  ăƗ  Ƙƙƚ  ƗĆĔĔĔ",
            "  ăƓ  ƛƜƝ  ƓĆ ĕ ",
            "  ă¬ƕ ƛƛƝ čƔĆ   ",
            "  ăƗ  ƛƛƝ  ƗĆ Ɩ ",
            "  ăƓ  ƛƛƝ  ƓĆĔĔĔ",
            "  ăƔƕ ƛƞƝ č¬Ć ĕ ",
            "  ăƗ  ƟƠơ  ƗĆ   ",
            "  ă´     ´  Ć Ɩ ",
            "  ă ĉĊ   ĉĊ ĆĔĔĔ",
            "  ăųÇÂŵ ųÂÇŵĆƢƣƣ",
            "  Ĳċċċċċċċċċĳ   ",
            "                ",
            "                ",
            "                "
        ],
        [
            "  ëƓ       ƓÐ   ",
            "  ëƤƥ     ěƦÐ   ",
            "  ëƗ       ƗÐ   ",
            "  ëƓ   Ł   ƓÐ   ",
            "  ëƤƥ Ŝ   ěƦÐ   ",
            "  ëƗ    Ƨ  ƗÐ   ",
            "  ëƓ       ƓÐ   ",
            "  ëƤƥ     ěƦÐ   ",
            "  ëƗ  Ŝ ś  ƗÐ   ",
            "  ë         Ð   ",
            "  ë Ęę   Ęę Ð   ",
            "  ëųÂÇƨƩƪÇÂƨÐ   ",
            "  œÏÏÏÏÏÏÏÏÏƫ   ",
            "                ",
            "                ",
            "                "
        ],
        [
            "  ă         Ć   ",
            "  ăƬ       ƭĆ   ",
            "  ă         Ć   ",
            "  ă         Ć   ",
            "  ăƬ       ƭĆ   ",
            "  ă         Ć   ",
            "  ă         Ć   ",
            "  ăƬ       ƭĆ   ",
            "  ă         Ć   ",
            "  ă         Ć   ",
            "  ă         Ć   ",
            "  ă ƮƮ   ƮƮ Ć   ",
            "  łċċċċċċċċċĳ   ",
            "                ",
            "                ",
            "                "
        ],
        [
            "  ëÌ       ÌÐ   ",
            "  ëÌ       ÌÐ   ",
            "  ëÌ       ÌÐ   ",
            "  ëÌ       ÌÐ   ",
            "  ëÌ  şşş  ÌÐ   ",
            "  ëÌ  şşş  ÌÐ   ",
            "  ëÌ  şşş  ÌÐ   ",
            "  ëÌ       ÌÐ   ",
            "  ëÌ       ÌÐ   ",
            "  ëÌ       ÌÐ   ",
            "  ëÌ       ÌÐ   ",
            "  ëÌÌÌÌÌÌÌÌÌÐ   ",
            "  œÏÏÏÏÏÏÏÏÏĻ   ",
            "                ",
            "                ",
            "                "
        ],
        [
            " ìĠġġġġġġġġġĠì  ",
            " ìĠġġġġġġġġġĠì  ",
            " ìĠġġġġġġġġġĠì  ",
            " ìĠġġġġġġġġġĠì  ",
            " ìĠġġġġġġġġġĠì  ",
            " ìĠġġġġġġġġġĠì  ",
            " ìĠġġġġġġġġġĠì  ",
            " ìĠġġġġġġġġġĠì  ",
            " ìĠġġġġġġġġġĠì  ",
            " ìĠġġġġġġġġġĠì  ",
            " ìĠġġġġġġġġġĠì  ",
            " ìĠġġġġġġġġġĠì  ",
            " ìĠĠĠĠĠĠĠĠĠĠĠì  ",
            " ììììììììììììì  ",
            "                ",
            "                "
        ]
    ],
    "refpalette": "building004_palette"
}