{
    "xsize": 16,
    "zsize": 16,
    "slices": [
        [
            "                ",
            "  ĪĪĪĪĪøøøøøøøø ",
            " īĝĝĝĝĝĝĝúúúúúø ",
            " īĝ¡¡¡¡¡¡¡¡ØØúø ",
            " īĝ¡¡¡¡¡¡¡¡¡¡úø ",
            " īĝ¡¡¡¡¡¡¡¡¡¡úø ",
            " īĝ¡¡¡¡¡¡¡¡¡¡úø ",
            " øĝ¡¡¡¡¡¡¡¡¡¡ĝø ",
            " øĝ¡¡¡¡¡¡¡¡¡¡ĝø ",
            " øú¡¡¡¡¡¡¡¡¡¡ĝĬ ",
            " øú¡¡¡¡¡¡¡¡¡¡ĝĬ ",
            " øú¡¡¡¡¡¡¡¡¡¡ĝĬ ",
            " øú¡¡¡¡¡¡¡¡¡¡ĝĬ ",
            " øĝĝĝĝĝĝĝĝĝĝĝĝĬ ",
            " øøøøøøøøĭĭĭĭĭ  ",
            "                "
        ],
        [
            "                ",
            " ĘĘĘĘĘĘøø       ",
            " Ęĝĝĝĝĝĝĝċċċċċ  ",
            " Ęĝ        ØØċ  ",
            " Ęĝ    Ą     ċ  ",
            " Ęĝ  œ    œ  ċ  ",
            " Ęĝ  Ŕ Ŕ Ŕ Ŕ ċ  ",
            " øĝ     Ą    ĝø ",
            " øĝ  œ    œ  ĝø ",
            "  ċ ŕ ŕ ŕ ŕ  ĝĘ ",
            "  ċ¬         ĝĘ ",
            "  ċ± œ    œ  ĝĘ ",
            "  ċŉ Ŗ ŗŗ Ŗ ŉĝĘ ",
            "  ċċċċċĝĝĝĝĝĝĝĘ ",
            "       øøĘĘĘĘĘĘ ",
            "                "
        ],
        [
            "                ",
            " Řěěěěěøø       ",
            " Ĝķķķĝĝĝĝċċċċċ  ",
            " Ĝķ        ØØċ  ",
            " Ĝķ          ċ  ",
            " Ĝĝ          ċ  ",
            " Ĝĝ ř Ś śŚŜ  ċ  ",
            " øĝ          ĝø ",
            " øĝ          ĝø ",
            "  ċ ŝŚŜ ŞŚş  ĝĤ ",
            "  ċ          ĝĤ ",
            "  ċ          ķĤ ",
            "  ċ ř Šŗŗšŝ  ķĤ ",
            "  ċċċċċĝĝĝĝķķķĤ ",
            "       øøĨĨĨĨĨĩ ",
            "                "
        ],
        [
            "                ",
            "     ĪĪøø       ",
            "  ķķķĝĝĝĝċċċċċ  ",
            "  ķ        ØØċ  ",
            "  ķ          ċ  ",
            " īĝ          ċ  ",
            " īĝ          ċ  ",
            " øĝ          ĝø ",
            " øĝ          ĝø ",
            "  ċ          ĝĬ ",
            "  ċ          ĝĬ ",
            "  ċ          ķ  ",
            "  ċ          ķ  ",
            "  ċċċċċĝĝĝĝķķķ  ",
            "       øøĭĭ     ",
            "                "
        ],
        [
            "                ",
            " őĻĻĻĻĻøø       ",
            " ļķķķĝĝĝĝċċċċċ  ",
            " ļķ        ØØċ  ",
            " ļķ          ċ  ",
            " ļĝ          ċ  ",
            " ļĝ          ċ  ",
            " øĝ          ĝø ",
            " øĝ     Ţ    ĝø ",
            "  ċ          ĝľ ",
            "  ċ          ĝľ ",
            "  ċ          ķľ ",
            "  ċ          ķľ ",
            "  ċċċċċĝĝĝĝķķķľ ",
            "       øøĿĿĿĿĿŀ ",
            "                "
        ],
        [
            "                ",
            " ŁŁŁŁŁŁøø       ",
            " Łĝĝĝĝĝĝĝúúúúú  ",
            " ŁĝĞğğğğğğĠØØú  ",
            " ŁĝġĢĢĢĢĢĢĢğĠú  ",
            " ŁĝġĢĢĢĢĢĢĢĢģú  ",
            " ŁĝġĢĢĢĢĢĢĢĢģú  ",
            " øĝġĢĢĢĢĢĢĢĢģĝø ",
            " øĝġĢĢĢĢĢĢĢĢģĝø ",
            "  úġĢĢĢĢĢĢĢĢģĝŁ ",
            "  úġĢĢĢĢĢĢĢĢģĝŁ ",
            "  úġĢĢĢĢĢĢĢĢģĝŁ ",
            "  úĥĦĦĦĦĦĦĦĦħĝŁ ",
            "  úúúúúĝĝĝĝĝĝĝŁ ",
            "       øøŁŁŁŁŁŁ ",
            "                "
        ]
    ],
    "refpalette": "building005_palette"
}