{
    "xsize": 16,
    "zsize": 16,
    "slices": [
        [
            "¢¢£¢¢¢¡¢¢¢¡¡¡¡¡¡",
            "£££££££££££££££¡",
            "£££££££££££££££¡",
            "£££££££££££££££¡",
            "£££££££££££££££¡",
            "£££££££££££££££¡",
            "£££££££££££££££¡",
            "£££££££££££££££¡",
            "£££££££££££££££¡",
            "£££££££££££££££¡",
            "£££££££££££££££¡",
            "£££££££££££££££¡",
            "£££££££££££££££¡",
            "£££££££££££££££¡",
            "£££££££££££££££¡",
            "£££££££££££££££¡"
        ],
        [
            "¥¥¤¥¥¥¤¥¥¥¢¢¢¢¢¢",
            "          ƛƝİİƲ¢",
            "          ƛƝİİƳ¢",
            " ©  ´  ©  ƛƝİİƴ¢",
            " ®   ® ®  ƛƝİİƵ¢",
            " °   ° °  ƛƝİİƳ¢",
            "          ƛƝİİƴ¢",
            " © § ©    ƛƝİİƲ¢",
            " ®   ® ®  ƛƝİİƶ¢",
            " °   ° °  ƛƝİİƴ¢",
            "    ¬     ƛƝİİƵ¢",
            "          ƛƝİİƳ¢",
            "¹¸¸¹      ƛƝİİƴ¢",
            "ººº¸  µ®  ƛƝİİƷ¢",
            "ººº¸ §    ƛƝİİƶ¢",
            "ººªƸ  µ®¶ ƛƝİİƳ¢"
        ],
        [
            "¤¤¥¤¤¤¥¤¤¤¢¢¢¢¢¢",
            "          ƹ    ¢",
            "          ƺƻ   ¢",
            "              Ƽ¢",
            "          ƽƾ   ¢",
            "          ƹ   ƿ¢",
            "          ƺ   ǀ¢",
            "           ¼   ¢",
            "     Ż ¼  ƽ   ǁ¢",
            "          ƹ   ǂ¢",
            "          ƺ    ¢",
            "           ƾ   ¢",
            "À¸¸ǃ      ƽ   ǀ¢",
            "Ǆ  ¸      ƹ    ¢",
            "   ¸      ƺž  ǅ¢",
            "Ǆ ªǃ          ¿¢"
        ],
        [
            "¥¥¤¥¥¥¤¥¥¥¢¢¢¢¢¢",
            "          ǆ   Ǉ¢",
            "          ǆ   Ǉ¢",
            "          ǆ   Ǉ¢",
            "          ǆ    ¢",
            "          ǆ    ¢",
            "          ǆ    ¢",
            "          ǆ   Ǉ¢",
            "          ǆ   Ǉ¢",
            "          ǆ   Ǉ¢",
            "          ǆ    ¢",
            "          ǆ    ¢",
            "¹¸¸¹      ǆ    ¢",
            "Ǆ  ¸      ǆ    ¢",
            "   ¸      ǆ   Ǉ¢",
            "Ǆ ªƸ      ǆ   Ǉ¢"
        ],
        [
            "¤¤¥¤¤¤¥¤¤¤¢¢¢¢¢¢",
            "              ǈ¢",
            "              ǈ¢",
            "              ǈ¢",
            "              ǈ¢",
            "              ǈ¢",
            "              ǈ¢",
            "              ǈ¢",
            "              ǈ¢",
            "              ǈ¢",
            "              ǈ¢",
            "              ǈ¢",
            "ÊÊÊǃ          ǈ¢",
            "Ǆ  ¸          ǈ¢",
            "   ¸          ǈ¢",
            "Ǆ ªǃ          ǈ¢"
        ],
        [
            "¥¥¤¥¥¥¤¥¥¥¢¢¢¢¢¢",
            "ËËËËËËËËËËËËËËË¢",
            "ËËËËËËËËËËËËËËË¢",
            "ËËËËËËËËËËËËËËË¢",
            "ËËËËËËËËËËËËËËË¢",
            "ËËËËËËËËËËËËËËË¢",
            "ËËËËËËËËËËËËËËË¢",
            "         ËËËËËË¢",
            "         ËËËËËË¢",
            "         ËËËËËË¢",
            "         ËËËËËË¢",
            "         ËËËËËË¢",
            "ÊÊÊ¹     ËËËËËË¢",
            "  Ì¸     ËËËËËË¢",
            "   ¸     ËËËËËË¢",
            "  ªƸ     ËËËËËË¢"
        ]
    ],
    "refpalette": "building004_palette"
}