{
    "xsize": 16,
    "zsize": 16,
    "slices": [
        [
            "¡¡¢¡¡¡¢¡¡¡¡¡¡¡¡¡",
            "¡¡¡¡¡¡¡¡¡¡¡¡¡¡¡¡",
            "¡¡¡¡¡¡¡¡¡¡¡¡¡¡¡¡",
            "¡¡¡¡¡¡¡¡¡¡¡¡¡¡¡¡",
            "¡¡¡¡¡¡¡¡¡¡¡¡¡¡¡¡",
            "ÍÍÍÍÍÍÍÍÍÍÍ¡¡¡¡¡",
            "ÍÍÍÍÍÍÍÍÍÍÍ¡¡¡¡¡",
            "ÏÏÏÏÏÏÏÏƏÍÍ¡¡¡¡¡",
            "        ëÍÍ¡¡¡¡¡",
            "        ëÍÍ¡¡¡¡¡",
            "        ëÍÍ¡¡¡¡¡",
            "        ëÍÍ¡¡¡¡¡",
            "À¸¸ǃ    ëÍÍ¡¡¡¡¡",
            "ººº¸    ëÍÍ¡¡¡¡¡",
            "ººº¸    ëÍÍ¡¡¡¡¡",
            "ººªǃ    ëÍÍ¡¡¡¡¡"
        ],
        [
            "¢¢¢¢¢¢¢¢¢¢¢¢¢¢¢¢",
            "ÑÒÅÓ ¢ÑÒÅÓ ¢   ¢",
            " §   ¢ §  ǉ¢   ¢",
            "     ¢    Ǌ¢   ¢",
            "¢¢¢Ô¢¢¢¢¢Ô¢¢   ¢",
            "           ¢¢¢¢¢",
            "¬        Õ ¢  ǋ¢",
            "××××××××ò  ¢ §ǌ¢",
            "        ó  ¢  Ǎ¢",
            "        ó  ǎ  Ǐ¢",
            "        ó  ¢   ¢",
            "        ó  ¢¢¢¢¢",
            "¹¸¸¹    ó  ¢  ǋ¢",
            "ÅǐÅ¸    ó  ¢ §ǌ¢",
            "   ¸    ó  ¢  Ǎ¢",
            "  ªƸ    ó¬ ǎ  Ǐ¢"
        ],
        [
            "¢¢¢¢¢¢¢¢¢¢¢¢¢¢¢¢",
            "     à     ¢   ¢",
            "     à    ŝ¢   ¢",
            "     à    Ş¢   ¢",
            "ááâã¢¢ááâã¢¢   ¢",
            "           ¢¢¢¢¢",
            "           à   ¢",
            "           à   ¢",
            "           Ǒ   ¢",
            "           ǒ   ¢",
            "           ¢   ¢",
            "           ¢ááá¢",
            "À¸¸ǃ       à   ¢",
            " Ǔ ¸       à   ¢",
            "   ¸       Ǒ   ¢",
            "  ªǃ       ǒ   ¢"
        ],
        [
            "¢¢¢¢¢¢¢¢¢¢¢¢¢¢¢¢",
            "     à     ¢   ¢",
            "     à     ¢   ¢",
            "     à     ¢   ¢",
            "áá¢¢¢¢áá¢¢¢¢   ¢",
            "           ¢¢¢¢¢",
            "           à   ¢",
            "           à   ¢",
            "           ¢   ¢",
            "           ¢   ¢",
            "           ¢   ¢",
            "           ¢ááá¢",
            "¹¸¸¹       à   ¢",
            "   ¸       à   ¢",
            "   ¸       ¢   ¢",
            "  ªƸ       ¢   ¢"
        ],
        [
            "¢¢¢¢¢¢¢¢¢¢¢¢¢¢¢¢",
            "     ¢     ¢   ¢",
            "     ¢     ¢   ¢",
            "     ¢     ¢   ¢",
            "¢¢¢¢¢¢¢¢¢¢¢¢   ¢",
            "           ¢¢¢¢¢",
            "           ¢   ¢",
            "           ¢   ¢",
            "           ¢   ¢",
            "           ¢   ¢",
            "           ¢   ¢",
            "           ¢¢¢¢¢",
            "ÊÊ¸ǃ       ¢   ¢",
            "   ¸       ¢   ¢",
            "   ¸       ¢   ¢",
            "  ªǃ       ¢   ¢"
        ],
        [
            "¢¢¢¢¢¢¢¢¢¢¢¢¢¢¢¢",
            "ËËËËË¢ËËËËË¢ËËË¢",
            "ËËËËË¢ËËËËË¢ËËË¢",
            "ËËËËË¢ËËËËË¢ËËË¢",
            "¢¢¢¢¢¢¢¢¢¢¢¢ËËË¢",
            "ËËËËËËËËËËË¢¢¢¢¢",
            "ËËËËËËËËËËË¢ËËË¢",
            "         ËË¢ËËË¢",
            "         ËË¢ËËË¢",
            "         ËË¢ËËË¢",
            "         ËË¢ËËË¢",
            "         ËË¢¢¢¢¢",
            "ÊÊ¸¹     ËË¢ËËË¢",
            "ÌÌÌ¸     ËË¢ËËË¢",
            "ÌÌÌ¸     ËË¢ËËË¢",
            "ÌÌªƸ     ËË¢ËËË¢"
        ]
    ],
    "refpalette": "building004_palette"
}