{
    "xsize": 16,
    "zsize": 16,
    "slices": [
        [
            "   Ô¡ÕÐÖÖÐÕ¡Ô   ",
            " ×Ø¡¡¡¡¡¡¡¡¡¡Ø× ",
            " ¡ÐÐÐÐÐÐÐÐÐÐÐÐ¡ ",
            " ¦Ð¢¢¢¢¢¢¢¢¢¢Ð¨ ",
            " ØÐ¢¢¢¢¢¢¢¢¢¢ÐØ ",
            " ìÐ¢¢¢¢¢¢¢¢¢¢Ðì ",
            " ìÐ¢¢¢¢¢¢¢¢¢¢Ðì ",
            " ìÐ¢¢¢¢¢¢¢¢¢¢Ðì ",
            " ìÐ¢¢¢¢¢¢¢¢¢¢Ðì ",
            " ìÐ¢¢¢¢¢¢¢¢¢¢Ðì ",
            " ìÐ¤¤¤¤¤¤¤¤¤¤Ðì ",
            " Ø¤¥¥¥  ¤   ¤¤Ø ",
            " ¦¤¥¥¥  ¤   ¤ ¨ ",
            " ¡¤¥À¥  ¤   ¤ ¡ ",
            " ×Ø¤¤¤¤¤¤¤¤¤¤Ø× ",
            "   ´¡ÕÐææÐÕ¡´   "
        ],
        [
            "   Ô¡ÕÐÖÖÐÕ¡Ô   ",
            " ×Ø¡¡¡¡¡¡¡¡¡¡Ø× ",
            " ¡ĳĴĵĵĴĶĴķĸ ÚĹ¡ ",
            " ¦ĺ           ¨ ",
            " ØĻ    º     ļØ ",
            " ìĽ     ľľ  Ŀŀì ",
            " ì   ď ÜÞÞÜ  ļì ",
            " ì     ÜÝÞÜ   ì ",
            " ì      ŁŁ    ì ",
            " ì » »»»»» »» ì ",
            " ì¼¤½¤¤¤¤¤½¤¤¾ì ",
            " Ø¤   ¤ ¤   ¤¤Ø ",
            " ¦¤   ¤ ¤   ¿ ¨ ",
            " ¡¤ À ¤ ¤   ¤ ¡ ",
            " ×Ø¤¤¤¤¤¤¤¤¤¤Ø× ",
            "   ´¡ÕÐææÐÕ¡´   "
        ],
        [
            "   Ô¡ÕÐÖÖÐÕ¡Ô   ",
            " ×Ø¡¡¡¡¡¡¡¡¡¡Ø× ",
            " ¡łŃńńŅ ņŇ    ¡ ",
            " ¦            ¨ ",
            " Øň          ŉØ ",
            " ì           Ŋì ",
            " ì      ŊŊ   ŋì ",
            " ì      Ō Ō   ì ",
            " ì            ì ",
            " ì » »»»»» »» ì ",
            " ì¼¤Ê¤¤¤¤¤Ê¤¤¾ì ",
            " Ø¤   ¤ ¤   ¤¤Ø ",
            " ¦¤   ¤ ¤   Ë ¨ ",
            " ¡¤ À ¤ ¤   ¤ ¡ ",
            " ×Ø¤¤¤¤¤¤¤¤¤¤Ø× ",
            "   ´¡ÕÐææÐÕ¡´   "
        ],
        [
            "   Ô¡ÕÐÖÖÐÕ¡Ô   ",
            " ×Ø¡¡¡¡¡¡¡¡¡¡Ø× ",
            " ¡ ōōōōōōō    ¡ ",
            " ¦            ¨ ",
            " Ø            Ø ",
            " ì            ì ",
            " ì            ì ",
            " ì            ì ",
            " ì            ì ",
            " ì »»»»»»»»»» ì ",
            " ì¼¤¤¤¤¤¤¤¤¤¤¾ì ",
            " Ø¤   ¤ ¤   ¤¤Ø ",
            " ¦¤   ¤ ¤   ¤ ¨ ",
            " ¡¤ À ¤ ¤   ¤ ¡ ",
            " ×Ø¤¤¤¤¤¤¤¤¤¤Ø× ",
            "   ´¡ÕÐææÐÕ¡´   "
        ],
        [
            "   Ô¡ÕÐÖÖÐÕ¡Ô   ",
            " ×Ø¡¡¡¡¡¡¡¡¡¡Ø× ",
            " ¡            ¡ ",
            " ¦            ¨ ",
            " Ø            Ø ",
            " ì            ì ",
            " ì            ì ",
            " ì            ì ",
            " ì            ì ",
            " ì »»»»»»»»»» ì ",
            " ì¼¤¤¤¤¤¤¤¤¤¤¾ì ",
            " Ø¤   ¤ ¤   ¤¤Ø ",
            " ¦¤   ¤ ¤   ¤ ¨ ",
            " ¡¤ À ¤ ¤   ¤ ¡ ",
            " ×Ø¤¤¤¤¤¤¤¤¤¤Ø× ",
            "   ´¡ÕÐææÐÕ¡´   "
        ],
        [
            "   Ô¡ÕÐÖÖÐÕ¡Ô   ",
            " ×Ø¡¡¡¡¡¡¡¡¡¡Ø× ",
            " ¡ØØØØØØØØØØØØ¡ ",
            " ¦ØŎŎŎŎŎŎŎŎŎŎØ¨ ",
            " ØØŎŎŎŎŎŎŎŎŎŎØØ ",
            " ìØŎŎŎŎŎŎŎŎŎŎØì ",
            " ìØŎŎŎŎŎŎŎŎŎŎØì ",
            " ìØŎŎŎŎŎŎŎŎŎŏØì ",
            " ìØŎŎŎŎŎŎŎŎŎŎØì ",
            " ìØŎŎŎŎŎŎŎŎŎŎØì ",
            " ìØ¤¤¤¤¤¤¤¤¤¤Øì ",
            " Ø¤   ¤ ¤   ¤¤Ø ",
            " ¦¤   ¤ ¤   ¤ ¨ ",
            " ¡¤ À ¤ ¤   ¤ ¡ ",
            " ×Ø¤¤¤¤¤¤¤¤¤¤Ø× ",
            "   ´¡ÕÐææÐÕ¡´   "
        ]
    ],
    "refpalette": "building001_palette"
}