{
    "xsize": 16,
    "zsize": 16,
    "slices": [
        [
            "þþþþþþþþþþþþþþþþ",
            "þþþþþþþþþþþþþþþþ",
            "ÿÿÿÿÿÿÿÿÿÿÿÿÿÿþþ",
            "«««««««««««««ÿþþ",
            "«««««««««««««ÿþþ",
            "«««««««««««««ÿþþ",
            "«««««««««««««ÿþþ",
            "«««««««««««««ÿþþ",
            "«««««««««««««ÿþþ",
            "«««««««««««««ÿþþ",
            "«««««««««««««ÿþþ",
            "«««««««««««««ÿþþ",
            "«««««««««««««ÿþþ",
            "ÿÿÿÿÿÿþþþþþÿÿÿþþ",
            "ĀĀĀĀĀĀþþþþþþþþþþ",
            "ĀĀĀĀĀĀþþþþþþþþþþ"
        ],
        [
            "                ",
            "                ",
            "ĂĂĂĂĂĂĂĂĂĂĂĂĂǘ  ",
            "  Å  ē     ¬ēĆ  ",
            "   Ǚ         Ć  ",
            "´    ǚ   ǛÇǛ Ć  ",
            "   ǜ     ǝǞǝ Ć  ",
            "  ĬĬĬĬ   ǟ ǟ Ć  ",
            "   ııĬĬ      Ć  ",
            "   ııııı     Ć  ",
            "    ıŹŹıı    Ć  ",
            "     ŹŹŹŹ  ´ Ć  ",
            "ŭ ď   ŹŹŹŹ   Ć  ",
            "ċċċċċċĞ   ĞċċǠ  ",
            "ĔĔĔĔĔ           ",
            "   ǡ            "
        ],
        [
            "                ",
            "                ",
            "ėėėėėėėėėėėėėė  ",
            "             ė  ",
            "          ǢǛ ė  ",
            "        ǣǤǞǝ ė  ",
            "   ǥ     ǟ ǟ ė  ",
            "             ė  ",
            "             ė  ",
            "             ė  ",
            "             ė  ",
            "             ė  ",
            "             ė  ",
            "ėėėėėėĞ   Ğėėė  ",
            "                ",
            "                "
        ],
        [
            "                ",
            "                ",
            "ėėėėėėėėėėėėėė  ",
            "        ǦǧǧǨ ė  ",
            "         Ĺ ǟ ė  ",
            "       ǣǩǪ   ė  ",
            "             ė  ",
            "             ė  ",
            "             ė  ",
            "             ė  ",
            "             ė  ",
            "             ė  ",
            "             ė  ",
            "ėėėėėėĞ   Ğėėė  ",
            "                ",
            "                "
        ],
        [
            "                ",
            "                ",
            "îîîîîîîîîîîîîǔ  ",
            "ÌÌÌÌÌÌÌÌÌÌÌÌÌÐ  ",
            "        Ĺ   ÌÐ  ",
            "            ÌÐ  ",
            "            ÌÐ  ",
            "            ÌÐ  ",
            "    şş      ÌÐ  ",
            "    şş      ÌÐ  ",
            "            ÌÐ  ",
            "            ÌÐ  ",
            "ÌÌÌÌÌÌÌÌÌÌÌÌÌÐ  ",
            "ÏÏÏÏÏÏÏÏÏÏÏÏÏƫ  ",
            "                ",
            "                "
        ],
        [
            "                ",
            "ììììììììììììììì ",
            "ĠĠĠĠĠĠĠĠĠĠĠĠĠĠì ",
            "ġġġġġġġġġġġġġĠì ",
            "ġġġġġġ Ĺ   ġġĠì ",
            "ġġġġġġġġġġġġġĠì ",
            "ġġġġġġġġġġġġġĠì ",
            "ġġġġġġġġġġġġġĠì ",
            "ġġġġġġġġġġġġġĠì ",
            "ġġġġġġġġġġġġġĠì ",
            "ġġġġġġġġġġġġġĠì ",
            "ġġġġġġġġġġġġġĠì ",
            "ġġġġġġġġġġġġġĠì ",
            "ĠĠĠĠĠĠĠĠĠĠĠĠĠĠì ",
            "ììììììììììììììì ",
            "                "
        ]
    ],
    "refpalette": "building004_palette"
}