{
    "xsize": 16,
    "zsize": 16,
    "slices": [
        [
            "                ",
            " íîîîîîîîîîîîîîî",
            " ëĢĢĢĢĢĢĢĢĢĢĢĢĢĢ",
            " ëĢĢĢĢĢĢĢĢĢĢĢĢĢĢ",
            " ëĢĢĢĢĢĢĢĢĢĢĢĢĢĢ",
            " ëĢĢĢĢĢĢĢĢĢĢĢĢĢĢ",
            " ëĢĢĢĢĢĢĢĢĢĢĢĢĢĢ",
            " ëĢĢĢĢĢĢĢĢĢĢĢĢĢĢ",
            " ëĢĢĢĢĢĢĢĢĢĢĢĢĢĢ",
            " ëĢĢĢĢĢĢĢĢĢĢĢĢĢĢ",
            " ëĢĢĢĢĢĢĢĢĢĢĢĢĢĢ",
            " ëĢĢĢĢĢĢĢĢĢĢĢĢĢĢ",
            " ëĢĢĢĢĢĢĢĢĢĢĢĢĢĢ",
            " ëĢĢĢĢģģģĢĢĢĢĢĢĢ",
            " ëĢĢĢĢģģģĢĢĢĢĝÏÏ",
            " ëĢĢĢĢģģģĢĢĢĢÐ  "
        ],
        [
            "                ",
            "                ",
            "  ĤĤĤĤĤĤĤĤĤĤĤĤĤĤ",
            "  ĤĠĠĠĠĠĠĠĠĠĠĠĠĠ",
            "  ĤĠģģģģģģģģģģģģ",
            "  ĤĠģģģģģģģģģģģģ",
            "  ĤĠģģģģģģģģģģģģ",
            "  ĤĠģģģģģģģģģģģģ",
            "  ĤĠģģģģģģģģģģģģ",
            "  ĤĠģģģģģģģģģģģģ",
            "  ĤĠģģģģģģģģģģģģ",
            "  ĤĠģģģģģģģģģģģģ",
            "  ĤĠģģĤĤĤģģĠĠĠĠĠ",
            "  ĤĠģģ   ģģĠĤĤĤĤ",
            "  ĤĠģģ   ģģĠĤ   ",
            "  ĤĠĠÍ   ÍĠĠĤ   "
        ],
        [
            "                ",
            "                ",
            "                ",
            "   ğĂĂĂĂĂĂĂĂĂĂĂĂ",
            "   ă¬ĥĦħĥÅēÍē  ¬",
            "   ăĨ      ÐĈ   ",
            "   ăĩ ĪīĪ  ÍĈ ĬĬ",
            "   ăĭ ĥīĥ  Į ĬĬĬ",
            "   ă       į ĬĬĬ",
            "   ăą İİİ  ÍĈ  ı",
            "   ă  İİİ  ÐĈ  ´",
            "   ă      ´Íą   ",
            "   ă       đċċċċ",
            "   ă       Ć    ",
            "   ăÛ     ¬Ć    ",
            "   ĲċÍ   Íċĳ    "
        ],
        [
            "                ",
            "                ",
            "                ",
            "   ĴĴĴĴĴĴĴĴĴĴĴĴĴ",
            "   Ĵ ĵ     Í    ",
            "   Ĵ       Ć    ",
            "   Ĵ    Ķ  Í    ",
            "   Ĵ   Ķ   ķ    ",
            "   Ĵ       ĸ    ",
            "   Ĵ       Í    ",
            "   Ĵ       Ć    ",
            "   Ĵ       Í    ",
            "   Ĵ       ĴĴĴĴĴ",
            "   Ĵ       Ĵ    ",
            "   Ĵ       Ĵ    ",
            "   ĴĴÍ   ÍĴĴ    "
        ],
        [
            "                ",
            "                ",
            "                ",
            "   íîîîîîîîîîîîî",
            "   ë       Í   Ĺ",
            "   ë       Ð    ",
            "   ë       Í    ",
            "   ë       Ð    ",
            "   ë       Ð    ",
            "   ë       Í    ",
            "   ë       Ð    ",
            "   ë       Í    ",
            "   ë       ĝÏÏÏÏ",
            "   ë       Ð    ",
            "   ë       Ð    ",
            "   ĺÏÍ   ÍÏĻ    "
        ],
        [
            "                ",
            "                ",
            "  ìììììììììììììì",
            "  ìĠĠĠĠĠĠĠĠĠĠĠĠĠ",
            "  ìĠļļĽĽļļĽĽļļĹ ",
            "  ìĠļļĽĽļļĽĽļļĽĽ",
            "  ìĠĽĽļļĽĽļļĽĽļļ",
            "  ìĠĽĽļļĽĽļļĽĽļļ",
            "  ìĠļļĽĽļļĽĽļļĽĽ",
            "  ìĠļļĽĽļļĽĽļļĽĽ",
            "  ìĠĽĽļļĽĽļļĽĽļļ",
            "  ìĠĽĽļļĽĽļ ĽĽļļ",
            "  ìĠļļĽĽļļĽĠĠĠĠĠ",
            "  ìĠļļĽĽļļĽĠìììì",
            "  ìĠĽĽļļĽĽļĠì   ",
            "  ìĠĠĠĠĠĠĠĠĠì   "
        ]
    ],
    "refpalette": "building004_palette"
}