{
    "xsize": 16,
    "zsize": 16,
    "slices": [
        [
            "   Ô¡ÕÐÖÖÐÕ¡Ô   ",
            " ×Ø¡¡¡¡¡¡¡¡¡¡Ø× ",
            " ¡ÐÐÐÐÐÐÐÐÐÐÐÐ¡ ",
            " ¦ÐććĈĈććĈĈććÐ¨ ",
            " ¦ÐĈĈććĈĈććĈĈÐ¨ ",
            " ¦ÐĈĈććĈĈććĈĈÐ¨ ",
            " ¦ÐććĈĈććĈĈććÐ¨ ",
            " ØÐććĈĈććĈĈććÐØ ",
            " ØÐĈĈććĈĈććĈĈÐØ ",
            " ìÐĈĈććĈĈććĈĈÐì ",
            " ìÐ¤¤¤¤¤¤¤¤¤¤Ðì ",
            " Ø¤¥¥¥¤ ¤   ¤ÐØ ",
            " ¦¤¥¥¥¤ ¤   ¤Ð¨ ",
            " ¡¤¥À¥¤ ¤   ¤Ð¡ ",
            " ×Ø¤¤¤¤  ¤¤¤¡Ø× ",
            "   ´¡ÕÐææÐÕ¡´   "
        ],
        [
            "   Ô¡ÕÐÖÖÐÕ¡Ô   ",
            " ×Ø¡¡¡¡¡¡¡¡¡¡Ø× ",
            " ¡ ĉ          ¡ ",
            " ¦    ù ù ù   ¨ ",
            " ¦Ċ ù ċ  ċ   Č¨ ",
            " ¦č   ċ  ċ   Č¨ ",
            " ¦Ď   ü ü ü   ¨ ",
            " ¦±    ďº     ¨ ",
            " Ø            Ø ",
            " Ø » »»»»» »» Ø ",
            " ì¼¤½¤¤¤¤¤½¤¤¾ì ",
            " Ø¤   ¤¤¤   ¤¤Ø ",
            " ¦¤   ¤¤¤   ¿¤¨ ",
            " ¡¤ À ¤¤¤   ¤¤¡ ",
            " ×Ø¤¤¤¤  ¤¤¤¡Ø× ",
            "   ´¡ÕÐææÐÕ¡´   "
        ],
        [
            "   Ô¡ÕÐÖÖÐÕ¡Ô   ",
            " ×Ø¡¡¡¡¡¡¡¡¡¡Ø× ",
            " ¡    ĐđĒē    ¡ ",
            " ¦            ¨ ",
            " ¦Ĕ          ĕ¨ ",
            " ¦           Ė¨ ",
            " ¦ė           ¨ ",
            " ¦            ¨ ",
            " ¦            ¨ ",
            " Ø » »»»»» »» Ø ",
            " Ø¼¤Ê¤¤¤¤¤Ê¤¤¾Ø ",
            " Ø¤   ¤¤¤   ¤¤Ø ",
            " ¦¤   ¤¤¤   Ë ¨ ",
            " ¡¤ À ¤¤¤   ¤ ¡ ",
            " ×Ø¤¤¤¤  ¤¤¤¡Ø× ",
            "   ´¡ÕÐææÐÕ¡´   "
        ],
        [
            "   Ô¡ÕÐÖÖÐÕ¡Ô   ",
            " ×Ø¡¡¡¡¡Ę¡¡¡¡Ø× ",
            " ¡    ęĚěĜ    ¡ ",
            " ¦            ¨ ",
            " Ø            Ø ",
            " Øĝ           Ø ",
            " Ø            Ø ",
            " ¦            ¨ ",
            " ¦            ¨ ",
            " ¦ »»»»»»»»»» ¨ ",
            " ¦¼¤¤¤¤¤¤¤¤¤¤¾¨ ",
            " ¦¤   ¤¤¤   ¤¤¨ ",
            " ¦¤   ¤ ¤   ¤ ¨ ",
            " ¡¤ À ¤ ¤   ¤ ¡ ",
            " ×Ø¤¤¤¤¤¤¤¤¤¤Ø× ",
            "   ´¡ÕÐææÐÕ¡´   "
        ],
        [
            "   Ô¡ÕÐÖÖÐÕ¡Ô   ",
            " ×Ø¡¡¡¡¡¡¡¡¡¡Ø× ",
            " ¡    ĞğĠġ    ¡ ",
            " ¦            ¨ ",
            " Ø            Ø ",
            " ì            ì ",
            " Ø            Ø ",
            " Ø            Ø ",
            " ¦            ¨ ",
            " ¦ »»»»»»»»»» ¨ ",
            " ¦¼¤¤¤¤¤¤¤¤¤¤¾¨ ",
            " ¦¤   ¤¤¤   ¤¤¨ ",
            " ¦¤   ¤ ¤   ¤ ¨ ",
            " ¡¤ À ¤ ¤   ¤ ¡ ",
            " ×Ø¤¤¤¤¤¤¤¤¤¤Ø× ",
            "   ´¡ÕÐææÐÕ¡´   "
        ],
        [
            "   Ô¡ÕÐÖÖÐÕ¡Ô   ",
            " ×Ø¡¡¡¡¡¡¡¡¡¡Ø× ",
            " ¡ØØØØØØØØØØØØ¡ ",
            " ¦ØĢĢĢĢĢĢĢĢĢĢØ¨ ",
            " ØØĢĢĢĢĢĢĢĢĢĢØØ ",
            " ìØĢĢĢĢĢĢĢĢĢĢØì ",
            " ìØĢĢĢĢĢĢĢĢĢĢØì ",
            " ØØĢĢĢĢĢĢĢĢĢĢØØ ",
            " ØØĢĢĢĢĢĢĢĢĢĢØØ ",
            " ¦ØĢĢĢĢĢĢĢĢĢĢØ¨ ",
            " ¦Ø¤¤¤¤¤¤¤¤¤¤Ø¨ ",
            " ¦¤   ¤ ¤   ¤¤¨ ",
            " ¦¤   ¤ ¤   ¤ ¨ ",
            " ¡¤ À ¤ ¤   ¤ ¡ ",
            " ×Ø¤¤¤¤¤¤¤¤¤¤Ø× ",
            "   ´¡ÕÐææÐÕ¡´   "
        ]
    ],
    "refpalette": "building001_palette"
}