{
    "xsize": 16,
    "zsize": 16,
    "slices": [
        [
            "óóóóóóóóóóóóóóóó",
            "óóóóóóóóóóóóóóóó",
            "óóôôôôôôôôôôôôóó",
            "óóôõõõõõõõõØØôóó",
            "óóôõöö÷÷öö÷÷õôóó",
            "óóôõö÷÷÷ö÷÷÷õôóó",
            "óóôõ÷÷öö÷÷÷öõôóó",
            "óóôõ÷÷ö÷÷÷ööõôóó",
            "óóôõöö÷÷öö÷÷õôóó",
            "óóôõö÷÷÷ö÷÷÷õôóó",
            "óóôõ÷÷÷ö÷÷ööõôóó",
            "óóôõ÷÷öö÷÷ö÷õôóó",
            "óóôõõõõõõõõõõôóó",
            "óóôôôôôôôôôôôôóó",
            "óóóóóóóóóóóóóóóó",
            "óóóóóóóóóóóóóóóó"
        ],
        [
            "                ",
            "           øøø  ",
            "  ùùùùùùùùùúúúø ",
            "  ùû       ØØúø ",
            "  ù±         úø ",
            "  ù üý  üý   ù  ",
            "  ùþþþþþþþþþÿù  ",
            "  ùÖĀ ā ā ĂÖ ù  ",
            "  ù ā ā ā ā  ù  ",
            "  ù ă ă ă ă  ù  ",
            "  ù¬         ù  ",
            " øú    Ą   Ą ą  ",
            " øúĆćććĆ     Ĉ  ",
            " øúúúùùùùùùĉĊù  ",
            "  øøø           ",
            "                "
        ],
        [
            "                ",
            "          øøø   ",
            "  ùċċċċċċċùúúú  ",
            "  ċ        ØØúø ",
            "  ċ          úø ",
            "  ċ Č   Č    ùø ",
            "  ċčĎ ďčĎ ďĎ ċ  ",
            "  ċ          ċ  ",
            "  ċ          ċ  ",
            "  ċ          ċ  ",
            " øùĐ         ù  ",
            " øúĒ         ē  ",
            " øú          Ĕ  ",
            "  úúúùċċċċùĕĖù  ",
            "   øøø          ",
            "                "
        ],
        [
            "                ",
            "         øøø    ",
            "  ùċċċċċċùùúúú  ",
            "  ċ        ØØú  ",
            "  ċ          úø ",
            "  ċ          ùø ",
            "  ċėėėėėėėėėėùø ",
            "  ċ          ċ  ",
            "  ċ          ċ  ",
            " øù          ċ  ",
            " øù          ù  ",
            " øú          ù  ",
            "  ú          ù  ",
            "  úúúùùċċċùùùù  ",
            "    øøø         ",
            "                "
        ],
        [
            "                ",
            " ĘĘĘĘĘĘøøøø     ",
            " Ęùùùùùùùùùúúú  ",
            " Ęù        ØØú  ",
            " Ęù          ú  ",
            " Ęù          ùø ",
            " Ęù    ę     ùø ",
            " øù     ę    ùø ",
            " øù     ę    ùø ",
            " øù          ùĘ ",
            " øú          ùĘ ",
            "  ú          ùĘ ",
            "  ú          ùĘ ",
            "  úúúúùùùùùùùùĘ ",
            "     øøøøĘĘĘĘĘĘ ",
            "                "
        ],
        [
            "                ",
            " Ěěěěěěøøø      ",
            " Ĝĝĝĝĝĝĝĝúúúúú  ",
            " ĜĝĞğğğğğğĠØØú  ",
            " ĜĝġĢĢĢĢĢĢĢğĠú  ",
            " ĜĝġĢĢĢĢĢĢĢĢģú  ",
            " ĜĝġĢĢĢĢĢĢĢĢģúø ",
            " øĝġĢĢĢĢĢĢĢĢģĝø ",
            " øĝġĢĢĢĢĢĢĢĢģĝø ",
            " øúġĢĢĢĢĢĢĢĢģĝĤ ",
            "  úġĢĢĢĢĢĢĢĢģĝĤ ",
            "  úġĢĢĢĢĢĢĢĢģĝĤ ",
            "  úĥĦĦĦĦĦĦĦĦħĝĤ ",
            "  úúúúúĝĝĝĝĝĝĝĤ ",
            "      øøøĨĨĨĨĨĩ ",
            "                "
        ]
    ],
    "refpalette": "building005_palette"
}