{
    "xsize": 16,
    "zsize": 16,
    "slices": [
        [
            "££ÿÿÿ££ÿÿ££ÿÿÿ££",
            "££ăăăççăăççăăă££",
            "ÿă   ¥»¼½º»¼½ºăÿ",
            "ÿă   ¥¼½º»¼½º»ăÿ",
            "ÿă   ¥½º»¼½º»¼ăÿ",
            "£ç¥¥¥¥º»¼½º»¼½ç£",
            "£ç»¼½º»¼½º»¼½ºç£",
            "ÿă¼½º»¼½º»¼½º»ăÿ",
            "ÿă½º»¼½º»¼½º»¼ăÿ",
            "£çº»¼½º»¼½º»¼½ç£",
            "£ç»¼½º»¼½º»¼½ºç£",
            "ÿă¼½º»¼½º»¼½º»ăÿ",
            "ÿă½º»¼½º»¼½º»¼ăÿ",
            "ÿăº»¼½º»¼½º»¼½ăÿ",
            "££ăăăççăăççăăă££",
            "££ÿÿÿ££ÿÿ££ÿÿÿ££"
        ],
        [
            "££èèè££èè££èèè££",
            "££çççççççççççç££",
            "èç   ¥  ĄąąąĆªçè",
            "èç   §        çè",
            "èç   ¥  ó     çè",
            "£ç¥¨¥¥     ó  ç£",
            "£ç   Ë        ç£",
            "èçććć¥   Ĉ    çè",
            "èç½º»¥ĉ   Ċ   çè",
            "£çº»¼¥ċ ö Č   ç£",
            "£ç»¼½¥č Ď ëď  ç£",
            "èç¼½º¥Đđ Ē´   çè",
            "èç½º»¥  Ĉ     çè",
            "èçº»¼¥ª      ´çè",
            "££çççççççççççç££",
            "££èèè££èè££èèè££"
        ],
        [
            "££ÿÿÿ££ÿÿ££ÿÿÿ££",
            "££ÜÜÜççÜÜççÜÜÜ££",
            "ÿÝ   ¥  ē ĔĕĖ Ýÿ",
            "ÿÝ   µ        Ýÿ",
            "ÿÝ   ¥        Ýÿ",
            "£ç¥¶¥¥        ç£",
            "£ç   Õ        ç£",
            "ÿÝ   ¥        Ýÿ",
            "ÿÝ  ėĘ    ę   Ýÿ",
            "£ç Ě Ęě       ç£",
            "£ç Ě ĘĜ       ç£",
            "ÿÝ Ě Ę        Ýÿ",
            "ÿÝ Ě Ę        Ýÿ",
            "ÿÝð  ¥        Ýÿ",
            "££ÜÜÜççÜÜççÜÜÜ££",
            "££ÿÿÿ££ÿÿ££ÿÿÿ££"
        ],
        [
            "££ÿÿÿ££ÿÿ££ÿÿÿ££",
            "££¹¹¹çç¹¹çç¹¹¹££",
            "ÿ¹   ¥        ¹ÿ",
            "ÿ¹   ¥        ¹ÿ",
            "ÿ¹   ¥        ¹ÿ",
            "£ç¥¥¥¥        ç£",
            "£ç   ¥        ç£",
            "ÿ¹   ¥        ¹ÿ",
            "ÿ¹   Ę        ¹ÿ",
            "£ç   Ę        ç£",
            "£ç   Ę        ç£",
            "ÿ¹   Ę        ¹ÿ",
            "ÿ¹   Ę        ¹ÿ",
            "ÿ¹   ¥        ¹ÿ",
            "££¹¹¹çç¹¹çç¹¹¹££",
            "££ÿÿÿ££ÿÿ££ÿÿÿ££"
        ],
        [
            "££èèè££èè££èèè££",
            "££çççççççççççç££",
            "èç   ¥        çè",
            "èç   ¥        çè",
            "èç   ¥        çè",
            "£ç¥¥¥¥        ç£",
            "£ç   ¥        ç£",
            "èç   ¥        çè",
            "èç   ¥        çè",
            "£ç   ¥ Ă Ă    ç£",
            "£ç   ¥  Ă Ă   ç£",
            "èç   ¥        çè",
            "èç   ¥        çè",
            "èç   ¥        çè",
            "££çççççççççççç££",
            "££èèè££èè££èèè££"
        ],
        [
            "££ÿÿÿ££ÿÿ££ÿÿÿ££",
            "££ÜÜÜççÜÜççÜÜÜ££",
            "ÿÝ   ¥ÞßßßßßßàÝÿ",
            "ÿÝ   ¥áââââââãÝÿ",
            "ÿÝ   ¥áââââââãÝÿ",
            "£ç¥¥¥¥áââââââãç£",
            "£çÞßßßâââââââãç£",
            "ÿÝáââââââââââãÝÿ",
            "ÿÝáââââââââââãÝÿ",
            "£çáââââââââââãç£",
            "£çáââââââââââãç£",
            "ÿÝáââââââââââãÝÿ",
            "ÿÝáââââââââââãÝÿ",
            "ÿÝäååååååååååæÝÿ",
            "££ÜÜÜççÜÜççÜÜÜ££",
            "££ÿÿÿ££ÿÿ££ÿÿÿ££"
        ]
    ],
    "refpalette": "building006_palette"
}