{
    "xsize": 16,
    "zsize": 16,
    "slices": [
        [
            "                ",
            "                ",
            "                ",
            "  ¥¥¥¥¥¥¥¥¥¥¥¥  ",
            "   ¦ÊÄ    ÊÊ¦   ",
            "  µÊËÌËÌÍÌÍÌÊµ  ",
            "  µÊÌÍÌËÌËÌÍÊµ  ",
            "  µÊËÌÍÌÍÌËÌÊµ  ",
            "  µÊÌËÌËÌÍÌËÊµ  ",
            "  µÊÍÌÍÌËÌÍÌÊµ  ",
            "  µÊÌËÌÍÌËÌÍÊµ  ",
            "  µÊÍÌËÌÍÌËÌÊµ  ",
            "  µÊÌÍÌËÌÍÌËÊµ  ",
            "  µÊËÌÍÌËÌÍÌÊµ  ",
            "  µÊÌËÌÍÌËÌÍÊµÎ ",
            "  µÊÍÌËÌÍÌËÌÊµÉ "
        ],
        [
            "                ",
            "                ",
            "                ",
            "  ¥¥¥¥¥¥¥¥¥¥¥¥  ",
            "   ¦        ¦   ",
            "  ©          ©  ",
            "  ©          ©  ",
            "  ©          ©  ",
            "  ©   ÏÐÐÏ   ©  ",
            "  ©    §     ©  ",
            "  Ñ          Ñ  ",
            "  Ñ          Ñ  ",
            "  ©   ÏÐÐÏ   ©  ",
            "  ©          ©  ",
            "  ©     Ò    ©  ",
            "  ©          ©  "
        ],
        [
            "                ",
            "                ",
            "                ",
            "  ¥¥¥¥¥¥¥¥¥¥¥¥  ",
            "   ¦        ¦   ",
            "  ©          ©  ",
            "  ©          ©  ",
            "  ©          ©  ",
            "  ©  ÓÔÔÕÔÖ  ©  ",
            "  ©          ©  ",
            "  Ñ          Ñ  ",
            "  Ñ          Ñ  ",
            "  ©  ÓÕÔÔÔÖ  ©  ",
            "  ©          ©  ",
            "  ©          ©  ",
            "  ©          ©  "
        ],
        [
            "                ",
            "                ",
            "                ",
            "  ¥¥¥¥¥¥¥¥¥¥¥¥  ",
            "   ¦        ¦   ",
            "  ©          ©  ",
            "  ©          ©  ",
            "  ©          ©  ",
            "  ©  ×ÔÕÔÔØ  ©  ",
            "  ©          ©  ",
            "  Ñ          Ñ  ",
            "  Ñ          Ñ  ",
            "  ©  ×ÔÔÔÔØ  ©  ",
            "  ©          ©  ",
            "  ©          ©  ",
            "  ©          ©  "
        ],
        [
            "                ",
            "                ",
            "                ",
            "  ¥¥¥¥¥¥¥¥¥¥¥¥  ",
            "   ¦        ¦   ",
            "  ©          ©  ",
            "  ©          ©  ",
            "  ©          ©  ",
            "  ©  ÓÔÔÔÔÖ  ©  ",
            "  ©          ©  ",
            "  Ñ          Ñ  ",
            "  Ñ          Ñ  ",
            "  ©  ÓÔÔÕ¨Ö  ©  ",
            "  ©          ©  ",
            "  ©          ©  ",
            "  ©          ©  "
        ],
        [
            "                ",
            "                ",
            "                ",
            "  ¥¥¥¥¥¥¥¥¥¥¥¥  ",
            "   ¦        ¦   ",
            "  ©          ©  ",
            "  ©          ©  ",
            "  ©          ©  ",
            "  ©   ÙÐÐÙ   ©  ",
            "  ©          ©  ",
            "  Ñ          Ñ  ",
            "  Ñ          Ñ  ",
            "  ©   ÙÐÐÙ   ©  ",
            "  ©          ©  ",
            "  ©          ©  ",
            "  ©          ©  "
        ]
    ],
    "refpalette": "building003_palette"
}