{
    "xsize": 16,
    "zsize": 16,
    "slices": [
        [
            "¡¡¡¡¡¡¡¡¡¡¡¡¡¡¡¡",
            "¡¡¡¡¡¡¡¡¡¡¡¡¡¡¡¡",
            "¡¡¡¡¡¡¡¡¡¡¡¡¡¡¡¡",
            "¡¡¡¡¡¡¡¡¡¡¡¡¡¡¡¡",
            "¢¢¢¢¢¢¢¢¢¢¢¢¢¢¢¢",
            "¤¤¤¤¤¤¤¤¤¤¤¤¤¤±±",
            "¤¤¤¤¤¤¤¤¤¤¤¤¤¤±±",
            "¤¤¤¤¤¤¤¤¤¤¤¤¤¤±±",
            "¤¤¤¤¤¤¤¤¤¤¤¤¤¤±±",
            "¤¤¤¤¤¤¤¤¤¤¤¤¤¤±±",
            "¤¤¤¤¤¤¤£¤¤¤¤¤¤±±",
            "¤¤¤¤¤¤¤¤¤¤¤¤¤¤±±",
            "¤¤¤¤¤¤¤¤¤¤¤¤¤¤±±",
            "¤¤¤¤¤¤¤¤¤¤¤¤¤¤±±",
            "¤¤¤¤¤¤¤¤¤¤¤¤¤¤±±",
            "¤¤¤¤¤¤¤¤¤¤¤¤¤¤±±"
        ],
        [
            "                ",
            "                ",
            "                ",
            "                ",
            "                ",
            "  §§§§©©§  § ¼  ",
            "  §©§§§©©§§§©§  ",
            "§§§©§§§§§§©©§§  ",
            "§§§§©§§§§ §©§   ",
            "§¨§¨ ¨ ¯§ ¨§    ",
            " ³§©§§ ² §§  §  ",
            "§§§§§§§§ § §§¿  ",
            "§§§§¨¨§§° §©§©  ",
            "©¨§©§§©§ §§§©§  ",
            "´¨¨§§§¨§§§§§§   ",
            "§ §§§§¨§§§§©§   "
        ],
        [
            "                ",
            "                ",
            "                ",
            "                ",
            "                ",
            "      ¬¬        ",
            "   ¬   ¬¬   ¬   ",
            "   ¬      ¬¬    ",
            "    ¬      ¬    ",
            "                ",
            "   ¬   ²        ",
            "                ",
            "           ¬ ¬  ",
            "¬  ¬  ¬     ¬   ",
            "                ",
            "           ¬    "
        ],
        [
            "                ",
            "                ",
            "                ",
            "                ",
            "                ",
            "                ",
            "                ",
            "     º¹¸¹º      ",
            "    º¹¸·¸¹º     ",
            "    ¹¸·¶·¸¹     ",
            "    ¸·¶²¶·¸     ",
            "    ¹¸·¶·¸¹     ",
            "    º¹¸·¸¹º     ",
            "     º¹¸¹º      ",
            "                ",
            "    ¸·¸         "
        ],
        [
            "                ",
            "                ",
            "                ",
            "                ",
            "                ",
            "                ",
            "                ",
            "                ",
            "      ¸·¸       ",
            "     ¸·¶·¸      ",
            "     ·¶²¶·      ",
            "     ¸·¶·¸      ",
            "      ¸·¸       ",
            "                ",
            "                ",
            "                "
        ],
        [
            "                ",
            "                ",
            "                ",
            "                ",
            "                ",
            "                ",
            "                ",
            "                ",
            "                ",
            "       ¶        ",
            "      ¶²¶       ",
            "       ¶        ",
            "                ",
            "                ",
            "                ",
            "    ¸·¸         "
        ]
    ],
    "refpalette": "building007_palette"
}