{
    "xsize": 16,
    "zsize": 16,
    "slices": [
        [
            "                ",
            " ¾¾¿¿¿¿¿¿¿¿¿¿¾¾ ",
            " ¾ÀÀÀÀÀÀÀÀÀÀÀÀ¾Á",
            " ÈÀÔÔÔÔÔÔÔÔ££££¾",
            " ÈÀÔÔÔÔÔÔÔÔ£   Ç",
            " ÈÀÔÔÔÔÔÔÔÔ£   Ç",
            " ÈÀÔÔÔÔÔÔÔÔ£   Ç",
            " ÈÀÔÔÔÔÔÔÔÔ££££¾",
            " ÈÀÔÔÔÔÔÔÔÔ££££¾",
            " ÈÀÔÔÔÔÔÔÔÔ££££Ç",
            " ÈÀÔÔÔÔÔÔÔÔ££££Ç",
            " ÈÀÔÔÔÔÔÔÔÔ££¥£Ç",
            " ÈÀÔÔÔÔÔÔÔÔ££££¾",
            " ¾ÀÀÀÀÀÀÀÀÀÀÀÀ¾Á",
            " ¾¾ÏÏÏÏÏÏÏÏÏÏ¾¾ ",
            "                "
        ],
        [
            "                ",
            " ¾¾          ¾¾ ",
            " ¾»»»ÇÇ»»ÇÇ»»»¾Á",
            "  »       ¬»»®»¾",
            "  » Õ      £   Ç",
            "  ÇÖ   ×   ©   Ç",
            "  Ç    ØÙÚÛ£   Ç",
            "  »³      Ü»»»»¾",
            "  » Ý     Þ»»»»¾",
            "  Ç ßßß àáâ£   Ç",
            "  Ç ßßß    °   Ç",
            "  »        £ ¥ Ç",
            "  »ã ä ±   »»»»¾",
            " ¾»»»ÇÇ»»ÇÇ»»»¾Á",
            " ¾¾          ¾¾ ",
            "                "
        ],
        [
            "                ",
            " ¾¾          ¾¾ ",
            " ¾»»»ÇÇ»»ÇÇ»»»¾Á",
            "  »        »»·»¾",
            "  »        £   Ç",
            "  Çå       ¶   Ç",
            "  Ç     æ  £   Ç",
            "  »        »»»»¾",
            "  » ç      »»»»¾",
            "  Ç        £   Ç",
            "  Ç        ¸   Ç",
            "  »        £ ¥ Ç",
            "  »        »»»»¾",
            " ¾»»»ÇÇ»»ÇÇ»»»¾Á",
            " ¾¾          ¾¾ ",
            "                "
        ],
        [
            "                ",
            " ¾¾          ¾¾ ",
            " ¾Àººººººººººº¾Á",
            "  º        »»»»¾",
            "  º        £   Ç",
            "  º        £   Ç",
            "  º        £   Ç",
            "  º        »»»»¾",
            "  º        »»»»¾",
            "  º        £   Ç",
            "  º        £   Ç",
            "  º        £ ¥ Ç",
            "  º        »»»»¾",
            " ¾Àººººººººººº¾Á",
            " ¾¾          ¾¾ ",
            "                "
        ],
        [
            "                ",
            " ¾¾          ¾¾ ",
            " ¾ÀÀÀÀÀÀÀÀÀÀÀÀ¾Á",
            "  À        ¤¤¤¤¾",
            "  À        ¤   Ç",
            "  À        ¤   Ç",
            "  À        ¤   Ç",
            "  À        ¤¤¤¤¾",
            "  À        ¤¤¤¤¾",
            "  À        ¤   Ç",
            "  À        ¤   Ç",
            "  À        ¤ ¥ Ç",
            "  À        ¤¤¤¤¾",
            " ¾ÀÀÀÀÀÀÀÀÀÀÀÀ¾Á",
            " ¾¾          ¾¾ ",
            "                "
        ],
        [
            "                ",
            " ¾¾¾¾¾¾¾¾¾¾¾¾¾¾ ",
            " ¾ÀÀÀÀÀÀÀÀÀÀÀÀ¾Á",
            " ¾ÀÔÔÔÔÔÔÔÔ»»»»¾",
            " ¾ÀÔÔÔÔÔÔÔÔ»   Ç",
            " ¾ÀÔÔÔÔÔÔÔÔ»   Ç",
            " ¾ÀÔÔÔÔÔÔÔÔ»   Ç",
            " ¾ÀÔÔÔÔÔÔÔÔ»»»»¾",
            " ¾ÀÔÔÔÔÔÔÔÔ»»»»¾",
            " ¾ÀÔÔÔÔÔÔÔÔ»   Ç",
            " ¾ÀÔÔÔÔÔÔÔÔ»   Ç",
            " ¾ÀÔÔÔÔÔÔÔÔ» ¥ Ç",
            " ¾ÀÔÔÔÔÔÔÔÔ»»»»¾",
            " ¾ÀÀÀÀÀÀÀÀÀÀÀÀ¾Á",
            " ¾¾¾¾¾¾¾¾¾¾¾¾¾¾ ",
            "                "
        ]
    ],
    "refpalette": "building002_palette"
}