{
    "xsize": 16,
    "zsize": 16,
    "slices": [
        [
            "   Ô¡ÕÐÖÖÐÕ¡Ô   ",
            " ×Ø¡¡¡¡¡¡¡¡¡¡Ø× ",
            " ¡ÐÐÐÐÐÐÐÐÐÐÐÐ¡ ",
            " ¦ÐÓÓÓÓÓÓÓÓÓÓÐ¨ ",
            " ØÐÓÓÓÓÓÓÓÓÓÓÐØ ",
            " ØÐÓÓÓÓÓÓÓÓÓÓÐØ ",
            " ìÐÓÓÓÓÓÓÓÓÓÓÐì ",
            " ìÐÓÓÓÓÓÓÓÓÓÓÐì ",
            " ìÐÓÓÓÓÓÓÓÓÓÓÐì ",
            " ìÐÓÓÓÓÓÓÓÓÓÓÐì ",
            " ìÐ¤¤¤¤¤¤¤¤¤¤Ðì ",
            " Ø¤¥¥¥¤ ¤   ¤¤Ø ",
            " ¦¤¥¥¥¤ ¤   ¤ ¨ ",
            " ¡¤¥À¥¤ ¤   ¤ ¡ ",
            " ×Ø¤¤¤¤¤¤¤¤¤¤Ø× ",
            "   ´¡ÕÐææÐÕ¡´   "
        ],
        [
            "   Ô¡ÕÐÖÖÐÕ¡Ô   ",
            " ×Ø¡¡¡¡¡¡¡¡¡¡Ø× ",
            " ¡ ƪ  ƪ  ƪ  ƪ ¡ ",
            " ¦            ¨ ",
            " Ø±    º      Ø ",
            " ì  ÛƫÛ  Û Û  ì ",
            " ì   Ƭ    Ƭ   ì ",
            " ì      ď     ì ",
            " ì            ì ",
            " ì » »»»»» »» ì ",
            " ì¼¤½¤¤¤¤¤½¤¤¾ì ",
            " Ø¤   ¤ ¤   ¤¤Ø ",
            " ¦¤   ¤ ¤   ¿ ¨ ",
            " ¡¤ À ¤ ¤   ¤ ¡ ",
            " ×Ø¤¤¤¤¤¤¤¤¤¤Ø× ",
            "   ´¡ÕÐææÐÕ¡´   "
        ],
        [
            "   Ô¡ÕÐÖÖÐÕ¡Ô   ",
            " ×Ø¡¡¡¡¡¡¡¡¡¡Ø× ",
            " ¡ƭƮƯ  ƭƭ ƮƯ ƭ¡ ",
            " ¦            ¨ ",
            " Ø            Ø ",
            " ì            ì ",
            " ì  êưê  êưê  ì ",
            " ì            ì ",
            " ì            ì ",
            " ì » »»»»» »» ì ",
            " ì¼¤Ê¤¤¤¤¤Ê¤¤¾ì ",
            " Ø¤   ¤ ¤   ¤¤Ø ",
            " ¦¤   ¤ ¤   Ë ¨ ",
            " ¡¤ À ¤ ¤   ¤ ¡ ",
            " ×Ø¤¤¤¤¤¤¤¤¤¤Ø× ",
            "   ´¡ÕÐææÐÕ¡´   "
        ],
        [
            "   Ô¡ÕÐÖÖÐÕ¡Ô   ",
            " ×Ø¡¡¡¡¡¡¡¡¡¡Ø× ",
            " ¡  ƱƱƱƱƱƱƱƱ  ¡ ",
            " ¦            ¨ ",
            " Ø            Ø ",
            " ì            ì ",
            " ì            ì ",
            " ì            ì ",
            " ì            ì ",
            " ì »»»»»»»»»» ì ",
            " ì¼¤¤¤¤¤¤¤¤¤¤¾ì ",
            " Ø¤   ¤ ¤   ¤¤Ø ",
            " ¦¤   ¤ ¤   ¤ ¨ ",
            " ¡¤ À ¤ ¤   ¤ ¡ ",
            " ×Ø¤¤¤¤¤¤¤¤¤¤Ø× ",
            "   ´¡ÕÐææÐÕ¡´   "
        ],
        [
            "   Ô¡ÕÐÖÖÐÕ¡Ô   ",
            " ×Ø¡¡¡¡¡¡¡¡¡¡Ø× ",
            " ¡  ¯¯¯¯¯¯¯¯  ¡ ",
            " ¦            ¨ ",
            " Ø            Ø ",
            " ì            ì ",
            " ì            ì ",
            " ì            ì ",
            " ì            ì ",
            " ì »»»»»»»»»» ì ",
            " ì¼¤¤¤¤¤¤¤¤¤¤¾ì ",
            " Ø¤   ¤ ¤   ¤¤Ø ",
            " ¦¤   ¤ ¤   ¤ ¨ ",
            " ¡¤ À ¤ ¤   ¤ ¡ ",
            " ×Ø¤¤¤¤¤¤¤¤¤¤Ø× ",
            "   ´¡ÕÐææÐÕ¡´   "
        ],
        [
            "   Ô¡ÕÐÖÖÐÕ¡Ô   ",
            " ×Ø¡¡¡¡¡¡¡¡¡¡Ø× ",
            " ¡ØØØØØØØØØØØØ¡ ",
            " ¦ØÏÏÏÏÏÏÏÏÏÏØ¨ ",
            " ØØÏÏÏÏÏÏÏÏÏÏØØ ",
            " ìØÏÏÏÏÏÏÏÏÏÏØì ",
            " ìØÏÏÏÏÏÏÏÏÏÏØì ",
            " ìØÏÏÏÏÏÏÏÏÏÏØì ",
            " ìØÏÏÏÏÏÏÏÏÏÏØì ",
            " ìØÏÏÏÏÏÏÏÏÏÏØì ",
            " ìØ¤¤¤¤¤¤¤¤¤¤Øì ",
            " Ø¤   ¤ ¤   ¤¤Ø ",
            " ¦¤   ¤ ¤   ¤ ¨ ",
            " ¡¤ À ¤ ¤   ¤ ¡ ",
            " ×Ø¤¤¤¤¤¤¤¤¤¤Ø× ",
            "   ´¡ÕÐææÐÕ¡´   "
        ]
    ],
    "refpalette": "building001_palette"
}