{
    "xsize": 16,
    "zsize": 16,
    "slices": [
        [
            "                ",
            "                ",
            "                ",
            "  ¥¥¥¥¥¥¥¥¥¥¥¥  ",
            "   ¦¤¤¤¤¤¤¤¤¦   ",
            "  µ¤¤¤¤¤¤¤¤¤¤µ  ",
            "  µ¤¤¤¤¤¤¤¤¤¤µ  ",
            "  µ¤¤¤¤¤¤¤¤¤¤µ  ",
            "  µ¤¤¤¤¤¤¤¤¤¤µ  ",
            "  µ¤¤¤¤¤¤¤¤¤¤µ  ",
            "  µ¤¤¤¤¤¤¤¤¤¤µ  ",
            "  µ¤¤¤¤¤¤¤¤¤¤µ  ",
            "  µ¤¤¤¤¤¤¤¤¤¤µ  ",
            "  µ¤¤¤¤¤¤¤¤¤¤µ  ",
            "  µ¤¤¤¤¤¤¤¤¤¤µ  ",
            "  µ¤¤¤¤¤¤¤¤¤¤µ  "
        ],
        [
            "                ",
            "                ",
            "                ",
            "  ¥¥¥¥¥¥¥¥¥¥¥¥  ",
            "   ¦ ¨  â   ¦   ",
            "  ©          ©  ",
            "  ©    ã§ä   ©  ",
            "  ©  å æ     ©  ",
            "  ©          ©  ",
            "  © ç è  è é ©  ",
            "  Ñ          Ñ  ",
            "  Ñ   êêêê   Ñ  ",
            "  © ë êêêê ë ©  ",
            "  ©   ììêì   ©  ",
            "  ©íî ìììì î ©  ",
            "  ©   ìììì   ©  "
        ],
        [
            "                ",
            "                ",
            "                ",
            "  ¥¥¥¥¥¥¥¥¥¥¥¥  ",
            "   ¦ï ð ð  ï¦   ",
            "  ©      ñ   ©  ",
            "  ©      ò   ©  ",
            "  ©     ó    ©  ",
            "  ©          ©  ",
            "  ©          ©  ",
            "  Ñ          Ñ  ",
            "  Ñ          Ñ  ",
            "  ©          ©  ",
            "  ©          ©  ",
            "  © ô      ô ©  ",
            "  ©          ©  "
        ],
        [
            "                ",
            "                ",
            "                ",
            "  ¥¥¥¥¥¥¥¥¥¥¥¥  ",
            "   ¦        ¦   ",
            "  ©          ©  ",
            "  ©          ©  ",
            "  ©          ©  ",
            "  ©          ©  ",
            "  ©          ©  ",
            "  Ñ          Ñ  ",
            "  Ñ          Ñ  ",
            "  ©          ©  ",
            "  ©          ©  ",
            "  © ô      ô ©  ",
            "  ©          ©  "
        ],
        [
            "                ",
            "                ",
            "                ",
            "  ¥¥¥¥¥¥¥¥¥¥¥¥  ",
            "   ¦  õõõõ  ¦   ",
            "  ©          ©  ",
            "  ©          ©  ",
            "  ©          ©  ",
            "  ©          ©  ",
            "  ©          ©  ",
            "  Ñ          Ñ  ",
            "  Ñ          Ñ  ",
            "  ©          ©  ",
            "  ©          ©  ",
            "  ©          ©  ",
            "  ©          ©  "
        ],
        [
            "                ",
            "                ",
            "                ",
            "  ¥¥¥¥¥¥¥¥¥¥¥¥  ",
            "   ¦  õõõõ  ¦   ",
            "  ©          ©  ",
            "  ©          ©  ",
            "  ©          ©  ",
            "  ©          ©  ",
            "  ©          ©  ",
            "  Ñ          Ñ  ",
            "  Ñ          Ñ  ",
            "  ©          ©  ",
            "  ©          ©  ",
            "  ©          ©  ",
            "  ©          ©  "
        ],
        [
            "                ",
            "                ",
            "                ",
            "  ¥¥¥¥¥¥¥¥¥¥¥¥  ",
            "   ¦  õõõõ  ¦   ",
            "  µ          µ  ",
            "  µ          µ  ",
            "  µ          µ  ",
            "  µ          µ  ",
            "  µ          µ  ",
            "  µ          µ  ",
            "  µ          µ  ",
            "  µ          µ  ",
            "  µ          µ  ",
            "  µ          µ  ",
            "  µ          µ  "
        ],
        [
            "                ",
            "                ",
            "                ",
            "  ¥¥¥¥¥¥¥¥¥¥¥¥  ",
            "   ¦  õõõõ  ¦   ",
            "  ©          ©  ",
            "  ©          ©  ",
            "  ©          ©  ",
            "  ©          ©  ",
            "  ©          ©  ",
            "  Ñ          Ñ  ",
            "  Ñ          Ñ  ",
            "  ©          ©  ",
            "  ©          ©  ",
            "  ©          ©  ",
            "  ©          ©  "
        ],
        [
            "                ",
            "                ",
            "                ",
            "  ¥¥¥¥¥¥¥¥¥¥¥¥  ",
            "   ö÷      øù   ",
            "   µ        µ   ",
            "   µ        µ   ",
            "   µ        µ   ",
            "   µ        µ   ",
            "   µ        µ   ",
            "   µ        µ   ",
            "   µ        µ   ",
            "   µ        µ   ",
            "   µ        µ   ",
            "   µ        µ   ",
            "   µ        µ   "
        ],
        [
            "                ",
            "                ",
            "                ",
            "  ¥¥¥¥¥¥¥¥¥¥¥¥  ",
            "    ö÷    øù    ",
            "    ©      ©    ",
            "    ©      ©    ",
            "    ©      ©    ",
            "    ©      ©    ",
            "    ©      ©    ",
            "    Ñ      Ñ    ",
            "    Ñ      Ñ    ",
            "    ©      ©    ",
            "    ©      ©    ",
            "    ©      ©    ",
            "    ©      ©    "
        ],
        [
            "                ",
            "                ",
            "                ",
            "  ¥¥¥¥¥¥¥¥¥¥¥¥  ",
            "     öúúúúù     ",
            "     µ©µµ©µ     ",
            "     µ©µµ©µ     ",
            "     µ©µµ©µ     ",
            "     µ©µµ©µ     ",
            "     µ©µµ©µ     ",
            "     µÑµµÑµ     ",
            "     µÑµµÑµ     ",
            "     µ©µµ©µ     ",
            "     µ©µµ©µ     ",
            "     µ©µµ©µ     ",
            "     µ©µµ©µ     "
        ],
        [
            "                ",
            "                ",
            "                ",
            "  ¥¥¥¥¥¥¥¥¥¥¥¥  ",
            "                ",
            "                ",
            "                ",
            "                ",
            "                ",
            "                ",
            "                ",
            "                ",
            "                ",
            "                ",
            "                ",
            "                "
        ]
    ],
    "refpalette": "building003_palette"
}