{
    "meta": [
        {
            "key": "support",
            "char": "v"
        }
    ],
    "xsize": 16,
    "zsize": 16,
    "palette": {
        "palette": [
            {
                "char": " ",
                "block": "minecraft:air"
            },
            {
                "char": "α",
                "block": "minecraft:smooth_stone"
            },
            {
                "char": "β",
                "block": "minecraft:gray_concrete"
            },
            {
                "char": "γ",
                "block": "minecraft:white_concrete"
            },
            {
                "char": "δ",
                "block": "minecraft:stone_bricks"
            },
            {
                "char": "ε",
                "block": "minecraft:sea_lantern"
            }
        ]
    },
    "slices": [
        [
            "vvvvvvvvvvvvvvvv",
            "vvvvvvvvvvvvvvvv",
            "vvvvvvvvvvvvvvvv",
            "vvvvvvvvvvvvvvvv",
            "vvvvvvvvvvvvvvvv",
            "vvvvvvvvvvvvvvvv",
            "vvvvvvvvvvvvvvvv",
            "vvvvvvvvvvvvvvvv",
            "vvvvvvvvvvvvvvvv",
            "vvvvvvvvvvvvvvvv",
            "vvvvvvvvvvvvvvvv",
            "vvvvvvvvvvvvvvvv",
            "vvvvvvvvvvvvvvvv",
            "vvvvvvvvvvvvvvvv",
            "vvvvvvvvvvvvvvvv",
            "vvvvvvvvvvvvvvvv"
        ],
        [
            "αααααααααααααααα",
            "αααααααααααααααα",
            "ββββββββββββββββ",
            "ββββββββββββββββ",
            "βγγββγγββγγββγγβ",
            "ββββββββββββββββ",
            "ββββββββββββββββ",
            "αααααααααααααααα",
            "αααααααααααααααα",
            "ββββββββββββββββ",
            "ββββββββββββββββ",
            "βγγββγγββγγββγγβ",
            "ββββββββββββββββ",
            "ββββββββββββββββ",
            "αααααααααααααααα",
            "αααααααααααααααα"
        ],
        [
            "δδδδδδδδδδδδδδδδ",
            "                ",
            "                ",
            "                ",
            "                ",
            "                ",
            "                ",
            "                ",
            "                ",
            "                ",
            "                ",
            "                ",
            "                ",
            "                ",
            "                ",
            "δδδδδδδδδδδδδδδδ"
        ],
        [
            "δδδδδδδδδδδδδδδδ",
            "                ",
            "                ",
            "                ",
            "                ",
            "                ",
            "                ",
            "                ",
            "                ",
            "                ",
            "                ",
            "                ",
            "                ",
            "                ",
            "                ",
            "δδδδδδδδδδδδδδδδ"
        ],
        [
            "δδδδδδδδδδδδδδδδ",
            "                ",
            "                ",
            "                ",
            "                ",
            "                ",
            "                ",
            "                ",
            "                ",
            "                ",
            "                ",
            "                ",
            "                ",
            "                ",
            "                ",
            "δδδδδδδδδδδδδδδδ"
        ],
        [
            "                ",
            "δδδδδδδδδδδδδδδδ",
            "                ",
            "                ",
            "                ",
            "                ",
            "                ",
            "                ",
            "                ",
            "                ",
            "                ",
            "                ",
            "                ",
            "                ",
            "δδδδδδδδδδδδδδδδ",
            "                "
        ],
        [
            "                ",
            "                ",
            "δδδδδδδδδδδδδδδδ",
            "δδδδδδδδδδδδδδδδ",
            "δδδδδδδδδδδδδδδδ",
            "δδδδδδδδδδδδδδδδ",
            "δδδδδδδδδδδδδδδδ",
            "δδδδδδδεεδδδδδδδ",
            "δδδδδδδεεδδδδδδδ",
            "δδδδδδδδδδδδδδδδ",
            "δδδδδδδδδδδδδδδδ",
            "δδδδδδδδδδδδδδδδ",
            "δδδδδδδδδδδδδδδδ",
            "δδδδδδδδδδδδδδδδ",
            "                ",
            "                "
        ]
    ]
}