{
    "xsize": 16,
    "zsize": 16,
    "palette": {
        "palette": [
            {
                "char": " ",
                "block": "minecraft:air"
            },
            {
                "char": "α",
                "block": "betterblockz:ironslate_blockz_1"
            },
            {
                "char": "β",
                "block": "betterblockz:cyberlight_blockz_0[lit=true]"
            },
            {
                "char": "γ",
                "block": "betterblockz:eclipse_blockz_0"
            },
            {
                "char": "δ",
                "block": "betterblockz:ironslate_blockz_12"
            },
            {
                "char": "ε",
                "block": "betterblockz:ironslate_blockz_11[facing=up]"
            },
            {
                "char": "ζ",
                "block": "minecraft:structure_void"
            },
            {
                "char": "η",
                "block": "betterblockz:ironslate_blockz_4"
            }
        ]
    },
    "slices": [
        [
            "αααααααααααααααα",
            "ββββββββββββββββ",
            "γγγγγγγγγγγγγγγγ",
            "γγγγγγγγγγγγγγγγ",
            "γγγγγγγγγγγγγγγγ",
            "γγγγγγγγγγγγγγγγ",
            "γγγγγγγγγγγγγγγγ",
            "ββββββββββββββββ",
            "ββββββββββββββββ",
            "γγγγγγγγγγγγγγγγ",
            "γγγγγγγγγγγγγγγγ",
            "γγγγγγγγγγγγγγγγ",
            "γγγγγγγγγγγγγγγγ",
            "γγγγγγγγγγγγγγγγ",
            "ββββββββββββββββ",
            "αααααααααααααααα"
        ],
        [
            "δεεεεεεεεεεεεεεδ",
            "ζζζζζζζζζζζζζζζζ",
            "ζζζζζζζζζζζζζζζζ",
            "ζζζζζζζζζζζζζζζζ",
            "ζζζζζζζζζζζζζζζζ",
            "ζζζζζζζζζζζζζζζζ",
            "ζζζζζζζζζζζζζζζζ",
            "ζζζζζζζζζζζζζζζζ",
            "ζζζζζζζζζζζζζζζζ",
            "ζζζζζζζζζζζζζζζζ",
            "ζζζζζζζζζζζζζζζζ",
            "ζζζζζζζζζζζζζζζζ",
            "ζζζζζζζζζζζζζζζζ",
            "ζζζζζζζζζζζζζζζζ",
            "ζζζζζζζζζζζζζζζζ",
            "δεεεεεεεεεεεεεεδ"
        ],
        [
            "δεεεεεεεεεεεεεεδ",
            "ζζζζζζζζζζζζζζζζ",
            "ζζζζζζζζζζζζζζζζ",
            "ζζζζζζζζζζζζζζζζ",
            "ζζζζζζζζζζζζζζζζ",
            "ζζζζζζζζζζζζζζζζ",
            "ζζζζζζζζζζζζζζζζ",
            "ζζζζζζζζζζζζζζζζ",
            "ζζζζζζζζζζζζζζζζ",
            "ζζζζζζζζζζζζζζζζ",
            "ζζζζζζζζζζζζζζζζ",
            "ζζζζζζζζζζζζζζζζ",
            "ζζζζζζζζζζζζζζζζ",
            "ζζζζζζζζζζζζζζζζ",
            "ζζζζζζζζζζζζζζζζ",
            "δεεεεεεεεεεεεεεδ"
        ],
        [
            "δηηηηηηηηηηηηηηδ",
            "ζζζζζζζζζζζζζζζζ",
            "ζζζζζζζζζζζζζζζζ",
            "ζζζζζζζζζζζζζζζζ",
            "ζζζζζζζζζζζζζζζζ",
            "ζζζζζζζζζζζζζζζζ",
            "ζζζζζζζζζζζζζζζζ",
            "ζζζζζζζζζζζζζζζζ",
            "ζζζζζζζζζζζζζζζζ",
            "ζζζζζζζζζζζζζζζζ",
            "ζζζζζζζζζζζζζζζζ",
            "ζζζζζζζζζζζζζζζζ",
            "ζζζζζζζζζζζζζζζζ",
            "ζζζζζζζζζζζζζζζζ",
            "ζζζζζζζζζζζζζζζζ",
            "δηηηηηηηηηηηηηηδ"
        ],
        [
            "δηηηηηηηηηηηηηηδ",
            "ζζζζζζζζζζζζζζζζ",
            "ζζζζζζζζζζζζζζζζ",
            "ζζζζζζζζζζζζζζζζ",
            "ζζζζζζζζζζζζζζζζ",
            "ζζζζζζζζζζζζζζζζ",
            "ζζζζζζζζζζζζζζζζ",
            "ζζζζζζζζζζζζζζζζ",
            "ζζζζζζζζζζζζζζζζ",
            "ζζζζζζζζζζζζζζζζ",
            "ζζζζζζζζζζζζζζζζ",
            "ζζζζζζζζζζζζζζζζ",
            "ζζζζζζζζζζζζζζζζ",
            "ζζζζζζζζζζζζζζζζ",
            "ζζζζζζζζζζζζζζζζ",
            "δηηηηηηηηηηηηηηδ"
        ],
        [
            "δηηηηηηηηηηηηηηδ",
            "δηηηηηηηηηηηηηηδ",
            "δηηηηηηηηηηηηηηδ",
            "δγγγγγγγγγγγγγγδ",
            "δγγγγγγββγγγγγγδ",
            "δγγγγγγγγγγγγγγδ",
            "δηηηηηηηηηηηηηηδ",
            "δγγγγγγγγγγγγγγδ",
            "δγγγγγγγγγγγγγγδ",
            "δηηηηηηηηηηηηηηδ",
            "δγγγγγγγγγγγγγγδ",
            "δγγγγγγββγγγγγγδ",
            "δγγγγγγγγγγγγγγδ",
            "δηηηηηηηηηηηηηηδ",
            "δηηηηηηηηηηηηηηδ",
            "δηηηηηηηηηηηηηηδ"
        ]
    ]
}