{
    "xsize": 16,
    "zsize": 16,
    "palette": {
        "palette": [
            {
                "char": " ",
                "block": "minecraft:air"
            },
            {
                "char": "α",
                "block": "betterblockz:ironslate_blockz_1"
            },
            {
                "char": "β",
                "block": "betterblockz:cyberlight_blockz_0[lit=true]"
            },
            {
                "char": "γ",
                "block": "betterblockz:cyberlight_blockz_1[lit=true]"
            },
            {
                "char": "δ",
                "block": "betterblockz:eclipse_blockz_0"
            },
            {
                "char": "ε",
                "block": "betterblockz:ironslate_blockz_3"
            },
            {
                "char": "ζ",
                "block": "minecraft:structure_void"
            },
            {
                "char": "η",
                "block": "betterblockz:ironslate_blockz_19[axis=x]"
            },
            {
                "char": "θ",
                "block": "betterblockz:ironslate_blockz_7[axis=z]"
            },
            {
                "char": "ι",
                "block": "betterblockz:ironslate_blockz_7[axis=x]"
            },
            {
                "char": "κ",
                "block": "betterblockz:tintedglass_blockz_3"
            }
        ]
    },
    "slices": [
        [
            "αααααααααααααααα",
            "αααααααααααααααα",
            "αααααααααααααααα",
            "ββββαααααααααααα",
            "γγγγαααααααααααα",
            "δδδδαααααααααααα",
            "δδδδαααααααααααα",
            "δδδδαααααααααααα",
            "δδδδαααααααααααα",
            "δδδδαααααααααααα",
            "δδδδαααααααααααα",
            "γγγγαααααααααααα",
            "ββββαααααααααααα",
            "αααααααααααααααα",
            "αααααααααααααααα",
            "αααααααααααααααα"
        ],
        [
            "εεεεαααααααααααα",
            "ζζζζαααααααααααα",
            "ζζζζαααααααααααα",
            "ζζζζββαααααααααα",
            "ζζζζγγαααααααααα",
            "ζζζζδδαααααααααα",
            "ζζζζδδαααααααααα",
            "ζζζζδδαααααααααα",
            "ζζζζδδαααααααααα",
            "ζζζζδδαααααααααα",
            "ζζζζδδαααααααααα",
            "ζζζζγγαααααααααα",
            "ζζζζββαααααααααα",
            "ζζζζαααααααααααα",
            "ζζζζαααααααααααα",
            "εεεεαααααααααααα"
        ],
        [
            "ηηηεεεαααααααααα",
            "ζζζζζζαααααααααα",
            "ζζζζζζαααααααααα",
            "ζζζζζζββαααααααα",
            "ζζζζζζγγαααααααα",
            "ζζζζζζδδαααααααα",
            "ζζζζζζδδαααααααα",
            "ζζζζζζδδαααααααα",
            "ζζζζζζδδαααααααα",
            "ζζζζζζδδαααααααα",
            "ζζζζζζδδαααααααα",
            "ζζζζζζγγαααααααα",
            "ζζζζζζββαααααααα",
            "ζζζζζζαααααααααα",
            "ζζζζζζαααααααααα",
            "ηηηεεεαααααααααα"
        ],
        [
            "ηηηηηεεεαααααααα",
            "ζζζζζζζζαααααααα",
            "ζζζζζζζζαααααααα",
            "ζζζζζζζζββαααααα",
            "ζζζζζζζζγγαααααα",
            "ζζζζζζζζδδαααααα",
            "ζζζζζζζζδδαααααα",
            "ζζζζζζζζδδαααααα",
            "ζζζζζζζζδδαααααα",
            "ζζζζζζζζδδαααααα",
            "ζζζζζζζζδδαααααα",
            "ζζζζζζζζγγαααααα",
            "ζζζζζζζζββαααααα",
            "ζζζζζζζζαααααααα",
            "ζζζζζζζζαααααααα",
            "ηηηηηεεεαααααααα"
        ],
        [
            "εηηηηηηεεεαααααα",
            "ζζζζζζζζζζαααααα",
            "ζζζζζζζζζζαααααα",
            "ζζζζζζζζζζββαααα",
            "ζζζζζζζζζζγγαααα",
            "ζζζζζζζζζζδδαααα",
            "ζζζζζζζζζζδδαααα",
            "ζζζζζζζζζζδδαααα",
            "ζζζζζζζζζζδδαααα",
            "ζζζζζζζζζζδδαααα",
            "ζζζζζζζζζζδδαααα",
            "ζζζζζζζζζζγγαααα",
            "ζζζζζζζζζζββαααα",
            "ζζζζζζζζζζαααααα",
            "ζζζζζζζζζζαααααα",
            "εηηηηηηεεεαααααα"
        ],
        [
            "εεεηηηηηηεεεαααα",
            "εζζζζζζζζζζζαααα",
            "εζζζζζζζζζζζαααα",
            "εζζζζζζζζζζζββαα",
            "εζζζζζζζζζζζγγαα",
            "εζζζζζζζζζζζδδαα",
            "εζζζζζζζζζζζδδαα",
            "εζζζζζζζζζζζδδαα",
            "εζζζζζζζζζζζδδαα",
            "εζζζζζζζζζζζδδαα",
            "εζζζζζζζζζζζδδαα",
            "εζζζζζζζζζζζγγαα",
            "εζζζζζζζζζζζββαα",
            "εζζζζζζζζζζζαααα",
            "εζζζζζζζζζζζαααα",
            "εεεηηηηηηεεεαααα"
        ],
        [
            "θιεεεηηηηηηεεεαα",
            "θζζζζζζζζζζζζζαα",
            "θζζζζζζζζζζζζζαα",
            "θζζζζζζζζζζζζζββ",
            "θζζζζζζζζζζζζζγγ",
            "θζζζζζζζζζζζζζδδ",
            "θζζζζζζζζζζζζζδδ",
            "θζζζζζζζζζζζζζδδ",
            "θζζζζζζζζζζζζζδδ",
            "θζζζζζζζζζζζζζδδ",
            "θζζζζζζζζζζζζζδδ",
            "θζζζζζζζζζζζζζγγ",
            "θζζζζζζζζζζζζζββ",
            "θζζζζζζζζζζζζζαα",
            "θζζζζζζζζζζζζζαα",
            "θιεεεηηηηηηεεεαα"
        ],
        [
            "βιιιεεεηηηηηηεεε",
            "βζζζζζζζζζζζζζζζ",
            "βζζζζζζζζζζζζζζζ",
            "βζζζζζζζζζζζζζζζ",
            "βζζζζζζζζζζζζζζζ",
            "βζζζζζζζζζζζζζζζ",
            "βζζζζζζζζζζζζζζζ",
            "βζζζζζζζζζζζζζζζ",
            "βζζζζζζζζζζζζζζζ",
            "βζζζζζζζζζζζζζζζ",
            "βζζζζζζζζζζζζζζζ",
            "βζζζζζζζζζζζζζζζ",
            "βζζζζζζζζζζζζζζζ",
            "βζζζζζζζζζζζζζζζ",
            "βζζζζζζζζζζζζζζζ",
            "βιιιεεεηηηηηηεεε"
        ],
        [
            "βββιιιεεεηηηηηηε",
            "βζζζζζζζζζζζζζζζ",
            "εζζζζζζζζζζζζζζζ",
            "εζζζζζζζζζζζζζζζ",
            "εζζζζζζζζζζζζζζζ",
            "εζζζζζζζζζζζζζζζ",
            "εζζζζζζζζζζζζζζζ",
            "εζζζζζζζζζζζζζζζ",
            "εζζζζζζζζζζζζζζζ",
            "εζζζζζζζζζζζζζζζ",
            "εζζζζζζζζζζζζζζζ",
            "εζζζζζζζζζζζζζζζ",
            "εζζζζζζζζζζζζζζζ",
            "εζζζζζζζζζζζζζζζ",
            "βζζζζζζζζζζζζζζζ",
            "βββιιιεεεηηηηηηε"
        ],
        [
            "εεβββιιιεεεηηηηε",
            "εζζζζζζζζζζζζζζζ",
            "εζζζζζζζζζζζζζζζ",
            "κζζζζζζζζζζζζζζζ",
            "κζζζζζζζζζζζζζζζ",
            "κζζζζζζζζζζζζζζζ",
            "κζζζζζζζζζζζζζζζ",
            "κζζζζζζζζζζζζζζζ",
            "κζζζζζζζζζζζζζζζ",
            "κζζζζζζζζζζζζζζζ",
            "κζζζζζζζζζζζζζζζ",
            "κζζζζζζζζζζζζζζζ",
            "κζζζζζζζζζζζζζζζ",
            "εζζζζζζζζζζζζζζζ",
            "εζζζζζζζζζζζζζζζ",
            "εεβββιιιεεεηηηηε"
        ],
        [
            "εεεεβββιιιεεεεεε",
            "εζζζζζζζζζζζζζζζ",
            "κζζζζζζζζζζζζζζζ",
            "κζζζζζζζζζζζζζζζ",
            "κζζζζζζζζζζζζζζζ",
            "κζζζζζζζζζζζζζζζ",
            "κζζζζζζζζζζζζζζζ",
            "κζζζζζζζζζζζζζζζ",
            "κζζζζζζζζζζζζζζζ",
            "κζζζζζζζζζζζζζζζ",
            "κζζζζζζζζζζζζζζζ",
            "κζζζζζζζζζζζζζζζ",
            "κζζζζζζζζζζζζζζζ",
            "κζζζζζζζζζζζζζζζ",
            "εζζζζζζζζζζζζζζζ",
            "εεεεβββιιιεεεεεε"
        ],
        [
            "εεεεεεεεεεεεεεεε",
            "εεεεεεεεεεεεεεεε",
            "κκκκκκκκκκκκκκκε",
            "κκκκκκκκκκκκκκκε",
            "κκκκκκκκκκκκκκκε",
            "κκκκκκκκκκκκκκκε",
            "κκκκκκκκκκκκκκκε",
            "κκκκκκκκκκκκκκκε",
            "κκκκκκκκκκκκκκκε",
            "κκκκκκκκκκκκκκκε",
            "κκκκκκκκκκκκκκκε",
            "κκκκκκκκκκκκκκκε",
            "κκκκκκκκκκκκκκκε",
            "κκκκκκκκκκκκκκκε",
            "εεεεεεεεεεεεεεεε",
            "εεεεεεεεεεεεεεεε"
        ]
    ]
}