{
    "xsize": 16,
    "zsize": 16,
    "palette": {
        "palette": [
            {
                "char": " ",
                "block": "minecraft:air"
            },
            {
                "char": "α",
                "block": "betterblockz:ironslate_blockz_1"
            },
            {
                "char": "β",
                "block": "betterblockz:cyberlight_blockz_0[lit=true]"
            },
            {
                "char": "γ",
                "block": "betterblockz:cyberlight_blockz_1[lit=true]"
            },
            {
                "char": "δ",
                "block": "betterblockz:eclipse_blockz_0"
            },
            {
                "char": "ε",
                "block": "betterblockz:ironslate_blockz_3"
            },
            {
                "char": "ζ",
                "block": "minecraft:structure_void"
            },
            {
                "char": "η",
                "block": "betterblockz:ironslate_blockz_19[axis=x]"
            },
            {
                "char": "θ",
                "block": "betterblockz:ironslate_blockz_6[axis=z]"
            },
            {
                "char": "ι",
                "block": "betterblockz:ironslate_blockz_6[axis=x]"
            }
        ]
    },
    "slices": [
        [
            "αααβγδδδδδδγβααα",
            "αααβγδδδδδδγβααα",
            "αααβγδδδδδδγβααα",
            "ββββγδδδδδδγββββ",
            "γγγγγδδδδδδγγγγγ",
            "δδδδδδδδδδδδδδδδ",
            "δδδδδδδδδδδδδδδδ",
            "δδδδδδδδδδδδδδδδ",
            "δδδδδδδδδδδδδδδδ",
            "δδδδδδδδδδδδδδδδ",
            "δδδδδδδδδδδδδδδδ",
            "γγγγγδδδδδδγγγγγ",
            "ββββγδδδδδδγββββ",
            "αααβγδδδδδδγβααα",
            "αααβγδδδδδδγβααα",
            "αααβγδδδδδδγβααα"
        ],
        [
            "εζζζζζζζζζζζζζζε",
            "ζζζζζζζζζζζζζζζζ",
            "ζζζζζζζζζζζζζζζζ",
            "ζζζζζζζζζζζζζζζζ",
            "ζζζζζζζζζζζζζζζζ",
            "ζζζζζζζζζζζζζζζζ",
            "ζζζζζζζζζζζζζζζζ",
            "ζζζζζζζζζζζζζζζζ",
            "ζζζζζζζζζζζζζζζζ",
            "ζζζζζζζζζζζζζζζζ",
            "ζζζζζζζζζζζζζζζζ",
            "ζζζζζζζζζζζζζζζζ",
            "ζζζζζζζζζζζζζζζζ",
            "ζζζζζζζζζζζζζζζζ",
            "ζζζζζζζζζζζζζζζζ",
            "εζζζζζζζζζζζζζζε"
        ],
        [
            "ηζζζζζζζζζζζζζζη",
            "ζζζζζζζζζζζζζζζζ",
            "ζζζζζζζζζζζζζζζζ",
            "ζζζζζζζζζζζζζζζζ",
            "ζζζζζζζζζζζζζζζζ",
            "ζζζζζζζζζζζζζζζζ",
            "ζζζζζζζζζζζζζζζζ",
            "ζζζζζζζζζζζζζζζζ",
            "ζζζζζζζζζζζζζζζζ",
            "ζζζζζζζζζζζζζζζζ",
            "ζζζζζζζζζζζζζζζζ",
            "ζζζζζζζζζζζζζζζζ",
            "ζζζζζζζζζζζζζζζζ",
            "ζζζζζζζζζζζζζζζζ",
            "ζζζζζζζζζζζζζζζζ",
            "ηζζζζζζζζζζζζζζη"
        ],
        [
            "ηζζζζζζζζζζζζζζη",
            "ζζζζζζζζζζζζζζζζ",
            "ζζζζζζζζζζζζζζζζ",
            "ζζζζζζζζζζζζζζζζ",
            "ζζζζζζζζζζζζζζζζ",
            "ζζζζζζζζζζζζζζζζ",
            "ζζζζζζζζζζζζζζζζ",
            "ζζζζζζζζζζζζζζζζ",
            "ζζζζζζζζζζζζζζζζ",
            "ζζζζζζζζζζζζζζζζ",
            "ζζζζζζζζζζζζζζζζ",
            "ζζζζζζζζζζζζζζζζ",
            "ζζζζζζζζζζζζζζζζ",
            "ζζζζζζζζζζζζζζζζ",
            "ζζζζζζζζζζζζζζζζ",
            "ηζζζζζζζζζζζζζζη"
        ],
        [
            "εζζζζζζζζζζζζζζε",
            "ζζζζζζζζζζζζζζζζ",
            "ζζζζζζζζζζζζζζζζ",
            "ζζζζζζζζζζζζζζζζ",
            "ζζζζζζζζζζζζζζζζ",
            "ζζζζζζζζζζζζζζζζ",
            "ζζζζζζζζζζζζζζζζ",
            "ζζζζζζζζζζζζζζζζ",
            "ζζζζζζζζζζζζζζζζ",
            "ζζζζζζζζζζζζζζζζ",
            "ζζζζζζζζζζζζζζζζ",
            "ζζζζζζζζζζζζζζζζ",
            "ζζζζζζζζζζζζζζζζ",
            "ζζζζζζζζζζζζζζζζ",
            "ζζζζζζζζζζζζζζζζ",
            "εζζζζζζζζζζζζζζε"
        ],
        [
            "αααθθδδδδδδθθααα",
            "αααθθδδδδδδθθααα",
            "αααθθδδδδδδθθααα",
            "ιιιεεδδββδδεειιι",
            "ιιιεδδδββδδδειιι",
            "δδδδδδδδδδδδδδδδ",
            "δδδδδδδδδδδδδδδδ",
            "δδδββδδδδδδββδδδ",
            "δδδββδδδδδδββδδδ",
            "δδδδδδδδδδδδδδδδ",
            "δδδδδδδδδδδδδδδδ",
            "ιιιεδδδββδδδειιι",
            "ιιιεεδδββδδεειιι",
            "αααθθδδδδδδθθααα",
            "αααθθδδδδδδθθααα",
            "αααθθδδδδδδθθααα"
        ]
    ]
}