{
    "xsize": 16,
    "zsize": 16,
    "palette": {
        "palette": [
            {
                "char": " ",
                "block": "minecraft:air"
            },
            {
                "char": "α",
                "block": "betterblockz:ironslate_blockz_1"
            },
            {
                "char": "β",
                "block": "betterblockz:cyberlight_blockz_0[lit=true]"
            },
            {
                "char": "γ",
                "block": "betterblockz:cyberlight_blockz_1[lit=true]"
            },
            {
                "char": "δ",
                "block": "betterblockz:eclipse_blockz_0"
            },
            {
                "char": "ε",
                "block": "betterblockz:ironslate_blockz_3"
            },
            {
                "char": "ζ",
                "block": "minecraft:structure_void"
            },
            {
                "char": "η",
                "block": "betterblockz:ironslate_blockz_19[axis=x]"
            },
            {
                "char": "θ",
                "block": "betterblockz:ironslate_blockz_19[axis=z]"
            },
            {
                "char": "ι",
                "block": "betterblockz:ironslate_blockz_6[axis=x]"
            },
            {
                "char": "κ",
                "block": "betterblockz:ironslate_blockz_6[axis=z]"
            }
        ]
    },
    "slices": [
        [
            "αααααααααααααααα",
            "αααααααααααααααα",
            "αααααααααααααααα",
            "βββββββββββββααα",
            "γγγγγγγγγγγγβααα",
            "δδδδδδδδδδδγβααα",
            "δδδδδδδδδδδγβααα",
            "δδδδδδδδδδδγβααα",
            "δδδδδδδδδδδγβααα",
            "δδδδδδδδδδδγβααα",
            "δδδδδδδδδδδγβααα",
            "γγγγγγγγγγγγβααα",
            "βββββββββββββααα",
            "αααααααααααααααα",
            "αααααααααααααααα",
            "αααααααααααααααα"
        ],
        [
            "εεεεεεεεεεεεεεεε",
            "ζζζζζζζζζζζζζζζε",
            "ζζζζζζζζζζζζζζζε",
            "ζζζζζζζζζζζζζζζε",
            "ζζζζζζζζζζζζζζζε",
            "ζζζζζζζζζζζζζζζε",
            "ζζζζζζζζζζζζζζζε",
            "ζζζζζζζζζζζζζζζε",
            "ζζζζζζζζζζζζζζζε",
            "ζζζζζζζζζζζζζζζε",
            "ζζζζζζζζζζζζζζζε",
            "ζζζζζζζζζζζζζζζε",
            "ζζζζζζζζζζζζζζζε",
            "ζζζζζζζζζζζζζζζε",
            "ζζζζζζζζζζζζζζζε",
            "εεεεεεεεεεεεεεεε"
        ],
        [
            "ηηηηηηηηηηηηηηηη",
            "ζζζζζζζζζζζζζζζθ",
            "ζζζζζζζζζζζζζζζθ",
            "ζζζζζζζζζζζζζζζθ",
            "ζζζζζζζζζζζζζζζθ",
            "ζζζζζζζζζζζζζζζθ",
            "ζζζζζζζζζζζζζζζθ",
            "ζζζζζζζζζζζζζζζθ",
            "ζζζζζζζζζζζζζζζθ",
            "ζζζζζζζζζζζζζζζθ",
            "ζζζζζζζζζζζζζζζθ",
            "ζζζζζζζζζζζζζζζθ",
            "ζζζζζζζζζζζζζζζθ",
            "ζζζζζζζζζζζζζζζθ",
            "ζζζζζζζζζζζζζζζθ",
            "ηηηηηηηηηηηηηηηη"
        ],
        [
            "ηηηηηηηηηηηηηηηη",
            "ζζζζζζζζζζζζζζζθ",
            "ζζζζζζζζζζζζζζζθ",
            "ζζζζζζζζζζζζζζζθ",
            "ζζζζζζζζζζζζζζζθ",
            "ζζζζζζζζζζζζζζζθ",
            "ζζζζζζζζζζζζζζζθ",
            "ζζζζζζζζζζζζζζζθ",
            "ζζζζζζζζζζζζζζζθ",
            "ζζζζζζζζζζζζζζζθ",
            "ζζζζζζζζζζζζζζζθ",
            "ζζζζζζζζζζζζζζζθ",
            "ζζζζζζζζζζζζζζζθ",
            "ζζζζζζζζζζζζζζζθ",
            "ζζζζζζζζζζζζζζζθ",
            "ηηηηηηηηηηηηηηηη"
        ],
        [
            "εεεεεεεεεεεεεεεε",
            "ζζζζζζζζζζζζζζζε",
            "ζζζζζζζζζζζζζζζε",
            "ζζζζζζζζζζζζζζζε",
            "ζζζζζζζζζζζζζζζε",
            "ζζζζζζζζζζζζζζζε",
            "ζζζζζζζζζζζζζζζε",
            "ζζζζζζζζζζζζζζζε",
            "ζζζζζζζζζζζζζζζε",
            "ζζζζζζζζζζζζζζζε",
            "ζζζζζζζζζζζζζζζε",
            "ζζζζζζζζζζζζζζζε",
            "ζζζζζζζζζζζζζζζε",
            "ζζζζζζζζζζζζζζζε",
            "ζζζζζζζζζζζζζζζε",
            "εεεεεεεεεεεεεεεε"
        ],
        [
            "αααααααααααααααα",
            "αααααααααααααααα",
            "αααααααααααααααα",
            "ιιιιιιιιιιιεαααα",
            "ιιιιιιιιιιιεεααα",
            "δδδδδδδδδδδκκααα",
            "δδδδδδδδδδδκκααα",
            "δδδββδδδδδδκκααα",
            "δδδββδδδδδδκκααα",
            "δδδδδδδδδδδκκααα",
            "δδδδδδδδδδδκκααα",
            "ιιιιιιιιιιιεεααα",
            "ιιιιιιιιιιιεαααα",
            "αααααααααααααααα",
            "αααααααααααααααα",
            "αααααααααααααααα"
        ]
    ]
}