{
    "xsize": 16,
    "zsize": 16,
    "palette": {
        "palette": [
            {
                "char": " ",
                "block": "minecraft:air"
            },
            {
                "char": "α",
                "block": "betterblockz:ironslate_blockz_1"
            },
            {
                "char": "β",
                "block": "betterblockz:cyberlight_blockz_0[lit=true]"
            },
            {
                "char": "γ",
                "block": "betterblockz:cyberlight_blockz_1[lit=true]"
            },
            {
                "char": "δ",
                "block": "betterblockz:eclipse_blockz_0"
            },
            {
                "char": "ε",
                "block": "betterblockz:ironslate_blockz_3"
            },
            {
                "char": "ζ",
                "block": "minecraft:structure_void"
            },
            {
                "char": "η",
                "block": "betterblockz:ironslate_blockz_19[axis=z]"
            },
            {
                "char": "θ",
                "block": "betterblockz:ironslate_blockz_6[axis=z]"
            },
            {
                "char": "ι",
                "block": "betterblockz:ironslate_blockz_6[axis=x]"
            }
        ]
    },
    "slices": [
        [
            "αααβγδδδδδδγβααα",
            "αααβγδδδδδδγβααα",
            "αααβγδδδδδδγβααα",
            "ββββγδδδδδδγβααα",
            "γγγγγδδδδδδγβααα",
            "δδδδδδδδδδδγβααα",
            "δδδδδδδδδδδγβααα",
            "δδδδδδδδδδδγβααα",
            "δδδδδδδδδδδγβααα",
            "δδδδδδδδδδδγβααα",
            "δδδδδδδδδδδγβααα",
            "γγγγγδδδδδδγβααα",
            "ββββγδδδδδδγβααα",
            "αααβγδδδδδδγβααα",
            "αααβγδδδδδδγβααα",
            "αααβγδδδδδδγβααα"
        ],
        [
            "εζζζζζζζζζζζζζζε",
            "ζζζζζζζζζζζζζζζε",
            "ζζζζζζζζζζζζζζζε",
            "ζζζζζζζζζζζζζζζε",
            "ζζζζζζζζζζζζζζζε",
            "ζζζζζζζζζζζζζζζε",
            "ζζζζζζζζζζζζζζζε",
            "ζζζζζζζζζζζζζζζε",
            "ζζζζζζζζζζζζζζζε",
            "ζζζζζζζζζζζζζζζε",
            "ζζζζζζζζζζζζζζζε",
            "ζζζζζζζζζζζζζζζε",
            "ζζζζζζζζζζζζζζζε",
            "ζζζζζζζζζζζζζζζε",
            "ζζζζζζζζζζζζζζζε",
            "εζζζζζζζζζζζζζζε"
        ],
        [
            "ηζζζζζζζζζζζζζζη",
            "ζζζζζζζζζζζζζζζη",
            "ζζζζζζζζζζζζζζζη",
            "ζζζζζζζζζζζζζζζη",
            "ζζζζζζζζζζζζζζζη",
            "ζζζζζζζζζζζζζζζη",
            "ζζζζζζζζζζζζζζζη",
            "ζζζζζζζζζζζζζζζη",
            "ζζζζζζζζζζζζζζζη",
            "ζζζζζζζζζζζζζζζη",
            "ζζζζζζζζζζζζζζζη",
            "ζζζζζζζζζζζζζζζη",
            "ζζζζζζζζζζζζζζζη",
            "ζζζζζζζζζζζζζζζη",
            "ζζζζζζζζζζζζζζζη",
            "ηζζζζζζζζζζζζζζη"
        ],
        [
            "ηζζζζζζζζζζζζζζη",
            "ζζζζζζζζζζζζζζζη",
            "ζζζζζζζζζζζζζζζη",
            "ζζζζζζζζζζζζζζζη",
            "ζζζζζζζζζζζζζζζη",
            "ζζζζζζζζζζζζζζζη",
            "ζζζζζζζζζζζζζζζη",
            "ζζζζζζζζζζζζζζζη",
            "ζζζζζζζζζζζζζζζη",
            "ζζζζζζζζζζζζζζζη",
            "ζζζζζζζζζζζζζζζη",
            "ζζζζζζζζζζζζζζζη",
            "ζζζζζζζζζζζζζζζη",
            "ζζζζζζζζζζζζζζζη",
            "ζζζζζζζζζζζζζζζη",
            "ηζζζζζζζζζζζζζζη"
        ],
        [
            "εζζζζζζζζζζζζζζε",
            "ζζζζζζζζζζζζζζζε",
            "ζζζζζζζζζζζζζζζε",
            "ζζζζζζζζζζζζζζζε",
            "ζζζζζζζζζζζζζζζε",
            "ζζζζζζζζζζζζζζζε",
            "ζζζζζζζζζζζζζζζε",
            "ζζζζζζζζζζζζζζζε",
            "ζζζζζζζζζζζζζζζε",
            "ζζζζζζζζζζζζζζζε",
            "ζζζζζζζζζζζζζζζε",
            "ζζζζζζζζζζζζζζζε",
            "ζζζζζζζζζζζζζζζε",
            "ζζζζζζζζζζζζζζζε",
            "ζζζζζζζζζζζζζζζε",
            "εζζζζζζζζζζζζζζε"
        ],
        [
            "αααθθδδδδδδθθααα",
            "αααθθδδδδδδθθααα",
            "αααθθδδδδδδθθααα",
            "ιιιεεδδββδδθθααα",
            "ιιιεδδδββδδθθααα",
            "δδδδδδδδδδδθθααα",
            "δδδδδδδδδδδθθααα",
            "δδδββδδδδδδθθααα",
            "δδδββδδδδδδθθααα",
            "δδδδδδδδδδδθθααα",
            "δδδδδδδδδδδθθααα",
            "ιιιεδδδββδδθθααα",
            "ιιιεεδδββδδθθααα",
            "αααθθδδδδδδθθααα",
            "αααθθδδδδδδθθααα",
            "αααθθδδδδδδθθααα"
        ]
    ]
}