{
    "xsize": 16,
    "zsize": 16,
    "slices": [
        [
            "±±±±±£££££££££££",
            "±±±±±£££££££££££",
            "±±±±±£££££££££££",
            "±±±±±±££££££££££",
            "¤±±±±±££££££££££",
            "¤¤±±±±££££££££££",
            "¤¤±±±±±£££££££££",
            "¤¤¤±±±±±££££££££",
            "¤¤¤¤±±±±±£££££££",
            "¤¤¤¤¤±±±±±££££££",
            "¤¤¤¤¤¤±±±±±±££££",
            "¤¤¤¤¤¤¤±±±±±±±££",
            "¤¤¤¤¤¤¤¤±±±±±±±±",
            "¤¤¤¤¤¤¤¤¤±±±±±±±",
            "¤¤¤£¤¤¤¤¤¤¤±±±±±",
            "¤¤¤¤¤¤¤¤¤¤¤¤¤±±±"
        ],
        [
            "     ÆÄÅÃÃÃ¥¥¥ÃÃ",
            "     ÆÃÄÅÃÃ¥¥¥ÃÃ",
            "     ÓÔÃÅÃÃ¥¥¥¥Ã",
            "      ÆÃÄÃÃÃ¥¥¥¥",
            "§     ÆÄÄÅÃÃÃ¥¥¥",
            "§§    ÕÔÃÅÃÄÃÃ¥¥",
            "§§     ÓÔÖÅÃÖÃÃ¥",
            "©³§     ÓÔÄÃÄÃÃÃ",
            "©©§      ÓÔÃÅÄÃÃ",
            "§§§§§     Ó×ØÄÃÅ",
            "©´§ §       Õ×ØÄ",
            "§ ¨  ©        Õ×",
            "  ¨¨ ©§§        ",
            " §§§§§ §        ",
            "¨§§²§§©© §      ",
            "´§§§ §¨§§§½ §   "
        ],
        [
            "       Ù  ÄËÌË¥¥",
            "          ÃËÌË¥¥",
            "          ÅËÌ°Ê¥",
            "          ÉÅËÌËË",
            "           ÄÃËÌÌ",
            "            ÃÄËË",
            "             ÄÅÊ",
            "¬             ÉÄ",
            "¬¬              ",
            "                ",
            "¬               ",
            "     ¬          ",
            "  ¸·¸¬          ",
            " ¸·¶·¸          ",
            " ·¶²¶·¬¬        ",
            " ¸·¶·¸          "
        ],
        [
            "            ÌÃÌË",
            "            ÌÃÌË",
            "            ËÌÃÌ",
            "             ÌÃÃ",
            "              ÌÌ",
            "                ",
            "                ",
            "                ",
            "                ",
            "                ",
            "                ",
            "                ",
            "                ",
            "   ¶            ",
            "  ¶²¶           ",
            "   ¶            "
        ],
        [
            "            ËÎÌ ",
            "            ËÎÌ ",
            "             ËÎÌ",
            "             ËÎÎ",
            "              ËË",
            "                ",
            "                ",
            "                ",
            "                ",
            "                ",
            "                ",
            "                ",
            "  ¸·¸           ",
            " ¸·¶·¸          ",
            " ·¶²¶·          ",
            " ¸·¶·¸          "
        ],
        [
            "              Ì¥",
            "              Ì¥",
            "               Ì",
            "                ",
            "                ",
            "                ",
            "                ",
            "                ",
            "                ",
            "                ",
            "                ",
            "                ",
            "                ",
            "   ¶            ",
            "  ¶²¶           ",
            "   ¶            "
        ]
    ],
    "refpalette": "building007_palette"
}