{
    "xsize": 16,
    "zsize": 16,
    "slices": [
        [
            "¡¡¡¡¡¡¡¡¡¡¡¡¡¡¡¡",
            "¡¡¡¡¡¡¡¡¡¡¡¡¡¡¡¡",
            "¡¡¥¥¥º»¼½º»¼½º¡¡",
            "¡¡¥¥¥»¼½º»¼½º»¡¡",
            "¡¡¥¥¥¼½º»¼½º»¼¡¡",
            "¡¡º»¼½º»¼½º»¼½¡¡",
            "¡¡»¼½º»¼½º»¼½º¡¡",
            "¡¡¼½º»¼½º»¼½º»¡¡",
            "¡¡½º»¼½º»¼½º»¼¡¡",
            "¡¡º»¼½º»¼½º»¼½¡¡",
            "¡¡»¼½º»¼½º»¼½º¡¡",
            "¡¡¼½º»¼½º»¼½º»¡¡",
            "¡¡½º»¼½º»¼½º»¼¡¡",
            "¡¡º»¼½º»¼½º»¼½¡¡",
            "¡¡¡¡¡¡¡¡¡¡¡¡¡¡¡¡",
            "¡¡¡¡¡¡¡¡¡¡¡¡¡¡¡¡"
        ],
        [
            "££   ££  ££   ££",
            "££¾¾¾¾¾¾¾¾¾¾¾¾££",
            " ¾   ¥     ¿ À¾ ",
            " ¾   §  Á  Â  ¾ ",
            " ¾   ¥     Ã Ä¾ ",
            "£¾¥¨¥¥     Â  ¾£",
            "£¾Å Æ         ¾£",
            " ¾Ç ÈÉ  Á     Ê ",
            " ¾Ç           Ë ",
            "£¾Ç Æ         ¾£",
            "£¾Ç  Ì     Í  ¾£",
            " ¾Ç È  ªÁ  Î Ä¾ ",
            " ¾Ç        Â  ¾ ",
            " ¾ÏÐÐÐÐÐÐÐ Ñ Ï¾ ",
            "££¾¾¾¾¾¾¾¾¾¾¾¾££",
            "££   ££  ££   ££"
        ],
        [
            "££   ££  ££   ££",
            "££¾¾¾¾¾¾¾¾¾¾¾¾££",
            " ¾   ¥        ¾ ",
            " ¾   µ        ¾ ",
            " ¾   ¥        ¾ ",
            "£¾¥¶¥¥        ¾£",
            "£¾            ¾£",
            " ¾   Ò        Ó ",
            " ¾   Ô        Õ ",
            "£¾            ¾£",
            "£¾   Ö        ¾£",
            " ¾   ×        ¾ ",
            " ¾            ¾ ",
            " ¾            ¾ ",
            "££¾¾¾¾¾¾¾¾¾¾¾¾££",
            "££   ££  ££   ££"
        ],
        [
            "££   ££  ££   ££",
            "££¾¾¾¾¾¾¾¾¾¾¾¾££",
            " ¾¥¥¥¥        ¾ ",
            " ¾¥¥¥¥        ¾ ",
            " ¾¥¥¥¥        ¾ ",
            "£¾¥¥¥¥        ¾£",
            "£¾            ¾£",
            " ¾            ¾ ",
            " ¾            ¾ ",
            "£¾            ¾£",
            "£¾            ¾£",
            " ¾            ¾ ",
            " ¾            ¾ ",
            " ¾            ¾ ",
            "££¾¾¾¾¾¾¾¾¾¾¾¾££",
            "££   ££  ££   ££"
        ],
        [
            "££   ££  ££   ££",
            "££¾¾¾¾¾¾¾¾¾¾¾¾££",
            " ¾   ¥ØØØØØØØ¹¾ ",
            " ¾   ¥       Ù¾ ",
            " ¾   ¥       Ù¾ ",
            "£¾¥¥¥¥       Ù¾£",
            "£¾Ú          Ù¾£",
            " ¾Ú          Ù¾ ",
            " ¾Ú          Ù¾ ",
            "£¾Ú          Ù¾£",
            "£¾Ú          Ù¾£",
            " ¾Ú          Ù¾ ",
            " ¾Ú          Ù¾ ",
            " ¾¹ÛÛÛÛÛÛÛÛÛÛ¹¾ ",
            "££¾¾¾¾¾¾¾¾¾¾¾¾££",
            "££   ££  ££   ££"
        ],
        [
            "££   ££  ££   ££",
            "££ÜÜÜ¾¾ÜÜ¾¾ÜÜÜ££",
            " Ý   ¥ÞßßßßßßàÝ ",
            " Ý   ¥áââââââãÝ ",
            " Ý   ¥áââââââãÝ ",
            "£¾¥¥¥¥áââââââã¾£",
            "£¾Þßßßâââââââã¾£",
            " ÝáââââââââââãÝ ",
            " ÝáââââââââââãÝ ",
            "£¾áââââââââââã¾£",
            "£¾áââââââââââã¾£",
            " ÝáââââââââââãÝ ",
            " ÝáââââââââââãÝ ",
            " ÝäååååååååååæÝ ",
            "££ÜÜÜ¾¾ÜÜ¾¾ÜÜÜ££",
            "££   ££  ££   ££"
        ]
    ],
    "refpalette": "building006_palette"
}