{
    "xsize": 16,
    "zsize": 16,
    "slices": [
        [
            "±±±±±¤¤¤¤¤¤¤¤¤¤¤",
            "±±±±±¤¤¤¤¤¤¤¤¤¤¤",
            "±±±±±¤¤¤¤¤¤¤¤¤¤¤",
            "±±±±±¤¤¤¤¤¤¤¤¤¤¤",
            "±±±±±¤¤¤¤¤¤¤¤¤¤¤",
            "±±±±±¤¤¤¤¤¤¤¤¤¤¤",
            "±±±±±¤¤¤¤¤¤¤¤¤¤¤",
            "±±±±±¤¤¤¤¤£¤¤¤¤¤",
            "±±±±±¤¤¤¤¤¤¤¤¤¤¤",
            "±±±±±¤¤¤¤¤¤¤¤¤¤¤",
            "±±±±±¤¤¤¤¤¤¤¤¤¤¤",
            "¢¢¢¢¢¢¢¢¢¢¢¢¢¢¢¢",
            "¡¡¡¡¡¡¡¡¡¡¡¡¡¡¡¡",
            "¡¡¡¡¡¡¡¡¡¡¡¡¡¡¡¡",
            "¡¡¡¡¡¡¡¡¡¡¡¡¡¡¡¡",
            "¡¡¡¡¡¡¡¡¡¡¡¡¡¡¡¡"
        ],
        [
            "     § §©©§© © §",
            "       ©§©§ §§°§",
            "        §§§§§§§§",
            "      §§§§©§§§§§",
            "      ©©§§  ¨§§§",
            "     Ý§§¨   §©§©",
            "     §¨©§§ §§½§§",
            "     § §§ ²§ § §",
            "     §§© § § §©§",
            "     §©§©§§  §§§",
            "     §§§ §§§ §§©",
            "                ",
            "                ",
            "                ",
            "                ",
            "                "
        ],
        [
            "        ¬¬ ¬ ¬¸·",
            "       ¬ ¬      ",
            "                ",
            "          ¬     ",
            "      ¬¬        ",
            "         ¸·¸ ¬ ¬",
            "       ¬¸·¶·¸   ",
            "        ·¶²¶·   ",
            "       ¬¸·¶·¸ ¬ ",
            "      ¬ ¬¸·¸    ",
            "               ¬",
            "                ",
            "                ",
            "                ",
            "                ",
            "                "
        ],
        [
            "                ",
            "                ",
            "                ",
            "                ",
            "                ",
            "                ",
            "          ¶     ",
            "         ¶²¶    ",
            "          ¶     ",
            "                ",
            "                ",
            "                ",
            "                ",
            "                ",
            "                ",
            "                "
        ],
        [
            "                ",
            "                ",
            "                ",
            "                ",
            "                ",
            "         ¸·¸    ",
            "        ¸·¶·¸   ",
            "        ·¶²¶·   ",
            "        ¸·¶·¸   ",
            "         ¸·¸    ",
            "                ",
            "                ",
            "                ",
            "                ",
            "                ",
            "                "
        ],
        [
            "                ",
            "                ",
            "                ",
            "                ",
            "                ",
            "                ",
            "          ¶     ",
            "         ¶²¶    ",
            "          ¶     ",
            "                ",
            "                ",
            "                ",
            "                ",
            "                ",
            "                ",
            "                "
        ]
    ],
    "refpalette": "building007_palette"
}