{
    "xsize": 16,
    "zsize": 16,
    "slices": [
        [
            "¤¤¤¤¤¤¤¤¤¤¤¢¡¡¡¡",
            "¤¤¤¤¤¤¤¤¤¤¤¢¡¡¡¡",
            "¤¤¤¤¤¤¤¤¤¤¤¢¡¡¡¡",
            "£¤¤¤¤¤¤¤¤¤¤¢¡¡¡¡",
            "¤¤¤¤¤¤¤¤¤¤¤¢¡¡¡¡",
            "¤¤¤¤¤¤¤¤¤¤¤¢¡¡¡¡",
            "¤¤¤¤¤¤¤¤¤¤¤¢¡¡¡¡",
            "¤¤¤¤£¤¤¤¤¤¤¢¡¡¡¡",
            "¤¤¤¤¤¤¤¤¤¤¤¢¡¡¡¡",
            "¤¤¤¤¤¤¤¤¤¤¤¢¡¡¡¡",
            "¤¤¤¤¤¤¤¤¤¤¤¢¡¡¡¡",
            "±¤¤¤¤¤¤¤¤¤¤¢¡¡¡¡",
            "±¤¤¤¤¤¤¤¤¤¤¢¡¡¡¡",
            "±±¤¤¤¤¤¤¤¤¤¢¡¡¡¡",
            "±±±±±±±±±±±¢¡¡¡¡",
            "±±±±±±±±±±±¢¡¡¡¡"
        ],
        [
            "§¨ ©½§§©¼       ",
            " § §¼§§©§§      ",
            "¨§§§©©§§©½      ",
            "²   ¨§§§§§©     ",
            "  §§¨©§§§©§     ",
            "§   ³§©´§§§     ",
            "´´  §§ ½§§§     ",
            "©¨´§²§§¨½§      ",
            "©³ §§   §©§     ",
            "§§Í§¨§§´§§©     ",
            "¨³§©§§©§©§§     ",
            " §©©§©§§©¨©     ",
            "  § §§ §§©§     ",
            "     µ  §§§     ",
            "                ",
            "                "
        ],
        [
            "¸¹º¬   ¬        ",
            "·¸¹º   ¬        ",
            "¶·¸¹¬¬  ¬       ",
            "²¶·¸      ¬     ",
            "¶·¸¹ ¬   ¬      ",
            "·¸¹¸·¸¬         ",
            "¸¹¸·¶·¸         ",
            "¬ ·¶²¶·         ",
            "¬ ¸·¶·¸  ¬      ",
            "   ¸·¸    ¬     ",
            "   ¬  ¬ ¬       ",
            "  ¬¬ ¬  ¬ ¬     ",
            "         ¬      ",
            "                ",
            "                ",
            "                "
        ],
        [
            "                ",
            "·¸              ",
            "¶·¸             ",
            "²¶·             ",
            "¶·¸             ",
            "·¸              ",
            "    ¶           ",
            "   ¶²¶          ",
            "    ¶           ",
            "                ",
            "                ",
            "                ",
            "                ",
            "                ",
            "                ",
            "                "
        ],
        [
            "                ",
            "                ",
            "¶               ",
            "²¶              ",
            "¶               ",
            "   ¸·¸          ",
            "  ¸·¶·¸         ",
            "  ·¶²¶·         ",
            "  ¸·¶·¸         ",
            "   ¸·¸          ",
            "                ",
            "                ",
            "                ",
            "                ",
            "                ",
            "                "
        ],
        [
            "                ",
            "·¸              ",
            "¶·¸             ",
            "²¶·             ",
            "¶·¸             ",
            "·¸              ",
            "    ¶           ",
            "   ¶²¶          ",
            "    ¶           ",
            "                ",
            "                ",
            "                ",
            "                ",
            "                ",
            "                ",
            "                "
        ]
    ],
    "refpalette": "building007_palette"
}