{
    "xsize": 16,
    "zsize": 16,
    "slices": [
        [
            "¡¡¡¡¡¡¡¡¡¡¡¡¡¡¡¡",
            "¡¡¡¡¡¡¡¡¡¡¡¡¡¡¡¡",
            "¡¡¡¡¡¡¡¡¡¡¡¡¡¡¡¡",
            "¡¡¡¡¡¡¡¡¡¡¡¡¡¡¡¡",
            "¢¢¢¢¢¢¢¢¢¢¢¢¡¡¡¡",
            "¤¤¤¤££¤¤¤¤¤¢¡¡¡¡",
            "¤¤¤¤££¤¤¤¤¤¢¡¡¡¡",
            "¤¤¤¤££¤¤¤¤¤¢¡¡¡¡",
            "¤¤¤¤££¤¤¤¤¤¢¡¡¡¡",
            "¤¤¤¤££¤¤¤¤¤¢¡¡¡¡",
            "¤¤¤¤££¤¤¤¤¤¢¡¡¡¡",
            "¤¤¤¤££¤¤¤¤¤¢¡¡¡¡",
            "¤¤¤¤££¤¤¤¤¤¢¡¡¡¡",
            "¤¤¤¤£££££££¢¡¡¡¡",
            "¤¤¤¤£££££££¢¡¡¡¡",
            "¤¤¤¤¤¤¤¤¤¤¤¢¡¡¡¡"
        ],
        [
            "                ",
            "                ",
            "                ",
            "    ¥¥¥¥¥¥¥¥¥¥¥ ",
            "    ¥¦¦¦¦¦¦¦¦¦¥ ",
            "§   ¥¦       ¦¥ ",
            "§§§ ¥¦       ¦¥ ",
            "§©§§¥¦       ¦¥ ",
            "§©©©¥¦       ¦¥ ",
            "§§§§¥¦       ¦¥ ",
            " ¨©§¥¦        ¥ ",
            "§³§¨¥¦       ¦¥ ",
            "§³§ ¥¦       ¦¥ ",
            "©§§ ¥¦¦¦¦¦¦¦¦¦¥ ",
            "§§§§¥¥¥¥¥¥¥¥¥¥¥ ",
            "½§§§¼ §§§       "
        ],
        [
            "                ",
            "                ",
            "                ",
            "                ",
            "     ªªªªªªªªª  ",
            "     ªªªªªªªªª  ",
            "     ªªªªªªªªª  ",
            " ¬   ªªªªªªªªª  ",
            " ¬¬¬ ªªªªªªªªª  ",
            "     ªªªªªªªªª  ",
            "  ¬  ªªªªªªªªª  ",
            "     ªªªªªªªªª  ",
            "     ªªªªªªªªª  ",
            "¬   Ï«««««««««  ",
            "                ",
            "                "
        ],
        [
            "                ",
            "                ",
            "                ",
            "                ",
            "                ",
            "    «««««««««   ",
            "    ««    « «   ",
            "    ««   ®  «   ",
            "    ««¾     «   ",
            "    ««      «   ",
            "    ««      «   ",
            "    ««¾   Í «   ",
            "    ««      «   ",
            "    «««««««««   ",
            "                ",
            "                "
        ],
        [
            "                ",
            "                ",
            "                ",
            "                ",
            "                ",
            "    ««««««««    ",
            "    ««««««« «   ",
            "    «       «   ",
            "    «       «   ",
            "    «       «   ",
            "    «       «   ",
            "¸   «       «   ",
            "·   «       «   ",
            "¸   «««««««««   ",
            "    «««««««««   ",
            "                "
        ],
        [
            "                ",
            "                ",
            "                ",
            "                ",
            "                ",
            "                ",
            "   «««««««««    ",
            "   ««      «    ",
            "   ««      «    ",
            "   ««      «    ",
            "   ««      «    ",
            "   ««      «    ",
            "   ««      «    ",
            "   ««      «    ",
            "   «««««««««    ",
            "                "
        ]
    ],
    "refpalette": "building007_palette"
}