{
    "xsize": 16,
    "zsize": 16,
    "slices": [
        [
            "¡¡¡¡¡¡¡¡¡¡¡¡¡¡¡¡",
            "¡¢¢¢¢¢¢¢¢¢¢¢¢¢¢¡",
            "¡¢   ¢¢¢¢¢¢¢¢¢¢¡",
            "¡£   ¢¢¢¢¢¢¢¢¢¢¡",
            "££   ¢¢¢¢¢¢¢¢¢¢¡",
            "£££££¢¢¢¢¢¢¢¢¢¢¡",
            "£¢¢¢¢¢¢¢¢¢¢¢¢¢¢¡",
            "¡¢¢¢¢¢¢¢¢¢¢¢¢¢¢¡",
            "¡¢¢¢¢¢¢¢¢¢¢¢¢¢¢¡",
            "£¢¢¢¢¢¢¢¢¢¢¢¢¢¢¡",
            "¤¢¢¢¢¢¢¢¢¢¢¢¢¢¢¡",
            "£¢¢¢¢¢¢¢¢¢¢¢¢¢¢¡",
            "¡¢¢¢¢¢¢¢¢¢¢¢¢¢¢¡",
            "¡¢¢¢¢¢¢¢¢¢¢¢¢¢¢¡",
            "¡¢¢¢¢¢¢¢¢¢¢¢¢¢¢¡",
            "¡¡¡¡¡¡¡¡¡¡¡¡¡¡¡¡"
        ],
        [
            "¡¡¡¡¡¡¡¡¡¡¡¡¡¡¡¡",
            "¡ ¥¥¥£   ¦ ¦ ¦ ¡",
            "¡¥   ¥         ¡",
            "¡¥   §         ¡",
            "£¥   ¥         ¡",
            "££¥¨¥£   © © ©ª¡",
            "¡¥       ¥¥¥¥¥¥¡",
            "¡¥«      ¥¬ ¥¬®¡",
            "¡¥      ¯¥° ¥° ¡",
            "¡¥«      ¥¥ ¥¥ ¡",
            "¡¥         ±   ¡",
            "¡¥«            ¡",
            "¡¥       ¥¥ ¥¥ ¡",
            "¡²«     ¯¥° ¥° ¡",
            "¡¥       ¥³´¥³ ¡",
            "¡¡¡¡¡¡¡¡¡¡¡¡¡¡¡¡"
        ],
        [
            "¡¡¡¡¡¡¡¡¡¡¡¡¡¡¡¡",
            "¡ ¥¥¥£         ¡",
            "¡¥   ¥         ¡",
            "¡¥   µ         ¡",
            "£¥   ¥         ¡",
            "££¥¶¥£         ¡",
            "¡¥       ¥¥¥¥¥¥¡",
            "¡¥       ¥  ¥  ¡",
            "¡¥       ¥  ¥  ¡",
            "¡¥       ¥¥ ¥¥ ¡",
            "¡¥             ¡",
            "¡¥             ¡",
            "¡¥       ¥¥ ¥¥ ¡",
            "¡¥       ¥  ¥  ¡",
            "¡¥       ¥  ¥  ¡",
            "¡¡¡¡¡¡¡¡¡¡¡¡¡¡¡¡"
        ],
        [
            "¡¡¡¡¡¡¡¡¡¡¡¡¡¡¡¡",
            "¡ ¥¥¥£         ¡",
            "¡¥   ¥         ¡",
            "¡¥   ¥         ¡",
            "£¥   ¥         ¡",
            "££¥¥¥£         ¡",
            "¡¥       ¥¥¥¥¥¥¡",
            "¡¥             ¡",
            "¡¥      ·      ¡",
            "¡¥             ¡",
            "¡¥             ¡",
            "¡¥             ¡",
            "¡¥             ¡",
            "¡¥      ·      ¡",
            "¡¥             ¡",
            "¡¡¡¡¡¡¡¡¡¡¡¡¡¡¡¡"
        ],
        [
            "¡¡¡¡¡¡¡¡¡¡¡¡¡¡¡¡",
            "¡ ££££         ¡",
            "¡£   £         ¡",
            "¡£   £         ¡",
            "££   £         ¡",
            "££££££         ¡",
            "¡              ¡",
            "¡              ¡",
            "¡              ¡",
            "¡              ¡",
            "¡              ¡",
            "¡              ¡",
            "¡              ¡",
            "¡              ¡",
            "¡              ¡",
            "¡¡¡¡¡¡¡¡¡¡¡¡¡¡¡¡"
        ],
        [
            "¡¡£¡¡¡¡¡¡¡¡¡¡¡¡¡",
            "¡¸£££¸¹¸¸¸¸¸¸¸¹¡",
            "¡£   £¹¸¸¸¸¸¸¸¹¡",
            "¡£   £¹¸¸¸¸¸¸¸¹¡",
            "££   £¹¸¸¸¸¸¸¸¹¡",
            "£££££¹¹¸¸¸¸¸¸¸¹¡",
            "£¹¸¸¸¹¹¸¸¸¸¸¸¸¹¡",
            "¡¹¸¸¸¹¸¸¸¸¸¸¸¸¹¡",
            "¤¹¸¸¸¹¸¸¸¸¸¸¸¸¹¡",
            "¤¹¸¸¸¹¸¸¸¸¸¸¸¸¹¡",
            "¤¹¸¸¸¹¸¸¸¸¸¸¸¸¹¡",
            "¤¹¸¸¸¹¸¸¸¸¸¸¸¸¹¡",
            "¤¹¸¸¸¹¸¸¸¸¸¸¸¸¹¡",
            "¡¹¸¸¸¹¸¸¸¸¸¸¸¸¹¡",
            "¡¹¸¸¸¹¸¸¸¸¸¸¸¸¹¡",
            "¡¡¡¡¡¡¡¡¡¡¡¡¡¡¡¡"
        ]
    ],
    "refpalette": "building006_palette"
}