{
    "xsize": 16,
    "zsize": 16,
    "slices": [
        [
            "                ",
            "  ĪĪĪĪĪøøøøøøøø ",
            " īĝĝĝĝĝĝĝúúúúúø ",
            " īĝ¡¡¡¡¡¡¡¡ØØúø ",
            " īĝ¡¡¡¡¡¡¡¡¡¡úø ",
            " īĝ¡¡¡¡¡¡¡¡¡¡úø ",
            " īĝ¡¡¡¡¡¡¡¡¡¡úø ",
            " øĝ¡¡¡¡¡¡¡¡¡¡ĝø ",
            " øĝ¡¡¡¡¡¡¡¡¡¡ĝø ",
            " øú¡¡¡¡¡¡¡¡¡¡ĝĬ ",
            " øú¡¡¡¡¡¡¡¡¡¡ĝĬ ",
            " øú¡¡¡¡¡¡¡¡¡¡ĝĬ ",
            " øú¡¡¡¡¡¡¡¡¡¡ĝĬ ",
            " øúúúúúĝĝĝĝĝĝĝĬ ",
            " øøøøøøøøĭĭĭĭĭ  ",
            "                "
        ],
        [
            "                ",
            " ĘĘĘĘĘĘøø       ",
            " Ęĝĝĝĝĝĝĝċċċċċ  ",
            " ĘĝÖ       ØØċ  ",
            " Ęĝţ         ċ  ",
            " Ęĝţ ł    ł  ċ  ",
            " Ęĝţ Ť  Ą Ť  ċ  ",
            " øĝţ ť    ť  ĝø ",
            " øĝţ         ĝø ",
            "  ċţ ł  Ą ł  ĝĘ ",
            "  ċţ Ť    Ť  ĝĘ ",
            "  ċţ ť ¬½ ť  ĝĘ ",
            "  ċŉĆĆĆĆĆĆĆĆŉĝĘ ",
            "  ċċċċċĝĝĝĝĝĝĝĘ ",
            "       øøĘĘĘĘĘĘ ",
            "                "
        ],
        [
            "                ",
            " Řěěěěěøø       ",
            " Ĝķķķĝĝĝĝċċċċċ  ",
            " Ĝķ        ØØċ  ",
            " Ĝķ          ċ  ",
            " Ĝĝ          ċ  ",
            " Ĝĝ          ċ  ",
            " øĝ          ĝø ",
            " øĝ          ĝø ",
            "  ċ          ĝĤ ",
            "  ċ          ĝĤ ",
            "  ċ          ķĤ ",
            "  ċ          ķĤ ",
            "  ċċċċċĝĝĝĝķķķĤ ",
            "       øøĨĨĨĨĨŌ ",
            "                "
        ],
        [
            "                ",
            "     ĪĪøø       ",
            "  ķķķĝĝĝĝċċċċċ  ",
            "  ķ        ØØċ  ",
            "  ķ          ċ  ",
            " īĝ          ċ  ",
            " īĝ          ċ  ",
            " øĝ          ĝø ",
            " øĝ          ĝø ",
            "  ċ          ĝĬ ",
            "  ċ          ĝĬ ",
            "  ċ          ķ  ",
            "  ċ          ķ  ",
            "  ċċċċċĝĝĝĝķķķ  ",
            "       øøĭĭ     ",
            "                "
        ],
        [
            "                ",
            " őĻĻĻĻĻøø       ",
            " ļķķķĝĝĝĝċċċċċ  ",
            " ļķ        ØØċ  ",
            " ļķ          ċ  ",
            " ļĝ          ċ  ",
            " ļĝ   Ŧ      ċ  ",
            " øĝ          ĝø ",
            " øĝ          ĝø ",
            "  ċ          ĝľ ",
            "  ċ       Ţ  ĝľ ",
            "  ċ          ķľ ",
            "  ċ          ķľ ",
            "  ċċċċċĝĝĝĝķķķľ ",
            "       øøĿĿĿĿĿŀ ",
            "                "
        ],
        [
            "                ",
            " ŁŁŁŁŁŁøø       ",
            " Łĝĝĝĝĝĝĝúúúúú  ",
            " ŁĝĞğğğğğğĠØØú  ",
            " ŁĝġĢĢĢĢĢĢĢğĠú  ",
            " ŁĝġĢĢĢĢĢĢĢĢģú  ",
            " ŁĝġĢĢĢĢĢĢĢĢģú  ",
            " øĝġĢĢĢĢĢĢĢĢģĝø ",
            " øĝġĢĢĢĢĢĢĢĢģĝø ",
            "  úġĢĢĢĢĢĢĢĢģĝŁ ",
            "  úġĢĢĢĢĢĢĢĢģĝŁ ",
            "  úġĢĢĢĢĢĢĢĢģĝŁ ",
            "  úĥĦĦĦĦĦĦĦĦħĝŁ ",
            "  úúúúúĝĝĝĝĝĝĝŁ ",
            "       øøŁŁŁŁŁŁ ",
            "                "
        ]
    ],
    "refpalette": "building005_palette"
}