{
    "xsize": 16,
    "zsize": 16,
    "slices": [
        [
            "¡¡¢¡¡¡¢¡¡¡¢¡¡¡¢¢",
            "¡ÍÍÍÍÍÍÍÍ¡¡¡¡¡¡¡",
            "¢ÍÍÍÍÍÍÍÍ¡¡¡¡¡¡¡",
            "¡ÍÍÍÍÍÍÍÍ¡¡¡¡¡¡¡",
            "¡ÍÍÍÍª«ÍÍ¡¡¡¡¡¡¡",
            "¡ÍÍÍÍª«ÍÍÍÍÍÍÍÍÍ",
            "¢ÍÍÍÍÍÍÍÍÍÍÍÍÍÍÍ",
            "¡ÍÍÍÍÍÍÎÏÏÏÏÏÏÏÏ",
            "¡¡¡¡¡ÍÍÐ        ",
            "¡¡¡¡¡ÍÍÐ        ",
            "¢¡¡¡¡ÍÍÐ        ",
            "¡¡¡¡¡ÍÍÐ        ",
            "¡¡¡¡¡ÍÍÐ    À¸¸À",
            "¡¡¡¡¡ÍÍÐ    ¸ººº",
            "¢¡¡¡¡ÍÍÐ    ¸ººº",
            "¡¡¡¡¡ÍÍÐ    Ãººº"
        ],
        [
            "¢¢¢¢¢¢¢¢¢¢¢¢¢¢¢¢",
            "¢        ¢ÑÒÅÓ ¢",
            "¢ ¬      ¢ §   ¢",
            "¢        ¢     ¢",
            "¢    ª«  ¢¢¢¢Ô¢¢",
            "¢  Õ ª«         ",
            "¢               ",
            "¢      Ö××××××××",
            "¢¢¢¢¢  Ø        ",
            "¢   ¢  Ø        ",
            "¢Ù  Ú  Ø        ",
            "¢Û  ¢  Ø        ",
            "¢Ü§ ¢  Ø    ·¸¸¹",
            "¢Ý  ¢  Ø    ¸ÅÅ¢",
            "¢¢¢¢¢  Ø    ¸Þß ",
            "¢   ¢ ¬Ø    ·   "
        ],
        [
            "¢¢¢¢¢¢¢¢¢¢¢¢¢¢¢¢",
            "¢        ¢     à",
            "¢        ¢     à",
            "¢        ¢     à",
            "¢    ª«  ¢ááâã¢¢",
            "¢    ª«         ",
            "¢               ",
            "¢               ",
            "¢¢¢¢¢           ",
            "¢   ¢           ",
            "¢   ä           ",
            "¢   å           ",
            "¢   à       À¸¸À",
            "¢   à       ¸  ¦",
            "¢ááá¢       ¸æç ",
            "¢   ¢       Ãè  "
        ],
        [
            "¢¢¢¢¢¢¢¢¢¢¢¢¢¢¢¢",
            "¢        ¢     à",
            "¢        ¢     à",
            "¢        ¢     à",
            "¢    ª«  ¢áá¢¢¢¢",
            "¢    ª«         ",
            "¢               ",
            "¢               ",
            "¢¢¢¢¢           ",
            "¢   ¢           ",
            "¢   ¢           ",
            "¢   ¢           ",
            "¢   à       ·¸¸¹",
            "¢   à       ¸éé ",
            "¢ááá¢       ¸   ",
            "¢   ¢       ·   "
        ],
        [
            "¢¢¢¢¢¢¢¢¢¢¢¢¢¢¢¢",
            "¢        ¢     ¢",
            "¢        ¢     ¢",
            "¢        ¢     ¢",
            "¢    ª«  ¢¢¢¢¢¢¢",
            "¢    ª«         ",
            "¢               ",
            "¢               ",
            "¢¢¢¢¢           ",
            "¢   ¢           ",
            "¢   ¢           ",
            "¢   ¢           ",
            "¢   ¢       À¸ÊÊ",
            "¢   ¢       Ê¬  ",
            "¢¢¢¢¢       Ê   ",
            "¢   ¢       Ê   "
        ],
        [
            "¢¢¢¢¢¢¢¢¢¢¢¢¢¢¢¢",
            "¢ËËËËËËËË¢ËËËËË¢",
            "¢ËËËËËËËË¢ËËËËË¢",
            "¢ËËËËËËËË¢ËËËËË¢",
            "¢ËËËËª«ËË¢¢¢¢¢¢¢",
            "¢ËËËËª«ËËËËËËËËË",
            "¢ËËËËËËËËËËËËËËË",
            "¢ËËËËËË         ",
            "¢¢¢¢¢ËË         ",
            "¢ËËË¢ËË         ",
            "¢ËËË¢ËË         ",
            "¢ËËË¢ËË         ",
            "¢ËËË¢ËË     ·¸ÊÊ",
            "¢ËËË¢ËË     ÊÌÌÌ",
            "¢¢¢¢¢ËË     ÊÌÌÌ",
            "¢ËËË¢ËË     ÊÌÌÌ"
        ]
    ],
    "refpalette": "building004_palette"
}