{
    "xsize": 16,
    "zsize": 16,
    "slices": [
        [
            "                ",
            "                ",
            "  Ėîîîîîîîîîîîîî",
            "  ëĴĴĴĴĴĴĴĴĴĴĴĴĴ",
            "  ëĴ««««««««««««",
            "  ëĴ««««««««««««",
            "  ëĴ««««««««««««",
            "  ëĴ««««««««««««",
            "  ëĴ«««««««««««ŀ",
            "  ëĴ«««««««««««ŀ",
            "  ëĴ««««««««««««",
            "  ëĴ««««««««««««",
            "  ëĴĴĴĴĴĴĴĴĴĴĴĴĴ",
            "  œÏÏÏÏÏÏÏÏÏÏÏÏÏ",
            "                ",
            "                "
        ],
        [
            "                ",
            "                ",
            "  ğĂĂĂĂĂĂĂĂĂĂĂĂĂ",
            "  ăĴĴĴĴĴĴĴĴĴĴĴĴĴ",
            "  ăĴÛ           ",
            "  ăĴ  Ŕ   Ŕ ŕ   ",
            "  ăĴ   ŕ        ",
            "  ăĴ    ´      ŀ",
            "  ăĴ           ŀ",
            "  ăĴ  Ŕ  ¬Ŕŕ   ŀ",
            "  ăĴ   Ŗ     ŗ Č",
            "  ăĴ           ŀ",
            "  ăĴĴĴĴĴĴĴĴĴĴĴĴĴ",
            "  łċċċċċċċċċċċċċ",
            "                ",
            "                "
        ],
        [
            "                ",
            "                ",
            "  ĤĤĤĤĤĤĤĤĤĤĤĤĤĤ",
            "  ĤĠĠĠĠĠĠĠĠĠĠĠĠĠ",
            "  ĤĠ            ",
            "  ĤĠ  Ř   Ř     ",
            "  ĤĠ  ř   Ś     ",
            "  ĤĠ           ŀ",
            "  ĤĠ           ŀ",
            "  ĤĠ  Ř   Ř    ŀ",
            "  ĤĠ  ś   Ŝ    Ě",
            "  ĤĠ           ŀ",
            "  ĤĠĠĠĠĠĠĠĠĠĠĠĠĠ",
            "  ĤĤĤĤĤĤĤĤĤĤĤĤĤĤ",
            "                ",
            "                "
        ],
        [
            "                ",
            "                ",
            "  ĤĤĤĤĤĤĤĤĤĤĤĤĤĤ",
            "  ĤĴĴĴĴĴĴĴĴĴĴĴĴĴ",
            "  ĤĴ            ",
            "  ĤĴ            ",
            "  ĤĴ            ",
            "  ĤĴ           ŀ",
            "  ĤĴ          ŝŀ",
            "  ĤĴ          Şŀ",
            "  ĤĴ           ŀ",
            "  ĤĴ           ŀ",
            "  ĤĴĴĴĴĴĴĴĴĴĴĴĴĴ",
            "  ĤĤĤĤĤĤĤĤĤĤĤĤĤĤ",
            "                ",
            "                "
        ],
        [
            "                ",
            "                ",
            "  ĤĤĤĤĤĤĤĤĤĤĤĤĤĤ",
            "  ĤĴĴĴĴĴĴĴĴĴĴĴĴĴ",
            "  ĤĴ            ",
            "  ĤĴ            ",
            "  ĤĴ            ",
            "  ĤĴ     ş     ŀ",
            "  ĤĴ    ş      ŀ",
            "  ĤĴ           ŀ",
            "  ĤĴ           ŀ",
            "  ĤĴ           ŀ",
            "  ĤĴĴĴĴĴĴĴĴĴĴĴĴĴ",
            "  ĤĤĤĤĤĤĤĤĤĤĤĤĤĤ",
            "                ",
            "                "
        ],
        [
            "                ",
            "                ",
            "  ìììììììììììììì",
            "  ìĠĠĠĠĠĠĠĠĠĠĠĠĠ",
            "  ìĠŠššššššššššš",
            "  ìĠŢţţţţţţţţţţţ",
            "  ìĠŢţţţţţţţţţţţ",
            "  ìĠŢţţţţţţţţţţŤ",
            "  ìĠŢţţţţţţţţţťŀ",
            "  ìĠŢţţţţţţţţţťŀ",
            "  ìĠŢţţţţţţţţţťŀ",
            "  ìĠŦŧŧŧŧŧŧŧŧŧŧŨ",
            "  ìĠĠĠĠĠĠĠĠĠĠĠĠĠ",
            "  ìììììììììììììì",
            "                ",
            "                "
        ]
    ],
    "refpalette": "building004_palette"
}