{
    "xsize": 16,
    "zsize": 16,
    "slices": [
        [
            "  µ¤¤¤¤¤¤¤¤¤¤µ  ",
            "  µ¤¤¤¤¤¤¤¤¤¤µ  ",
            "  µ¤¤¤¤¤¤¤¤¤¤µ  ",
            "  µ¤¤¤¤¤¤¤¤¤¤µ  ",
            "  µ¤¤¤¤¤¤¤¤¤¤µ  ",
            "  µ¤¤¤¤¤¤¤¤¤¤µ  ",
            "  µ¤¤¤¤¤¤¤¤¤¤µ  ",
            "  µ¤¤¤¤¤¤¤¤¤¤µ  ",
            "  µ¤¤¤¤¤¤¤¤¤¤µ  ",
            "  µ¤¤¤¤¤¤¤¤¤¤µ  ",
            "  µ¤¤¤¤¤¤¤¤¤¤µ  ",
            "   ¦¤¤¤ĒĒ¤¤¤¦   ",
            "  čččččččččččč  ",
            "                ",
            "                ",
            "                "
        ],
        [
            "  © Ě ìěìě Ĝ ©  ",
            "  ©   ěěěě   ©  ",
            "  © î ěěěě îĝ©  ",
            "  ©   ²²ěě   ©  ",
            "  Ñ Ğ ²²²² ğ Ñ  ",
            "  Ñ   ²²²²   Ñ  ",
            "  © Ġ ²²²ê î¨©  ",
            "  ©  ġ²êêêĢ  ©  ",
            "  © ë êêêê ë ©  ",
            "  ©   êêêê   ©  ",
            "  ©          ©  ",
            "   ¦   ĒĒ   ¦   ",
            "  čččččččččččč  ",
            "                ",
            "                ",
            "                "
        ],
        [
            "  ©          ©  ",
            "  ©          ©  ",
            "  © ô      ô ©  ",
            "  ©          ©  ",
            "  Ñ          Ñ  ",
            "  Ñ          Ñ  ",
            "  © ô      ô ©  ",
            "  ©          ©  ",
            "  ©          ©  ",
            "  ©          ©  ",
            "  ©          ©  ",
            "   ¦        ¦   ",
            "  čččččččččččč  ",
            "                ",
            "                ",
            "                "
        ],
        [
            "  ©          ©  ",
            "  ©          ©  ",
            "  © ô      ô ©  ",
            "  ©          ©  ",
            "  Ñ          Ñ  ",
            "  Ñ          Ñ  ",
            "  © ô      ô ©  ",
            "  ©          ©  ",
            "  ©          ©  ",
            "  ©          ©  ",
            "  ©          ©  ",
            "   ¦        ¦   ",
            "  čččččččččččč  ",
            "                ",
            "                ",
            "                "
        ],
        [
            "  ©          ©  ",
            "  ©          ©  ",
            "  ©          ©  ",
            "  ©          ©  ",
            "  Ñ          Ñ  ",
            "  Ñ          Ñ  ",
            "  ©          ©  ",
            "  ©          ©  ",
            "  ©          ©  ",
            "  ©          ©  ",
            "  ©          ©  ",
            "   ¦     ģ  ¦   ",
            "  čččččččččččč  ",
            "                ",
            "                ",
            "                "
        ],
        [
            "  ©          ©  ",
            "  ©          ©  ",
            "  ©          ©  ",
            "  ©          ©  ",
            "  Ñ          Ñ  ",
            "  Ñ          Ñ  ",
            "  ©          ©  ",
            "  ©          ©  ",
            "  ©          ©  ",
            "  ©          ©  ",
            "  ©          ©  ",
            "   ¦  ģ     ¦   ",
            "  čččččččččččč  ",
            "                ",
            "                ",
            "                "
        ],
        [
            "  µ          µ  ",
            "  µ          µ  ",
            "  µ          µ  ",
            "  µ          µ  ",
            "  µ          µ  ",
            "  µ          µ  ",
            "  µ          µ  ",
            "  µ          µ  ",
            "  µ          µ  ",
            "  µ          µ  ",
            "  µ          µ  ",
            "   ¦        ¦   ",
            "  čččččččččččč  ",
            "                ",
            "                ",
            "                "
        ],
        [
            "  ©          ©  ",
            "  ©          ©  ",
            "  ©          ©  ",
            "  ©          ©  ",
            "  Ñ          Ñ  ",
            "  Ñ          Ñ  ",
            "  ©          ©  ",
            "  ©          ©  ",
            "  ©          ©  ",
            "  ©          ©  ",
            "  ©          ©  ",
            "   ¦     ģ  ¦   ",
            "  čččččččččččč  ",
            "                ",
            "                ",
            "                "
        ],
        [
            "   µ        µ   ",
            "   µ        µ   ",
            "   µ        µ   ",
            "   µ        µ   ",
            "   µ        µ   ",
            "   µ        µ   ",
            "   µ        µ   ",
            "   µ        µ   ",
            "   µ        µ   ",
            "   µ        µ   ",
            "   µ        µ   ",
            "   ö÷ ģ    øù   ",
            "  čččččččččččč  ",
            "                ",
            "                ",
            "                "
        ],
        [
            "    ©      ©    ",
            "    ©      ©    ",
            "    ©      ©    ",
            "    ©      ©    ",
            "    Ñ      Ñ    ",
            "    Ñ      Ñ    ",
            "    ©      ©    ",
            "    ©      ©    ",
            "    ©      ©    ",
            "    ©      ©    ",
            "    ©      ©    ",
            "    ö÷    øù    ",
            "  čččččččččččč  ",
            "                ",
            "                ",
            "                "
        ],
        [
            "     µ©µµ©µ     ",
            "     µ©µµ©µ     ",
            "     µ©µµ©µ     ",
            "     µ©µµ©µ     ",
            "     µÑµµÑµ     ",
            "     µÑµµÑµ     ",
            "     µ©µµ©µ     ",
            "     µ©µµ©µ     ",
            "     µ©µµ©µ     ",
            "     µ©µµ©µ     ",
            "     µ©µµ©µ     ",
            "     öúúúúù     ",
            "  čččččččččččč  ",
            "                ",
            "                ",
            "                "
        ],
        [
            "                ",
            "                ",
            "                ",
            "                ",
            "                ",
            "                ",
            "                ",
            "                ",
            "                ",
            "                ",
            "                ",
            "                ",
            "  čččččččččččč  ",
            "                ",
            "                ",
            "                "
        ]
    ],
    "refpalette": "building003_palette"
}