{
    "xsize": 16,
    "zsize": 16,
    "slices": [
        [
            "££££££££££££££±±",
            "££££££££££££££±±",
            "££££££££££££££±±",
            "£££££££££££££±±±",
            "£££££££££££££±±±",
            "£££££££££££££±±±",
            "££££££££££££±±±±",
            "£££££££££££±±±±¤",
            "££££££££££±±±±¤¤",
            "£££££££££±±±±¤¤¤",
            "£££££££±±±±±¤¤¤¤",
            "£££££±±±±±±±¤¤¤¤",
            "±±±±±±±±±±±¤¤¤¤¤",
            "±±±±±±±±±¤¤¤¤¤¤¤",
            "±±±±±±±±¤¤¤¤¤¤¤£",
            "±±±±±±¤¤¤¤¤¤¤¤¤¤"
        ],
        [
            "ÃÃÃÃÃ¥¥¥ÃÄÄÄÃã  ",
            "ÃÃÃÃÃ¥¥¥ÃÃÃÄÄã  ",
            "ÃÃÃÃ¥¥¥¥ÃÃÄÅæç  ",
            "ÃÃÃ¥¥¥¥ÃÃÃÄÃã   ",
            "¥¥¥¥¥¥ÃÃÃÃÄÃã   ",
            "¥¥¥¥¥ÃÃÄÄÅÄèé   ",
            "¥¥¥¥ÃÃÃÄÅÄèé    ",
            "ÃÃÃÃÃÃÅÄÃæé     ",
            "ÄÄÄÄÄÄÄÃæç     §",
            "ÄÖÄÅÄÃè×ç      §",
            "ÄÄÅÄè×é       ¨§",
            "××××ç        §§©",
            "            ©©§§",
            "          §¨©§  ",
            "        §§§¨§§ ²",
            "      §§©§ §§§ §"
        ],
        [
            "ÃÃÃ¥¥ËÌËÃ  Ù    ",
            "¥Ã¥¥¥ËÌËÅ       ",
            "¥¥¥¥ËÌËÊÄ       ",
            "¥¥¥ËËÌËÅÉ       ",
            "ËËËÌÌËÃÄ        ",
            "ÌÌÌËËÄÄ         ",
            "ËËËÊÄÃ          ",
            "ÅÃÄÄÉ           ",
            "                ",
            " Ù              ",
            "                ",
            "               ¬",
            "            ¬¬¸·",
            "            ¬¸·¶",
            "             ·¶²",
            "        ¬    ¸·¶"
        ],
        [
            "ÃÃÃËÌÃÌ         ",
            "ÊÃÊËÌÃÌ         ",
            "ËËËÌÃÌ          ",
            "ÌÌÌÃÃÌ          ",
            "ÃÃÃÌÌ           ",
            "ÌÌÌ            º",
            "               ¹",
            "               ¸",
            "               ¹",
            "               º",
            "                ",
            "                ",
            "                ",
            "               ¶",
            "              ¶²",
            "               ¶"
        ],
        [
            "ÃÃÃ ÌÎË         ",
            " Ã  ÌÎË         ",
            "   ÌÎË          ",
            "ÌÌÌÎÎË          ",
            "ÎÎÎËË           ",
            "ËËË             ",
            "                ",
            "                ",
            "                ",
            "                ",
            "                ",
            "                ",
            "                ",
            "                ",
            "               ²",
            "                "
        ],
        [
            "Ã  ¥Ì           ",
            "¥ ¥¥Ì           ",
            "¥¥¥Ì            ",
            "ÌÌÌ             ",
            "                ",
            "                ",
            "                ",
            "                ",
            "                ",
            "                ",
            "                ",
            "                ",
            "                ",
            "               ¶",
            "              ¶²",
            "               ¶"
        ]
    ],
    "refpalette": "building007_palette"
}