{
    "xsize": 16,
    "zsize": 16,
    "slices": [
        [
            "                ",
            "                ",
            "îîîîǫ           ",
            "ĴĴĴĴÐ           ",
            "«««ĴÐ           ",
            "«««ĴÐ           ",
            "«««ĴÐ           ",
            "ŀŀŀĴÐ           ",
            "   ĴÐ           ",
            "   ĴÐ           ",
            "   ĴÐ           ",
            "ŀŀŀĴÐ           ",
            "ĴĴĴĴÐ           ",
            "ÏÏÏÏƫ           ",
            "                ",
            "                "
        ],
        [
            "                ",
            "                ",
            "ĂĂĂĂǘ           ",
            "ĴĴĴĴĆ           ",
            "   ĴĆ           ",
            "ǳ ǍĴĆ           ",
            "   ĴĆ           ",
            "ŀǱŀĴĆ           ",
            "   ĴĆ           ",
            "   ĴĆ           ",
            "   ĴĆ           ",
            "ŀŀŀĴĆ           ",
            "ĴĴĴĴĆ           ",
            "ċċċċĳ           ",
            "                ",
            "                "
        ],
        [
            "                ",
            "                ",
            "ĤĤĤĤĤ           ",
            "ĠĠĠĠĤ           ",
            "   ĠĤ           ",
            "   ĠĤ           ",
            "   ĠĤ           ",
            "ŀǲŀĠĤ           ",
            "   ĠĤ           ",
            "   ĠĤ           ",
            "   ĠĤ           ",
            "ŀŀŀĠĤ           ",
            "ĠĠĠĠĤ           ",
            "ĤĤĤĤĤ           ",
            "                ",
            "                "
        ],
        [
            "                ",
            "                ",
            "ĤĤĤĤĤ           ",
            "ĴĴĴĴĤ           ",
            "   ĴĤ           ",
            "   ĴĤ           ",
            "   ĴĤ           ",
            "ŀŀŀĴĤ           ",
            "   ĴĤ           ",
            "   ĴĤ           ",
            "   ĴĤ           ",
            "ŀŀŀĴĤ           ",
            "ĴĴĴĴĤ           ",
            "ĤĤĤĤĤ           ",
            "                ",
            "                "
        ],
        [
            "                ",
            "                ",
            "ĤĤĤĤĤ           ",
            "ĴĴĴĴĤ           ",
            "   ĴĤ           ",
            "   ĴĤ           ",
            "   ĴĤ           ",
            "ŀŀŀĴĤ           ",
            "   ĴĤ           ",
            "   ĴĤ           ",
            "   ĴĤ           ",
            "ŀŀŀĴĤ           ",
            "ĴĴĴĴĤ           ",
            "ĤĤĤĤĤ           ",
            "                ",
            "                "
        ],
        [
            "                ",
            "                ",
            "ììììì           ",
            "ĠĠĠĠì           ",
            "ššǴĠì           ",
            "ţţťĠì           ",
            "ŧŧŤĠì           ",
            "ŀŀŀĠì           ",
            "   Ġì           ",
            "   Ġì           ",
            "   Ġì           ",
            "ŀŀŀĠì           ",
            "ĠĠĠĠì           ",
            "ììììì           ",
            "                ",
            "                "
        ]
    ],
    "refpalette": "building004_palette"
}