{
    "xsize": 16,
    "zsize": 16,
    "slices": [
        [
            "¡¡¡¡¡¡¡¡¡¡¡¡¡¡¡¡",
            "¡¡¡¡¡¡¡¡¡¡¡¡¡¡¡¡",
            "¡¡¡¡¡¡¡¡¡¡¡¡¡¡¡¡",
            "¡¡¡¡¡¡¡¡¡¡¡¡¡¡¡¡",
            "¡¡¡¡¡¡¡¡¡¡¡¡¡¡¡¡",
            "¡¡¡¡¡¡¡¡¡¡¡¡¡¡¡¡",
            "¡¡¡¡¡¡¡¡¡¡¡¡¡¡¡¡",
            "¡¡¡¡¡¡¡¡¡¡¡¡¡¡¡¡",
            "¡¡¡¡¡¡¡¡¡¡¡¡¡¡¡¡",
            "¡¡¡¡¡¡¡¡¡¡¡¡¡¡¡¡",
            "¡¡¡¡¡¡¡¡¡¡¡¡¡¡¡¡",
            "¡¡¡¡¡¡¡¡¡¡¡¡¡¡¡¡",
            "¡¡¡¡¡¡¡¡¡¡¡¡¡¡¡¡",
            "¡¡¡¡¡¡¡¡¡¡¡¡¡¡¡¡",
            "¡¡¡¡¡¡¡¡¡¡¡¡¡¡¡¡",
            "¡¡¡¡¡¡¡¡¡¡¡¡¡¡¡¡"
        ],
        [
            "¢¢¢¢¢¢¢¢¢¢¢¢¢¢¢¢",
            "¢       £¤¥¤¤¦ ¢",
            "¢  §¨     ¤© ª ¢",
            "¢  «           ¢",
            "¢    ¬      ¬  ¢",
            "¢£         ©® ¯¢",
            "¢°±    © ²³³³ ´¢",
            "¢µ¶£   ¥¤¥³³³ ·¢",
            "¢µ±   ²¤¤¤³³® ¸¢",
            "¢°£  ©¥¥¥¥³³   ¢",
            "¢    ¥¥¤¥³³©   ¢",
            "¢     ©  ³    ¹¢",
            "¢º ¬        ¬ »¢",
            "¢°£  ¼      £»½¢",
            "¢¾°¿       À½¾¾¢",
            "¢¢¢¢¢¢¢¢¢¢¢¢¢¢¢¢"
        ],
        [
            "¢¢¢¢¢¢¢¢¢¢¢¢¢¢¢¢",
            "¢         ¤£®  ¢",
            "¢              ¢",
            "¢   §          ¢",
            "¢   ¨          ¢",
            "¢             Á¢",
            "¢Â            Ã¢",
            "¢°       ³³   Ä¢",
            "¢±     ¥¥³³®  Å¢",
            "¢      ¤¥³©    ¢",
            "¢     ©®       ¢",
            "¢        ®     ¢",
            "¢              ¢",
            "¢Æ           Ç»¢",
            "¢¾          º½»¢",
            "¢¢¢¢¢¢¢¢¢¢¢¢¢¢¢¢"
        ],
        [
            "¢¢¢¢¢¢¢¢¢¢¢¢¢¢¢¢",
            "¢         ©    ¢",
            "¢              ¢",
            "¢  È           ¢",
            "¢ ¨§           ¢",
            "¢             É¢",
            "¢             Ê¢",
            "¢±        ®   Ë¢",
            "¢       ¥³    Ì¢",
            "¢      ©©      ¢",
            "¢              ¢",
            "¢              ¢",
            "¢              ¢",
            "¢              ¢",
            "¢£            »¢",
            "¢¢¢¢¢¢¢¢¢¢¢¢¢¢¢¢"
        ],
        [
            "¢¢¢¢¢¢¢¢¢¢¢¢¢¢¢¢",
            "¢ÍÍÍÍÍÍÍÍÍÍÍÍÍÍ¢",
            "¢Í¨  ÍÍÍÍÍÍÍÍÍÍ¢",
            "¢Í§  ÍÍÍÍÍÍÍÍÍÍ¢",
            "¢Í   ÍÍÍÍÍÍÍÍÍÍ¢",
            "¢ÍÍÍÍÍÍÍÍÍÍÍÍÍÍ¢",
            "¢ÍÍÍÍÍÍÍÍÍÍÍÍÍÍ¢",
            "¢ÍÍÍÍÍÍÍÍÍÍÍÍÍÍ¢",
            "¢ÍÍÍÍÍÍÍÍÍÍÍÍÍÍ¢",
            "¢ÍÍÍÍÍÍÍÍÍÍÍÍÍÍ¢",
            "¢ÍÍÍÍÍÍÍÍÍÍÍÍÍÍ¢",
            "¢ÍÍÍÍÍÍÍÍÍÍÍÍÍÍ¢",
            "¢ÍÍÍÍÍÍÍÍÍÍÍÍÍÍ¢",
            "¢ÍÍÍÍÍÍÍÍÍÍÍÍÍÍ¢",
            "¢ÍÍÍÍÍÍÍÍÍÍÍÍÍÍ¢",
            "¢¢¢¢¢¢¢¢¢¢¢¢¢¢¢¢"
        ],
        [
            "¢¢¢¢¢¢¢¢¢¢¢¢¢¢¢¢",
            "¢ÎÎÎÎÎÎÎÎÎÎÎÎÎÎ¢",
            "¢Î §¨ÎÎÎÎÎÎÎÎÎÎ¢",
            "¢Î « ÎÎÎÎÎÎÎÎÎÎ¢",
            "¢Î   ÎÎÎÎÎÎÎÎÎÎ¢",
            "¢ÎÎÎÎÎÎÎÎÎÎÎÎÎÎ¢",
            "¢ÎÎÎÎÎÎÎÎÎÎÎÎÎÎ¢",
            "¢ÎÎÎÎÎÎÎÎÎÎÎÎÎÎ¢",
            "¢ÎÎÎÎÎÎÎÎÎÎÎÎÎÎ¢",
            "¢ÎÎÎÎÎÎÎÎÎÎÎÎÎÎ¢",
            "¢ÎÎÎÎÎÎÎÎÎÎÎÎÎÎ¢",
            "¢ÎÎÎÎÎÎÎÎÎÎÎÎÎÎ¢",
            "¢ÎÎÎÎÎÎÎÎÎÎÎÎÎÎ¢",
            "¢ÎÎÎÎÎÎÎÎÎÎÎÎÎÎ¢",
            "¢ÎÎÎÎÎÎÎÎÎÎÎÎÎÎ¢",
            "¢¢¢¢¢¢¢¢¢¢¢¢¢¢¢¢"
        ]
    ],
    "refpalette": "building005_palette"
}