{
    "xsize": 16,
    "zsize": 16,
    "slices": [
        [
            "þþþþþþþþþþþþþþþþ",
            "þþþþþþþþþþþþþþþþ",
            "þþ««««ÿÿÿÿÿÿÿÿÿÿ",
            "þþ««««««««««««««",
            "þþ«««ª««««««««««",
            "þþ«««ª««««««««««",
            "þþÿ«««««««««««««",
            "þþÿ«««««««««««««",
            "þþÿ«««««««««««««",
            "þþÿ«««««««««««««",
            "þþÿ«««««««««««««",
            "þþÿ«««««««««««««",
            "þþÿ«««««««««««««",
            "þþÿ«««««««««ÿÿÿÿ",
            "þþÿºººººººººÿĀĀĀ",
            "þþÿºººººººººÿĀĀĀ"
        ],
        [
            "                ",
            "                ",
            "  āĂĂĂĂĂĂĂĂĂĂĂĂĂ",
            "  ă    ÍĄĄĄĄÍą  ",
            "  ă    Ć   ÅĆ¬  ",
            "  ă    Ć    Ćć  ",
            "  ă    Í    ÍĈ  ",
            "  ăÍĉĊÍċ    Č   ",
            "  ăĈ        č   ",
            "  ăĈ        ÍĈ  ",
            "  ăĈ      ´ Ćć  ",
            "  ăĈ        Ć   ",
            "  ăĈ¬      ĎÍ ď ",
            "  ăÍĂĂÍĐÍĂĂÍđċċċ",
            "  ă Ē ē ē Ē ĆĔĔĔ",
            "  ă         Ć ĕ "
        ],
        [
            "                ",
            "                ",
            "  Ėîîîîîėėėėėėėė",
            "  ë    Í    Í   ",
            "  ë    Ð    Ð   ",
            "  ë    Ð    Ð   ",
            "  ë    Í    Í   ",
            "  ëÍĘęÍÐ    Ě   ",
            "  ė         ě   ",
            "  ė         Í   ",
            "  ė         Ð   ",
            "  ė         Ð   ",
            "  ė         Í   ",
            "  ëÍîîÍĜÍîîÍĝĞėė",
            "  ë         Ð   ",
            "  ë         Ð   "
        ],
        [
            "                ",
            "                ",
            "  ğĂĂĂĂĂėėėėėėėė",
            "  ă    Í    Í   ",
            "  ă    Ć    Ć   ",
            "  ă    Ć    Ć   ",
            "  ă    Í    Ć   ",
            "  ăÍċċÍÏ    Í   ",
            "  ė         Í   ",
            "  ė         Ć   ",
            "  ė         Ć   ",
            "  ė         Ć   ",
            "  ė         Í   ",
            "  ăÍĂĂÍĂÍĂĂÍđĞėė",
            "  ă         Ć   ",
            "  ă         Ć   "
        ],
        [
            "                ",
            "                ",
            "  Ėîîîîîîîîîîîîî",
            "  ëÌÌÌÌÍÌÌÌÌÍÌÌÌ",
            "  ëÌÌÌÌÐ   ÌÐÌ  ",
            "  ëÌÌÌÌÐ   ÌÐÌ  ",
            "  ëÌÌÌÌÍ   ÌÐÌ  ",
            "  ëÍÏÏÍÐ   ÌÍÌ  ",
            "  ëÌ       ÌÍÌ  ",
            "  ëÌ       ÌÐÌ  ",
            "  ëÌ       ÌÐÌ  ",
            "  ëÌ       ÌÐÌ  ",
            "  ëÌÌÌÌÌÌÌÌÌÍÌÌÌ",
            "  ëÍîîÍîÍîîÍĝÏÏÏ",
            "  ëÌÌÌÌÌÌÌÌÌÐ   ",
            "  ëÌ       ÌÐ   "
        ],
        [
            "                ",
            " ììììììììììììììì",
            " ìĠĠĠĠĠĠĠĠĠĠĠĠĠĠ",
            " ìĠġġġġġġġġġġġġġ",
            " ìĠġġġġġġġġġġġġġ",
            " ìĠġġġġġġġġġġġġġ",
            " ìĠġġġġġġġġġġġġġ",
            " ìĠġġġġġġġġġġġġġ",
            " ìĠġġġġġġġġġġġġġ",
            " ìĠġġġġġġġġġġġġġ",
            " ìĠġġġġġġġġġġġġġ",
            " ìĠġġġġġġġġġġġġġ",
            " ìĠġġġġġġġġġġġġġ",
            " ìĠġġġġġġġġġĠĠĠĠ",
            " ìĠġġġġġġġġġĠììì",
            " ìĠġġġġġġġġġĠì  "
        ]
    ],
    "refpalette": "building004_palette"
}