{
    "xsize": 16,
    "zsize": 16,
    "slices": [
        [
            "  µ¤¤  ÐÐ  ¤¤µ  ",
            "  µ¤¤      ¤¤µ  ",
            "  µ¤¤      ¤¤µ  ",
            "  µ¤¤      ¤¤µ  ",
            "  µ¤¤  ÐÐ  ¤¤µ  ",
            "  µ¤¤      ¤¤µ  ",
            "  µ¤¤      ¤¤µ  ",
            "  µ¤¤      ¤¤µ  ",
            "  µ¤¤      ¤¤µ  ",
            "  µ¤¤¤¤¤¤¤¤¤¤µ  ",
            "  µ¤¤¤¤¤¤¤¤¤¤µ  ",
            "   ¦¤¤¤ĒĒ¤¤¤¦   ",
            "  čččččččččččč  ",
            "                ",
            "                ",
            "                "
        ],
        [
            "  © Þ ÏÐÐÏ ß ©  ",
            "  © Þ      ß ©  ",
            "  © Þ      ß ©  ",
            "  © Þ      ß ©  ",
            "  Ñ Þ ÏÐÐÏ ß Ñ  ",
            "  Ñ Þ      ß Ñ  ",
            "  © Þ      ß ©  ",
            "  © Þ      ß ©  ",
            "  © Þ      ß ©  ",
            "  © ĖėėėėėėĘ ©  ",
            "  ©  ę       ©  ",
            "   ¦   ĒĒ   ¦   ",
            "  čččččččččččč  ",
            "                ",
            "                ",
            "                "
        ],
        [
            "  ©  ÓáÔÔ¨Ö  ©  ",
            "  ©          ©  ",
            "  ©          ©  ",
            "  ©          ©  ",
            "  Ñ  ÓÔÔ§áÖ  Ñ  ",
            "  Ñ          Ñ  ",
            "  ©          ©  ",
            "  ©          ©  ",
            "  ©          ©  ",
            "  ©          ©  ",
            "  ©          ©  ",
            "   ¦   ĒĒ   ¦   ",
            "  čččččččččččč  ",
            "                ",
            "                ",
            "                "
        ],
        [
            "  ©  ×ÔÔáÔØ  ©  ",
            "  ©          ©  ",
            "  ©          ©  ",
            "  ©          ©  ",
            "  Ñ  ×ÔáÔÔØ  Ñ  ",
            "  Ñ          Ñ  ",
            "  ©          ©  ",
            "  ©          ©  ",
            "  ©          ©  ",
            "  ©          ©  ",
            "  ©          ©  ",
            "   ¦   ĒĒ   ¦   ",
            "  čččččččččččč  ",
            "                ",
            "                ",
            "                "
        ],
        [
            "  ©  ÓÔÔÔáÖ  ©  ",
            "  ©          ©  ",
            "  ©          ©  ",
            "  ©          ©  ",
            "  Ñ  ÓÔÔÔáÖ  Ñ  ",
            "  Ñ          Ñ  ",
            "  ©          ©  ",
            "  ©          ©  ",
            "  ©          ©  ",
            "  ©          ©  ",
            "  ©          ©  ",
            "   ¦   ĒĒ   ¦   ",
            "  čččččččččččč  ",
            "                ",
            "                ",
            "                "
        ],
        [
            "  ©   ÙÐÐÙ   ©  ",
            "  ©          ©  ",
            "  ©          ©  ",
            "  ©          ©  ",
            "  Ñ   ÙÐÐÙ   Ñ  ",
            "  Ñ          Ñ  ",
            "  ©          ©  ",
            "  ©          ©  ",
            "  ©          ©  ",
            "  ©          ©  ",
            "  ©          ©  ",
            "   ¦   ĒĒ   ¦   ",
            "  čččččččččččč  ",
            "                ",
            "                ",
            "                "
        ]
    ],
    "refpalette": "building003_palette"
}