{
    "xsize": 16,
    "zsize": 16,
    "slices": [
        [
            "±±±±±±±±±±±¢¡¡¡¡",
            "±±±±±±±±±±±¢¡¡¡¡",
            "±±±±±±±±±±±¢¡¡¡¡",
            "±±¤¤¤¤¤¤¤¤¤¢¡¡¡¡",
            "±¤¤¤¤¤¤¤¤¤¤¢¡¡¡¡",
            "±¤¤¤¤¤¤¤¤¤¤¢¡¡¡¡",
            "¤¤¤¤¤¤¤¤¤¤¤¢¡¡¡¡",
            "¤¤£¤¤¤¤¤¤¤¤¢¡¡¡¡",
            "¤¤¤¤¤¤¤¤¤¤¤¢¡¡¡¡",
            "¤¤¤¤¤¤¤¤¤¤¤¢¡¡¡¡",
            "¤¤¤¤¤¤¤¤¤¤¤¢¡¡¡¡",
            "¤¤¤¤¤¤¤¤¤¤¤¢¡¡¡¡",
            "¤¤¤¤¤¤¤¤£¤¤¢¡¡¡¡",
            "¤¤¤¤¤¤¤¤¤¤¤¢¡¡¡¡",
            "¤¤¤¤¤¤¤¤¤¤¤¢¡¡¡¡",
            "¤¤¤¤¤¤¤¤¤¤¤¢¡¡¡¡"
        ],
        [
            "                ",
            "                ",
            "                ",
            "  ¨  »  §§¨     ",
            "  ¼§©§§§§©      ",
            " §§§§§§§§§§     ",
            "§ § § § §§      ",
            " ¨²§ § ¨©§§     ",
            "§ ©§§ § §©©     ",
            "§ §³§§© §§§     ",
            "§¨§§§§§§¨§´     ",
            "§§ §§§§§ §      ",
            "§§§© §§§² §     ",
            "§§¨§§¨§§ ¨§     ",
            " §§§ §§§§¨©     ",
            " ¨ ¨§§ §§©§     "
        ],
        [
            "                ",
            "                ",
            "                ",
            "                ",
            "    ¬    ¬      ",
            "                ",
            "                ",
            "  ²     ¬       ",
            "  ¬      ¬¬     ",
            "      ¬         ",
            "       ¸·¸      ",
            "      ¸·¶·¸     ",
            "¸  ¬  ·¶²¶·     ",
            "·¸    ¸·¶·¸     ",
            "¶·     ¸·¸¬     ",
            "·¸       ¬      "
        ],
        [
            "                ",
            "                ",
            "                ",
            "                ",
            "º¹¸¹º           ",
            "¹¸·¸¹º          ",
            "¸·¶·¸¹          ",
            "·¶²¶·¸          ",
            "¸·¶·¸¹          ",
            "¹¸·¸¹º          ",
            "º¹¸¹º           ",
            "        ¶       ",
            "       ¶²¶      ",
            "        ¶       ",
            "¶               ",
            "                "
        ],
        [
            "                ",
            "                ",
            "                ",
            "                ",
            "                ",
            " ¸·¸            ",
            "¸·¶·¸           ",
            "·¶²¶·           ",
            "¸·¶·¸           ",
            " ¸·¸            ",
            "       ¸·¸      ",
            "      ¸·¶·¸     ",
            "      ·¶²¶·     ",
            "      ¸·¶·¸     ",
            "       ¸·¸      ",
            "                "
        ],
        [
            "                ",
            "                ",
            "                ",
            "                ",
            "                ",
            "                ",
            "  ¶             ",
            " ¶²¶            ",
            "  ¶             ",
            "                ",
            "                ",
            "        ¶       ",
            "       ¶²¶      ",
            "        ¶       ",
            "¶               ",
            "                "
        ]
    ],
    "refpalette": "building007_palette"
}