{
    "xsize": 16,
    "zsize": 16,
    "slices": [
        [
            "¡¡¡¡¡ÍÍÐ    Ãººº",
            "¡¡¡¡¡ÍÍÐ    ¸ººº",
            "¢¡¡¡¡ÍÍÐ    ¸ººº",
            "¡¡¡¡¡ÍÍÐ    Ã¸¸ż",
            "¡¡¡¡¡ÍÍÐ        ",
            "¡¡¡¡¡ÍÍÐ        ",
            "¢¡¡¡¡ÍÍÐ        ",
            "¡¡¡¡¡ÍÍÐ        ",
            "¡¡¡¡¡ÍÍðîîîîîîîî",
            "¡¡¡¡¡ÍÍÍÍÍÍÍÍÍÍÍ",
            "¢¡¡¡¡ÍÍÍÍÍÍÍÍÍÍÍ",
            "¡¡¡¡¡¡¡¡¡¡¡¡¡¡¡¡",
            "¡¡¡¡¡¡¡¡¡¡¡¡¡¡¡¡",
            "¡¡¡¡¡¡¡¡¡¡¡¡¡¡¡¡",
            "¡¡¡¡¡¡¡¡¡¡¡¡¡¡¡¡",
            "¡¡¡¡¡¡¡¡¡¡¡¡¡¡¡¡"
        ],
        [
            "¢Ù  Ú  Ø    · ´ ",
            "¢Û  ¢  Ø    ¸ſƀ ",
            "¢Ü§ ¢  Ø    ¸ÇÇ¢",
            "¢Ý  ¢  Ø    Ŷ¸¸Ŷ",
            "¢¢¢¢¢  Ø        ",
            "¢   ¢  Ø        ",
            "¢Ù  Ú  Ø        ",
            "¢Û  ¢  Ø        ",
            "¢Ü± ¢  øôôôôôôôô",
            "¢ÝƁƂ¢ Õ         ",
            "¢¢ƃ¢¢           ",
            "¢   Ƅ¢¢¢¢¢ƅ¢¢¢¢¢",
            "¢     Å ¢     ¢ ",
            "¢       ¢   § ¢ ",
            "¢       ¢ ƆÇƇƈ¢ ",
            "¢¢¢¢¢¢¢¢¢¢¢¢¢¢¢¢"
        ],
        [
            "¢   ä       Ãè  ",
            "¢   å       ¸ƉƊ ",
            "¢   à       ¸  ¦",
            "¢   à       Ã¸¸ż",
            "¢ááá¢           ",
            "¢   ¢           ",
            "¢   ä           ",
            "¢   å           ",
            "¢   à           ",
            "¢ Ƌƌà           ",
            "¢¢ƃ¢¢           ",
            "¢    ¢¢¢¢¢ƍúáá¢¢",
            "¢       ¢     à ",
            "¢       ¢Ǝ    à ",
            "¢       ¢     à ",
            "¢¢¢¢¢¢¢¢¢¢¢¢¢¢¢¢"
        ],
        [
            "¢   ¢       ·   ",
            "¢   ¢       ¸   ",
            "¢   à       ¸éé ",
            "¢   à       Ŷ¸¸Ŷ",
            "¢ááá¢           ",
            "¢   ¢           ",
            "¢   ¢           ",
            "¢   ¢           ",
            "¢   à           ",
            "¢   à           ",
            "¢¢¢¢¢           ",
            "¢    ¢¢¢¢¢¢¢áá¢¢",
            "¢       ¢     à ",
            "¢       ¢     à ",
            "¢       ¢     à ",
            "¢¢¢¢¢¢¢¢¢¢¢¢¢¢¢¢"
        ],
        [
            "¢   ¢       Ê   ",
            "¢   ¢       Ê   ",
            "¢   ¢       Ê   ",
            "¢   ¢       ÃÊÊÊ",
            "¢¢¢¢¢           ",
            "¢   ¢           ",
            "¢   ¢           ",
            "¢   ¢           ",
            "¢   ¢           ",
            "¢   ¢           ",
            "¢¢¢¢¢           ",
            "¢    ¢¢¢¢¢¢¢¢¢¢¢",
            "¢       ¢     ¢ ",
            "¢       ¢     ¢ ",
            "¢       ¢     ¢ ",
            "¢¢¢¢¢¢¢¢¢¢¢¢¢¢¢¢"
        ],
        [
            "¢ËËË¢ËË     ÊÌÌÌ",
            "¢ËËË¢ËË     ÊÌÌÌ",
            "¢ËËË¢ËË     ÊÌÌÌ",
            "¢ËËË¢ËË     ŶÊÊÊ",
            "¢¢¢¢¢ËË         ",
            "¢ËËË¢ËË         ",
            "¢ËËË¢ËË         ",
            "¢ËËË¢ËË         ",
            "¢ËËË¢ËË         ",
            "¢ËËË¢ËËËËËËËËËËË",
            "¢¢¢¢¢ËËËËËËËËËËË",
            "¢ËËËË¢¢¢¢¢¢¢¢¢¢¢",
            "¢ËËËËËËË¢ËËËËË¢Ë",
            "¢ËËËËËËË¢ËËËËË¢Ë",
            "¢ËËËËËËË¢ËËËËË¢Ë",
            "¢¢¢¢¢¢¢¢¢¢¢¢¢¢¢¢"
        ]
    ],
    "refpalette": "building004_palette"
}