{
    "xsize": 16,
    "zsize": 16,
    "slices": [
        [
            "¤¤¤¤¤¤¤¤¤¤¤¤¤¤±±",
            "¤¤¤¤¤¤¤¤¤¤¤¤¤¤±±",
            "¤¤¤¤¤¤¤¤¤¤¤¤¤¤±±",
            "¤¤¤¤¤¤£¤¤¤¤¤¤¤±±",
            "¤¤¤¤¤¤¤¤¤¤¤¤¤¤±±",
            "¤¤¤¤¤¤¤¤¤¤¤¤¤¤±±",
            "¤¤¤¤¤¤¤¤¤¤¤¤¤¤±±",
            "¤¤¤¤¤¤¤¤¤¤¤¤¤¤±±",
            "¤¤¤£¤¤¤¤¤¤¤¤¤¤±±",
            "¤¤¤¤¤¤¤¤¤¤¤¤¤¤±±",
            "¤¤¤¤¤¤¤¤¤¤¤¤¤¤±±",
            "¢¢¢¢¢¢¢¢¢¢¢¢¢¢¢¢",
            "¡¡¡¡¡¡¡¡¡¡¡¡¡¡¡¡",
            "¡¡¡¡¡¡¡¡¡¡¡¡¡¡¡¡",
            "¡¡¡¡¡¡¡¡¡¡¡¡¡¡¡¡",
            "¡¡¡¡¡¡¡¡¡¡¡¡¡¡¡¡"
        ],
        [
            "§§§ §§§ §§§§§   ",
            "§ §§©§§§°§§§©§  ",
            "§§©©³§§¨§§§§©¨  ",
            "§©©§´ ²¨§ ¨§§   ",
            " §§¨§ § §§©©§   ",
            "§§§§©¨§ §¨³©§¿  ",
            " © §§§¨§ ¨©§§§  ",
            "§©§§§ §©§§§§©   ",
            "§¨¨²§§§©§§§§    ",
            "§§§§©§©§§       ",
            "§§ §©¨  §       ",
            "                ",
            "                ",
            "                ",
            "                ",
            "                "
        ],
        [
            "  ¸·¸           ",
            "    ¬¸·¸    ¬   ",
            "  ¬¬¸·¶·¸   ¬   ",
            " ¬¬ ·¶²¶·       ",
            "    ¸·¶·¸ ¬¬    ",
            "    ¬¸·¸   ¬    ",
            " ¬        ¬     ",
            " ¬     ¬    ¬   ",
            "   ²   ¬        ",
            "    ¬ ¬         ",
            "    ¬           ",
            "                ",
            "                ",
            "                ",
            "                ",
            "                "
        ],
        [
            "                ",
            "                ",
            "      ¶         ",
            "     ¶²¶        ",
            "      ¶         ",
            "                ",
            "  ¸·¸           ",
            " ¸·¶·¸          ",
            " ·¶²¶·          ",
            " ¸·¶·¸          ",
            "  ¸·¸           ",
            "                ",
            "                ",
            "                ",
            "                ",
            "                "
        ],
        [
            "  ¸·¸           ",
            "     ¸·¸        ",
            "    ¸·¶·¸       ",
            "    ·¶²¶·       ",
            "    ¸·¶·¸       ",
            "     ¸·¸        ",
            "                ",
            "   ¶            ",
            "  ¶²¶           ",
            "   ¶            ",
            "                ",
            "                ",
            "                ",
            "                ",
            "                ",
            "                "
        ],
        [
            "                ",
            "                ",
            "      ¶         ",
            "     ¶²¶        ",
            "      ¶         ",
            "                ",
            "  ¸·¸           ",
            " ¸·¶·¸          ",
            " ·¶²¶·          ",
            " ¸·¶·¸          ",
            "  ¸·¸           ",
            "                ",
            "                ",
            "                ",
            "                ",
            "                "
        ]
    ],
    "refpalette": "building007_palette"
}