{
    "xsize": 16,
    "zsize": 16,
    "slices": [
        [
            "                ",
            "  ĪĪĪĪĪøøøøøøøø ",
            " īĝĝĝĝĝĝĝúúúúúø ",
            " īĝ¡¡¡¡¡¡¡¡ØØúø ",
            " īĝ¡¡¡¡¡¡¡¡¡¡úø ",
            " īĝ¡¡¡¡¡¡¡¡¡¡úø ",
            " īĝ¡¡¡¡¡¡¡¡¡¡úø ",
            " øĝ¡¡¡¡¡¡¡¡¡¡ĝø ",
            " øĝ¡¡¡¡¡¡¡¡¡¡ĝø ",
            " øú¡¡¡¡¡¡¡¡¡¡ĝĬ ",
            " øú¡¡¡¡¡¡¡¡¡¡ĝĬ ",
            " øú¡¡¡¡¡¡¡¡¡¡ĝĬ ",
            " øú¡¡¡¡¡¡¡¡¡¡ĝĬ ",
            " øúúúúúĝĝĝĝĝĝĝĬ ",
            " øøøøøøøøĭĭĭĭĭ  ",
            "                "
        ],
        [
            "                ",
            " ĘĘĘĘĘĘøø       ",
            " Ęĝĝĝĝĝĝĝċċċċċ  ",
            " ĘĝÖ       ØØċ  ",
            " Ęĝ ł    ł   ċ  ",
            " Ęĝ  Ń    ń  ċ  ",
            " ĘĝŅ ņ  Ň ņ  ċ  ",
            " øĝ   Ą    Ą ĝø ",
            " øĝ ł    ł   ĝø ",
            "  ċ  ń    ń  ĝĘ ",
            "  ċň ņ  Ņ ņ  ĝĘ ",
            "  ċ          ĝĘ ",
            "  ċŉ    ½¬  ŉĝĘ ",
            "  ċċċċċĝĝĝĝĝĝĝĘ ",
            "       øøĘĘĘĘĘĘ ",
            "                "
        ],
        [
            "                ",
            " Ěěěěěěøø       ",
            " Ĝķķķĝĝĝĝċċċċċ  ",
            " Ĝķ        ØØċ  ",
            " Ĝķ          ċ  ",
            " Ĝĝ          ċ  ",
            " Ĝĝ  Ŋ    ŋ  ċ  ",
            " øĝ          ĝø ",
            " øĝ          ĝø ",
            "  ċ          ĝĤ ",
            "  ċ  Ŋ    ŋ  ĝĤ ",
            "  ċ          ķĤ ",
            "  ċ          ķĤ ",
            "  ċċċċċĝĝĝĝķķķĤ ",
            "       øøĨĨĨĨĨŌ ",
            "                "
        ],
        [
            "                ",
            "     ĪĪøø       ",
            "  ķķķĝĝĝĝċċċċċ  ",
            "  ķ        ØØċ  ",
            "  ķ          ċ  ",
            " īĝ          ċ  ",
            " īĝō         ċ  ",
            " øĝŎ         ĝø ",
            " øĝ          ĝø ",
            "  ċ          ĝĬ ",
            "  ċ          ĝĬ ",
            "  ċ          ķ  ",
            "  ċ     ŏŐ   ķ  ",
            "  ċċċċċĝĝĝĝķķķ  ",
            "       øøĭĭ     ",
            "                "
        ],
        [
            "                ",
            " őĻĻĻĻĻøø       ",
            " ļķķķĝĝĝĝċċċċċ  ",
            " ļķ        ØØċ  ",
            " ļķ          ċ  ",
            " ļĝ          ċ  ",
            " ļĝ   ę      ċ  ",
            " øĝ    ę     ĝø ",
            " øĝ     ę    ĝø ",
            "  ċ      ę   ĝľ ",
            "  ċ          ĝľ ",
            "  ċ          ķľ ",
            "  ċ          ķľ ",
            "  ċċċċċĝĝĝĝķķķľ ",
            "       øøĿĿĿĿĿŒ ",
            "                "
        ],
        [
            "                ",
            " ŁŁŁŁŁŁøø       ",
            " Łĝĝĝĝĝĝĝúúúúú  ",
            " ŁĝĞğğğğğğĠØØú  ",
            " ŁĝġĢĢĢĢĢĢĢğĠú  ",
            " ŁĝġĢĢĢĢĢĢĢĢģú  ",
            " ŁĝġĢĢĢĢĢĢĢĢģú  ",
            " øĝġĢĢĢĢĢĢĢĢģĝø ",
            " øĝġĢĢĢĢĢĢĢĢģĝø ",
            "  úġĢĢĢĢĢĢĢĢģĝŁ ",
            "  úġĢĢĢĢĢĢĢĢģĝŁ ",
            "  úġĢĢĢĢĢĢĢĢģĝŁ ",
            "  úĥĦĦĦĦĦĦĦĦħĝŁ ",
            "  úúúúúĝĝĝĝĝĝĝŁ ",
            "       øøŁŁŁŁŁŁ ",
            "                "
        ]
    ],
    "refpalette": "building005_palette"
}