{
    "xsize": 16,
    "zsize": 16,
    "slices": [
        [
            "¢£££££££££££££££",
            "¢£££££££££££££££",
            "¡£££££££££££££££",
            "¢£££££££££££££££",
            "¢£££££££££££££££",
            "¢£££££££££££££££",
            "¡£££££££££££££££",
            "¢£££££££££££££££",
            "¢£££££££££££££££",
            "¢£££££££££££££££",
            "¡£££££££££££££££",
            "¢£££££££££££££££",
            "¢£££££££££££££££",
            "¢£££££££££££££££",
            "¡£££££££££££££££",
            "¡¡¢¢¢¡¢¢¢¡¢¢¢¡¢¢"
        ],
        [
            "¨ųŴÂÂŵ      ·ººº",
            "¨ »    µ®¶  ¸ººº",
            "¦     ´     ¸ººº",
            "¨ »    µ®¶  Ŷ¸¸Ŷ",
            "¨ųŴÂÂŵ          ",
            "¨ »       ¬     ",
            "¦           © § ",
            "¨ »    µ® ± ® ® ",
            "¨ųŴÂÂŵ      ° ° ",
            "¨ »     ©       ",
            "¦     ´ ®¶      ",
            "¨ »            ´",
            "¨ųŴÂÂŵ          ",
            "¨ »             ",
            "¢               ",
            "¢¢ŷŷŷŸŷŷŷŸŷŷŷŸŷŷ"
        ],
        [
            "¦  ŹŹ       ÃÁÂÂ",
            "¦ »     ź   ¸¬ ´",
            "¨           ¸ÁÂÂ",
            "¦ »     Ż   Ã¸¸ż",
            "¦  ŹŹ           ",
            "¦ »             ",
            "¨               ",
            "¦ »     Ž   ž   ",
            "¦  ŹŹ           ",
            "¦ »             ",
            "¨               ",
            "¦ »             ",
            "¦  ŹŹ           ",
            "¦ »             ",
            "¢               ",
            "¢¢ŸŸŸŷŸŸŸŷŸŸŸŷŸŸ"
        ],
        [
            "¨ ³         ·Á  ",
            "¨ Æ         ¸   ",
            "¦           ¸ÁÇ ",
            "¨ Æ         Ŷ¸¸Ŷ",
            "¨ ³             ",
            "¨ Æ             ",
            "¦               ",
            "¨ ²             ",
            "¨ ³             ",
            "¨ ²             ",
            "¦               ",
            "¨ Æ             ",
            "¨ ³             ",
            "¨ Æ             ",
            "¢               ",
            "¢¢ŷŷŷŸŷŷŷŸŷŷŷŸŷŷ"
        ],
        [
            "¦           ÊÁÂÂ",
            "¦           Ê   ",
            "¨           ÊÁÂÂ",
            "¦           ÃÊÊÊ",
            "¦               ",
            "¦               ",
            "¨               ",
            "¦               ",
            "¦               ",
            "¦               ",
            "¨               ",
            "¦               ",
            "¦               ",
            "¦               ",
            "¢               ",
            "¢¢ŸŸŸŷŸŸŸŷŸŸŸŷŸŸ"
        ],
        [
            "¨ËËËËËË     Ê Å ",
            "¨ËËËËËË     Ê   ",
            "¦ËËËËËË     ÊÌ Ç",
            "¨ËËËËËË     ŶÊÊÊ",
            "¨ËËËËËË         ",
            "¨ËËËËËË         ",
            "¦ËËËËËË         ",
            "¨ËËËËËË         ",
            "¨ËËËËËË         ",
            "¨ËËËËËËËËËËËËËËË",
            "¦ËËËËËËËËËËËËËËË",
            "¨ËËËËËËËËËËËËËËË",
            "¨ËËËËËËËËËËËËËËË",
            "¨ËËËËËËËËËËËËËËË",
            "¢ËËËËËËËËËËËËËËË",
            "¢¢ŷŷŷŸŷŷŷŸŷŷŷŸŷŷ"
        ]
    ],
    "refpalette": "building004_palette"
}