{
    "xsize": 16,
    "zsize": 16,
    "slices": [
        [
            "                ",
            "                ",
            "îîîîǫ           ",
            "ĴĴĴĴÐ           ",
            "«««ĴÐ           ",
            "«««ĴÐ           ",
            "«««ĴÐ           ",
            "ŀŀŀĴÐ           ",
            "   ĴÐ           ",
            "   ĴÐ           ",
            "   ĴÐ           ",
            "ŀŀŀĴÐ           ",
            "ĴĴĴĴÐ           ",
            "ÏÏÏÏƫ           ",
            "                ",
            "                "
        ],
        [
            "                ",
            "                ",
            "ĂĂĂĂǬ           ",
            "ĴĴĴĴĆ           ",
            "   ĴĆ           ",
            "  ǍĴĆ           ",
            "   ĴĆ           ",
            "ŀǱŀĴĆ           ",
            "   ĴĆ           ",
            "   ĴĆ           ",
            "   ĴĆ           ",
            "ŀŀŀĴĆ           ",
            "ĴĴĴĴĆ           ",
            "ċċċċǠ           ",
            "                ",
            "                "
        ],
        [
            "                ",
            "                ",
            "ĤĤĤĤĤ           ",
            "ĠĠĠĠĤ           ",
            "   ĠĤ           ",
            "   ĠĤ           ",
            "   ĠĤ           ",
            "ŀǲŀĠĤ           ",
            "   ĠĤ           ",
            "   ĠĤ           ",
            "   ĠĤ           ",
            "ŀŀŀĠĤ           ",
            "ĠĠĠĠĤ           ",
            "ĤĤĤĤĤ           ",
            "                ",
            "                "
        ],
        [
            "                ",
            "                ",
            "ĤĤĤĤĤ           ",
            "ĴĴĴĴĤ           ",
            "   ĴĤ           ",
            "   ĴĤ           ",
            "   ĴĤ           ",
            "ŀŀŀĴĤ           ",
            "   ĴĤ           ",
            "   ĴĤ           ",
            "   ĴĤ           ",
            "ŀŀŀĴĤ           ",
            "ĴĴĴĴĤ           ",
            "ĤĤĤĤĤ           ",
            "                ",
            "                "
        ],
        [
            "                ",
            "                ",
            "ĤĤĤĤĤ           ",
            "ĴĴĴĴĤ           ",
            "   ĴĤ           ",
            "   ĴĤ           ",
            "   ĴĤ           ",
            "ŀŀŀĴĤ           ",
            "   ĴĤ           ",
            "   ĴĤ           ",
            "   ĴĤ           ",
            "ŀŀŀĴĤ           ",
            "ĴĴĴĴĤ           ",
            "ĤĤĤĤĤ           ",
            "                ",
            "                "
        ],
        [
            "                ",
            "                ",
            "ììììì           ",
            "ĠĠĠĠì           ",
            "ššǴĠì           ",
            "ţţťĠì           ",
            "ţţťĠì           ",
            "ţţťĠì           ",
            "ţţťĠì           ",
            "ţţťĠì           ",
            "ţţťĠì           ",
            "ŧŧŤĠì           ",
            "ĠĠĠĠì           ",
            "ììììì           ",
            "                ",
            "                "
        ],
        [
            "                ",
            "                ",
            "îîîîǔ           ",
            "ĢĢĢĢÐ           ",
            "ĢĢĢĢÐ           ",
            "ĢĢĢĢÐ           ",
            "ĢĢĢĢÐ           ",
            "ĢĢĢĢÐ           ",
            "ĢĢĢĢÐ           ",
            "ĢĢĢĢÐ           ",
            "ĢĢĢĢÐ           ",
            "ĢĢĢĢÐ           ",
            "ĢĢĢĢÐ           ",
            "ÏÏÏÏĻ           ",
            "                ",
            "                "
        ]
    ],
    "refpalette": "building004_palette"
}