{
    "xsize": 16,
    "zsize": 16,
    "slices": [
        [
            "                ",
            "  ĪĪĪĪĪøøøøøøøø ",
            " īĝĝĝĝĝĝĝúúúúúø ",
            " īĝ¡¡¡¡¡¡¡¡ØØúø ",
            " īĝ¡¡¡¡¡¡¡¡¡¡úø ",
            " īĝ¡¡¡¡¡¡¡¡¡¡úø ",
            " īĝ¡¡¡¡¡¡¡¡¡¡úø ",
            " øĝ¡¡¡¡¡¡¡¡¡¡ĝø ",
            " øĝ¡¡¡¡¡¡¡¡¡¡ĝø ",
            " øú¡¡¡¡¡¡¡¡¡¡ĝĬ ",
            " øú¡¡¡¡¡¡¡¡¡¡ĝĬ ",
            " øú¡¡¡¡¡¡¡¡¡¡ĝĬ ",
            " øú¡¡¡¡¡¡¡¡¡¡ĝĬ ",
            " øúúúúúĝĝĝĝĝĝĝĬ ",
            " øøøøøøøøĭĭĭĭĭ  ",
            "                "
        ],
        [
            "                ",
            " ĘĘĘĘĘĘøø       ",
            " Ęĝĝĝĝĝĝĝċċċċċ  ",
            " ĘĝÖ      ×ØØċ  ",
            " Ęĝ   Ą ŷ××××ċ  ",
            " Ęĝ  ÙÙÙÙÙ×××ċ  ",
            " ĘĝŸĄÜÜÙÙÙÙÙ ċ  ",
            " øĝ ÜÜÜÙÙÙÙŷ ĝø ",
            " øĝ ÜÜÜÜÙ Ą  ĝø ",
            "  ċ ÜÜÜ Ą    ĝĘ ",
            "  ċ  Ź ź ¬Ż żĝĘ ",
            "  ċ  Ž       ĝĘ ",
            "  ċû½     ć ŉĝĘ ",
            "  ċċċċċĝĝĝĝĝĝĝĘ ",
            "       øøĘĘĘĘĘĘ ",
            "                "
        ],
        [
            "                ",
            " Řěěěěěøø       ",
            " Ĝķķķĝĝĝĝċċċċċ  ",
            " Ĝķ        ØØċ  ",
            " Ĝķ          ċ  ",
            " Ĝĝ          ċ  ",
            " Ĝĝ          ċ  ",
            " øĝ          ĝø ",
            " øĝ          ĝø ",
            "  ċ          ĝĤ ",
            "  ċ  ž       ĝĤ ",
            "  ċ          ķĤ ",
            "  ċ    ſ     ķĤ ",
            "  ċċċċċĝĝĝĝķķķĤ ",
            "       øøĨĨĨĨĨŌ ",
            "                "
        ],
        [
            "                ",
            "     ĪĪøø       ",
            "  ķķķĝĝĝĝċċċċċ  ",
            "  ķ   ƀƁ     ċ  ",
            "  ķ          ċ  ",
            " īĝ          ċ  ",
            " īĝƂ         ċ  ",
            " øĝƃ         ĝø ",
            " øĝ         Ƅĝø ",
            "  ċ         ƅĝĬ ",
            "  ċ          ĝĬ ",
            "  ċ          ķ  ",
            "  ċ     ƆƇ   ķ  ",
            "  ċċċċċĝĝƈĝķķķ  ",
            "       øøĭĭ     ",
            "                "
        ],
        [
            "                ",
            " őĻĻĻĻĻøø       ",
            " ļķķķĝĝĝĝċċċċċ  ",
            " ļķ          ċ  ",
            " ļķ          ċ  ",
            " ļĝ          ċ  ",
            " ļĝ    ęę    ċ  ",
            " øĝ     ę    ĝø ",
            " øĝ          ĝø ",
            "  ċ          ĝľ ",
            "  ċ          ĝľ ",
            "  ċ          ķľ ",
            "  ċ          ķľ ",
            "  ċċċċċĝĝĝĝķķķľ ",
            "       øøĿĿĿĿĿŒ ",
            "                "
        ],
        [
            "                ",
            " ŁŁŁŁŁŁøø       ",
            " Łøøøøøøøúúúúú  ",
            " ŁøĞğğğğğğğğĠú  ",
            " ŁøġĢĢĢĢĢĢĢĢģú  ",
            " ŁøġĢĢĢĢĢĢĢĢģú  ",
            " ŁøġĢĢĢĢĢĢĢĢģú  ",
            " øøġĢĢĢĢĢĢĢĢģøø ",
            " øøġĢĢĢĢĢĢĢĢģøø ",
            "  úġĢĢĢĢĢĢĢĢģĝŁ ",
            "  úġĢĢĢĢĢĢĢĢģĝŁ ",
            "  úġĢĢĢĢĢĢĢĢģĝŁ ",
            "  úĥĦĦĦĦĦĦĦĦħĝŁ ",
            "  úúúúúøøĝĝĝĝĝŁ ",
            "       øøŁŁŁŁŁŁ ",
            "                "
        ],
        [
            "                ",
            "        øøøøøøø ",
            "       øøøøøøøø ",
            "   øøøøøøøøøøøø ",
            "   øøøøøøøøøøøø ",
            "   øøøøøøøøøøøø ",
            "   øøøøøøøøøøøø ",
            " øøøøøøøøøøøøøø ",
            " øøøøøøøøøøøøøø ",
            " øøøøøøøøøøøø   ",
            " øøøøøøøøøøøø   ",
            " øøøøøøøøøøøø   ",
            " øøøøøøøøøøøø   ",
            " øøøøøøøø       ",
            " øøøøøøø        ",
            "                "
        ]
    ],
    "refpalette": "building005_palette"
}