{
    "xsize": 16,
    "zsize": 16,
    "slices": [
        [
            "                ",
            "                ",
            "  Ėîîîîîîîîîîîîî",
            "  ëĢĢĢĢĢĢĢĢĢĢĢĢĢ",
            "  ëĢ«««««««««Ĺ  ",
            "  ëĢ««««««««««««",
            "  ëĢ««««««««««««",
            "  ëĢ««««««««««««",
            "  ëĢ««««««««««««",
            "  ëĢ««««««««««««",
            "  ëĢ««««««««««««",
            "  ëĢ««««««««««««",
            "  ëĢĢĢĢĢĢĢĢĢĢĢĢĢ",
            "  ëĢĢĢĢĢĢĢĢĢĝÏÏÏ",
            "  ëĢĢĢĢĢĢĢĢĢÐ   ",
            "  ëĢĢĢĢĢĢĢĢĢÐ   "
        ],
        [
            "                ",
            "                ",
            "  āĂĂĂĂĂĂĂĂĂĂĂĂĂ",
            "  ăĴĴĴĴĴĴĴĴĴĴĴĴĴ",
            "  ăĴ            ",
            "  ăĴ            ",
            "  ăĴ ľ Ŀ ľÛĿ    ",
            "  ăĴ           ŀ",
            "  ăĴ    ´      ŀ",
            "  ăĴ¬          ŀ",
            "  ăĴ ľ Ŀ ľ Ŀ   Č",
            "  ăĴÛ    Ł     ŀ",
            "  ăĴĴĴĴĴĴĴĴĴĴĴĴĴ",
            "  łċċċċċċċċċċċċċ",
            "                ",
            "                "
        ],
        [
            "                ",
            "                ",
            "  ĤĤĤĤĤĤĤĤĤĤĤĤĤĤ",
            "  ĤĠĠĠĠĠĠĠĠĠĠĠĠĠ",
            "  ĤĠ            ",
            "  ĤĠ   Ń   ń    ",
            "  ĤĠ   Ņ   Ņ    ",
            "  ĤĠ           ŀ",
            "  ĤĠ           ŀ",
            "  ĤĠ   ņ       ŀ",
            "  ĤĠ   Ņ   Ņ   Ě",
            "  ĤĠ           ŀ",
            "  ĤĠĠĠĠĠĠĠĠĠĠĠĠĠ",
            "  ĤĤĤĤĤĤĤĤĤĤĤĤĤĤ",
            "                ",
            "                "
        ],
        [
            "                ",
            "                ",
            "  ĤĤĤĤĤĤĤĤĤĤĤĤĤĤ",
            "  ĤĴĴĴĴĴĴĴĴĴĴĴĴĴ",
            "  ĤĴ            ",
            "  ĤĴ            ",
            "  ĤĴ            ",
            "  ĤĴ           ŀ",
            "  ĤĴ           ŀ",
            "  ĤĴ           ŀ",
            "  ĤĴ           ŀ",
            "  ĤĴ           ŀ",
            "  ĤĴĴĴĴĴĴĴĴĴĴĴĴĴ",
            "  ĤĤĤĤĤĤĤĤĤĤĤĤĤĤ",
            "                ",
            "                "
        ],
        [
            "                ",
            "                ",
            "  ĤĤĤĤĤĤĤĤĤĤĤĤĤĤ",
            "  ĤĴĴĴĴĴĴĴĴĴĴĴĴĴ",
            "  ĤĴ            ",
            "  ĤĴ            ",
            "  ĤĴ            ",
            "  ĤĴ           ŀ",
            "  ĤĴ           ŀ",
            "  ĤĴ           ŀ",
            "  ĤĴ           ŀ",
            "  ĤĴ           ŀ",
            "  ĤĴĴĴĴĴĴĴĴĴĴĴĴĴ",
            "  ĤĤĤĤĤĤĤĤĤĤĤĤĤĤ",
            "         ŇňŉňŊŋŌ",
            "                "
        ],
        [
            "                ",
            "                ",
            "  ìììììììììììììì",
            "  ìĠĠĠĠĠĠĠĠĠĠĠĠĠ",
            "  ìĠōŎŎōōŎŎōōŎŎō",
            "  ìĠōŎŎōōŎŎōōŎŎō",
            "  ìĠŎōōŎŎōōŎŎōōŎ",
            "  ìĠŎōōŎŎōōŎŎōōŎ",
            "  ìĠōŎŎōōŎŎōōŎŎŀ",
            "  ìĠōŎŎōōŎŎōōŎŎŀ",
            "  ìĠŎōōŎŎōōŎŎōōŀ",
            "  ìĠŎōōŎŎōōŎŎōōŎ",
            "  ìĠĠĠĠĠĠĠĠĠĠĠĠĠ",
            "  ìììììììììììììì",
            "     ŏŋŐŊőŒ     ",
            "                "
        ]
    ],
    "refpalette": "building004_palette"
}