{
    "xsize": 16,
    "zsize": 16,
    "slices": [
        [
            "                ",
            " ¾¾¿¿¿¿¿¿¿¿¿¿¾¾ ",
            " ¾ÀÀÀÀÀÀÀÀÀÀÀÀ¾Á",
            " ÈÀÔÔÔÔÔÔÔÔ££££¾",
            " ÈÀÔÔÔÔÔÔÔÔ£   Ç",
            " ÈÀÔÔÔÔÔÔÔÔ£   Ç",
            " ÈÀÔÔÔÔÔÔÔÔ£   Ç",
            " ÈÀÔÔÔÔÔÔÔÔ££££¾",
            " ÈÀÔÔÔÔÔÔÔÔ££££¾",
            " ÈÀÔÔÔÔÔÔÔÔ££££Ç",
            " ÈÀÔÔÔÔÔÔÔÔ££££Ç",
            " ÈÀÔÔÔÔÔÔÔÔ££¥£Ç",
            " ÈÀÔÔÔÔÔÔÔÔ££££¾",
            " ¾ÀÀÀÀÀÀÀÀÀÀÀÀ¾Á",
            " ¾¾ÏÏÏÏÏÏÏÏÏÏ¾¾ ",
            "                "
        ],
        [
            "                ",
            " ¾¾          ¾¾ ",
            " ¾»»»ÇÇ»»ÇÇ»»»¾Á",
            "  »ØèÙé   Â»»®»¾",
            "  »ê    ßß £   Ç",
            "  Çëàáì ßß ©   Ç",
            "  Çí    ßß £   Ç",
            "  »    î   »»»»¾",
            "  »  ï     »»»»¾",
            "  Ç   ³ Ý  £   Ç",
            "  Ç    ßßß °   Ç",
            "  » ð  ßßß £ ¥ Ç",
            "  »  ñã ä ±»»»»¾",
            " ¾»»»ÇÇ»»ÇÇ»»»¾Á",
            " ¾¾          ¾¾ ",
            "                "
        ],
        [
            "                ",
            " ¾¾          ¾¾ ",
            " ¾»»»ÇÇ»»ÇÇ»»»¾Á",
            "  »        »»·»¾",
            "  »        £   Ç",
            "  Ç        ¶   Ç",
            "  Ç        £   Ç",
            "  »        »»»»¾",
            "  »        »»»»¾",
            "  Ç     ç  £   Ç",
            "  Ç        ¸   Ç",
            "  »        £ ¥ Ç",
            "  »  ò     »»»»¾",
            " ¾»»»ÇÇ»»ÇÇ»»»¾Á",
            " ¾¾          ¾¾ ",
            "                "
        ],
        [
            "                ",
            " ¾¾          ¾¾ ",
            " ¾Àººººººººººº¾Á",
            "  º        »»»»¾",
            "  º        £   Ç",
            "  º        £   Ç",
            "  º        £   Ç",
            "  º        »»»»¾",
            "  º        »»»»¾",
            "  º        £   Ç",
            "  º        £   Ç",
            "  º        £ ¥ Ç",
            "  º        »»»»¾",
            " ¾Àººººººººººº¾Á",
            " ¾¾          ¾¾ ",
            "                "
        ],
        [
            "                ",
            " ¾¾          ¾¾ ",
            " ¾ÀÀÀÀÀÀÀÀÀÀÀÀ¾Á",
            "  À        ¤¤¤¤¾",
            "  À        ¤   Ç",
            "  À        ¤   Ç",
            "  À        ¤   Ç",
            "  À        ¤¤¤¤¾",
            "  À        ¤¤¤¤¾",
            "  À        ¤   Ç",
            "  À        ¤   Ç",
            "  À        ¤ ¥ Ç",
            "  À        ¤¤¤¤¾",
            " ¾ÀÀÀÀÀÀÀÀÀÀÀÀ¾Á",
            " ¾¾          ¾¾ ",
            "                "
        ],
        [
            "                ",
            " ¾¾¾¾¾¾¾¾¾¾¾¾¾¾ ",
            " ¾ÀÀÀÀÀÀÀÀÀÀÀÀ¾Á",
            " ¾ÀÔÔÔÔÔÔÔÔ»»»»¾",
            " ¾ÀÔÔÔÔÔÔÔÔ»   Ç",
            " ¾ÀÔÔÔÔÔÔÔÔ»   Ç",
            " ¾ÀÔÔÔÔÔÔÔÔ»   Ç",
            " ¾ÀÔÔÔÔÔÔÔÔ»»»»¾",
            " ¾ÀÔÔÔÔÔÔÔÔ»»»»¾",
            " ¾ÀÔÔÔÔÔÔÔÔ»   Ç",
            " ¾ÀÔÔÔÔÔÔÔÔ»   Ç",
            " ¾ÀÔÔÔÔÔÔÔÔ» ¥ Ç",
            " ¾ÀÔÔÔÔÔÔÔÔ»»»»¾",
            " ¾ÀÀÀÀÀÀÀÀÀÀÀÀ¾Á",
            " ¾¾¾¾¾¾¾¾¾¾¾¾¾¾ ",
            "                "
        ]
    ],
    "refpalette": "building002_palette"
}