{
    "xsize": 16,
    "zsize": 16,
    "slices": [
        [
            "±±±±±¤¤¤¤£¤¤¤¤¤¤",
            "±±±±±±¤¤¤¤¤¤¤¤¤¤",
            "±±±±±±±±¤¤¤¤¤¤¤¤",
            "±±±±±±±±±¤¤¤¤¤¤¤",
            "±±±±±±±±±±±¤¤¤¤¤",
            "£££££±±±±±±±¤¤¤¤",
            "£££££££±±±±±±¤¤¤",
            "£££££££££±±±±±¤¤",
            "££££££££££±±±±±¤",
            "£££££££££££±±±±±",
            "££££££££££££±±±±",
            "£££££££££££££±±±",
            "£££££££££££££±±±",
            "£££££££££££££±±±",
            "££££££££££££££±±",
            "££££££££££££££±±"
        ],
        [
            "     §©§§²§§ §³¨",
            "      §½§ §©§§§§",
            "         §§§§  §",
            "           §¨ °§",
            "            § §§",
            "ÁÁÁÁß         §§",
            "ÅÃÃÃàÁß       ¨§",
            "ÄÄÄÄÄÄàÁá     §§",
            "ÄÄÅÃÄÅÃÃâá     ¨",
            "ÃÃÃÃÃÃÄÄÅâá     ",
            "¥¥¥¥ÃÃÄÄÄÄâá    ",
            "¥¥¥¥¥ÃÃÃÃÄÃâß   ",
            "¥¥¥¥¥¥ÃÃÃÄÃÃã   ",
            "ÃÃÃ¥¥¥¥ÃÃÄÅÄã   ",
            "ÃÃÃÃ¥¥¥¥ÃÃÄÄâá  ",
            "ÃÃÃÃÃ¥¥¥ÃÄÃÅÃã  "
        ],
        [
            "      ¬ ¶²¶   º¹",
            "         ¶ ¬ º¹¸",
            "             ¹¸·",
            "             ¸·¶",
            "             ¹¸·",
            "             º¹¸",
            "              º¹",
            "  Ù             ",
            "                ",
            "ÄÄÃÄÉ           ",
            "ËËËÊÅÃ          ",
            "ÌÌÌËËÃÅ         ",
            "ËËËÌÌËÄÄ        ",
            "¥¥¥Ë°ÌËÃÉ       ",
            "¥¥¥¥ËÌËÊÅ       ",
            "¥Ã¥¥¥ËÌËÄ       "
        ],
        [
            "       ·¶²¶·    ",
            "       ¸·¶·¸   ¸",
            "        ¸·¸   ¸·",
            "              ·¶",
            "              ¸·",
            "               ¸",
            "                ",
            "                ",
            "                ",
            "                ",
            "                ",
            "ÌÌÌ             ",
            "ÃÃÃÌÌ           ",
            "ÌÌÌÃÃÌ          ",
            "ËËËÌÃÌ          ",
            "ÊÃÊËÌÃÌ         "
        ],
        [
            "        ¶²¶     ",
            "         ¶      ",
            "                ",
            "               ¶",
            "                ",
            "                ",
            "                ",
            "                ",
            "                ",
            "                ",
            "                ",
            "ËËË             ",
            "ÎÎÎËË           ",
            "ÌÌÌÎÎË          ",
            "   ÌÎË          ",
            " Ã  ÌÎË         "
        ],
        [
            "       ·¶²¶·    ",
            "       ¸·¶·¸   ¸",
            "        ¸·¸   ¸·",
            "              ·¶",
            "              ¸·",
            "               ¸",
            "                ",
            "                ",
            "                ",
            "                ",
            "                ",
            "                ",
            "                ",
            "ÌÌÌ             ",
            "¥¥¥Ì            ",
            "¥ ¥¥Ì           "
        ]
    ],
    "refpalette": "building007_palette"
}