{
    "xsize": 16,
    "zsize": 16,
    "slices": [
        [
            "¡¡¡¢¢¢¡¢¢¢¢¢¢¢¡¢",
            "¡£££££££££££££££",
            "¡£££££££££££££££",
            "¢£££££££££££££££",
            "¢£££££££££££££££",
            "¢£££££££££££££££",
            "¡£££££££££££££££",
            "¢£££££££££££££££",
            "¢£££££££££££££££",
            "¢£££££££££££££££",
            "¢£££££££££££££££",
            "¢£££££££££££££££",
            "¢£££££££££££££££",
            "¢£££££££££££££££",
            "¡£££££££££££££££",
            "¢£££££££££££££££"
        ],
        [
            "¡¢¤¥¥¥¤¥¥¥¤¥¥¥¤¥",
            "¢               ",
            "¦             § ",
            "¨         © ©  ©",
            "¨    ª«¬  ® ®  ®",
            "¨ ¯  ª«     °   ",
            "¦             ± ",
            "¨      ©  © ©  ©",
            "¨ ²    ®  ® ®  ®",
            "¨ ³  ´   §° °   ",
            "¦ ³        ¬    ",
            "¨ ²             ",
            "¨      µ®¶  ·¸¸¹",
            "¨           ¸ººº",
            "¦      µ®¶  ¸ººº",
            "¨ »       § ·ººº"
        ],
        [
            "¢¢¥¤¤¤¥¤¤¤¥¤¤¤¥¤",
            "¢               ",
            "¨               ",
            "¦               ",
            "¦    ª«        ¼",
            "¦ ½  ª«         ",
            "¨               ",
            "¦               ",
            "¦           ¾   ",
            "¦               ",
            "¨               ",
            "¦               ",
            "¦       ¿   À¸¸À",
            "¦           ¸ÁÂÂ",
            "¨           ¸  ´",
            "¦ »         ÃÁÂÂ"
        ],
        [
            "¢¢¤¥¥¥¤¥¥¥¤¥¥¥¤¥",
            "¢               ",
            "¦               ",
            "¨               ",
            "¨    ª«         ",
            "¨ Ä  ª«         ",
            "¦               ",
            "¨               ",
            "¨               ",
            "¨               ",
            "¦               ",
            "¨               ",
            "¨           ·¸¸¹",
            "¨           ¸ÁÅ ",
            "¦           ¸   ",
            "¨ Æ         ·Á Ç"
        ],
        [
            "¢¢¥¤¤¤¥¤¤¤¥¤¤¤¥¤",
            "¢               ",
            "¨               ",
            "¦               ",
            "¦    ª«         ",
            "¦ÈÉ  ª«         ",
            "¨               ",
            "¦               ",
            "¦               ",
            "¦               ",
            "¨               ",
            "¦               ",
            "¦           ÀÊÊÊ",
            "¦           ÊÁÂÂ",
            "¨           Ê   ",
            "¦           ÊÁÂÂ"
        ],
        [
            "¢¢¤¥¥¥¤¥¥¥¤¥¥¥¤¥",
            "¢ËËËËËËËËËËËËËËË",
            "¦ËËËËËËËËËËËËËËË",
            "¨ËËËËËËËËËËËËËËË",
            "¨ËËËËª«ËËËËËËËËË",
            "¨ËËËËª«ËËËËËËËËË",
            "¦ËËËËËËËËËËËËËËË",
            "¨ËËËËËË         ",
            "¨ËËËËËË         ",
            "¨ËËËËËË         ",
            "¦ËËËËËË         ",
            "¨ËËËËËË         ",
            "¨ËËËËËË     ·ÊÊÊ",
            "¨ËËËËËË     ÊÌÅ ",
            "¦ËËËËËË     Ê   ",
            "¨ËËËËËË     Ê   "
        ]
    ],
    "refpalette": "building004_palette"
}