{
    "xsize": 16,
    "zsize": 16,
    "slices": [
        [
            "   Ô¡ÕÐÖÖÐÕ¡Ô   ",
            " ×Ø¡¡¡¡¡¡¡¡¡¡Ø× ",
            " ¡ÐÐÐÐÐÐÐÐÐÐÐÐ¡ ",
            " ¦ÐƲƲƲƲƲƲƲƲƲƲÐ¨ ",
            " ØÐƲƲƲƲƲƲƲƲƲƲÐØ ",
            " ìÐƲƲƲƲƲƲƲƲƲƲÐì ",
            " ìÐƲƲƲƲƲƲƲƲƲƲÐì ",
            " ìÐƲƲƲƲƲƲƲƲƲƲÐì ",
            " ìÐƲƲƲƲƲƲƲƲƲƲÐì ",
            " ìÐƲƲƲƲƲƲƲƲƲƲÐì ",
            " ìÐ¤¤¤¤¤¤¤¤¤¤Ðì ",
            " Ø¤¥¥¥¤ ¤   ¤¤Ø ",
            " ¦¤¥¥¥¤ ¤   ¤ ¨ ",
            " ¡¤¥À¥¤ ¤   ¤ ¡ ",
            " ×Ø¤¤¤¤¤¤¤¤¤¤Ø× ",
            "   ´¡ÕÐææÐÕ¡´   "
        ],
        [
            "   Ô¡ÕÐÖÖÐÕ¡Ô   ",
            " ×Ø¡¡¡¡¡¡¡¡¡¡Ø× ",
            " ¡  ±         ¡ ",
            " ¦   Û  º     ¨ ",
            " Ø   Ƴ     ƴ  Ø ",
            " ì         Ƶ  ì ",
            " ì   ƶ Ʒ Ƹ ƹ  ì ",
            " ì   ã     ã  ì ",
            " ì            ì ",
            " ì » »»»»» »» ì ",
            " ì¼¤½¤¤¤¤¤½¤¤¾ì ",
            " Ø¤   ¤ ¤   ¤¤Ø ",
            " ¦¤   ¤ ¤   ¿ ¨ ",
            " ¡¤ À ¤ ¤   ¤ ¡ ",
            " ×Ø¤¤¤¤¤¤¤¤¤¤Ø× ",
            "   ´¡ÕÐææÐÕ¡´   "
        ],
        [
            "   Ô¡ÕÐÖÖÐÕ¡Ô   ",
            " ×Ø¡¡¡¡¡¡¡¡¡¡Ø× ",
            " ¡ƺ    èè    ƺ¡ ",
            " ¦            ¨ ",
            " Ø   ā        Ø ",
            " ì            ì ",
            " ì            ì ",
            " ì            ì ",
            " ì            ì ",
            " ì » »»»»» »» ì ",
            " ì¼¤Ê¤¤¤¤¤Ê¤¤¾ì ",
            " Ø¤   ¤ ¤   ¤¤Ø ",
            " ¦¤   ¤ ¤   Ë ¨ ",
            " ¡¤ À ¤ ¤   ¤ ¡ ",
            " ×Ø¤¤¤¤¤¤¤¤¤¤Ø× ",
            "   ´¡ÕÐææÐÕ¡´   "
        ],
        [
            "   Ô¡ÕÐÖÖÐÕ¡Ô   ",
            " ×Ø¡¡¡¡¡¡¡¡¡¡Ø× ",
            " ¡ ƻ Ƽ èè Ƽ   ¡ ",
            " ¦            ¨ ",
            " Ø            Ø ",
            " ì            ì ",
            " ì            ì ",
            " ì            ì ",
            " ì            ì ",
            " ì »»»»»»»»»» ì ",
            " ì¼¤¤¤¤¤¤¤¤¤¤¾ì ",
            " Ø¤   ¤ ¤   ¤¤Ø ",
            " ¦¤   ¤ ¤   ¤ ¨ ",
            " ¡¤ À ¤ ¤   ¤ ¡ ",
            " ×Ø¤¤¤¤¤¤¤¤¤¤Ø× ",
            "   ´¡ÕÐææÐÕ¡´   "
        ],
        [
            "   Ô¡ÕÐÖÖÐÕ¡Ô   ",
            " ×Ø¡¡¡¡¡¡¡¡¡¡Ø× ",
            " ¡            ¡ ",
            " ¦            ¨ ",
            " Ø            Ø ",
            " Ø            Ø ",
            " ì            ì ",
            " ì            ì ",
            " ì     ƽ      ì ",
            " ì »»»»»»»»»» ì ",
            " ì¼¤¤¤¤¤¤¤¤¤¤¾ì ",
            " Ø¤   ¤ ¤   ¤¤Ø ",
            " ¦¤   ¤ ¤   ¤ ¨ ",
            " ¡¤   ¤ ¤   ¤ ¡ ",
            " ×Ø¤¤¤¤¤¤¤¤¤¤Ø× ",
            "   ´¡ÕÐææÐÕ¡´   "
        ],
        [
            "   Ô¡ÕÐÖÖÐÕ¡Ô   ",
            " ×Ø¡¡¡¡¡¡¡¡¡¡Ø× ",
            " ¡¡¡¡¡¡¡¡¡¡¡¡¡¡ ",
            " ¦¡¡¡¡¡¡¡¡¡¡¡¡¨ ",
            " ¦ƾƾƾƾƾƾƾƾƾƾƾƾ¨ ",
            " Ø            Ø ",
            " Ø            Ø ",
            " ì            ì ",
            " ì     ƿ      ì ",
            " ì »»»»»»»»»» ì ",
            " ì¼¤¤¤¤¤¤¤¤¤¤¾ì ",
            " Ø¤   ¤ ¤   ¤¤Ø ",
            " ¦¤   ¤ ¤   ¤ ¨ ",
            " ¡¤   ¤ ¤   ¤ ¡ ",
            " ×Ø¤¤¤¤¤¤¤¤¤¤Ø× ",
            "   ´¡ÕÐææÐÕ¡´   "
        ],
        [
            "   Ô¡ÕÐÖÖÐÕ¡Ô   ",
            " ×Ø          Ø× ",
            " ¡¡¡¡¡¡¡¡¡¡¡¡¡¡ ",
            " ¡¡¡¡¡¡¡¡¡¡¡¡¡¡ ",
            " ¦¡¡¡¡¡¡¡¡¡¡¡¡¨ ",
            " ¦ƾƾƾƾƾƾƾƾƾƾƾƾ¨ ",
            " Ø            Ø ",
            " Ø            Ø ",
            " ì     ƿ      ì ",
            " ì »»»»»»»»»» ì ",
            " ì¼¤¤¤¤¤¤¤¤¤¤¾ì ",
            " Ø¤   ¤ ¤   ¤¤Ø ",
            " ¦¤   ¤ ¤   ¤ ¨ ",
            " ¡¤   ¤ ¤   ¤ ¡ ",
            " ×Ø¤¤¤¤¤¤¤¤¤¤Ø× ",
            "   ´¡ÕÐææÐÕ¡´   "
        ],
        [
            "   Ô¡ÕÐÖÖÐÕ¡Ô   ",
            " ×Ø          Ø× ",
            " ¡¡¡¡¡¡¡¡¡¡¡¡¡¡ ",
            " ¡¡¡¡¡¡¡¡¡¡¡¡¡¡ ",
            " ¡¡¡¡¡¡¡¡¡¡¡¡¡¡ ",
            " ¦¡¡¡¡¡¡¡¡¡¡¡¡¨ ",
            " ¦ƾƾƾƾƾƾƾƾƾƾƾƾ¨ ",
            " Ø            Ø ",
            " Ø     ƿ      Ø ",
            " ì »»»»»»»»»» ì ",
            " ì¼¤¤¤¤¤¤¤¤¤¤¾ì ",
            " Ø¤   ¤ ¤   ¤¤Ø ",
            " ¦¤   ¤ ¤   ¤ ¨ ",
            " ¡¤   ¤ ¤   ¤ ¡ ",
            " ×Ø¤¤¤¤¤¤¤¤¤¤Ø× ",
            "   ´¡ÕÐææÐÕ¡´   "
        ],
        [
            "   Ô¡ÕÐÖÖÐÕ¡Ô   ",
            " ×Ø      ¡   Ø× ",
            " ¡¡¡¡¡¡¡¡¡¡¡¡¡¡ ",
            " ¡¡¡¡¡¡¡¡¡¡¡¡¡¡ ",
            " ¡¡¡¡¡¡¡¡¡¡¡¡¡¡ ",
            " ¡¡¡¡¡¡¡¡¡¡¡¡¡¡ ",
            " ¦¡¡¡¡¡¡¡¡¡¡¡¡¨ ",
            " ¦ƾƾƾƾƾƾƾƾƾƾƾƾ¨ ",
            " Ø     ƿ      Ø ",
            " Ø »»»»»»»»»» Ø ",
            " ì¼¤¤¤¤¤¤¤¤¤¤¾ì ",
            " Ø¤   ¤ ¤   ¤¤Ø ",
            " ¦¤   ¤ ¤   ¤ ¨ ",
            " ¡¤   ¤ ¤   ¤ ¡ ",
            " ×Ø¤¤¤¤¤¤¤¤¤¤Ø× ",
            "   ´¡ÕÐææÐÕ¡´   "
        ],
        [
            "    ǀÕÐǁǁÐÕǀ    ",
            "  Ø¯ǀÕÐǁǁÐÕǀ¯Ø  ",
            " ǀØ¯ǀÕÐǁǁÐÕǀ¯Øǀ ",
            " ǂØǃǂÕÐǄǄÐÕǂǃØǂ ",
            " ¡¡¡¡¡¡¡¡¡¡¡ ¡¡ ",
            " ¡¡¡¡¡¡¡¡¡¡¡¡¡¡ ",
            " ¡¡¡¡¡¡¡¡¡¡¡¡¡¡ ",
            " ¦¡¡¡¡¡¡¡¡¡¡¡¡¨ ",
            " ¦¡¡¡¡¡¡¡¡¡¡¡¡¨ ",
            " ØƾƾƾƾƾƾƾƾƾƾƾƾØ ",
            " Ø ¤¤¤¤¤¤¤¤¤¤ Ø ",
            " Ø¤¤¤¤¤ ¤   ¤¤Ø ",
            " ¦¤¤¤¤¤ ¤   ¤ ¨ ",
            " ¡¤¤¤¤¤ ¤   ¤ ¡ ",
            " ×Ø¤¤¤¤¤¤¤¤¤¤Ø× ",
            "   ´¡ÕÐææÐÕ¡´   "
        ],
        [
            "                ",
            "                ",
            "                ",
            "                ",
            " ǀØ¯ǀÕÐǁǁÐÕǀ¯Øǀ ",
            " ǂØǃǂÕÐǄǄÐÕǂǃØǂ ",
            " ¡¡¡¡¡¡¡¡¡¡¡¡¡¡ ",
            " ¡¡¡¡¡¡¡¡¡¡¡¡¡¡ ",
            " ¦¡¡¡¡¡¡¡¡¡¡¡¡¨ ",
            " ¦¡¡¡¡¡¡¡¡¡¡¡¡¨ ",
            " ¦¡¡¡¡¡¡¡¡¡¡¡¡¨ ",
            " ¦¤     ¤   ¤ ¨ ",
            " ¦¤     ¤   ¤ ¨ ",
            " ¡¤     ¤   ¤ ¡ ",
            " ×Ø¤¤¤¤¤¤¤¤¤¤Ø× ",
            "   ´¡ÕÐææÐÕ¡´   "
        ],
        [
            "                ",
            "                ",
            "                ",
            "                ",
            "                ",
            "                ",
            " ǀØ¯ǀÕÐǁǁÐÕǀ¯Øǀ ",
            " ǂØǃǂÕÐǄǄÐÕǂǃØǂ ",
            " ¡¡¡¡¡¡¡¡¡¡¡¡¡¡ ",
            " ¡¡¡¡¡¡¡¡¡¡¡¡¡¡ ",
            " ¦¡¡¡¡¡¡¡¡¡¡¡¡¨ ",
            " ¦¡¡¡¡¡¡¡¡¡¡¡¡¨ ",
            " ¦¡¡¡¡¡¡¡¡¡¡¡¡¨ ",
            " ¡¤     ¤   ¤ ¡ ",
            " ×Ø¤¤¤¤¤¤¤¤¤¤Ø× ",
            "   ´¡ÕÐææÐÕ¡´   "
        ],
        [
            "                ",
            "                ",
            "                ",
            "                ",
            "                ",
            "                ",
            "                ",
            "                ",
            " ǀØ¯ǀÕÐǁǁÐÕǀ¯Øǀ ",
            " ǂØǃǂÕÐǄǄÐÕǂǃØǂ ",
            " ¡¡¡¡¡¡¡¡¡¤¡¡¡¡ ",
            " ¡¡¡¡¡¡¡¡¡¡¡¡¡¡ ",
            " ¦¡¡¡¡¡¡¡¡¡¡¡¡¨ ",
            " ¡¡¡¡¡¡¡¡¡¡¡¡¡¡ ",
            " ×Ø¡¡¡¡¡¡¡¡¡¡Ø× ",
            "   ´¡ÕÐææÐÕ¡´   "
        ],
        [
            "                ",
            "                ",
            "                ",
            "                ",
            "                ",
            "                ",
            "                ",
            "                ",
            "                ",
            "                ",
            " ǀØ¯ǀÕÐǁǁÐÕǀ¯Øǀ ",
            " ǂØǃǂÕÐǄǄÐÕǂǃØǂ ",
            " ¡¡¡¡¡¡¡¡¡¡¡¡¡¡ ",
            " ¡¡¡¡¡¡¡¡¡¡¡¡¡¡ ",
            " ×Ø      ¡   Ø× ",
            "   ´¡ÕÐææÐÕ¡´   "
        ],
        [
            "                ",
            "                ",
            "                ",
            "                ",
            "                ",
            "                ",
            "                ",
            "                ",
            "                ",
            "                ",
            "                ",
            "                ",
            " ǀØ¯ǀÕÐǁǁÐÕǀ¯Øǀ ",
            " ǂØǃǂÕÐǄǄÐÕǂǅØǂ ",
            " ×Øǃ¡¡¡¡¡¡¡¡ǃØ× ",
            "   ´¡ÕÐææÐÕ¡´   "
        ],
        [
            "                ",
            "                ",
            "                ",
            "                ",
            "                ",
            "                ",
            "                ",
            "                ",
            "                ",
            "                ",
            "                ",
            "                ",
            "                ",
            " ¡            ¡ ",
            " ×  ǀÕÐǁǁÐÕǀ  × ",
            "    ǀÕÐǁǁÐÕǀ    "
        ]
    ],
    "refpalette": "building001_palette"
}