{
    "xsize": 16,
    "zsize": 16,
    "slices": [
        [
            " ëĢĢĢĢĢģĢĢĢĢĢÐ  ",
            " ëƯƯƯƯƯƯƯƯƯƯƯÐ  ",
            " ëƯƯƯƯƯƯƯƯƯƯƯÐ  ",
            " ëƯƯưưưưưưưƯƯÐ  ",
            " ëƯưƯƯƯƯƯƯƯưƯÐ  ",
            " ëƯưƯưƯƯƯưƯưƯÐ  ",
            " ëƯưƯưƯƯƯưƯưƯÐ  ",
            " ëƯưƯưưưưưƯưƯÐ  ",
            " ëƯưƯưƯƯƯưƯưƯÐ  ",
            " ëƯưƯưƯƯƯưƯưƯÐ  ",
            " ëƯưƯƯƯƯƯƯƯưƯÐ  ",
            " ëƯƯưưưưưưưƯƯÐ  ",
            " ëƯƯƯƯƯƯƯƯƯƯƯÐ  ",
            " œÏÏÏÏÏÏÏÏÏÏÏƫ  ",
            "                ",
            "                "
        ],
        [
            "  ĤĤĤÍĆ ăÍĤĤĤ   ",
            "                ",
            "                ",
            "                ",
            "                ",
            "                ",
            "                ",
            "       Ʊ        ",
            "                ",
            "                ",
            "                ",
            "           ¬    ",
            "                ",
            "                ",
            "                ",
            "                "
        ],
        [
            "     Í   Í      ",
            "                ",
            "                ",
            "                ",
            "                ",
            "                ",
            "                ",
            "                ",
            "                ",
            "                ",
            "                ",
            "                ",
            "                ",
            "                ",
            "                ",
            "                "
        ],
        [
            "     ÍÐìëÍ      ",
            "                ",
            "                ",
            "                ",
            "                ",
            "                ",
            "                ",
            "                ",
            "                ",
            "                ",
            "                ",
            "                ",
            "                ",
            "                ",
            "                ",
            "                "
        ],
        [
            "     ÍĴĴĴÍ      ",
            "                ",
            "                ",
            "                ",
            "                ",
            "                ",
            "                ",
            "                ",
            "                ",
            "                ",
            "                ",
            "                ",
            "                ",
            "                ",
            "                ",
            "                "
        ],
        [
            "  ìììÍìììÍììì   ",
            "                ",
            "                ",
            "                ",
            "                ",
            "                ",
            "                ",
            "                ",
            "                ",
            "                ",
            "                ",
            "                ",
            "                ",
            "                ",
            "                ",
            "                "
        ]
    ],
    "refpalette": "building004_palette"
}