{
    "xsize": 16,
    "zsize": 16,
    "slices": [
        [
            "¡¡¡¡¡¡¡¡¡¡¡¡¡¡¡¡",
            "¡¡¡¡¡¡¡¡¡¡¡¡¡¡¡¡",
            "¡¡¡¡¡¡¡¡¡¡¡¡¡¡¡¡",
            "¡¡¡¡¡¡¡¡¡¡¡¡¡¡¡¡",
            "¡¡¡¡¡¡¡¡¡¡¡¡¡¡¡¡",
            "ÍÍÍÍÍÍÍÍÍÍÍ¡¡¡¡¡",
            "ÍÍÍÍÍÍÍÍÍÍÍ¡¡¡¡¡",
            "ÏÎÏÏÏÏÏÏêÍÍ¡¡¡¡¡",
            "ìÐ      ëÍÍ¡¡¡¡¡",
            "ìÐ      ëÍÍ¡¡¡¡¡",
            "ìðîîîǔ  ëÍÍ¡¡¡¡¡",
            "ìììììÐ  ëÍÍ¡¡¡¡¡",
            "À¸¸ǃìÐ  ëÍÍ¡¡¡¡¡",
            "ººº¸ìÐ  ëÍÍ¡¡¡¡¡",
            "ººº¸ìƐîîïÍÍ¡¡¡¡¡",
            "ººªǃììììëÍÍ¡¡¡¡¡"
        ],
        [
            "¢¢¢¢¢¢¢¢¢¢¢¢¢¢¢¢",
            "ÑÒÅÓ ¢ÑÒÅÓ ¢   ¢",
            " §   ¢ §   ¢   ¢",
            "     ¢     ¢   ¢",
            "¢¢¢Ô¢¢¢¢¢Ô¢¢   ¢",
            "           ¢¢¢¢¢",
            "         Õ ¢  ǋ¢",
            " Ö××××××ò  ¢ §ǌ¢",
            " Ø      ó  ¢  Ǎ¢",
            " Ø      ó  ǎ  Ǐ¢",
            " øôôôò  ó  ¢   ¢",
            "     Ø  ó  ¢¢¢¢¢",
            "ƅ¸ÀǕ Ø  ó  ¢  ǋ¢",
            "   ǃ Ø  ó  ¢ §ǌ¢",
            "   ¸ øôôõ  ¢  Ǎ¢",
            "  ªǃ   ¬   ǎ  Ǐ¢"
        ],
        [
            "¢¢¢¢¢¢¢¢¢¢¢¢¢¢¢¢",
            "     à     ¢   ¢",
            "     à     ¢   ¢",
            "     à     ¢   ¢",
            "ááâã¢¢ááâã¢¢   ¢",
            "           ¢¢¢¢¢",
            "           à   ¢",
            "           à   ¢",
            "           Ǒ   ¢",
            "           ǒ   ¢",
            "           ¢   ¢",
            "           ¢ááá¢",
            "ƍ¸¹ǖ       à   ¢",
            "   Ƹ       à   ¢",
            "   ¸       Ǒ   ¢",
            "  ªƸ       ǒ   ¢"
        ],
        [
            "¢¢¢¢¢¢¢¢¢¢¢¢¢¢¢¢",
            "     à     ¢   ¢",
            "     à     ¢   ¢",
            "     à     ¢   ¢",
            "áá¢¢¢¢áá¢¢¢¢   ¢",
            "           ¢¢¢¢¢",
            "           à   ¢",
            "           à   ¢",
            "           ¢   ¢",
            "           ¢   ¢",
            "           ¢   ¢",
            "           ¢ááá¢",
            "¹¸ÀǕ       à   ¢",
            "   ǃ       à   ¢",
            "   ¸       ¢   ¢",
            "   ǃ       ¢   ¢"
        ],
        [
            "¢¢¢¢¢Í¢¢¢¢¢¢¢¢¢¢",
            "ËËËËË¢ËËËËË¢   ¢",
            "ËËËËË¢ËËËËË¢   ¢",
            "ËËËËË¢ËËËËË¢   ¢",
            "¢¢¢¢¢¢¢¢¢¢¢¢   ¢",
            "ËËËËËËËËËËË¢¢¢¢Í",
            "ËËËËËËËËËËË¢ËËË¢",
            "ËËËËËËËËËËË¢ËËË¢",
            "ËËËËËËËËËËË¢ËËË¢",
            "ËËËËËËËËËËË¢ËËË¢",
            "ËËËËËËËËËËË¢ËËË¢",
            "ËËËËËËËËËËË¢¢¢¢Í",
            "À¸¹ǗËËËËËËË¢ËËË¢",
            "ËËËƸËËËËËËË¢ËËË¢",
            "ËËË¸ËËËËËËË¢ËËË¢",
            "ËËËƸËËËËËËË¢ËËË¢"
        ],
        [
            "¡¡¡¡¡¡¡¡¡¡¡¡¡¡¡¡",
            "¡¡¡¡¡¡¡¡¡¡¡¡¡¡¡¡",
            "¡¡¡¡¡¡¡¡¡¡¡¡¡¡¡¡",
            "¡¡¡¡¡¡¡¡¡¡¡¡¡¡¡¡",
            "¡¡¡¡¡¡¡¡¡¡¡¡¡¡¡¡",
            "¡¡¡¡¡¡¡¡¡¡¡¡¡¡¡¡",
            "¡¡¡¡¡¡¡¡¡¡¡¡¡¡¡¡",
            "¡¡¡¡¡¡¡¡¡¡¡¡¡¡¡¡",
            "¡¡¡¡¡¡¡¡¡¡¡¡¡¡¡¡",
            "¡¡¡¡¡¡¡¡¡¡¡¡¡¡¡¡",
            "¡¡¡¡¡¡¡¡¡¡¡¡¡¡¡¡",
            "¡¡¡¡¡¡¡¡¡¡¡¡¡¡¡¡",
            "¡¡¸¸¡¡¡¡¡¡¡¡¡¡¡¡",
            "¡¡¡¸¡¡¡¡¡¡¡¡¡¡¡¡",
            "¡¡¡¡¡¡¡¡¡¡¡¡¡¡¡¡",
            "¡¡¡¡¡¡¡¡¡¡¡¡¡¡¡¡"
        ]
    ],
    "refpalette": "building004_palette"
}