{
    "xsize": 16,
    "zsize": 16,
    "slices": [
        [
            "¢¢¢¢¢¢¢¢¢¢¢¢¢¢¢¢",
            "¢¡¡¡¡¡¡¡¡ÏÏÏÏÏÏ¢",
            "¢¡   ¡¡¡¡ÏÏÏÏÏÏ¢",
            "¢¡  §¡¡¡¡ÏÏÏÏÏÏ¢",
            "¢¡  ¨¡¡¡¡ÏÏÏÏÏÏ¢",
            "¢¡¡¡¡¡¡¡¡ÏÏÏÏÏÏ¢",
            "¢¡¡¡¡¡¡¡¡ÏÏÏÏÏÏ¢",
            "¢¡¡¡¡¡¡¡¡¡¡¡¡¡¡¢",
            "¢¡¡¡¡¡¡¡¡¡¡¡¡¡¡¢",
            "¢¡¡¡¡¡¡¡¡¡¡¡¡¡¡¢",
            "¢¡¡¡¡¡¡¡¡¡¡¡¡¡¡¢",
            "¢¡¡¡¡¡¡¡¡¡¡¡¡¡¡¢",
            "¢¡¡¡¡¡¡¡¡¡¡¡¡¡¡¢",
            "¢¡¡¡¡¡¡¡¡¡¡¡¡¡¡¢",
            "¢¡¡¡¡¡¡¡¡¡¡¡¡¡¡¢",
            "¢¢¢¢¢¢¢¢¢¢¢¢¢¢¢¢"
        ],
        [
            "¢¢¢¢¢¢¢¢¢¢¢¢¢¢¢¢",
            "¢°Ð©¤¤ÑÒÓ      ¢",
            "¢±   Ô£ÒÕ Ö¢¢Ö ¢",
            "¢    ³³ÒÓ××ØØÙÚ¢",
            "¢Û    ³ÒÓ×××ÙÙÚ¢",
            "¢     ³ÒÕÙ×ÙÙÜÚ¢",
            "¢Ý    ÔÒÓÙÙÜÜÜÜ¢",
            "¢°± ¬  ÒÒÞÕßàÕÞ¢",
            "¢°½    ÒÒÒÒ  ÒÒ¢",
            "¢Ðá¾    ÐâÒ  Òµ¢",
            "¢Ð±Ð     âÒ  Ò ¢",
            "¢±£       ÒãäÒ ¢",
            "¢å   ©         ¢",
            "¢±æç³¤è ¥     »¢",
            "¢°¾³³¤¤ ¥¥¥  ½á¢",
            "¢¢¢¢¢¢¢¢¢¢¢¢¢¢¢¢"
        ],
        [
            "¢¢¢¢¢¢¢¢¢¢¢¢¢¢¢¢",
            "¢Ð  ©¤ Òé     ê¢",
            "¢      ÒÕ  ¢¢  ¢",
            "¢     ³Òé  ØØ  ¢",
            "¢      Òé      ¢",
            "¢      ÒÕ      ¢",
            "¢      Òé      ¢",
            "¢      ÒÒëìíîÕë¢",
            "¢°     ÒÒÒÒ  ÒÒ¢",
            "¢Ð±      »Ò  Òµ¢",
            "¢±       »Ò  Ò ¢",
            "¢         ïðñÒ ¢",
            "¢              ¢",
            "¢    ©         ¢",
            "¢½  ®¤£  ¥    ½¢",
            "¢¢¢¢¢¢¢¢¢¢¢¢¢¢¢¢"
        ],
        [
            "¢¢¢¢¢¢¢¢¢¢¢¢¢¢¢¢",
            "¢    ® ÒÓ      ¢",
            "¢      ÒÕ  ¢¢  ¢",
            "¢     ®ÒÕ  ØØ  ¢",
            "¢      ÒÕ      ¢",
            "¢      ÒÕ      ¢",
            "¢      ÒÓ      ¢",
            "¢      ÒÒÞÕÕÕÕÞ¢",
            "¢      ÒÒÒÒÒÒÒÒ¢",
            "¢±       ÐÒÒÒÒ ¢",
            "¢         ÒÒÒÒ ¢",
            "¢         ÒÒÒÒ ¢",
            "¢              ¢",
            "¢              ¢",
            "¢    ò         ¢",
            "¢¢¢¢¢¢¢¢¢¢¢¢¢¢¢¢"
        ],
        [
            "¢¢¢¢¢¢¢¢¢¢¢¢¢¢¢¢",
            "¢ÍÍÍÍÍÍÒéÍÍÍÍÍÍ¢",
            "¢ÍÍÍÍÍÍÒÒÍÍ¢¢ÍÍ¢",
            "¢ÍÍÍÍÍÍÒÓÍÍØØÍÍ¢",
            "¢ÍÍÍÍÍÍÒÓÍÍÍÍÍÍ¢",
            "¢ÍÍÍÍÍÍÒÒÍÍÍÍÍÍ¢",
            "¢ÍÍÍÍÍÍÒéÍÍÍÍÍÍ¢",
            "¢ÍÍÍÍÍÍÒÒëëÞÞëë¢",
            "¢ÍÍÍÍÍÍÒÒÒÒÒÒÒÒ¢",
            "¢ÍÍÍÍÍÍÍÍÍÍÍÍÍÍ¢",
            "¢ÍÍÍÍÍÍÍÍÍÍÍÍÍÍ¢",
            "¢ÍÍÍÍÍÍÍÍÍÍÍÍÍÍ¢",
            "¢ÍÍÍÍÍÍÍÍÍÍÍÍÍÍ¢",
            "¢ÍÍÍÍÍÍÍÍÍÍÍÍÍÍ¢",
            "¢ÍÍÍÍÍÍÍÍÍÍÍÍÍÍ¢",
            "¢¢¢¢¢¢¢¢¢¢¢¢¢¢¢¢"
        ],
        [
            "ÎÎÎÎÎÎÎÎÎÎÎÎÎÎÎÎ",
            "ÎÎÎÎÎÎÎÎÎÎÎÎÎÎÎÎ",
            "ÎÎÎÎÎÎÎÎÎÎÎÎÎÎÎÎ",
            "ÎÎÎÎÎÎÎÎÎÎÎØØÎÎÎ",
            "ÎÎÎÎÎÎÎÎÎÎÎÎÎÎÎÎ",
            "ÎÎÎÎÎÎÎÎÎÎÎÎÎÎÎÎ",
            "ÎÎÎÎÎÎÎÎÎÎÎÎÎÎÎÎ",
            "ÎÎÎÎÎÎÎÎÎÎÎÎÎÎÎÎ",
            "ÎÎÎÎÎÎÎÎÎÎÎÎÎÎÎÎ",
            "ÎÎÎÎÎÎÎÎÎÎÎÎÎÎÎÎ",
            "ÎÎÎÎÎÎÎÎÎÎÎÎÎÎÎÎ",
            "ÎÎÎÎÎÎÎÎÎÎÎÎÎÎÎÎ",
            "ÎÎÎÎÎÎÎÎÎÎÎÎÎÎÎÎ",
            "ÎÎÎÎÎÎÎÎÎÎÎÎÎÎÎÎ",
            "ÎÎÎÎÎÎÎÎÎÎÎÎÎÎÎÎ",
            "ÎÎÎÎÎÎÎÎÎÎÎÎÎÎÎÎ"
        ]
    ],
    "refpalette": "building005_palette"
}