{
    "xsize": 16,
    "zsize": 16,
    "slices": [
        [
            "                ",
            "  ĪĪĪĪĪøøøøøøøø ",
            " īĝĝĝĝĝĝĝúúúúúø ",
            " īĝ¡¡¡¡¡¡¡¡ØØúø ",
            " īĝ¡¡¡¡¡¡¡¡¡¡úø ",
            " īĝ¡¡¡¡¡¡¡¡¡¡úø ",
            " īĝ¡¡¡¡¡¡¡¡¡¡úø ",
            " øĝ¡¡¡¡¡¡¡¡¡¡ĝø ",
            " øĝ¡¡¡¡¡¡¡¡¡¡ĝø ",
            " øú¡¡¡¡¡¡¡¡¡¡ĝĬ ",
            " øú¡¡¡¡¡¡¡¡¡¡ĝĬ ",
            " øú¡¡¡¡¡¡¡¡¡¡ĝĬ ",
            " øú¡¡¡¡¡¡¡¡¡¡ĝĬ ",
            " øúúúúúĝĝĝĝĝĝĝĬ ",
            " øøøøøøøøĭĭĭĭĭ  ",
            "                "
        ],
        [
            "                ",
            " ĘĘĘĘĘĘøø       ",
            " Ęĝĝĝĝĝĝĝċċċċċ  ",
            " ĘĝÖ  Ą    ØØċ  ",
            " Ęĝ   ŧŧ     ċ  ",
            " Ęĝ    Ũ     ċ  ",
            " Ęĝ ũŪ  ŪūŬ  ċ  ",
            " øĝ      ū   ĝø ",
            " øĝ ũ       Ąĝø ",
            "  ċ ũŪ  Ūū ŭ ĝĘ ",
            "  ċ    Ũ     ĝĘ ",
            "  ċ   ŮŮ     ĝĘ ",
            "  ċ ů     ½¬ŉĝĘ ",
            "  ċċċċċĝĝĝĝĝĝĝĘ ",
            "       øøĘĘĘĘĘĘ ",
            "                "
        ],
        [
            "                ",
            " Řěěěěěøø       ",
            " Ĝķķķĝĝĝĝċċċċċ  ",
            " Ĝķ        ØØċ  ",
            " Ĝķ          ċ  ",
            " Ĝĝ   ŰŰŜ    ċ  ",
            " Ĝĝ  ű  Ų    ċ  ",
            " øĝ     Ų    ĝø ",
            " øĝ  ű       ĝø ",
            "  ċ  ű  Ų    ĝĤ ",
            "  ċ   ųŴ     ĝĤ ",
            "  ċ          ķĤ ",
            "  ċ          ķĤ ",
            "  ċċċċċĝĝĝĝķķķĤ ",
            "       øøĨĨĨĨĨŌ ",
            "                "
        ],
        [
            "                ",
            "     ĪĪøø       ",
            "  ķķķĝĝĝĝċċċċċ  ",
            "  ķ        ØØċ  ",
            "  ķ          ċ  ",
            " īĝ          ċ  ",
            " īĝ          ċ  ",
            " øĝŵ         ĝø ",
            " øĝ          ĝø ",
            "  ċ          ĝĬ ",
            "  ċ          ĝĬ ",
            "  ċ          ķ  ",
            "  ċ          ķ  ",
            "  ċċċċċĝĝĝĝķķķ  ",
            "       øøĭĭ     ",
            "                "
        ],
        [
            "                ",
            " őĻĻĻĻĻøø       ",
            " ļķķķĝĝĝĝċċċċċ  ",
            " ļķ        ØØċ  ",
            " ļķ          ċ  ",
            " ļĝ          ċ  ",
            " ļĝ          ċ  ",
            " øĝ          ĝø ",
            " øĝ    Ŷ     ĝø ",
            "  ċ          ĝľ ",
            "  ċ          ĝľ ",
            "  ċ          ķľ ",
            "  ċ          ķľ ",
            "  ċċċċċĝĝĝĝķķķľ ",
            "       øøĿĿĿĿĿŒ ",
            "                "
        ],
        [
            "                ",
            " ŁŁŁŁŁŁøø       ",
            " Łĝĝĝĝĝĝĝúúúúú  ",
            " ŁĝĞğğğğğğĠØØú  ",
            " ŁĝġĢĢĢĢĢĢĢğĠú  ",
            " ŁĝġĢĢĢĢĢĢĢĢģú  ",
            " ŁĝġĢĢĢĢĢĢĢĢģú  ",
            " øĝġĢĢĢĢĢĢĢĢģĝø ",
            " øĝġĢĢĢĢĢĢĢĢģĝø ",
            "  úġĢĢĢĢĢĢĢĢģĝŁ ",
            "  úġĢĢĢĢĢĢĢĢģĝŁ ",
            "  úġĢĢĢĢĢĢĢĢģĝŁ ",
            "  úĥĦĦĦĦĦĦĦĦħĝŁ ",
            "  úúúúúĝĝĝĝĝĝĝŁ ",
            "       øøŁŁŁŁŁŁ ",
            "                "
        ]
    ],
    "refpalette": "building005_palette"
}