{
    "xsize": 16,
    "zsize": 16,
    "slices": [
        [
            "                ",
            "                ",
            "                ",
            "  ¥¥¥¥¥¥¥¥¥¥¥¥  ",
            "   ¦¤¤¤¤¤¤¤¤¦   ",
            "  µ¤¤¤¤¤¤¤¤¤¤µ  ",
            "  µ¤¤¤¤¤¤¤¤¤¤µ  ",
            "  µ¤¤      ¤¤µ  ",
            "  µ¤¤  ÐÐ  ¤¤µ  ",
            "  µ¤¤      ¤¤µ  ",
            "  µ¤¤      ¤¤µ  ",
            "  µ¤¤      ¤¤µ  ",
            "  µ¤¤  ÐÐ  ¤¤µ  ",
            "  µ¤¤      ¤¤µ  ",
            "  µ¤¤      ¤¤µ  ",
            "  µ¤¤      ¤¤µ  "
        ],
        [
            "                ",
            "                ",
            "                ",
            "  ¥¥¥¥¥¥¥¥¥¥¥¥  ",
            "   ¦        ¦   ",
            "  ©   Ú      ©  ",
            "  © ÛÜÜÜÜÜÜÝ ©  ",
            "  © Þ      ß ©  ",
            "  © Þ ÏÐÐÏ ß ©  ",
            "  © Þ      ß ©  ",
            "  Ñ Þ      ß Ñ  ",
            "  Ñ Þ      ß Ñ  ",
            "  © Þ ÏÐÐÏ ß ©  ",
            "  © Þ      ß ©  ",
            "  © Þ      ß ©  ",
            "  © Þ      ß ©  "
        ],
        [
            "                ",
            "                ",
            "                ",
            "  ¥¥¥¥¥¥¥¥¥¥¥¥  ",
            "   ¦        ¦   ",
            "  ©          ©  ",
            "  ©          ©  ",
            "  ©          ©  ",
            "  ©  ÓÔÔáÔÖ  ©  ",
            "  ©          ©  ",
            "  Ñ          Ñ  ",
            "  Ñ          Ñ  ",
            "  ©  ÓÔÔáÔÖ  ©  ",
            "  ©          ©  ",
            "  ©          ©  ",
            "  ©          ©  "
        ],
        [
            "                ",
            "                ",
            "                ",
            "  ¥¥¥¥¥¥¥¥¥¥¥¥  ",
            "   ¦        ¦   ",
            "  ©          ©  ",
            "  ©          ©  ",
            "  ©          ©  ",
            "  ©  ×Ô§ÔÔØ  ©  ",
            "  ©          ©  ",
            "  Ñ          Ñ  ",
            "  Ñ          Ñ  ",
            "  ©  ×áÔÔÔØ  ©  ",
            "  ©          ©  ",
            "  ©          ©  ",
            "  ©          ©  "
        ],
        [
            "                ",
            "                ",
            "                ",
            "  ¥¥¥¥¥¥¥¥¥¥¥¥  ",
            "   ¦        ¦   ",
            "  ©          ©  ",
            "  ©          ©  ",
            "  ©          ©  ",
            "  ©  ÓÔáÔáÖ  ©  ",
            "  ©          ©  ",
            "  Ñ          Ñ  ",
            "  Ñ          Ñ  ",
            "  ©  ÓáÔÔÔÖ  ©  ",
            "  ©          ©  ",
            "  ©          ©  ",
            "  ©          ©  "
        ],
        [
            "                ",
            "                ",
            "                ",
            "  ¥¥¥¥¥¥¥¥¥¥¥¥  ",
            "   ¦        ¦   ",
            "  ©          ©  ",
            "  ©          ©  ",
            "  ©          ©  ",
            "  ©   ÙÐÐÙ   ©  ",
            "  ©          ©  ",
            "  Ñ          Ñ  ",
            "  Ñ          Ñ  ",
            "  ©   ÙÐÐÙ   ©  ",
            "  ©          ©  ",
            "  ©          ©  ",
            "  ©          ©  "
        ]
    ],
    "refpalette": "building003_palette"
}