{
    "xsize": 16,
    "zsize": 16,
    "slices": [
        [
            "   Ô¡ÕÐÖÖÐÕ¡Ô   ",
            " ×Ø¡¡¡¡¡¡¡¡¡¡Ø× ",
            " ¡ÐÐÐÐÐÐÐÐÐÐÐÐ¡ ",
            " ¦ÐĈĈĈĈĈĈĈĈĈĈÐ¨ ",
            " ØÐĈĈĈĈĈĈĈĈĈĈÐØ ",
            " ìÐĈĈĈĈĈĈĈĈĈĈÐì ",
            " ìÐĈĈĈĈĈĈĈĈĈĈÐì ",
            " ìÐĈĈĈĈĈĈĈĈĈĈÐì ",
            " ìÐĈĈĈĈĈĈĈĈĈĈÐì ",
            " ìÐĈĈĈĈĈĈĈĈĈĈÐì ",
            " ìÐ¤¤¤¤¤¤¤¤¤¤Ðì ",
            " Ø¤¥¥¥¤ ¤   ¤¤Ø ",
            " ¦¤¥¥¥¤ ¤   ¤ ¨ ",
            " ¡¤¥À¥¤ ¤   ¤ ¡ ",
            " ×Ø¤¤¤¤¤¤¤¤¤¤Ø× ",
            "   ´¡ÕÐææÐÕ¡´   "
        ],
        [
            "   Ô¡ÕÐÖÖÐÕ¡Ô   ",
            " ×Ø¡¡¡¡¡¡¡¡¡¡Ø× ",
            " ¡ť     Ú    Ŧ¡ ",
            " ¦   ŧ    ŧ   ¨ ",
            " Ø            Ø ",
            " ì  ŨũũũũũũŪ  ì ",
            " ì   ū º ū    ì ",
            " ì     ď      ì ",
            " ì            ì ",
            " ì » »»»»» »» ì ",
            " Ø¼¤½¤¤¤¤¤½¤¤¾Ø ",
            " Ø¤   ¤ ¤   ¤¤Ø ",
            " ¦¤   ¤ ¤   ¿ ¨ ",
            " ¡¤ À ¤ ¤   ¤ ¡ ",
            " ×Ø¤¤¤¤¤¤¤¤¤¤Ø× ",
            "   ´¡ÕÐææÐÕ¡´   "
        ],
        [
            "   Ô¡ÕÐÖÖÐÕ¡Ô   ",
            " ×Ø¡¡¡¡¡¡¡¡¡¡Ø× ",
            " ¡            ¡ ",
            " ¦            ¨ ",
            " Ø            Ø ",
            " ì            ì ",
            " ì   Ŭŭ  Ůů   ì ",
            " ì            ì ",
            " ì            ì ",
            " Ø » »»»»» »» Ø ",
            " Ø¼¤Ê¤¤¤¤¤Ê¤¤¾Ø ",
            " ¦¤   ¤ ¤   ¤¤¨ ",
            " ¦¤   ¤ ¤   Ë ¨ ",
            " ¡¤ À ¤ ¤   ¤ ¡ ",
            " ×Ø¤¤¤¤¤¤¤¤¤¤Ø× ",
            "   ´¡ÕÐææÐÕ¡´   "
        ],
        [
            "   Ô¡ÕÐÖÖÐÕ¡Ô   ",
            " ×Ø¡¡¡¡¡¡¡¡¡¡Ø× ",
            " ¡   Ű    ñ   ¡ ",
            " ¦            ¨ ",
            " Ø            Ø ",
            " ì            ì ",
            " ì            ì ",
            " ì            ì ",
            " Ø            Ø ",
            " Ø »»»»»»»»»» Ø ",
            " ¦¼¤¤¤¤¤¤¤¤¤¤¾¨ ",
            " ¦¤   ¤ ¤   ¤¤¨ ",
            " ¦¤   ¤ ¤   ¤ ¨ ",
            " ¡¤ À ¤ ¤   ¤ ¡ ",
            " ×Ø¤¤¤¤¤¤¤¤¤¤Ø× ",
            "   ´¡ÕÐææÐÕ¡´   "
        ],
        [
            "   Ô¡ÕÐÖÖÐÕ¡Ô   ",
            " ×Ø¡¡¡¡¡¡¡¡¡¡Ø× ",
            " ¡            ¡ ",
            " ¦            ¨ ",
            " Ø            Ø ",
            " ì            ì ",
            " ì            ì ",
            " Ø            Ø ",
            " Ø            Ø ",
            " ¦ »»»»»»»»»» ¨ ",
            " ¦¼¤¤¤¤¤¤¤¤¤¤¾¨ ",
            " ¦¤   ¤ ¤   ¤¤¨ ",
            " ¦¤   ¤ ¤   ¤ ¨ ",
            " ¡¤ À ¤ ¤   ¤ ¡ ",
            " ×Ø¤¤¤¤¤¤¤¤¤¤Ø× ",
            "   ´¡ÕÐææÐÕ¡´   "
        ],
        [
            "   Ô¡ÕÐÖÖÐÕ¡Ô   ",
            " ×Ø¡¡¡¡¡¡¡¡¡¡Ø× ",
            " ¡ØØØØØØØØØØØØ¡ ",
            " ¦ØÏÏÏÏÏÏÏÏÏÏØ¨ ",
            " ØØÏÏÏÏÏÏÏÏÏÏØØ ",
            " ìØÏÏÏÏÏÏÏÏÏÏØì ",
            " ØØÏÏÏÏÏÏÏÏÏÏØØ ",
            " ØØÏÏÏÏÏÏÏÏÏÏØØ ",
            " ¦ØÏÏÏÏÏÏÏÏÏÏØ¨ ",
            " ¦ØÏÏÏÏÏÏÏÏÏÏØ¨ ",
            " ¦Ø¤¤¤¤¤¤¤¤¤¤Ø¨ ",
            " ¦¤   ¤ ¤   ¤¤¨ ",
            " ¦¤   ¤ ¤   ¤ ¨ ",
            " ¡¤ À ¤ ¤   ¤ ¡ ",
            " ×Ø¤¤¤¤¤¤¤¤¤¤Ø× ",
            "   ´¡ÕÐææÐÕ¡´   "
        ]
    ],
    "refpalette": "building001_palette"
}