{
    "xsize": 16,
    "zsize": 16,
    "slices": [
        [
            "   Ô¡ÕÐÖÖÐÕ¡Ô   ",
            " ×Ø¡¡¡¡¡¡¡¡¡¡Ø× ",
            " ¡ÐÐÐÐÐÐÐÐÐÐÐÐ¡ ",
            " ¦ÐģģģģģģģģģģÐ¨ ",
            " ØÐģģģģģģģģģģÐØ ",
            " ìÐģģģģģģģģģģÐì ",
            " ìÐģģģģģģģģģģÐì ",
            " ìÐģģģģģģģģģģÐì ",
            " ØÐģģģģģģģģģģÐØ ",
            " ØÐģģģģģģģģģģÐØ ",
            " ¦Ð¤¤¤¤¤¤¤¤¤¤Ð¨ ",
            " ¦ ¥¥¥  ¤   ¤¤¨ ",
            " ¦ ¥¥¥  ¤   ¤ ¨ ",
            " ¡ ¥À¥  ¤   ¤ ¡ ",
            " ×Ø¤¤¤¤¤¤¤¤¤¤Ø× ",
            "   ´¡ÕÐææÐÕ¡´   "
        ],
        [
            "   Ô¡ÕÐÖÖÐÕ¡Ô   ",
            " ×Ø¡¡¡¡¡¡¡¡¡¡Ø× ",
            " ¡ĤÙÙÙÙ ĥ  Ú  ¡ ",
            " ¦ĦħĨĨĩ     Ī ¨ ",
            " ØĦī Ĭ     ĭ  Ø ",
            " ì     Į      ì ",
            " ì      º  ã  ì ",
            " ì   į        ì ",
            " ì            ì ",
            " Ø » »»»»» »» Ø ",
            " Ø¼¤½¤¤¤¤¤½¤¤¾Ø ",
            " ¦¤   ¤ ¤   ¤¤¨ ",
            " ¦¤   ¤ ¤   ¿ ¨ ",
            " ¡¤ À ¤ ¤   ¤ ¡ ",
            " ×Ø¤¤¤¤¤¤¤¤¤¤Ø× ",
            "   ´¡ÕÐææÐÕ¡´   "
        ],
        [
            "   Ô¡ÕÐÖÖÐÕ¡Ô   ",
            " ×Ø¡¡¡¡¡¡¡¡¡¡Ø× ",
            " ¡         İ  ¡ ",
            " ¦            ¨ ",
            " Ø         ıĲ Ø ",
            " ì            ì ",
            " ì            ì ",
            " ì            ì ",
            " ì            ì ",
            " ì » »»»»» »» ì ",
            " Ø¼¤Ê¤¤¤¤¤Ê¤¤¾Ø ",
            " Ø¤   ¤ ¤   ¤¤Ø ",
            " ¦¤   ¤ ¤   Ë ¨ ",
            " ¡¤ À ¤ ¤   ¤ ¡ ",
            " ×Ø¤¤¤¤¤¤¤¤¤¤Ø× ",
            "   ´¡ÕÐææÐÕ¡´   "
        ],
        [
            "   Ô¡ÕÐÖÖÐÕ¡Ô   ",
            " ×Ø¡¡¡¡¡¡¡¡¡¡Ø× ",
            " ¡            ¡ ",
            " ¦            ¨ ",
            " Ø            Ø ",
            " ì            ì ",
            " ì            ì ",
            " ì            ì ",
            " ì            ì ",
            " ì »»»»»»»»»» ì ",
            " ì¼¤¤¤¤¤¤¤¤¤¤¾ì ",
            " Ø¤   ¤ ¤   ¤¤Ø ",
            " ¦¤   ¤ ¤   ¤ ¨ ",
            " ¡¤ À ¤ ¤   ¤ ¡ ",
            " ×Ø¤¤¤¤¤¤¤¤¤¤Ø× ",
            "   ´¡ÕÐææÐÕ¡´   "
        ],
        [
            "   Ô¡ÕÐÖÖÐÕ¡Ô   ",
            " ×Ø¡¡¡¡¡¡¡¡¡¡Ø× ",
            " ¡            ¡ ",
            " ¦            ¨ ",
            " Ø            Ø ",
            " ì            ì ",
            " ì            ì ",
            " ì            ì ",
            " ì            ì ",
            " ì »»»»»»»»»» ì ",
            " ì¼¤¤¤¤¤¤¤¤¤¤¾ì ",
            " Ø¤   ¤ ¤   ¤¤Ø ",
            " ¦¤   ¤ ¤   ¤ ¨ ",
            " ¡¤ À ¤ ¤   ¤ ¡ ",
            " ×Ø¤¤¤¤¤¤¤¤¤¤Ø× ",
            "   ´¡ÕÐææÐÕ¡´   "
        ],
        [
            "   Ô¡ÕÐÖÖÐÕ¡Ô   ",
            " ×Ø¡¡¡¡¡¡¡¡¡¡Ø× ",
            " ¡ØØØØØØØØØØØØ¡ ",
            " ¦ØµµµµµµµµµµØ¨ ",
            " ØØµµµµµµµµµµØØ ",
            " ìØµµµµµµµµµµØì ",
            " ìØµµµµµµµµµµØì ",
            " ìØµµµµµµµµµµØì ",
            " ìØµµµµµµµµµµØì ",
            " ìØµµµµµµµµµµØì ",
            " ìØ¤¤¤   ¤¤¤ Øì ",
            " Ø¤   ¤ ¤   ¤¤Ø ",
            " ¦¤   ¤ ¤   ¤ ¨ ",
            " ¡¤ À ¤ ¤   ¤ ¡ ",
            " ×Ø¤¤¤¤¤¤¤¤¤¤Ø× ",
            "   ´¡ÕÐææÐÕ¡´   "
        ]
    ],
    "refpalette": "building001_palette"
}