{
    "xsize": 16,
    "zsize": 16,
    "slices": [
        [
            "¡¡¡¡¢±±±±±±±±±±±",
            "¡¡¡¡¢±±±±±±±±±±±",
            "¡¡¡¡¢±±±±±±±±±±±",
            "¡¡¡¡¢¤¤¤¤¤¤¤¤¤¤¤",
            "¡¡¡¡¢¤¤¤¤¤¤¤¤¤¤¤",
            "¡¡¡¡¢¤¤¤¤¤¤¤¤¤¤¤",
            "¡¡¡¡¢¤¤¤¤¤¤¤¤¤¤¤",
            "¡¡¡¡¢¤¤¤¤¤¤¤¤¤¤¤",
            "¡¡¡¡¢¤¤¤¤¤¤¤¤¤¤¤",
            "¡¡¡¡¢¤¤¤¤¤¤¤¤¤¤¤",
            "¡¡¡¡¢¤¤¤¤¤¤¤¤£¤¤",
            "¡¡¡¡¢¤¤¤¤¤¤¤¤¤¤¤",
            "¡¡¡¡¢¤¤¤¤¤¤¤¤¤¤¤",
            "¡¡¡¡¢¤¤¤¤¤¤¤¤¤¤¤",
            "¡¡¡¡¢¤¤¤¤¤¤¤¤¤¤¤",
            "¡¡¡¡¢¤¤¤¤¤¤¤¤¤¤¤"
        ],
        [
            "                ",
            "                ",
            "                ",
            "          »§§ §§",
            "         ¼§©§§ §",
            "     § ©  © ©§§§",
            "     §§§ ½§© §¨©",
            "     ³©©§ §¨§§§ ",
            "     ´    § §¨¨§",
            "     ©©¨´§ §©§¨§",
            "     §§©   §§²  ",
            "      §§§§§§§ ¨ ",
            "      §§§§§¼§§ §",
            "     §§© §©§§©©§",
            "     §©¨½§§¨©§§§",
            "     §§§§³§§§§§§"
        ],
        [
            "                ",
            "                ",
            "                ",
            "                ",
            "           ¬    ",
            "       ¬  ¬ ¬   ",
            "           ¬   ¬",
            "      ¬¬        ",
            "                ",
            "     ¬¬     ¬¶  ",
            "       ¬    ¶²¶ ",
            "             ¶  ",
            "                ",
            "       ¬  ¬  ¬¬ ",
            "      ¬     ¬   ",
            "                "
        ],
        [
            "                ",
            "                ",
            "                ",
            "                ",
            "                ",
            "                ",
            "                ",
            "                ",
            "            ¸·¸ ",
            "           ¸·¶·¸",
            "           ·¶²¶·",
            "           ¸·¶·¸",
            "            ¸·¸ ",
            "                ",
            "                ",
            "                "
        ],
        [
            "                ",
            "                ",
            "                ",
            "                ",
            "                ",
            "                ",
            "                ",
            "                ",
            "                ",
            "             ¶  ",
            "            ¶²¶ ",
            "             ¶  ",
            "                ",
            "                ",
            "                ",
            "                "
        ],
        [
            "                ",
            "                ",
            "                ",
            "                ",
            "                ",
            "                ",
            "                ",
            "                ",
            "                ",
            "                ",
            "             ²  ",
            "                ",
            "                ",
            "                ",
            "                ",
            "                "
        ]
    ],
    "refpalette": "building007_palette"
}