{
    "meta": [
        {
            "key": "support",
            "char": "v"
        }
    ],
    "xsize": 16,
    "zsize": 16,
    "palette": {
        "palette": [
            {
                "char": " ",
                "block": "minecraft:air"
            },
            {
                "char": "α",
                "block": "minecraft:smooth_stone"
            },
            {
                "char": "β",
                "block": "minecraft:gray_concrete"
            },
            {
                "char": "γ",
                "block": "minecraft:white_concrete"
            },
            {
                "char": "δ",
                "block": "minecraft:stone_bricks"
            },
            {
                "char": "ε",
                "block": "minecraft:stone_brick_wall[east=low,north=none,south=none,up=false,waterlogged=false,west=low]"
            },
            {
                "char": "ζ",
                "block": "minecraft:stone_brick_wall[east=none,north=none,south=none,up=true,waterlogged=false,west=none]"
            },
            {
                "char": "η",
                "block": "minecraft:sea_lantern"
            },
            {
                "char": "θ",
                "block": "minecraft:stone_brick_stairs[facing=south,half=bottom,shape=straight,waterlogged=false]"
            },
            {
                "char": "ι",
                "block": "minecraft:stone_brick_slab[type=top,waterlogged=false]"
            },
            {
                "char": "κ",
                "block": "minecraft:stone_brick_stairs[facing=north,half=bottom,shape=straight,waterlogged=false]"
            }
        ]
    },
    "slices": [
        [
            "vvvvvvvvvvvvvvvv",
            "vvvvvvvvvvvvvvvv",
            "vvvvvvvvvvvvvvvv",
            "vvvvvvvvvvvvvvvv",
            "vvvvvvvvvvvvvvvv",
            "vvvvvvvvvvvvvvvv",
            "vvvvvvvvvvvvvvvv",
            "vvvvvvvvvvvvvvvv",
            "vvvvvvvvvvvvvvvv",
            "vvvvvvvvvvvvvvvv",
            "vvvvvvvvvvvvvvvv",
            "vvvvvvvvvvvvvvvv",
            "vvvvvvvvvvvvvvvv",
            "vvvvvvvvvvvvvvvv",
            "vvvvvvvvvvvvvvvv",
            "vvvvvvvvvvvvvvvv"
        ],
        [
            "αααααααααααααααα",
            "αααααααααααααααα",
            "ββββββββββββββββ",
            "ββββββββββββββββ",
            "βγγββγγββγγββγγβ",
            "ββββββββββββββββ",
            "ββββββββββββββββ",
            "αααααααααααααααα",
            "αααααααααααααααα",
            "ββββββββββββββββ",
            "ββββββββββββββββ",
            "βγγββγγββγγββγγβ",
            "ββββββββββββββββ",
            "ββββββββββββββββ",
            "αααααααααααααααα",
            "αααααααααααααααα"
        ],
        [
            "δεεεεεεδδεεεεεεδ",
            "                ",
            "                ",
            "                ",
            "                ",
            "                ",
            "                ",
            "                ",
            "                ",
            "                ",
            "                ",
            "                ",
            "                ",
            "                ",
            "                ",
            "δεεεεεεδδεεεεεεδ"
        ],
        [
            "        δ       ",
            "                ",
            "                ",
            "                ",
            "                ",
            "                ",
            "                ",
            "                ",
            "                ",
            "                ",
            "                ",
            "                ",
            "                ",
            "                ",
            "                ",
            "        δ       "
        ],
        [
            "        ζ       ",
            "                ",
            "                ",
            "                ",
            "                ",
            "                ",
            "                ",
            "                ",
            "                ",
            "                ",
            "                ",
            "                ",
            "                ",
            "                ",
            "                ",
            "        ζ       "
        ],
        [
            "        ζ       ",
            "                ",
            "                ",
            "                ",
            "                ",
            "                ",
            "                ",
            "                ",
            "                ",
            "                ",
            "                ",
            "                ",
            "                ",
            "                ",
            "                ",
            "        ζ       "
        ],
        [
            "        ζ       ",
            "                ",
            "                ",
            "                ",
            "                ",
            "                ",
            "                ",
            "                ",
            "                ",
            "                ",
            "                ",
            "                ",
            "                ",
            "                ",
            "                ",
            "        ζ       "
        ],
        [
            "        ζ       ",
            "                ",
            "                ",
            "                ",
            "                ",
            "                ",
            "                ",
            "                ",
            "                ",
            "                ",
            "                ",
            "                ",
            "                ",
            "                ",
            "                ",
            "        ζ       "
        ],
        [
            "        ζ       ",
            "                ",
            "                ",
            "                ",
            "                ",
            "                ",
            "                ",
            "                ",
            "                ",
            "                ",
            "                ",
            "                ",
            "                ",
            "                ",
            "                ",
            "        ζ       "
        ],
        [
            "        δ       ",
            "                ",
            "        η       ",
            "                ",
            "                ",
            "                ",
            "                ",
            "                ",
            "                ",
            "                ",
            "                ",
            "                ",
            "                ",
            "        η       ",
            "                ",
            "        δ       "
        ],
        [
            "        θ       ",
            "        ι       ",
            "        κ       ",
            "                ",
            "                ",
            "                ",
            "                ",
            "                ",
            "                ",
            "                ",
            "                ",
            "                ",
            "                ",
            "        θ       ",
            "        ι       ",
            "        κ       "
        ]
    ]
}