{
    "xsize": 16,
    "zsize": 16,
    "palette": {
        "palette": [
            {
                "char": " ",
                "block": "minecraft:air"
            },
            {
                "char": "α",
                "block": "betterblockz:ironslate_blockz_1"
            },
            {
                "char": "β",
                "block": "betterblockz:cyberlight_blockz_0[lit=true]"
            },
            {
                "char": "γ",
                "block": "betterblockz:eclipse_blockz_0"
            },
            {
                "char": "δ",
                "block": "minecraft:structure_void"
            },
            {
                "char": "ε",
                "block": "betterblockz:cyberlight_thin_0[facing=up]"
            }
        ]
    },
    "slices": [
        [
            "αβγγγγγββγγγγγβα",
            "ββγγγγγββγγγγγββ",
            "γγγγγγγββγγγγγγγ",
            "γγγγγγγββγγγγγγγ",
            "γγγγγγγββγγγγγγγ",
            "γγγγγγγββγγγγγγγ",
            "γγγγγγγββγγγγγγγ",
            "ββββββββββββββββ",
            "ββββββββββββββββ",
            "γγγγγγγββγγγγγγγ",
            "γγγγγγγββγγγγγγγ",
            "γγγγγγγββγγγγγγγ",
            "γγγγγγγββγγγγγγγ",
            "γγγγγγγββγγγγγγγ",
            "ββγγγγγββγγγγγββ",
            "αβγγγγγββγγγγγβα"
        ],
        [
            "βδδδδδδδδδδδδδδβ",
            "δδδδδδδδδδδδδδδδ",
            "δδδδδδδδδδδδδδδδ",
            "δδδδδδδδδδδδδδδδ",
            "δδδδδδδδδδδδδδδδ",
            "δδδδδδδδδδδδδδδδ",
            "δδδδδδδδδδδδδδδδ",
            "δδδδδδδδδδδδδδδδ",
            "δδδδδδδδδδδδδδδδ",
            "δδδδδδδδδδδδδδδδ",
            "δδδδδδδδδδδδδδδδ",
            "δδδδδδδδδδδδδδδδ",
            "δδδδδδδδδδδδδδδδ",
            "δδδδδδδδδδδδδδδδ",
            "δδδδδδδδδδδδδδδδ",
            "βδδδδδδδδδδδδδδβ"
        ],
        [
            "εδδδδδδδδδδδδδδε",
            "δδδδδδδδδδδδδδδδ",
            "δδδδδδδδδδδδδδδδ",
            "δδδδδδδδδδδδδδδδ",
            "δδδδδδδδδδδδδδδδ",
            "δδδδδδδδδδδδδδδδ",
            "δδδδδδδδδδδδδδδδ",
            "δδδδδδδδδδδδδδδδ",
            "δδδδδδδδδδδδδδδδ",
            "δδδδδδδδδδδδδδδδ",
            "δδδδδδδδδδδδδδδδ",
            "δδδδδδδδδδδδδδδδ",
            "δδδδδδδδδδδδδδδδ",
            "δδδδδδδδδδδδδδδδ",
            "δδδδδδδδδδδδδδδδ",
            "εδδδδδδδδδδδδδδε"
        ],
        [
            "δδδδδδδδδδδδδδδδ",
            "δδδδδδδδδδδδδδδδ",
            "δδδδδδδδδδδδδδδδ",
            "δδδδδδδδδδδδδδδδ",
            "δδδδδδδδδδδδδδδδ",
            "δδδδδδδδδδδδδδδδ",
            "δδδδδδδδδδδδδδδδ",
            "δδδδδδδδδδδδδδδδ",
            "δδδδδδδδδδδδδδδδ",
            "δδδδδδδδδδδδδδδδ",
            "δδδδδδδδδδδδδδδδ",
            "δδδδδδδδδδδδδδδδ",
            "δδδδδδδδδδδδδδδδ",
            "δδδδδδδδδδδδδδδδ",
            "δδδδδδδδδδδδδδδδ",
            "δδδδδδδδδδδδδδδδ"
        ],
        [
            "δδδδδδδδδδδδδδδδ",
            "δδδδδδδδδδδδδδδδ",
            "δδδδδδδδδδδδδδδδ",
            "δδδδδδδδδδδδδδδδ",
            "δδδδδδδδδδδδδδδδ",
            "δδδδδδδδδδδδδδδδ",
            "δδδδδδδδδδδδδδδδ",
            "δδδδδδδδδδδδδδδδ",
            "δδδδδδδδδδδδδδδδ",
            "δδδδδδδδδδδδδδδδ",
            "δδδδδδδδδδδδδδδδ",
            "δδδδδδδδδδδδδδδδ",
            "δδδδδδδδδδδδδδδδ",
            "δδδδδδδδδδδδδδδδ",
            "δδδδδδδδδδδδδδδδ",
            "δδδδδδδδδδδδδδδδ"
        ],
        [
            "δδδδδδδδδδδδδδδδ",
            "δδδδδδδδδδδδδδδδ",
            "δδδδδδδδδδδδδδδδ",
            "δδδδδδδδδδδδδδδδ",
            "δδδδδδδδδδδδδδδδ",
            "δδδδδδδδδδδδδδδδ",
            "δδδδδδδδδδδδδδδδ",
            "δδδδδδδδδδδδδδδδ",
            "δδδδδδδδδδδδδδδδ",
            "δδδδδδδδδδδδδδδδ",
            "δδδδδδδδδδδδδδδδ",
            "δδδδδδδδδδδδδδδδ",
            "δδδδδδδδδδδδδδδδ",
            "δδδδδδδδδδδδδδδδ",
            "δδδδδδδδδδδδδδδδ",
            "δδδδδδδδδδδδδδδδ"
        ]
    ]
}