{
    "xsize": 16,
    "zsize": 16,
    "palette": {
        "palette": [
            {
                "char": " ",
                "block": "minecraft:air"
            },
            {
                "char": "α",
                "block": "betterblockz:ironslate_blockz_1"
            },
            {
                "char": "β",
                "block": "betterblockz:cyberlight_blockz_0[lit=true]"
            },
            {
                "char": "γ",
                "block": "betterblockz:eclipse_blockz_0"
            },
            {
                "char": "δ",
                "block": "minecraft:structure_void"
            },
            {
                "char": "ε",
                "block": "betterblockz:cyberlight_thin_0[facing=up]"
            }
        ]
    },
    "slices": [
        [
            "αααααααααααααααα",
            "ββββββββββββββββ",
            "γγγγγγγγγγγγγγγγ",
            "γγγγγγγγγγγγγγγγ",
            "γγγγγγγγγγγγγγγγ",
            "γγγγγγγγγγγγγγγγ",
            "γγγγγγγγγγγγγγγγ",
            "ββββββββββββββββ",
            "ββββββββββββββββ",
            "γγγγγγγγγγγγγγγγ",
            "γγγγγγγγγγγγγγγγ",
            "γγγγγγγγγγγγγγγγ",
            "γγγγγγγγγγγγγγγγ",
            "γγγγγγγγγγγγγγγγ",
            "ββββββββββββββββ",
            "αααααααααααααααα"
        ],
        [
            "βδδδδδδδδδδδδδδβ",
            "δδδδδδδδδδδδδδδδ",
            "δδδδδδδδδδδδδδδδ",
            "δδδδδδδδδδδδδδδδ",
            "δδδδδδδδδδδδδδδδ",
            "δδδδδδδδδδδδδδδδ",
            "δδδδδδδδδδδδδδδδ",
            "δδδδδδδδδδδδδδδδ",
            "δδδδδδδδδδδδδδδδ",
            "δδδδδδδδδδδδδδδδ",
            "δδδδδδδδδδδδδδδδ",
            "δδδδδδδδδδδδδδδδ",
            "δδδδδδδδδδδδδδδδ",
            "δδδδδδδδδδδδδδδδ",
            "δδδδδδδδδδδδδδδδ",
            "βδδδδδδδδδδδδδδβ"
        ],
        [
            "εεεεεεεεεεεεεεεε",
            "δδδδδδδδδδδδδδδδ",
            "δδδδδδδδδδδδδδδδ",
            "δδδδδδδδδδδδδδδδ",
            "δδδδδδδδδδδδδδδδ",
            "δδδδδδδδδδδδδδδδ",
            "δδδδδδδδδδδδδδδδ",
            "δδδδδδδδδδδδδδδδ",
            "δδδδδδδδδδδδδδδδ",
            "δδδδδδδδδδδδδδδδ",
            "δδδδδδδδδδδδδδδδ",
            "δδδδδδδδδδδδδδδδ",
            "δδδδδδδδδδδδδδδδ",
            "δδδδδδδδδδδδδδδδ",
            "δδδδδδδδδδδδδδδδ",
            "εεεεεεεεεεεεεεεε"
        ],
        [
            "δδδδδδδδδδδδδδδδ",
            "δδδδδδδδδδδδδδδδ",
            "δδδδδδδδδδδδδδδδ",
            "δδδδδδδδδδδδδδδδ",
            "δδδδδδδδδδδδδδδδ",
            "δδδδδδδδδδδδδδδδ",
            "δδδδδδδδδδδδδδδδ",
            "δδδδδδδδδδδδδδδδ",
            "δδδδδδδδδδδδδδδδ",
            "δδδδδδδδδδδδδδδδ",
            "δδδδδδδδδδδδδδδδ",
            "δδδδδδδδδδδδδδδδ",
            "δδδδδδδδδδδδδδδδ",
            "δδδδδδδδδδδδδδδδ",
            "δδδδδδδδδδδδδδδδ",
            "δδδδδδδδδδδδδδδδ"
        ],
        [
            "δδδδδδδδδδδδδδδδ",
            "δδδδδδδδδδδδδδδδ",
            "δδδδδδδδδδδδδδδδ",
            "δδδδδδδδδδδδδδδδ",
            "δδδδδδδδδδδδδδδδ",
            "δδδδδδδδδδδδδδδδ",
            "δδδδδδδδδδδδδδδδ",
            "δδδδδδδδδδδδδδδδ",
            "δδδδδδδδδδδδδδδδ",
            "δδδδδδδδδδδδδδδδ",
            "δδδδδδδδδδδδδδδδ",
            "δδδδδδδδδδδδδδδδ",
            "δδδδδδδδδδδδδδδδ",
            "δδδδδδδδδδδδδδδδ",
            "δδδδδδδδδδδδδδδδ",
            "δδδδδδδδδδδδδδδδ"
        ],
        [
            "δδδδδδδδδδδδδδδδ",
            "δδδδδδδδδδδδδδδδ",
            "δδδδδδδδδδδδδδδδ",
            "δδδδδδδδδδδδδδδδ",
            "δδδδδδδδδδδδδδδδ",
            "δδδδδδδδδδδδδδδδ",
            "δδδδδδδδδδδδδδδδ",
            "δδδδδδδδδδδδδδδδ",
            "δδδδδδδδδδδδδδδδ",
            "δδδδδδδδδδδδδδδδ",
            "δδδδδδδδδδδδδδδδ",
            "δδδδδδδδδδδδδδδδ",
            "δδδδδδδδδδδδδδδδ",
            "δδδδδδδδδδδδδδδδ",
            "δδδδδδδδδδδδδδδδ",
            "δδδδδδδδδδδδδδδδ"
        ]
    ]
}