{
    "xsize": 16,
    "zsize": 16,
    "palette": {
        "palette": [
            {
                "char": " ",
                "block": "minecraft:air"
            },
            {
                "char": "α",
                "block": "betterblockz:ironslate_blockz_1"
            },
            {
                "char": "β",
                "block": "betterblockz:cyberlight_blockz_0[lit=true]"
            },
            {
                "char": "γ",
                "block": "betterblockz:eclipse_blockz_0"
            },
            {
                "char": "δ",
                "block": "betterblockz:ironslate_blockz_12"
            },
            {
                "char": "ε",
                "block": "minecraft:structure_void"
            },
            {
                "char": "ζ",
                "block": "betterblockz:ironslate_blockz_4"
            }
        ]
    },
    "slices": [
        [
            "αβγγγγγββγγγγγβα",
            "ββγγγγγββγγγγγββ",
            "γγγγγγγββγγγγγγγ",
            "γγγγγγγββγγγγγγγ",
            "γγγγγγγββγγγγγγγ",
            "γγγγγγγββγγγγγγγ",
            "γγγγγγγββγγγγγγγ",
            "ββββββββββββββββ",
            "ββββββββββββββββ",
            "γγγγγγγββγγγγγγγ",
            "γγγγγγγββγγγγγγγ",
            "γγγγγγγββγγγγγγγ",
            "γγγγγγγββγγγγγγγ",
            "γγγγγγγββγγγγγγγ",
            "ββγγγγγββγγγγγββ",
            "αβγγγγγββγγγγγβα"
        ],
        [
            "δεεεεεεεεεεεεεεδ",
            "εεεεεεεεεεεεεεεε",
            "εεεεεεεεεεεεεεεε",
            "εεεεεεεεεεεεεεεε",
            "εεεεεεεεεεεεεεεε",
            "εεεεεεεεεεεεεεεε",
            "εεεεεεεεεεεεεεεε",
            "εεεεεεεεεεεεεεεε",
            "εεεεεεεεεεεεεεεε",
            "εεεεεεεεεεεεεεεε",
            "εεεεεεεεεεεεεεεε",
            "εεεεεεεεεεεεεεεε",
            "εεεεεεεεεεεεεεεε",
            "εεεεεεεεεεεεεεεε",
            "εεεεεεεεεεεεεεεε",
            "δεεεεεεεεεεεεεεδ"
        ],
        [
            "δεεεεεεεεεεεεεεδ",
            "εεεεεεεεεεεεεεεε",
            "εεεεεεεεεεεεεεεε",
            "εεεεεεεεεεεεεεεε",
            "εεεεεεεεεεεεεεεε",
            "εεεεεεεεεεεεεεεε",
            "εεεεεεεεεεεεεεεε",
            "εεεεεεεεεεεεεεεε",
            "εεεεεεεεεεεεεεεε",
            "εεεεεεεεεεεεεεεε",
            "εεεεεεεεεεεεεεεε",
            "εεεεεεεεεεεεεεεε",
            "εεεεεεεεεεεεεεεε",
            "εεεεεεεεεεεεεεεε",
            "εεεεεεεεεεεεεεεε",
            "δεεεεεεεεεεεεεεδ"
        ],
        [
            "δεεεεεεεεεεεεεεδ",
            "εεεεεεεεεεεεεεεε",
            "εεεεεεεεεεεεεεεε",
            "εεεεεεεεεεεεεεεε",
            "εεεεεεεεεεεεεεεε",
            "εεεεεεεεεεεεεεεε",
            "εεεεεεεεεεεεεεεε",
            "εεεεεεεεεεεεεεεε",
            "εεεεεεεεεεεεεεεε",
            "εεεεεεεεεεεεεεεε",
            "εεεεεεεεεεεεεεεε",
            "εεεεεεεεεεεεεεεε",
            "εεεεεεεεεεεεεεεε",
            "εεεεεεεεεεεεεεεε",
            "εεεεεεεεεεεεεεεε",
            "δεεεεεεεεεεεεεεδ"
        ],
        [
            "δεεεεεεεεεεεεεεδ",
            "εεεεεεεεεεεεεεεε",
            "εεεεεεεεεεεεεεεε",
            "εεεεεεεεεεεεεεεε",
            "εεεεεεεεεεεεεεεε",
            "εεεεεεεεεεεεεεεε",
            "εεεεεεεεεεεεεεεε",
            "εεεεεεεεεεεεεεεε",
            "εεεεεεεεεεεεεεεε",
            "εεεεεεεεεεεεεεεε",
            "εεεεεεεεεεεεεεεε",
            "εεεεεεεεεεεεεεεε",
            "εεεεεεεεεεεεεεεε",
            "εεεεεεεεεεεεεεεε",
            "εεεεεεεεεεεεεεεε",
            "δεεεεεεεεεεεεεεδ"
        ],
        [
            "δδδδδδδδδδδδδδδδ",
            "δζζζζζζζζζζζζζζδ",
            "δζζζζζζζζζζζζζζδ",
            "δζζγγγζγγζγγγζζδ",
            "δζζγβγζγγζγβγζζδ",
            "δζζγγγζγγζγγγζζδ",
            "δζζζζζζγγζζζζζζδ",
            "δζζγγγγγγγγγγζζδ",
            "δζζγγγγγγγγγγζζδ",
            "δζζζζζζγγζζζζζζδ",
            "δζζγγγζγγζγγγζζδ",
            "δζζγβγζγγζγβγζζδ",
            "δζζγγγζγγζγγγζζδ",
            "δζζζζζζζζζζζζζζδ",
            "δζζζζζζζζζζζζζζδ",
            "δδδδδδδδδδδδδδδδ"
        ]
    ]
}