{
    "xsize": 16,
    "zsize": 16,
    "palette": {
        "palette": [
            {
                "char": " ",
                "block": "minecraft:air"
            },
            {
                "char": "α",
                "block": "betterblockz:ironslate_blockz_1"
            },
            {
                "char": "β",
                "block": "betterblockz:cyberlight_blockz_0[lit=true]"
            },
            {
                "char": "γ",
                "block": "betterblockz:cyberlight_blockz_1[lit=true]"
            },
            {
                "char": "δ",
                "block": "betterblockz:eclipse_blockz_0"
            },
            {
                "char": "ε",
                "block": "betterblockz:ironslate_blockz_3"
            },
            {
                "char": "ζ",
                "block": "minecraft:structure_void"
            },
            {
                "char": "η",
                "block": "betterblockz:tintedglass_blockz_3"
            },
            {
                "char": "θ",
                "block": "betterblockz:ironslate_blockz_6[axis=x]"
            }
        ]
    },
    "slices": [
        [
            "αααααααααααααααα",
            "αααααααααααααααα",
            "αααααααααααααααα",
            "ββββββββββββββββ",
            "γγγγγγγγγγγγγγγγ",
            "δδδδδδδδδδδδδδδδ",
            "δδδδδδδδδδδδδδδδ",
            "δδδδδδδδδδδδδδδδ",
            "δδδδδδδδδδδδδδδδ",
            "δδδδδδδδδδδδδδδδ",
            "δδδδδδδδδδδδδδδδ",
            "γγγγγγγγγγγγγγγγ",
            "ββββββββββββββββ",
            "αααααααααααααααα",
            "αααααααααααααααα",
            "αααααααααααααααα"
        ],
        [
            "εεεεεεεεεεεεεεεε",
            "ζζζζζζζζζζζζζζζζ",
            "ζζζζζζζζζζζζζζζζ",
            "ζζζζζζζζζζζζζζζζ",
            "ζζζζζζζζζζζζζζζζ",
            "ζζζζζζζζζζζζζζζζ",
            "ζζζζζζζζζζζζζζζζ",
            "ζζζζζζζζζζζζζζζζ",
            "ζζζζζζζζζζζζζζζζ",
            "ζζζζζζζζζζζζζζζζ",
            "ζζζζζζζζζζζζζζζζ",
            "ζζζζζζζζζζζζζζζζ",
            "ζζζζζζζζζζζζζζζζ",
            "ζζζζζζζζζζζζζζζζ",
            "ζζζζζζζζζζζζζζζζ",
            "εεεεεεεεεεεεεεεε"
        ],
        [
            "ηηηηηηηηηηηηηηηη",
            "ζζζζζζζζζζζζζζζζ",
            "ζζζζζζζζζζζζζζζζ",
            "ζζζζζζζζζζζζζζζζ",
            "ζζζζζζζζζζζζζζζζ",
            "ζζζζζζζζζζζζζζζζ",
            "ζζζζζζζζζζζζζζζζ",
            "ζζζζζζζζζζζζζζζζ",
            "ζζζζζζζζζζζζζζζζ",
            "ζζζζζζζζζζζζζζζζ",
            "ζζζζζζζζζζζζζζζζ",
            "ζζζζζζζζζζζζζζζζ",
            "ζζζζζζζζζζζζζζζζ",
            "ζζζζζζζζζζζζζζζζ",
            "ζζζζζζζζζζζζζζζζ",
            "ηηηηηηηηηηηηηηηη"
        ],
        [
            "ηηηηηηηηηηηηηηηη",
            "ζζζζζζζζζζζζζζζζ",
            "ζζζζζζζζζζζζζζζζ",
            "ζζζζζζζζζζζζζζζζ",
            "ζζζζζζζζζζζζζζζζ",
            "ζζζζζζζζζζζζζζζζ",
            "ζζζζζζζζζζζζζζζζ",
            "ζζζζζζζζζζζζζζζζ",
            "ζζζζζζζζζζζζζζζζ",
            "ζζζζζζζζζζζζζζζζ",
            "ζζζζζζζζζζζζζζζζ",
            "ζζζζζζζζζζζζζζζζ",
            "ζζζζζζζζζζζζζζζζ",
            "ζζζζζζζζζζζζζζζζ",
            "ζζζζζζζζζζζζζζζζ",
            "ηηηηηηηηηηηηηηηη"
        ],
        [
            "εεεεεεεεεεεεεεεε",
            "ζζζζζζζζζζζζζζζζ",
            "ζζζζζζζζζζζζζζζζ",
            "ζζζζζζζζζζζζζζζζ",
            "ζζζζζζζζζζζζζζζζ",
            "ζζζζζζζζζζζζζζζζ",
            "ζζζζζζζζζζζζζζζζ",
            "ζζζζζζζζζζζζζζζζ",
            "ζζζζζζζζζζζζζζζζ",
            "ζζζζζζζζζζζζζζζζ",
            "ζζζζζζζζζζζζζζζζ",
            "ζζζζζζζζζζζζζζζζ",
            "ζζζζζζζζζζζζζζζζ",
            "ζζζζζζζζζζζζζζζζ",
            "ζζζζζζζζζζζζζζζζ",
            "εεεεεεεεεεεεεεεε"
        ],
        [
            "αααααααααααααααα",
            "αααααααααααααααα",
            "αααααααααααααααα",
            "θθθθθθθθθθθθθθθθ",
            "θθθθθθθθθθθθθθθθ",
            "δδδδδδδδδδδδδδδδ",
            "δδδδδδδδδδδδδδδδ",
            "δδδββδδδδδδββδδδ",
            "δδδββδδδδδδββδδδ",
            "δδδδδδδδδδδδδδδδ",
            "δδδδδδδδδδδδδδδδ",
            "θθθθθθθθθθθθθθθθ",
            "θθθθθθθθθθθθθθθθ",
            "αααααααααααααααα",
            "αααααααααααααααα",
            "αααααααααααααααα"
        ]
    ]
}