{
    "xsize": 16,
    "zsize": 16,
    "palette": {
        "palette": [
            {
                "char": " ",
                "block": "minecraft:air"
            },
            {
                "char": "α",
                "block": "betterblockz:ironslate_blockz_1"
            },
            {
                "char": "β",
                "block": "betterblockz:cyberlight_blockz_0[lit=true]"
            },
            {
                "char": "γ",
                "block": "betterblockz:cyberlight_blockz_1[lit=true]"
            },
            {
                "char": "δ",
                "block": "betterblockz:eclipse_blockz_0"
            },
            {
                "char": "ε",
                "block": "betterblockz:ironslate_blockz_3"
            },
            {
                "char": "ζ",
                "block": "minecraft:structure_void"
            },
            {
                "char": "η",
                "block": "betterblockz:ironslate_blockz_19[axis=x]"
            },
            {
                "char": "θ",
                "block": "betterblockz:ironslate_blockz_7[axis=x]"
            },
            {
                "char": "ι",
                "block": "betterblockz:ironslate_blockz_7[axis=z]"
            }
        ]
    },
    "slices": [
        [
            "αααααααααααααααα",
            "αααααααααααααααα",
            "αααααααααααααααα",
            "βββααααααααααααα",
            "γγγααααααααααααα",
            "δδδααααααααααααα",
            "δδδααααααααααααα",
            "δδδααααααααααααα",
            "δδδααααααααααααα",
            "δδδααααααααααααα",
            "δδδααααααααααααα",
            "γγγααααααααααααα",
            "βββααααααααααααα",
            "αααααααααααααααα",
            "αααααααααααααααα",
            "αααααααααααααααα"
        ],
        [
            "εεεααααααααααααα",
            "ζζζααααααααααααα",
            "ζζζααααααααααααα",
            "ζζζβαααααααααααα",
            "ζζζγαααααααααααα",
            "ζζζδαααααααααααα",
            "ζζζδαααααααααααα",
            "ζζζδαααααααααααα",
            "ζζζδαααααααααααα",
            "ζζζδαααααααααααα",
            "ζζζδαααααααααααα",
            "ζζζγαααααααααααα",
            "ζζζβαααααααααααα",
            "ζζζααααααααααααα",
            "ζζζααααααααααααα",
            "εεεααααααααααααα"
        ],
        [
            "ηηεεαααααααααααα",
            "ζζζζαααααααααααα",
            "ζζζζαααααααααααα",
            "ζζζζβααααααααααα",
            "ζζζζγααααααααααα",
            "ζζζζδααααααααααα",
            "ζζζζδααααααααααα",
            "ζζζζδααααααααααα",
            "ζζζζδααααααααααα",
            "ζζζζδααααααααααα",
            "ζζζζδααααααααααα",
            "ζζζζγααααααααααα",
            "ζζζζβααααααααααα",
            "ζζζζαααααααααααα",
            "ζζζζαααααααααααα",
            "ηηεεαααααααααααα"
        ],
        [
            "ηηηεεααααααααααα",
            "ζζζζζααααααααααα",
            "ζζζζζααααααααααα",
            "ζζζζζβαααααααααα",
            "ζζζζζγαααααααααα",
            "ζζζζζδαααααααααα",
            "ζζζζζδαααααααααα",
            "ζζζζζδαααααααααα",
            "ζζζζζδαααααααααα",
            "ζζζζζδαααααααααα",
            "ζζζζζδαααααααααα",
            "ζζζζζγαααααααααα",
            "ζζζζζβαααααααααα",
            "ζζζζζααααααααααα",
            "ζζζζζααααααααααα",
            "ηηηεεααααααααααα"
        ],
        [
            "ηηηηεεαααααααααα",
            "ζζζζζζαααααααααα",
            "ζζζζζζαααααααααα",
            "ζζζζζζβααααααααα",
            "ζζζζζζγααααααααα",
            "ζζζζζζδααααααααα",
            "ζζζζζζδααααααααα",
            "ζζζζζζδααααααααα",
            "ζζζζζζδααααααααα",
            "ζζζζζζδααααααααα",
            "ζζζζζζδααααααααα",
            "ζζζζζζγααααααααα",
            "ζζζζζζβααααααααα",
            "ζζζζζζαααααααααα",
            "ζζζζζζαααααααααα",
            "ηηηηεεαααααααααα"
        ],
        [
            "εηηηηεεααααααααα",
            "ζζζζζζζααααααααα",
            "ζζζζζζζααααααααα",
            "ζζζζζζζβαααααααα",
            "ζζζζζζζγαααααααα",
            "ζζζζζζζδαααααααα",
            "ζζζζζζζδαααααααα",
            "ζζζζζζζδαααααααα",
            "ζζζζζζζδαααααααα",
            "ζζζζζζζδαααααααα",
            "ζζζζζζζδαααααααα",
            "ζζζζζζζγαααααααα",
            "ζζζζζζζβαααααααα",
            "ζζζζζζζααααααααα",
            "ζζζζζζζααααααααα",
            "εηηηηεεααααααααα"
        ],
        [
            "εεηηηηεεαααααααα",
            "εζζζζζζζαααααααα",
            "εζζζζζζζαααααααα",
            "εζζζζζζζβααααααα",
            "εζζζζζζζγααααααα",
            "εζζζζζζζδααααααα",
            "εζζζζζζζδααααααα",
            "εζζζζζζζδααααααα",
            "εζζζζζζζδααααααα",
            "εζζζζζζζδααααααα",
            "εζζζζζζζδααααααα",
            "εζζζζζζζγααααααα",
            "εζζζζζζζβααααααα",
            "εζζζζζζζαααααααα",
            "εζζζζζζζαααααααα",
            "εεηηηηεεαααααααα"
        ],
        [
            "θεεηηηηεεααααααα",
            "ιζζζζζζζζααααααα",
            "ιζζζζζζζζααααααα",
            "ιζζζζζζζζβαααααα",
            "ιζζζζζζζζγαααααα",
            "ιζζζζζζζζδαααααα",
            "ιζζζζζζζζδαααααα",
            "ιζζζζζζζζδαααααα",
            "ιζζζζζζζζδαααααα",
            "ιζζζζζζζζδαααααα",
            "ιζζζζζζζζδαααααα",
            "ιζζζζζζζζγαααααα",
            "ιζζζζζζζζβαααααα",
            "ιζζζζζζζζααααααα",
            "ιζζζζζζζζααααααα",
            "θεεηηηηεεααααααα"
        ],
        [
            "θθεεηηηηεεαααααα",
            "ιζζζζζζζζζαααααα",
            "ιζζζζζζζζζαααααα",
            "ιζζζζζζζζζβααααα",
            "ιζζζζζζζζζγααααα",
            "ιζζζζζζζζζδααααα",
            "ιζζζζζζζζζδααααα",
            "ιζζζζζζζζζδααααα",
            "ιζζζζζζζζζδααααα",
            "ιζζζζζζζζζδααααα",
            "ιζζζζζζζζζδααααα",
            "ιζζζζζζζζζγααααα",
            "ιζζζζζζζζζβααααα",
            "ιζζζζζζζζζαααααα",
            "ιζζζζζζζζζαααααα",
            "θθεεηηηηεεαααααα"
        ],
        [
            "βθθεεηηηηεεααααα",
            "βζζζζζζζζζζααααα",
            "βζζζζζζζζζζααααα",
            "βζζζζζζζζζζβαααα",
            "βζζζζζζζζζζγαααα",
            "βζζζζζζζζζζδαααα",
            "βζζζζζζζζζζδαααα",
            "βζζζζζζζζζζδαααα",
            "βζζζζζζζζζζδαααα",
            "βζζζζζζζζζζδαααα",
            "βζζζζζζζζζζδαααα",
            "βζζζζζζζζζζγαααα",
            "βζζζζζζζζζζβαααα",
            "βζζζζζζζζζζααααα",
            "βζζζζζζζζζζααααα",
            "βθθεεηηηηεεααααα"
        ],
        [
            "ββθθεεηηηηεεαααα",
            "βζζζζζζζζζζζαααα",
            "βζζζζζζζζζζζαααα",
            "βζζζζζζζζζζζβααα",
            "βζζζζζζζζζζζγααα",
            "βζζζζζζζζζζζδααα",
            "βζζζζζζζζζζζδααα",
            "βζζζζζζζζζζζδααα",
            "βζζζζζζζζζζζδααα",
            "βζζζζζζζζζζζδααα",
            "βζζζζζζζζζζζδααα",
            "βζζζζζζζζζζζγααα",
            "βζζζζζζζζζζζβααα",
            "βζζζζζζζζζζζαααα",
            "βζζζζζζζζζζζαααα",
            "ββθθεεηηηηεεαααα"
        ],
        [
            "εββθθεεηηηηεεααα",
            "εζζζζζζζζζζζζααα",
            "εζζζζζζζζζζζζααα",
            "εζζζζζζζζζζζζβαα",
            "εζζζζζζζζζζζζγαα",
            "εζζζζζζζζζζζζδαα",
            "εζζζζζζζζζζζζδαα",
            "εζζζζζζζζζζζζδαα",
            "εζζζζζζζζζζζζδαα",
            "εζζζζζζζζζζζζδαα",
            "εζζζζζζζζζζζζδαα",
            "εζζζζζζζζζζζζγαα",
            "εζζζζζζζζζζζζβαα",
            "εζζζζζζζζζζζζααα",
            "εζζζζζζζζζζζζααα",
            "εββθθεεηηηηεεααα"
        ],
        [
            "εεββθθεεηηηηεεαα",
            "εζζζζζζζζζζζζζαα",
            "δζζζζζζζζζζζζζαα",
            "δζζζζζζζζζζζζζββ",
            "δζζζζζζζζζζζζζγγ",
            "δζζζζζζζζζζζζζδδ",
            "δζζζζζζζζζζζζζδδ",
            "δζζζζζζζζζζζζζδδ",
            "δζζζζζζζζζζζζζδδ",
            "δζζζζζζζζζζζζζδδ",
            "δζζζζζζζζζζζζζδδ",
            "δζζζζζζζζζζζζζγγ",
            "δζζζζζζζζζζζζζββ",
            "δζζζζζζζζζζζζζαα",
            "εζζζζζζζζζζζζζαα",
            "εεββθθεεηηηηεεαα"
        ],
        [
            "εεεββθθεεηηηηεεε",
            "εζζζζζζζζζζζζζζζ",
            "εζζζζζζζζζζζζζζζ",
            "εζζζζζζζζζζζζζζζ",
            "εζζζζζζζζζζζζζζζ",
            "εζζζζζζζζζζζζζζζ",
            "εζζζζζζζζζζζζζζζ",
            "εζζζζζζζζζζζζζζζ",
            "εζζζζζζζζζζζζζζζ",
            "εζζζζζζζζζζζζζζζ",
            "εζζζζζζζζζζζζζζζ",
            "εζζζζζζζζζζζζζζζ",
            "εζζζζζζζζζζζζζζζ",
            "εζζζζζζζζζζζζζζζ",
            "εζζζζζζζζζζζζζζζ",
            "εεεββθθεεηηηηεεε"
        ],
        [
            "εεεεββθθεεηηηηηη",
            "εεζζζζζζζζζζζζζζ",
            "εδζζζζζζζζζζζζζζ",
            "εδζζζζζζζζζζζζζζ",
            "εδζζζζζζζζζζζζζζ",
            "εδζζζζζζζζζζζζζζ",
            "εδζζζζζζζζζζζζζζ",
            "εδζζζζζζζζζζζζζζ",
            "εδζζζζζζζζζζζζζζ",
            "εδζζζζζζζζζζζζζζ",
            "εδζζζζζζζζζζζζζζ",
            "εδζζζζζζζζζζζζζζ",
            "εδζζζζζζζζζζζζζζ",
            "εδζζζζζζζζζζζζζζ",
            "εεζζζζζζζζζζζζζζ",
            "εεεεββθθεεηηηηηη"
        ],
        [
            "εεεεεββθθεεηηηηη",
            "εεεζζζζζζζζζζζζζ",
            "εεεζζζζζζζζζζζζζ",
            "εεεζζζζζζζζζζζζζ",
            "εεεζζζζζζζζζζζζζ",
            "εεεζζζζζζζζζζζζζ",
            "εεεζζζζζζζζζζζζζ",
            "εεεζζζζζζζζζζζζζ",
            "εεεζζζζζζζζζζζζζ",
            "εεεζζζζζζζζζζζζζ",
            "εεεζζζζζζζζζζζζζ",
            "εεεζζζζζζζζζζζζζ",
            "εεεζζζζζζζζζζζζζ",
            "εεεζζζζζζζζζζζζζ",
            "εεεζζζζζζζζζζζζζ",
            "εεεεεββθθεεηηηηη"
        ],
        [
            "εεεεεεββθθεεεεεε",
            "εεεεζζζζζζζζζζζζ",
            "εεεδζζζζζζζζζζζζ",
            "εεεδζζζζζζζζζζζζ",
            "εεεδζζζζζζζζζζζζ",
            "εεεδζζζζζζζζζζζζ",
            "εεεδζζζζζζζζζζζζ",
            "εεεδζζζζζζζζζζζζ",
            "εεεδζζζζζζζζζζζζ",
            "εεεδζζζζζζζζζζζζ",
            "εεεδζζζζζζζζζζζζ",
            "εεεδζζζζζζζζζζζζ",
            "εεεδζζζζζζζζζζζζ",
            "εεεδζζζζζζζζζζζζ",
            "εεεεζζζζζζζζζζζζ",
            "εεεεεεββθθεεεεεε"
        ],
        [
            "εεεεεεεεεεεεεεεε",
            "εεεεεεεεεεεεεεεε",
            "εεεεεδδδδδδδδδδε",
            "εεεεεδδδδδδδδδδε",
            "εεεεεδδδδδδδδδδε",
            "εεεεεδδδδδδδδδδε",
            "εεεεεδδδδδδδδδδε",
            "εεεεεδδδδδδδδδδε",
            "εεεεεδδδδδδδδδδε",
            "εεεεεδδδδδδδδδδε",
            "εεεεεδδδδδδδδδδε",
            "εεεεεδδδδδδδδδδε",
            "εεεεεδδδδδδδδδδε",
            "εεεεεδδδδδδδδδδε",
            "εεεεεεεεεεεεεεεε",
            "εεεεεεεεεεεεεεεε"
        ]
    ]
}