{
    "xsize": 16,
    "zsize": 16,
    "palette": {
        "palette": [
            {
                "char": " ",
                "block": "minecraft:air"
            },
            {
                "char": "α",
                "block": "betterblockz:ironslate_blockz_1"
            },
            {
                "char": "β",
                "block": "betterblockz:cyberlight_blockz_0[lit=true]"
            },
            {
                "char": "γ",
                "block": "betterblockz:cyberlight_blockz_1[lit=true]"
            },
            {
                "char": "δ",
                "block": "betterblockz:eclipse_blockz_0"
            },
            {
                "char": "ε",
                "block": "betterblockz:ironslate_blockz_3"
            },
            {
                "char": "ζ",
                "block": "minecraft:structure_void"
            },
            {
                "char": "η",
                "block": "betterblockz:ironslate_blockz_19[axis=z]"
            },
            {
                "char": "θ",
                "block": "betterblockz:ironslate_blockz_6[axis=z]"
            }
        ]
    },
    "slices": [
        [
            "αααβγδδδδδδγβααα",
            "αααβγδδδδδδγβααα",
            "αααβγδδδδδδγβααα",
            "αααβγδδδδδδγβααα",
            "αααβγδδδδδδγβααα",
            "αααβγδδδδδδγβααα",
            "αααβγδδδδδδγβααα",
            "αααβγδδδδδδγβααα",
            "αααβγδδδδδδγβααα",
            "αααβγδδδδδδγβααα",
            "αααβγδδδδδδγβααα",
            "αααβγδδδδδδγβααα",
            "αααβγδδδδδδγβααα",
            "αααβγδδδδδδγβααα",
            "αααβγδδδδδδγβααα",
            "αααβγδδδδδδγβααα"
        ],
        [
            "εζζζζζζζζζζζζζζε",
            "εζζζζζζζζζζζζζζε",
            "εζζζζζζζζζζζζζζε",
            "εζζζζζζζζζζζζζζε",
            "εζζζζζζζζζζζζζζε",
            "εζζζζζζζζζζζζζζε",
            "εζζζζζζζζζζζζζζε",
            "εζζζζζζζζζζζζζζε",
            "εζζζζζζζζζζζζζζε",
            "εζζζζζζζζζζζζζζε",
            "εζζζζζζζζζζζζζζε",
            "εζζζζζζζζζζζζζζε",
            "εζζζζζζζζζζζζζζε",
            "εζζζζζζζζζζζζζζε",
            "εζζζζζζζζζζζζζζε",
            "εζζζζζζζζζζζζζζε"
        ],
        [
            "ηζζζζζζζζζζζζζζη",
            "ηζζζζζζζζζζζζζζη",
            "ηζζζζζζζζζζζζζζη",
            "ηζζζζζζζζζζζζζζη",
            "ηζζζζζζζζζζζζζζη",
            "ηζζζζζζζζζζζζζζη",
            "ηζζζζζζζζζζζζζζη",
            "ηζζζζζζζζζζζζζζη",
            "ηζζζζζζζζζζζζζζη",
            "ηζζζζζζζζζζζζζζη",
            "ηζζζζζζζζζζζζζζη",
            "ηζζζζζζζζζζζζζζη",
            "ηζζζζζζζζζζζζζζη",
            "ηζζζζζζζζζζζζζζη",
            "ηζζζζζζζζζζζζζζη",
            "ηζζζζζζζζζζζζζζη"
        ],
        [
            "ηζζζζζζζζζζζζζζη",
            "ηζζζζζζζζζζζζζζη",
            "ηζζζζζζζζζζζζζζη",
            "ηζζζζζζζζζζζζζζη",
            "ηζζζζζζζζζζζζζζη",
            "ηζζζζζζζζζζζζζζη",
            "ηζζζζζζζζζζζζζζη",
            "ηζζζζζζζζζζζζζζη",
            "ηζζζζζζζζζζζζζζη",
            "ηζζζζζζζζζζζζζζη",
            "ηζζζζζζζζζζζζζζη",
            "ηζζζζζζζζζζζζζζη",
            "ηζζζζζζζζζζζζζζη",
            "ηζζζζζζζζζζζζζζη",
            "ηζζζζζζζζζζζζζζη",
            "ηζζζζζζζζζζζζζζη"
        ],
        [
            "εζζζζζζζζζζζζζζε",
            "εζζζζζζζζζζζζζζε",
            "εζζζζζζζζζζζζζζε",
            "εζζζζζζζζζζζζζζε",
            "εζζζζζζζζζζζζζζε",
            "εζζζζζζζζζζζζζζε",
            "εζζζζζζζζζζζζζζε",
            "εζζζζζζζζζζζζζζε",
            "εζζζζζζζζζζζζζζε",
            "εζζζζζζζζζζζζζζε",
            "εζζζζζζζζζζζζζζε",
            "εζζζζζζζζζζζζζζε",
            "εζζζζζζζζζζζζζζε",
            "εζζζζζζζζζζζζζζε",
            "εζζζζζζζζζζζζζζε",
            "εζζζζζζζζζζζζζζε"
        ],
        [
            "αααθθδδδδδδθθααα",
            "αααθθδδδδδδθθααα",
            "αααθθδδδδδδθθααα",
            "αααθθδδββδδθθααα",
            "αααθθδδββδδθθααα",
            "αααθθδδδδδδθθααα",
            "αααθθδδδδδδθθααα",
            "αααθθδδδδδδθθααα",
            "αααθθδδδδδδθθααα",
            "αααθθδδδδδδθθααα",
            "αααθθδδδδδδθθααα",
            "αααθθδδββδδθθααα",
            "αααθθδδββδδθθααα",
            "αααθθδδδδδδθθααα",
            "αααθθδδδδδδθθααα",
            "αααθθδδδδδδθθααα"
        ]
    ]
}