{
    "xsize": 16,
    "zsize": 16,
    "palette": {
        "palette": [
            {
                "char": " ",
                "block": "minecraft:air"
            },
            {
                "char": "α",
                "block": "betterblockz:ironslate_blockz_1"
            },
            {
                "char": "β",
                "block": "betterblockz:cyberlight_blockz_0[lit=true]"
            },
            {
                "char": "γ",
                "block": "betterblockz:cyberlight_blockz_1[lit=true]"
            },
            {
                "char": "δ",
                "block": "betterblockz:eclipse_blockz_0"
            },
            {
                "char": "ε",
                "block": "betterblockz:ironslate_blockz_20[lit=true]"
            },
            {
                "char": "ζ",
                "block": "betterblockz:ironslate_blockz_3"
            },
            {
                "char": "η",
                "block": "betterblockz:jelt_blockz_15"
            },
            {
                "char": "θ",
                "block": "betterblockz:tintedglass_blockz_3"
            }
        ]
    },
    "slices": [
        [
            "αααααααααααααααα",
            "αααααααααααααααα",
            "αααααααααααααααα",
            "ββββββββββββββββ",
            "γγγγγγγγγγγγγγγγ",
            "δδδδδδδδδδδδδδδδ",
            "δδδδδδδδδδδδδδδδ",
            "δδδδδδδδδδδδδδδδ",
            "δδδδδδδδδδδδδδδδ",
            "δδδδδδδδδδδδδδδδ",
            "δδδδδδδδδδδδδδδδ",
            "γγγγγγγγγγγγγγγγ",
            "ββββββββββββββββ",
            "αααααααααααααααα",
            "αααααααααααααααα",
            "αααααααααααααααα"
        ],
        [
            "εε            εε",
            "                ",
            "                ",
            "                ",
            "                ",
            "                ",
            "                ",
            "                ",
            "                ",
            "                ",
            "                ",
            "                ",
            "                ",
            "                ",
            "                ",
            "εε            εε"
        ],
        [
            "ζε            εζ",
            "                ",
            "                ",
            "                ",
            "                ",
            "                ",
            "                ",
            "                ",
            "                ",
            "                ",
            "                ",
            "                ",
            "                ",
            "                ",
            "                ",
            "ζε            εζ"
        ],
        [
            "ζεε          εεζ",
            "                ",
            "                ",
            "                ",
            "                ",
            "                ",
            "                ",
            "                ",
            "                ",
            "                ",
            "                ",
            "                ",
            "                ",
            "                ",
            "                ",
            "ζεε          εεζ"
        ],
        [
            "ζζεεε      εεεζζ",
            "                ",
            "                ",
            "                ",
            "                ",
            "                ",
            "                ",
            "                ",
            "                ",
            "                ",
            "                ",
            "                ",
            "                ",
            "                ",
            "                ",
            "ζζεεε      εεεζζ"
        ],
        [
            "ζζζζεεεεεεεεζζζζ",
            "ζηθθθθθθθθθθθθηζ",
            "ζθηθθθθθθθθθθηθζ",
            "ζθθηθθθθθθθθηθθζ",
            "ζθθθηθθθθθθηθθθζ",
            "ζθθθθηθθθθηθθθθζ",
            "ζθθθθθηθθηθθθθθζ",
            "ζθθθθθθηηθθθθθθζ",
            "ζθθθθθθηηθθθθθθζ",
            "ζθθθθθηθθηθθθθθζ",
            "ζθθθθηθθθθηθθθθζ",
            "ζθθθηθθθθθθηθθθζ",
            "ζθθηθθθθθθθθηθθζ",
            "ζθηθθθθθθθθθθηθζ",
            "ζηθθθθθθθθθθθθηζ",
            "ζζζζεεεεεεεεζζζζ"
        ]
    ]
}