{
    "xsize": 16,
    "zsize": 16,
    "palette": {
        "palette": [
            {
                "char": " ",
                "block": "minecraft:air"
            },
            {
                "char": "α",
                "block": "betterblockz:ironslate_blockz_1"
            },
            {
                "char": "β",
                "block": "betterblockz:cyberlight_blockz_0[lit=true]"
            },
            {
                "char": "γ",
                "block": "betterblockz:cyberlight_blockz_1[lit=true]"
            },
            {
                "char": "δ",
                "block": "betterblockz:eclipse_blockz_0"
            },
            {
                "char": "ε",
                "block": "betterblockz:ironslate_blockz_3"
            },
            {
                "char": "ζ",
                "block": "minecraft:structure_void"
            },
            {
                "char": "η",
                "block": "minecraft:iron_door[facing=west,half=lower,hinge=right,open=false,powered=false]"
            },
            {
                "char": "θ",
                "block": "minecraft:ladder[facing=north,waterlogged=false]"
            },
            {
                "char": "ι",
                "block": "minecraft:iron_door[facing=east,half=lower,hinge=left,open=false,powered=false]"
            },
            {
                "char": "κ",
                "block": "betterblockz:ironslate_blockz_19[axis=x]"
            },
            {
                "char": "λ",
                "block": "minecraft:iron_door[facing=west,half=upper,hinge=right,open=false,powered=false]"
            },
            {
                "char": "μ",
                "block": "minecraft:iron_door[facing=east,half=upper,hinge=left,open=false,powered=false]"
            },
            {
                "char": "ν",
                "block": "betterblockz:ironslate_blockz_19[axis=z]"
            },
            {
                "char": "ξ",
                "block": "betterblockz:ironslate_blockz_6[axis=x]"
            }
        ]
    },
    "slices": [
        [
            "αααααααααααααααα",
            "αααααααααααααααα",
            "αααααααααααααααα",
            "ββββββββββββββββ",
            "γγγγγγγγγγγγγγγγ",
            "δδδδδδδδδδδδδδδδ",
            "δδδδδδδδδδδδδδδδ",
            "δδδδδδδδδδδδδδδδ",
            "δδδδδδδδδδδδδδδδ",
            "δδδδδδδδδδδδδδδδ",
            "δδδδδδδδδδδδδδδδ",
            "γγγγγγγγγγγγγγγγ",
            "ββββββββββββββββ",
            "αααααααααααααααα",
            "αααααααααααααααα",
            "αααααααααααααααα"
        ],
        [
            "εεεεεεεεεεεεεεεε",
            "ζζζζζζζζζζζζζζζζ",
            "ζζζζζζζζζζζζζζζζ",
            "ζζζζζζζζζζζζζζζζ",
            "ζζζζζζζζζζζζζζζζ",
            "ζζζζζζζζζζζζζζζζ",
            "ζζζζζζζζζζζζζζζζ",
            "ζζζζζζζζζζζζζζζζ",
            "ζζζζζζζζζζζζζζζζ",
            "ζζζζζζζζζζζζζζζζ",
            "ζζζζζζζζζζζζζζζζ",
            "ζζζζζζζζζζζζζζζζ",
            "ζζζζζζζζζζζζζζζζ",
            "ζζζζζζεεεεζζζζζζ",
            "ζζζζζζηθθιζζζζζζ",
            "εεεεεεεααεεεεεεε"
        ],
        [
            "κκκκκκκκκκκκκκκκ",
            "ζζζζζζζζζζζζζζζζ",
            "ζζζζζζζζζζζζζζζζ",
            "ζζζζζζζζζζζζζζζζ",
            "ζζζζζζζζζζζζζζζζ",
            "ζζζζζζζζζζζζζζζζ",
            "ζζζζζζζζζζζζζζζζ",
            "ζζζζζζζζζζζζζζζζ",
            "ζζζζζζζζζζζζζζζζ",
            "ζζζζζζζζζζζζζζζζ",
            "ζζζζζζζζζζζζζζζζ",
            "ζζζζζζζζζζζζζζζζ",
            "ζζζζζζζζζζζζζζζζ",
            "ζζζζζζκκκκζζζζζζ",
            "ζζζζζζλθθμζζζζζζ",
            "κκκκκκκαακκκκκκκ"
        ],
        [
            "κκκκκκκκκκκκκκκκ",
            "ζζζζζζζζζζζζζζζζ",
            "ζζζζζζζζζζζζζζζζ",
            "ζζζζζζζζζζζζζζζζ",
            "ζζζζζζζζζζζζζζζζ",
            "ζζζζζζζζζζζζζζζζ",
            "ζζζζζζζζζζζζζζζζ",
            "ζζζζζζζζζζζζζζζζ",
            "ζζζζζζζζζζζζζζζζ",
            "ζζζζζζζζζζζζζζζζ",
            "ζζζζζζζζζζζζζζζζ",
            "ζζζζζζζζζζζζζζζζ",
            "ζζζζζζζζζζζζζζζζ",
            "ζζζζζζκκκκζζζζζζ",
            "ζζζζζζνθθνζζζζζζ",
            "κκκκκκκαακκκκκκκ"
        ],
        [
            "εεεεεεεεεεεεεεεε",
            "ζζζζζζζζζζζζζζζζ",
            "ζζζζζζζζζζζζζζζζ",
            "ζζζζζζζζζζζζζζζζ",
            "ζζζζζζζζζζζζζζζζ",
            "ζζζζζζζζζζζζζζζζ",
            "ζζζζζζζζζζζζζζζζ",
            "ζζζζζζζζζζζζζζζζ",
            "ζζζζζζζζζζζζζζζζ",
            "ζζζζζζζζζζζζζζζζ",
            "ζζζζζζζζζζζζζζζζ",
            "ζζζζζζζζζζζζζζζζ",
            "ζζζζζζζζζζζζζζζζ",
            "ζζζζζζεεεεζζζζζζ",
            "ζζζζζζεθθεζζζζζζ",
            "εεεεεεεααεεεεεεε"
        ],
        [
            "αααααααααααααααα",
            "αααααααααααααααα",
            "αααααααααααααααα",
            "ξξξξξξξξξξξξξξξξ",
            "ξξξξξξξξξξξξξξξξ",
            "δδδδδδδδδδδδδδδδ",
            "δδδδδδδδδδδδδδδδ",
            "δδδββδδδδδδββδδδ",
            "δδδββδδδδδδββδδδ",
            "δδδδδδδδδδδδδδδδ",
            "δδδδδδδδδδδδδδδδ",
            "ξξξξξξξξξξξξξξξξ",
            "ξξξξξξξξξξξξξξξξ",
            "αααααααεεααααααα",
            "ααααααεθθεαααααα",
            "αααααααααααααααα"
        ]
    ]
}